Workbook

Sheet Como_usar
A1: RECETAS DE COSTO — PLAYMAKER (v2)
A2: Armado desde el Sistema de Costeo v2. Todo dato dice "Por confirmar" hasta que lo valides.
A4: QUÉ HACE
B5: Por cada producto calcula: COSTO DE PRODUCCIÓN + GASTOS FIJOS (como % del precio) = GANANCIA REAL, y el PRECIO MÍNIMO para no perder plata.
B6: Precio mínimo = costo de producción ÷ (1 − recargo − ganancia deseada).
A7: COLORES
B8: AZUL = lo escribes tú. GRIS = se calcula solo, no tocar. Semáforo: PIERDE (rojo) · BAJO META (amarillo) · OK (verde).
A9: LAS HOJAS
B10: Recetas — una fila por producto. Aquí ves la ganancia, el precio mínimo y qué datos faltan.
B11: Parametros — el recargo %, tu meta de ganancia y el costo de papel + tinta por metro.
B12: Gastos_Ventas — gastos fijos y ventas de los últimos 3 meses. De aquí sale el recargo.
B13: Precios — precio de cada tela y avío. Confeccion — lo que se paga al taller por prenda.
B14: Catalogo — todos los productos vendidos y cuáles ya tienen receta completa.
A15: PARA COMPLETAR UNA RECETA (en la hoja Recetas)
B16: 1) Elige la tela en la lista y escribe cuántos kg gasta una prenda (kg de la ficha de corte ÷ prendas cortadas). Si lleva malla u otra tela, usa "Tela 2".
B17: 2) Escribe los metros impresos por prenda (0 si no se sublima). 3) Elige el tipo de confección.
B18: 4) Si lleva avíos (cuello, cierre, elástico, etiqueta), suma su valor en "Otros avíos". 5) Cuando todo esté verificado, cambia el estado a "Confirmado".
B19: Para un producto nuevo, usa la primera fila vacía al final de la hoja.
A20: CADA TRIMESTRE (próximo: diciembre 2026)
B21: En Gastos_Ventas cambia los nombres de los meses y escribe los gastos y ventas de los 3 meses más recientes. El recargo y todas las recetas se actualizan solos.
A22: QUÉ CAMBIÓ RESPECTO DEL SISTEMA ANTERIOR (y del borrador v1)
B23: • Sueldos: ya no se cobran dentro de la receta y además en los gastos fijos (se contaban dos veces). Ahora todos los sueldos están en gastos de fábrica.
B24: • Camiseta Fútbol Playmaker (la más vendida): el consumo que tenía (0,161 kg) era del short. Queda en blanco hasta tener su ficha de corte.
B25: • Camiseta básquet: el consumo mezclaba camiseta y short. Ahora usa solo la camiseta (0,203 kg).
B26: • Camisetas Pro: ahora incluyen la malla (MESH) que aparece en la ficha de corte y antes no se cobraba.
B27: • Short Rugby: ahora usa la confección de short de rugby ($2.200) y no la de fútbol ($1.700).
B28: • Estampado ya no se cobra a todas las prendas por defecto.
A29: PENDIENTES QUE AFECTAN LOS RESULTADOS
B30: ="• Papel y tinta: "&IF(Parametros!$B$27=0,"SIN DATO → las prendas sublimadas salen más baratas de lo real.","ingresado ("&TEXT(Parametros!$B$27,"$#,##0")&" por metro).") -> • Papel y tinta: SIN DATO → las prendas sublimadas salen más baratas de lo real.
B31: ="• Recetas completas: "&COUNTIF(Catalogo!F6:F200,"Completa")&" · con datos faltantes: "&COUNTIF(Catalogo!F6:F200,"Faltan datos") -> • Recetas completas: 6 · con datos faltantes: 68
B32: ="• Precios por confirmar: "&(COUNTIF(Precios!E5:E200,"Por confirmar")+COUNTIF(Confeccion!D5:D200,"Por confirmar"))&" · telas sin precio: "&COUNTIF(Precios!E5:E200,"SIN PRECIO") -> • Precios por confirmar: 88 · telas sin precio: 1
B33: • Gastos: el archivo original trae un solo mes; se repitió en los 3 meses. Reemplazar con el gasto real.
B34: • Consumos de tela: casi todos vienen de 1 solo corte. Cada ficha de corte nueva los hace más confiables.

Sheet Recetas
A1: RECETAS — costo de producción, gastos y ganancia por prenda
A2: Una fila = un producto. Llena solo las columnas azules (E a M). Todo lo gris se calcula solo. Fuente de datos iniciales: Sistema de Costeo v2.
A3: ="Recargo usado: "&TEXT(Parametros!$B$14,"0.0%")&" del precio (fábrica "&TEXT(Parametros!$B$12,"0.0%")&" + comercial "&TEXT(Parametros!$B$13,"0.0%")&") · Meta de ganancia: "&TEXT(Parametros!$B$18,"0%")&" · Impresión: "&IF(Parametros!$B$27=0,"SIN COSTO (pendiente)",TEXT(Parametros!$B$27,"$#,##0")&" por metro") -> Recargo usado: 48.0% del precio (fábrica 35.3% + comercial 12.7%) · Meta de ganancia: 10% · Impresión: SIN COSTO (pendiente)
A4: PRODUCTO | E4: DATOS DE LA RECETA (los llenas tú) | O4: COSTO DE PRODUCCIÓN ($ por prenda) | T4: RESULTADO AL PRECIO ACTUAL
A5: Código | B5: Producto | C5: Tipo | D5: Unid. vendidas jun–sep | E5: Precio venta neto ($) | F5: Tela principal | G5: Kg tela por prenda | H5: Tela 2 (malla, etc.) | I5: Kg tela 2 por prenda | J5: Metros impresos por prenda | K5: Confección (tipo) | L5: Otros avíos ($ por prenda) | M5: Estado del dato | N5: Notas | O5: $ Telas | P5: $ Papel y tinta | Q5: $ Confección | R5: $ Avíos | S5: COSTO DE PRODUCCIÓN | T5: Gastos de fábrica | U5: Gastos comerciales | V5: GANANCIA ($) | W5: GANANCIA (%) | X5: Precio mínimo (sin perder) | Y5: Precio mínimo (con meta) | Z5: Semáforo | AA5: Qué falta
A6: FUTCSUBMC | B6: Camiseta Fútbol Playmaker, m/c | C6: Juego | D6: 198 | E6: 15994 | F6: CIRE BLANCO | K6: Camiseta De Futbol | M6: Por confirmar | N6: FALTA CONSUMO: el sistema anterior usaba 0,161 kg pero ese dato es del SHORT (OT 2547 y 2588). Hacer ficha de corte de camiseta adulto. | O6: =IF(B6="","",IFERROR(G6*INDEX(Precios!$D$5:$D$120,MATCH(F6,Precios!$A$5:$A$120,0)),0)+IF(H6="",0,IFERROR(I6*INDEX(Precios!$D$5:$D$120,MATCH(H6,Precios!$A$5:$A$120,0)),0))) -> 0 | P6: =IF(B6="","",N(J6)*Parametros!$B$27) -> 0 | Q6: =IF(B6="","",IFERROR(INDEX(Confeccion!$B$5:$B$100,MATCH(K6,Confeccion!$A$5:$A$100,0)),0)) -> 2000 | R6: =IF(B6="","",N(L6)) -> 0 | S6: =IF(B6="","",IF(AND(F6<>"",ISNUMBER(G6),ISNUMBER(IFERROR(INDEX(Precios!$D$5:$D$120,MATCH(F6,Precios!$A$5:$A$120,0)),"x")),OR(H6="",ISNUMBER(IFERROR(INDEX(Precios!$D$5:$D$120,MATCH(H6,Precios!$A$5:$A$120,0)),"x"))),J6<>"",K6<>"",Q6>0),SUM(O6:R6),"")) | T6: =IF(AND(S6<>"",ISNUMBER(E6)),E6*Parametros!$B$12,"") | U6: =IF(AND(S6<>"",ISNUMBER(E6)),E6*Parametros!$B$13,"") | V6: =IF(AND(S6<>"",ISNUMBER(E6)),E6-S6-T6-U6,"") | W6: =IF(AND(S6<>"",ISNUMBER(E6)),V6/E6,"") | X6: =IF(OR(S6="",Parametros!$B$14>=1),"",S6/(1-Parametros!$B$14)) | Y6: =IF(OR(S6="",Parametros!$B$14+Parametros!$B$18>=1),"",S6/(1-Parametros!$B$14-Parametros!$B$18)) | Z6: =IF(B6="","",IF(S6="","FALTAN DATOS",IF(NOT(ISNUMBER(E6)),"FALTA PRECIO",IF(V6<0,"PIERDE",IF(W6<Parametros!$B$18,"BAJO META","OK"))))) -> FALTAN DATOS | AA6: =IF(B6="","",IF(F6="","Tela. ","")&IF(NOT(ISNUMBER(G6)),"Kg de tela. ","")&IF(AND(F6<>"",NOT(ISNUMBER(IFERROR(INDEX(Precios!$D$5:$D$120,MATCH(F6,Precios!$A$5:$A$120,0)),"x")))),"Tela sin precio. ","")&IF(AND(H6<>"",NOT(ISNUMBER(IFERROR(INDEX(Precios!$D$5:$D$120,MATCH(H6,Precios!$A$5:$A$120,0)),"x")))),"Tela 2 sin precio. ","")&IF(J6="","Metros impresos. ","")&IF(AND(N(J6)>0,Parametros!$B$27=0),"Impresión sin costo. ","")&IF(K6="","Confección. ",IF(Q6=0,"Confección sin valor. ",""))&IF(NOT(ISNUMBER(E6)),"Precio de venta. ","")) -> Kg de tela. Metros impresos.
A7: FUTCSUBREDMC | B7: Camiseta Fútbol Playmaker Cuello Redondo m/c | C7: Juego | D7: 190 | E7: 16073 | F7: CIRE BLANCO | K7: Camiseta De Futbol | M7: Por confirmar | N7: FALTA CONSUMO (ver Camiseta Fútbol Playmaker m/c). | O7: =IF(B7="","",IFERROR(G7*INDEX(Precios!$D$5:$D$120,MATCH(F7,Precios!$A$5:$A$120,0)),0)+IF(H7="",0,IFERROR(I7*INDEX(Precios!$D$5:$D$120,MATCH(H7,Precios!$A$5:$A$120,0)),0))) -> 0 | P7: =IF(B7="","",N(J7)*Parametros!$B$27) -> 0 | Q7: =IF(B7="","",IFERROR(INDEX(Confeccion!$B$5:$B$100,MATCH(K7,Confeccion!$A$5:$A$100,0)),0)) -> 2000 | R7: =IF(B7="","",N(L7)) -> 0 | S7: =IF(B7="","",IF(AND(F7<>"",ISNUMBER(G7),ISNUMBER(IFERROR(INDEX(Precios!$D$5:$D$120,MATCH(F7,Precios!$A$5:$A$120,0)),"x")),OR(H7="",ISNUMBER(IFERROR(INDEX(Precios!$D$5:$D$120,MATCH(H7,Precios!$A$5:$A$120,0)),"x"))),J7<>"",K7<>"",Q7>0),SUM(O7:R7),"")) | T7: =IF(AND(S7<>"",ISNUMBER(E7)),E7*Parametros!$B$12,"") | U7: =IF(AND(S7<>"",ISNUMBER(E7)),E7*Parametros!$B$13,"") | V7: =IF(AND(S7<>"",ISNUMBER(E7)),E7-S7-T7-U7,"") | W7: =IF(AND(S7<>"",ISNUMBER(E7)),V7/E7,"") | X7: =IF(OR(S7="",Parametros!$B$14>=1),"",S7/(1-Parametros!$B$14)) | Y7: =IF(OR(S7="",Parametros!$B$14+Parametros!$B$18>=1),"",S7/(1-Parametros!$B$14-Parametros!$B$18)) | Z7: =IF(B7="","",IF(S7="","FALTAN DATOS",IF(NOT(ISNUMBER(E7)),"FALTA PRECIO",IF(V7<0,"PIERDE",IF(W7<Parametros!$B$18,"BAJO META","OK"))))) -> FALTAN DATOS | AA7: =IF(B7="","",IF(F7="","Tela. ","")&IF(NOT(ISNUMBER(G7)),"Kg de tela. ","")&IF(AND(F7<>"",NOT(ISNUMBER(IFERROR(INDEX(Precios!$D$5:$D$120,MATCH(F7,Precios!$A$5:$A$120,0)),"x")))),"Tela sin precio. ","")&IF(AND(H7<>"",NOT(ISNUMBER(IFERROR(INDEX(Precios!$D$5:$D$120,MATCH(H7,Precios!$A$5:$A$120,0)),"x")))),"Tela 2 sin precio. ","")&IF(J7="","Metros impresos. ","")&IF(AND(N(J7)>0,Parametros!$B$27=0),"Impresión sin costo. ","")&IF(K7="","Confección. ",IF(Q7=0,"Confección sin valor. ",""))&IF(NOT(ISNUMBER(E7)),"Precio de venta. ","")) -> Kg de tela. Metros impresos.
A8: FUTCSUBPROREDMC | B8: Camiseta Fútbol Pro Playmaker Cuello Redondo m/c | C8: Juego | D8: 160 | E8: 18403 | F8: MONTESIMONE TRAINING (fut pro) | G8: 0.12 | H8: MESH | I8: 0.0775 | J8: 1.9 | K8: Camiseta De Futbol | M8: Por confirmar | N8: Ficha OT 2547 (20 prendas masc.). Femenino dio 0,1225 kg (OT 2257). Metros: la ficha dice 1,9 (38 m / 20), la receta anterior 1,2 y la hoja de reprocesos 1,125 → confirmar. | O8: =IF(B8="","",IFERROR(G8*INDEX(Precios!$D$5:$D$120,MATCH(F8,Precios!$A$5:$A$120,0)),0)+IF(H8="",0,IFERROR(I8*INDEX(Precios!$D$5:$D$120,MATCH(H8,Precios!$A$5:$A$120,0)),0))) -> 1020.47 | P8: =IF(B8="","",N(J8)*Parametros!$B$27) -> 0 | Q8: =IF(B8="","",IFERROR(INDEX(Confeccion!$B$5:$B$100,MATCH(K8,Confeccion!$A$5:$A$100,0)),0)) -> 2000 | R8: =IF(B8="","",N(L8)) -> 0 | S8: =IF(B8="","",IF(AND(F8<>"",ISNUMBER(G8),ISNUMBER(IFERROR(INDEX(Precios!$D$5:$D$120,MATCH(F8,Precios!$A$5:$A$120,0)),"x")),OR(H8="",ISNUMBER(IFERROR(INDEX(Precios!$D$5:$D$120,MATCH(H8,Precios!$A$5:$A$120,0)),"x"))),J8<>"",K8<>"",Q8>0),SUM(O8:R8),"")) -> 3020.47 | T8: =IF(AND(S8<>"",ISNUMBER(E8)),E8*Parametros!$B$12,"") -> 6495.2752 | U8: =IF(AND(S8<>"",ISNUMBER(E8)),E8*Parametros!$B$13,"") -> 2331.5946 | V8: =IF(AND(S8<>"",ISNUMBER(E8)),E8-S8-T8-U8,"") -> 6555.6601 | W8: =IF(AND(S8<>"",ISNUMBER(E8)),V8/E8,"") -> 0.3562278 | X8: =IF(OR(S8="",Parametros!$B$14>=1),"",S8/(1-Parametros!$B$14)) -> 5804.6109 | Y8: =IF(OR(S8="",Parametros!$B$14+Parametros!$B$18>=1),"",S8/(1-Parametros!$B$14-Parametros!$B$18)) -> 7185.4873 | Z8: =IF(B8="","",IF(S8="","FALTAN DATOS",IF(NOT(ISNUMBER(E8)),"FALTA PRECIO",IF(V8<0,"PIERDE",IF(W8<Parametros!$B$18,"BAJO META","OK"))))) -> OK | AA8: =IF(B8="","",IF(F8="","Tela. ","")&IF(NOT(ISNUMBER(G8)),"Kg de tela. ","")&IF(AND(F8<>"",NOT(ISNUMBER(IFERROR(INDEX(Precios!$D$5:$D$120,MATCH(F8,Precios!$A$5:$A$120,0)),"x")))),"Tela sin precio. ","")&IF(AND(H8<>"",NOT(ISNUMBER(IFERROR(INDEX(Precios!$D$5:$D$120,MATCH(H8,Precios!$A$5:$A$120,0)),"x")))),"Tela 2 sin precio. ","")&IF(J8="","Metros impresos. ","")&IF(AND(N(J8)>0,Parametros!$B$27=0),"Impresión sin costo. ","")&IF(K8="","Confección. ",IF(Q8=0,"Confección sin valor. ",""))&IF(NOT(ISNUMBER(E8)),"Precio de venta. ","")) -> Impresión sin costo.
A9: VOLMASC-CSUB-V-MC | B9: Camiseta Voley fem Playmaker, V m/c | C9: Juego | D9: 139 | E9: 17563 | K9: Camiseta Voley | M9: Por confirmar | N9: Confección sugerida por el nombre: confirmar. | O9: =IF(B9="","",IFERROR(G9*INDEX(Precios!$D$5:$D$120,MATCH(F9,Precios!$A$5:$A$120,0)),0)+IF(H9="",0,IFERROR(I9*INDEX(Precios!$D$5:$D$120,MATCH(H9,Precios!$A$5:$A$120,0)),0))) -> 0 | P9: =IF(B9="","",N(J9)*Parametros!$B$27) -> 0 | Q9: =IF(B9="","",IFERROR(INDEX(Confeccion!$B$5:$B$100,MATCH(K9,Confeccion!$A$5:$A$100,0)),0)) -> 1700 | R9: =IF(B9="","",N(L9)) -> 0 | S9: =IF(B9="","",IF(AND(F9<>"",ISNUMBER(G9),ISNUMBER(IFERROR(INDEX(Precios!$D$5:$D$120,MATCH(F9,Precios!$A$5:$A$120,0)),"x")),OR(H9="",ISNUMBER(IFERROR(INDEX(Precios!$D$5:$D$120,MATCH(H9,Precios!$A$5:$A$120,0)),"x"))),J9<>"",K9<>"",Q9>0),SUM(O9:R9),"")) | T9: =IF(AND(S9<>"",ISNUMBER(E9)),E9*Parametros!$B$12,"") | U9: =IF(AND(S9<>"",ISNUMBER(E9)),E9*Parametros!$B$13,"") | V9: =IF(AND(S9<>"",ISNUMBER(E9)),E9-S9-T9-U9,"") | W9: =IF(AND(S9<>"",ISNUMBER(E9)),V9/E9,"") | X9: =IF(OR(S9="",Parametros!$B$14>=1),"",S9/(1-Parametros!$B$14)) | Y9: =IF(OR(S9="",Parametros!$B$14+Parametros!$B$18>=1),"",S9/(1-Parametros!$B$14-Parametros!$B$18)) | Z9: =IF(B9="","",IF(S9="","FALTAN DATOS",IF(NOT(ISNUMBER(E9)),"FALTA PRECIO",IF(V9<0,"PIERDE",IF(W9<Parametros!$B$18,"BAJO META","OK"))))) -> FALTAN DATOS | AA9: =IF(B9="","",IF(F9="","Tela. ","")&IF(NOT(ISNUMBER(G9)),"Kg de tela. ","")&IF(AND(F9<>"",NOT(ISNUMBER(IFERROR(INDEX(Precios!$D$5:$D$120,MATCH(F9,Precios!$A$5:$A$120,0)),"x")))),"Tela sin precio. ","")&IF(AND(H9<>"",NOT(ISNUMBER(IFERROR(INDEX(Precios!$D$5:$D$120,MATCH(H9,Precios!$A$5:$A$120,0)),"x")))),"Tela 2 sin precio. ","")&IF(J9="","Metros impresos. ","")&IF(AND(N(J9)>0,Parametros!$B$27=0),"Impresión sin costo. ","")&IF(K9="","Confección. ",IF(Q9=0,"Confección sin valor. ",""))&IF(NOT(ISNUMBER(E9)),"Precio de venta. ","")) -> Tela. Kg de tela. Metros impresos.
A10: FUTCSUBPROMC | B10: Camiseta Fútbol Pro Playmaker, m/c | C10: Juego | D10: 109 | E10: 18403 | F10: MONTESIMONE TRAINING (fut pro) | G10: 0.12 | H10: MESH | I10: 0.0775 | J10: 1.9 | K10: Camiseta De Futbol | M10: Por confirmar | N10: Igual que Pro cuello redondo (OT 2547). Confirmar metros impresos. | O10: =IF(B10="","",IFERROR(G10*INDEX(Precios!$D$5:$D$120,MATCH(F10,Precios!$A$5:$A$120,0)),0)+IF(H10="",0,IFERROR(I10*INDEX(Precios!$D$5:$D$120,MATCH(H10,Precios!$A$5:$A$120,0)),0))) -> 1020.47 | P10: =IF(B10="","",N(J10)*Parametros!$B$27) -> 0 | Q10: =IF(B10="","",IFERROR(INDEX(Confeccion!$B$5:$B$100,MATCH(K10,Confeccion!$A$5:$A$100,0)),0)) -> 2000 | R10: =IF(B10="","",N(L10)) -> 0 | S10: =IF(B10="","",IF(AND(F10<>"",ISNUMBER(G10),ISNUMBER(IFERROR(INDEX(Precios!$D$5:$D$120,MATCH(F10,Precios!$A$5:$A$120,0)),"x")),OR(H10="",ISNUMBER(IFERROR(INDEX(Precios!$D$5:$D$120,MATCH(H10,Precios!$A$5:$A$120,0)),"x"))),J10<>"",K10<>"",Q10>0),SUM(O10:R10),"")) -> 3020.47 | T10: =IF(AND(S10<>"",ISNUMBER(E10)),E10*Parametros!$B$12,"") -> 6495.2752 | U10: =IF(AND(S10<>"",ISNUMBER(E10)),E10*Parametros!$B$13,"") -> 2331.5946 | V10: =IF(AND(S10<>"",ISNUMBER(E10)),E10-S10-T10-U10,"") -> 6555.6601 | W10: =IF(AND(S10<>"",ISNUMBER(E10)),V10/E10,"") -> 0.3562278 | X10: =IF(OR(S10="",Parametros!$B$14>=1),"",S10/(1-Parametros!$B$14)) -> 5804.6109 | Y10: =IF(OR(S10="",Parametros!$B$14+Parametros!$B$18>=1),"",S10/(1-Parametros!$B$14-Parametros!$B$18)) -> 7185.4873 | Z10: =IF(B10="","",IF(S10="","FALTAN DATOS",IF(NOT(ISNUMBER(E10)),"FALTA PRECIO",IF(V10<0,"PIERDE",IF(W10<Parametros!$B$18,"BAJO META","OK"))))) -> OK | AA10: =IF(B10="","",IF(F10="","Tela. ","")&IF(NOT(ISNUMBER(G10)),"Kg de tela. ","")&IF(AND(F10<>"",NOT(ISNUMBER(IFERROR(INDEX(Precios!$D$5:$D$120,MATCH(F10,Precios!$A$5:$A$120,0)),"x")))),"Tela sin precio. ","")&IF(AND(H10<>"",NOT(ISNUMBER(IFERROR(INDEX(Precios!$D$5:$D$120,MATCH(H10,Precios!$A$5:$A$120,0)),"x")))),"Tela 2 sin precio. ","")&IF(J10="","Metros impresos. ","")&IF(AND(N(J10)>0,Parametros!$B$27=0),"Impresión sin costo. ","")&IF(K10="","Confección. ",IF(Q10=0,"Confección sin valor. ",""))&IF(NOT(ISNUMBER(E10)),"Precio de venta. ","")) -> Impresión sin costo.
A11: FUTCSUBMC-V | B11: Camiseta Fútbol Playmaker, V m/c | C11: Juego | D11: 109 | E11: 16589 | F11: CIRE BLANCO | K11: Camiseta De Futbol | M11: Por confirmar | N11: FALTA CONSUMO (ver Camiseta Fútbol Playmaker m/c). | O11: =IF(B11="","",IFERROR(G11*INDEX(Precios!$D$5:$D$120,MATCH(F11,Precios!$A$5:$A$120,0)),0)+IF(H11="",0,IFERROR(I11*INDEX(Precios!$D$5:$D$120,MATCH(H11,Precios!$A$5:$A$120,0)),0))) -> 0 | P11: =IF(B11="","",N(J11)*Parametros!$B$27) -> 0 | Q11: =IF(B11="","",IFERROR(INDEX(Confeccion!$B$5:$B$100,MATCH(K11,Confeccion!$A$5:$A$100,0)),0)) -> 2000 | R11: =IF(B11="","",N(L11)) -> 0 | S11: =IF(B11="","",IF(AND(F11<>"",ISNUMBER(G11),ISNUMBER(IFERROR(INDEX(Precios!$D$5:$D$120,MATCH(F11,Precios!$A$5:$A$120,0)),"x")),OR(H11="",ISNUMBER(IFERROR(INDEX(Precios!$D$5:$D$120,MATCH(H11,Precios!$A$5:$A$120,0)),"x"))),J11<>"",K11<>"",Q11>0),SUM(O11:R11),"")) | T11: =IF(AND(S11<>"",ISNUMBER(E11)),E11*Parametros!$B$12,"") | U11: =IF(AND(S11<>"",ISNUMBER(E11)),E11*Parametros!$B$13,"") | V11: =IF(AND(S11<>"",ISNUMBER(E11)),E11-S11-T11-U11,"") | W11: =IF(AND(S11<>"",ISNUMBER(E11)),V11/E11,"") | X11: =IF(OR(S11="",Parametros!$B$14>=1),"",S11/(1-Parametros!$B$14)) | Y11: =IF(OR(S11="",Parametros!$B$14+Parametros!$B$18>=1),"",S11/(1-Parametros!$B$14-Parametros!$B$18)) | Z11: =IF(B11="","",IF(S11="","FALTAN DATOS",IF(NOT(ISNUMBER(E11)),"FALTA PRECIO",IF(V11<0,"PIERDE",IF(W11<Parametros!$B$18,"BAJO META","OK"))))) -> FALTAN DATOS | AA11: =IF(B11="","",IF(F11="","Tela. ","")&IF(NOT(ISNUMBER(G11)),"Kg de tela. ","")&IF(AND(F11<>"",NOT(ISNUMBER(IFERROR(INDEX(Precios!$D$5:$D$120,MATCH(F11,Precios!$A$5:$A$120,0)),"x")))),"Tela sin precio. ","")&IF(AND(H11<>"",NOT(ISNUMBER(IFERROR(INDEX(Precios!$D$5:$D$120,MATCH(H11,Precios!$A$5:$A$120,0)),"x")))),"Tela 2 sin precio. ","")&IF(J11="","Metros impresos. ","")&IF(AND(N(J11)>0,Parametros!$B$27=0),"Impresión sin costo. ","")&IF(K11="","Confección. ",IF(Q11=0,"Confección sin valor. ",""))&IF(NOT(ISNUMBER(E11)),"Precio de venta. ","")) -> Kg de tela. Metros impresos.
A12: SALPOLPRESLISA | B12: Polera de Presentación Lisa | C12: Salida | D12: 109 | E12: 17004 | M12: Por confirmar | O12: =IF(B12="","",IFERROR(G12*INDEX(Precios!$D$5:$D$120,MATCH(F12,Precios!$A$5:$A$120,0)),0)+IF(H12="",0,IFERROR(I12*INDEX(Precios!$D$5:$D$120,MATCH(H12,Precios!$A$5:$A$120,0)),0))) -> 0 | P12: =IF(B12="","",N(J12)*Parametros!$B$27) -> 0 | Q12: =IF(B12="","",IFERROR(INDEX(Confeccion!$B$5:$B$100,MATCH(K12,Confeccion!$A$5:$A$100,0)),0)) -> 0 | R12: =IF(B12="","",N(L12)) -> 0 | S12: =IF(B12="","",IF(AND(F12<>"",ISNUMBER(G12),ISNUMBER(IFERROR(INDEX(Precios!$D$5:$D$120,MATCH(F12,Precios!$A$5:$A$120,0)),"x")),OR(H12="",ISNUMBER(IFERROR(INDEX(Precios!$D$5:$D$120,MATCH(H12,Precios!$A$5:$A$120,0)),"x"))),J12<>"",K12<>"",Q12>0),SUM(O12:R12),"")) | T12: =IF(AND(S12<>"",ISNUMBER(E12)),E12*Parametros!$B$12,"") | U12: =IF(AND(S12<>"",ISNUMBER(E12)),E12*Parametros!$B$13,"") | V12: =IF(AND(S12<>"",ISNUMBER(E12)),E12-S12-T12-U12,"") | W12: =IF(AND(S12<>"",ISNUMBER(E12)),V12/E12,"") | X12: =IF(OR(S12="",Parametros!$B$14>=1),"",S12/(1-Parametros!$B$14)) | Y12: =IF(OR(S12="",Parametros!$B$14+Parametros!$B$18>=1),"",S12/(1-Parametros!$B$14-Parametros!$B$18)) | Z12: =IF(B12="","",IF(S12="","FALTAN DATOS",IF(NOT(ISNUMBER(E12)),"FALTA PRECIO",IF(V12<0,"PIERDE",IF(W12<Parametros!$B$18,"BAJO META","OK"))))) -> FALTAN DATOS | AA12: =IF(B12="","",IF(F12="","Tela. ","")&IF(NOT(ISNUMBER(G12)),"Kg de tela. ","")&IF(AND(F12<>"",NOT(ISNUMBER(IFERROR(INDEX(Precios!$D$5:$D$120,MATCH(F12,Precios!$A$5:$A$120,0)),"x")))),"Tela sin precio. ","")&IF(AND(H12<>"",NOT(ISNUMBER(IFERROR(INDEX(Precios!$D$5:$D$120,MATCH(H12,Precios!$A$5:$A$120,0)),"x")))),"Tela 2 sin precio. ","")&IF(J12="","Metros impresos. ","")&IF(AND(N(J12)>0,Parametros!$B$27=0),"Impresión sin costo. ","")&IF(K12="","Confección. ",IF(Q12=0,"Confección sin valor. ",""))&IF(NOT(ISNUMBER(E12)),"Precio de venta. ","")) -> Tela. Kg de tela. Metros impresos. Confección.
A13: CSUBRUGSFROSA | B13: CAMISETA DE RUGBY STADE FRANCAIS ANIVERSARIO (ROSADA) | C13: Juego | D13: 100 | E13: 25714 | M13: Por confirmar | O13: =IF(B13="","",IFERROR(G13*INDEX(Precios!$D$5:$D$120,MATCH(F13,Precios!$A$5:$A$120,0)),0)+IF(H13="",0,IFERROR(I13*INDEX(Precios!$D$5:$D$120,MATCH(H13,Precios!$A$5:$A$120,0)),0))) -> 0 | P13: =IF(B13="","",N(J13)*Parametros!$B$27) -> 0 | Q13: =IF(B13="","",IFERROR(INDEX(Confeccion!$B$5:$B$100,MATCH(K13,Confeccion!$A$5:$A$100,0)),0)) -> 0 | R13: =IF(B13="","",N(L13)) -> 0 | S13: =IF(B13="","",IF(AND(F13<>"",ISNUMBER(G13),ISNUMBER(IFERROR(INDEX(Precios!$D$5:$D$120,MATCH(F13,Precios!$A$5:$A$120,0)),"x")),OR(H13="",ISNUMBER(IFERROR(INDEX(Precios!$D$5:$D$120,MATCH(H13,Precios!$A$5:$A$120,0)),"x"))),J13<>"",K13<>"",Q13>0),SUM(O13:R13),"")) | T13: =IF(AND(S13<>"",ISNUMBER(E13)),E13*Parametros!$B$12,"") | U13: =IF(AND(S13<>"",ISNUMBER(E13)),E13*Parametros!$B$13,"") | V13: =IF(AND(S13<>"",ISNUMBER(E13)),E13-S13-T13-U13,"") | W13: =IF(AND(S13<>"",ISNUMBER(E13)),V13/E13,"") | X13: =IF(OR(S13="",Parametros!$B$14>=1),"",S13/(1-Parametros!$B$14)) | Y13: =IF(OR(S13="",Parametros!$B$14+Parametros!$B$18>=1),"",S13/(1-Parametros!$B$14-Parametros!$B$18)) | Z13: =IF(B13="","",IF(S13="","FALTAN DATOS",IF(NOT(ISNUMBER(E13)),"FALTA PRECIO",IF(V13<0,"PIERDE",IF(W13<Parametros!$B$18,"BAJO META","OK"))))) -> FALTAN DATOS | AA13: =IF(B13="","",IF(F13="","Tela. ","")&IF(NOT(ISNUMBER(G13)),"Kg de tela. ","")&IF(AND(F13<>"",NOT(ISNUMBER(IFERROR(INDEX(Precios!$D$5:$D$120,MATCH(F13,Precios!$A$5:$A$120,0)),"x")))),"Tela sin precio. ","")&IF(AND(H13<>"",NOT(ISNUMBER(IFERROR(INDEX(Precios!$D$5:$D$120,MATCH(H13,Precios!$A$5:$A$120,0)),"x")))),"Tela 2 sin precio. ","")&IF(J13="","Metros impresos. ","")&IF(AND(N(J13)>0,Parametros!$B$27=0),"Impresión sin costo. ","")&IF(K13="","Confección. ",IF(Q13=0,"Confección sin valor. ",""))&IF(NOT(ISNUMBER(E13)),"Precio de venta. ","")) -> Tela. Kg de tela. Metros impresos. Confección.
A14: SAL-PLA-SUB-MC | B14: Polera de presentación Sublim m/c | C14: Salida | D14: 99 | E14: 18729 | M14: Por confirmar | O14: =IF(B14="","",IFERROR(G14*INDEX(Precios!$D$5:$D$120,MATCH(F14,Precios!$A$5:$A$120,0)),0)+IF(H14="",0,IFERROR(I14*INDEX(Precios!$D$5:$D$120,MATCH(H14,Precios!$A$5:$A$120,0)),0))) -> 0 | P14: =IF(B14="","",N(J14)*Parametros!$B$27) -> 0 | Q14: =IF(B14="","",IFERROR(INDEX(Confeccion!$B$5:$B$100,MATCH(K14,Confeccion!$A$5:$A$100,0)),0)) -> 0 | R14: =IF(B14="","",N(L14)) -> 0 | S14: =IF(B14="","",IF(AND(F14<>"",ISNUMBER(G14),ISNUMBER(IFERROR(INDEX(Precios!$D$5:$D$120,MATCH(F14,Precios!$A$5:$A$120,0)),"x")),OR(H14="",ISNUMBER(IFERROR(INDEX(Precios!$D$5:$D$120,MATCH(H14,Precios!$A$5:$A$120,0)),"x"))),J14<>"",K14<>"",Q14>0),SUM(O14:R14),"")) | T14: =IF(AND(S14<>"",ISNUMBER(E14)),E14*Parametros!$B$12,"") | U14: =IF(AND(S14<>"",ISNUMBER(E14)),E14*Parametros!$B$13,"") | V14: =IF(AND(S14<>"",ISNUMBER(E14)),E14-S14-T14-U14,"") | W14: =IF(AND(S14<>"",ISNUMBER(E14)),V14/E14,"") | X14: =IF(OR(S14="",Parametros!$B$14>=1),"",S14/(1-Parametros!$B$14)) | Y14: =IF(OR(S14="",Parametros!$B$14+Parametros!$B$18>=1),"",S14/(1-Parametros!$B$14-Parametros!$B$18)) | Z14: =IF(B14="","",IF(S14="","FALTAN DATOS",IF(NOT(ISNUMBER(E14)),"FALTA PRECIO",IF(V14<0,"PIERDE",IF(W14<Parametros!$B$18,"BAJO META","OK"))))) -> FALTAN DATOS | AA14: =IF(B14="","",IF(F14="","Tela. ","")&IF(NOT(ISNUMBER(G14)),"Kg de tela. ","")&IF(AND(F14<>"",NOT(ISNUMBER(IFERROR(INDEX(Precios!$D$5:$D$120,MATCH(F14,Precios!$A$5:$A$120,0)),"x")))),"Tela sin precio. ","")&IF(AND(H14<>"",NOT(ISNUMBER(IFERROR(INDEX(Precios!$D$5:$D$120,MATCH(H14,Precios!$A$5:$A$120,0)),"x")))),"Tela 2 sin precio. ","")&IF(J14="","Metros impresos. ","")&IF(AND(N(J14)>0,Parametros!$B$27=0),"Impresión sin costo. ","")&IF(K14="","Confección. ",IF(Q14=0,"Confección sin valor. ",""))&IF(NOT(ISNUMBER(E14)),"Precio de venta. ","")) -> Tela. Kg de tela. Metros impresos. Confección.
A15: POL-CSUB-POL-MC | B15: Polera Playmaker, Cuello Redondo m/c | C15: Juego | D15: 96 | E15: 15588 | M15: Por confirmar | O15: =IF(B15="","",IFERROR(G15*INDEX(Precios!$D$5:$D$120,MATCH(F15,Precios!$A$5:$A$120,0)),0)+IF(H15="",0,IFERROR(I15*INDEX(Precios!$D$5:$D$120,MATCH(H15,Precios!$A$5:$A$120,0)),0))) -> 0 | P15: =IF(B15="","",N(J15)*Parametros!$B$27) -> 0 | Q15: =IF(B15="","",IFERROR(INDEX(Confeccion!$B$5:$B$100,MATCH(K15,Confeccion!$A$5:$A$100,0)),0)) -> 0 | R15: =IF(B15="","",N(L15)) -> 0 | S15: =IF(B15="","",IF(AND(F15<>"",ISNUMBER(G15),ISNUMBER(IFERROR(INDEX(Precios!$D$5:$D$120,MATCH(F15,Precios!$A$5:$A$120,0)),"x")),OR(H15="",ISNUMBER(IFERROR(INDEX(Precios!$D$5:$D$120,MATCH(H15,Precios!$A$5:$A$120,0)),"x"))),J15<>"",K15<>"",Q15>0),SUM(O15:R15),"")) | T15: =IF(AND(S15<>"",ISNUMBER(E15)),E15*Parametros!$B$12,"") | U15: =IF(AND(S15<>"",ISNUMBER(E15)),E15*Parametros!$B$13,"") | V15: =IF(AND(S15<>"",ISNUMBER(E15)),E15-S15-T15-U15,"") | W15: =IF(AND(S15<>"",ISNUMBER(E15)),V15/E15,"") | X15: =IF(OR(S15="",Parametros!$B$14>=1),"",S15/(1-Parametros!$B$14)) | Y15: =IF(OR(S15="",Parametros!$B$14+Parametros!$B$18>=1),"",S15/(1-Parametros!$B$14-Parametros!$B$18)) | Z15: =IF(B15="","",IF(S15="","FALTAN DATOS",IF(NOT(ISNUMBER(E15)),"FALTA PRECIO",IF(V15<0,"PIERDE",IF(W15<Parametros!$B$18,"BAJO META","OK"))))) -> FALTAN DATOS | AA15: =IF(B15="","",IF(F15="","Tela. ","")&IF(NOT(ISNUMBER(G15)),"Kg de tela. ","")&IF(AND(F15<>"",NOT(ISNUMBER(IFERROR(INDEX(Precios!$D$5:$D$120,MATCH(F15,Precios!$A$5:$A$120,0)),"x")))),"Tela sin precio. ","")&IF(AND(H15<>"",NOT(ISNUMBER(IFERROR(INDEX(Precios!$D$5:$D$120,MATCH(H15,Precios!$A$5:$A$120,0)),"x")))),"Tela 2 sin precio. ","")&IF(J15="","Metros impresos. ","")&IF(AND(N(J15)>0,Parametros!$B$27=0),"Impresión sin costo. ","")&IF(K15="","Confección. ",IF(Q15=0,"Confección sin valor. ",""))&IF(NOT(ISNUMBER(E15)),"Precio de venta. ","")) -> Tela. Kg de tela. Metros impresos. Confección.
A16: RUGCSUBPRO | B16: Camiseta Rugby Pro Pmk | C16: Juego | D16: 93 | E16: 21765 | M16: Por confirmar | O16: =IF(B16="","",IFERROR(G16*INDEX(Precios!$D$5:$D$120,MATCH(F16,Precios!$A$5:$A$120,0)),0)+IF(H16="",0,IFERROR(I16*INDEX(Precios!$D$5:$D$120,MATCH(H16,Precios!$A$5:$A$120,0)),0))) -> 0 | P16: =IF(B16="","",N(J16)*Parametros!$B$27) -> 0 | Q16: =IF(B16="","",IFERROR(INDEX(Confeccion!$B$5:$B$100,MATCH(K16,Confeccion!$A$5:$A$100,0)),0)) -> 0 | R16: =IF(B16="","",N(L16)) -> 0 | S16: =IF(B16="","",IF(AND(F16<>"",ISNUMBER(G16),ISNUMBER(IFERROR(INDEX(Precios!$D$5:$D$120,MATCH(F16,Precios!$A$5:$A$120,0)),"x")),OR(H16="",ISNUMBER(IFERROR(INDEX(Precios!$D$5:$D$120,MATCH(H16,Precios!$A$5:$A$120,0)),"x"))),J16<>"",K16<>"",Q16>0),SUM(O16:R16),"")) | T16: =IF(AND(S16<>"",ISNUMBER(E16)),E16*Parametros!$B$12,"") | U16: =IF(AND(S16<>"",ISNUMBER(E16)),E16*Parametros!$B$13,"") | V16: =IF(AND(S16<>"",ISNUMBER(E16)),E16-S16-T16-U16,"") | W16: =IF(AND(S16<>"",ISNUMBER(E16)),V16/E16,"") | X16: =IF(OR(S16="",Parametros!$B$14>=1),"",S16/(1-Parametros!$B$14)) | Y16: =IF(OR(S16="",Parametros!$B$14+Parametros!$B$18>=1),"",S16/(1-Parametros!$B$14-Parametros!$B$18)) | Z16: =IF(B16="","",IF(S16="","FALTAN DATOS",IF(NOT(ISNUMBER(E16)),"FALTA PRECIO",IF(V16<0,"PIERDE",IF(W16<Parametros!$B$18,"BAJO META","OK"))))) -> FALTAN DATOS | AA16: =IF(B16="","",IF(F16="","Tela. ","")&IF(NOT(ISNUMBER(G16)),"Kg de tela. ","")&IF(AND(F16<>"",NOT(ISNUMBER(IFERROR(INDEX(Precios!$D$5:$D$120,MATCH(F16,Precios!$A$5:$A$120,0)),"x")))),"Tela sin precio. ","")&IF(AND(H16<>"",NOT(ISNUMBER(IFERROR(INDEX(Precios!$D$5:$D$120,MATCH(H16,Precios!$A$5:$A$120,0)),"x")))),"Tela 2 sin precio. ","")&IF(J16="","Metros impresos. ","")&IF(AND(N(J16)>0,Parametros!$B$27=0),"Impresión sin costo. ","")&IF(K16="","Confección. ",IF(Q16=0,"Confección sin valor. ",""))&IF(NOT(ISNUMBER(E16)),"Precio de venta. ","")) -> Tela. Kg de tela. Metros impresos. Confección.
A17: MDBZCOMENTPITSUB | B17: Conjunto Polerón de Entrenamiento + Buzo Pitillo Subl | C17: Salida | D17: 76 | E17: 44010 | M17: Por confirmar | N17: Son 2 prendas: armar como kit (polerón + pantalón). | O17: =IF(B17="","",IFERROR(G17*INDEX(Precios!$D$5:$D$120,MATCH(F17,Precios!$A$5:$A$120,0)),0)+IF(H17="",0,IFERROR(I17*INDEX(Precios!$D$5:$D$120,MATCH(H17,Precios!$A$5:$A$120,0)),0))) -> 0 | P17: =IF(B17="","",N(J17)*Parametros!$B$27) -> 0 | Q17: =IF(B17="","",IFERROR(INDEX(Confeccion!$B$5:$B$100,MATCH(K17,Confeccion!$A$5:$A$100,0)),0)) -> 0 | R17: =IF(B17="","",N(L17)) -> 0 | S17: =IF(B17="","",IF(AND(F17<>"",ISNUMBER(G17),ISNUMBER(IFERROR(INDEX(Precios!$D$5:$D$120,MATCH(F17,Precios!$A$5:$A$120,0)),"x")),OR(H17="",ISNUMBER(IFERROR(INDEX(Precios!$D$5:$D$120,MATCH(H17,Precios!$A$5:$A$120,0)),"x"))),J17<>"",K17<>"",Q17>0),SUM(O17:R17),"")) | T17: =IF(AND(S17<>"",ISNUMBER(E17)),E17*Parametros!$B$12,"") | U17: =IF(AND(S17<>"",ISNUMBER(E17)),E17*Parametros!$B$13,"") | V17: =IF(AND(S17<>"",ISNUMBER(E17)),E17-S17-T17-U17,"") | W17: =IF(AND(S17<>"",ISNUMBER(E17)),V17/E17,"") | X17: =IF(OR(S17="",Parametros!$B$14>=1),"",S17/(1-Parametros!$B$14)) | Y17: =IF(OR(S17="",Parametros!$B$14+Parametros!$B$18>=1),"",S17/(1-Parametros!$B$14-Parametros!$B$18)) | Z17: =IF(B17="","",IF(S17="","FALTAN DATOS",IF(NOT(ISNUMBER(E17)),"FALTA PRECIO",IF(V17<0,"PIERDE",IF(W17<Parametros!$B$18,"BAJO META","OK"))))) -> FALTAN DATOS | AA17: =IF(B17="","",IF(F17="","Tela. ","")&IF(NOT(ISNUMBER(G17)),"Kg de tela. ","")&IF(AND(F17<>"",NOT(ISNUMBER(IFERROR(INDEX(Precios!$D$5:$D$120,MATCH(F17,Precios!$A$5:$A$120,0)),"x")))),"Tela sin precio. ","")&IF(AND(H17<>"",NOT(ISNUMBER(IFERROR(INDEX(Precios!$D$5:$D$120,MATCH(H17,Precios!$A$5:$A$120,0)),"x")))),"Tela 2 sin precio. ","")&IF(J17="","Metros impresos. ","")&IF(AND(N(J17)>0,Parametros!$B$27=0),"Impresión sin costo. ","")&IF(K17="","Confección. ",IF(Q17=0,"Confección sin valor. ",""))&IF(NOT(ISNUMBER(E17)),"Precio de venta. ","")) -> Tela. Kg de tela. Metros impresos. Confección.
A18: FUTCSUBPROPIQMC | B18: Camiseta Fútbol Pro Playmaker, Piqué m/c | C18: Juego | D18: 66 | E18: 21554 | K18: Camiseta De Futbol | M18: Por confirmar | N18: Confección sugerida por el nombre: confirmar. | O18: =IF(B18="","",IFERROR(G18*INDEX(Precios!$D$5:$D$120,MATCH(F18,Precios!$A$5:$A$120,0)),0)+IF(H18="",0,IFERROR(I18*INDEX(Precios!$D$5:$D$120,MATCH(H18,Precios!$A$5:$A$120,0)),0))) -> 0 | P18: =IF(B18="","",N(J18)*Parametros!$B$27) -> 0 | Q18: =IF(B18="","",IFERROR(INDEX(Confeccion!$B$5:$B$100,MATCH(K18,Confeccion!$A$5:$A$100,0)),0)) -> 2000 | R18: =IF(B18="","",N(L18)) -> 0 | S18: =IF(B18="","",IF(AND(F18<>"",ISNUMBER(G18),ISNUMBER(IFERROR(INDEX(Precios!$D$5:$D$120,MATCH(F18,Precios!$A$5:$A$120,0)),"x")),OR(H18="",ISNUMBER(IFERROR(INDEX(Precios!$D$5:$D$120,MATCH(H18,Precios!$A$5:$A$120,0)),"x"))),J18<>"",K18<>"",Q18>0),SUM(O18:R18),"")) | T18: =IF(AND(S18<>"",ISNUMBER(E18)),E18*Parametros!$B$12,"") | U18: =IF(AND(S18<>"",ISNUMBER(E18)),E18*Parametros!$B$13,"") | V18: =IF(AND(S18<>"",ISNUMBER(E18)),E18-S18-T18-U18,"") | W18: =IF(AND(S18<>"",ISNUMBER(E18)),V18/E18,"") | X18: =IF(OR(S18="",Parametros!$B$14>=1),"",S18/(1-Parametros!$B$14)) | Y18: =IF(OR(S18="",Parametros!$B$14+Parametros!$B$18>=1),"",S18/(1-Parametros!$B$14-Parametros!$B$18)) | Z18: =IF(B18="","",IF(S18="","FALTAN DATOS",IF(NOT(ISNUMBER(E18)),"FALTA PRECIO",IF(V18<0,"PIERDE",IF(W18<Parametros!$B$18,"BAJO META","OK"))))) -> FALTAN DATOS | AA18: =IF(B18="","",IF(F18="","Tela. ","")&IF(NOT(ISNUMBER(G18)),"Kg de tela. ","")&IF(AND(F18<>"",NOT(ISNUMBER(IFERROR(INDEX(Precios!$D$5:$D$120,MATCH(F18,Precios!$A$5:$A$120,0)),"x")))),"Tela sin precio. ","")&IF(AND(H18<>"",NOT(ISNUMBER(IFERROR(INDEX(Precios!$D$5:$D$120,MATCH(H18,Precios!$A$5:$A$120,0)),"x")))),"Tela 2 sin precio. ","")&IF(J18="","Metros impresos. ","")&IF(AND(N(J18)>0,Parametros!$B$27=0),"Impresión sin costo. ","")&IF(K18="","Confección. ",IF(Q18=0,"Confección sin valor. ",""))&IF(NOT(ISNUMBER(E18)),"Precio de venta. ","")) -> Tela. Kg de tela. Metros impresos.
A19: RUNCSUBPROSM | B19: Camiseta Running Pro s/m | C19: Juego | D19: 65 | E19: 19244 | F19: 5K NACIONAL (running pro) | G19: 0.082 | J19: 1.2 | K19: Camiseta De Running | M19: Por confirmar | N19: Ficha OT 2223 (25 prendas). Metros 1,2 viene de la receta anterior, sin ficha: confirmar. | O19: =IF(B19="","",IFERROR(G19*INDEX(Precios!$D$5:$D$120,MATCH(F19,Precios!$A$5:$A$120,0)),0)+IF(H19="",0,IFERROR(I19*INDEX(Precios!$D$5:$D$120,MATCH(H19,Precios!$A$5:$A$120,0)),0))) -> 348.008 | P19: =IF(B19="","",N(J19)*Parametros!$B$27) -> 0 | Q19: =IF(B19="","",IFERROR(INDEX(Confeccion!$B$5:$B$100,MATCH(K19,Confeccion!$A$5:$A$100,0)),0)) -> 1800 | R19: =IF(B19="","",N(L19)) -> 0 | S19: =IF(B19="","",IF(AND(F19<>"",ISNUMBER(G19),ISNUMBER(IFERROR(INDEX(Precios!$D$5:$D$120,MATCH(F19,Precios!$A$5:$A$120,0)),"x")),OR(H19="",ISNUMBER(IFERROR(INDEX(Precios!$D$5:$D$120,MATCH(H19,Precios!$A$5:$A$120,0)),"x"))),J19<>"",K19<>"",Q19>0),SUM(O19:R19),"")) -> 2148.008 | T19: =IF(AND(S19<>"",ISNUMBER(E19)),E19*Parametros!$B$12,"") -> 6792.1033 | U19: =IF(AND(S19<>"",ISNUMBER(E19)),E19*Parametros!$B$13,"") -> 2438.1464 | V19: =IF(AND(S19<>"",ISNUMBER(E19)),E19-S19-T19-U19,"") -> 7865.7424 | W19: =IF(AND(S19<>"",ISNUMBER(E19)),V19/E19,"") -> 0.40873739 | X19: =IF(OR(S19="",Parametros!$B$14>=1),"",S19/(1-Parametros!$B$14)) -> 4127.9505 | Y19: =IF(OR(S19="",Parametros!$B$14+Parametros!$B$18>=1),"",S19/(1-Parametros!$B$14-Parametros!$B$18)) -> 5109.9611 | Z19: =IF(B19="","",IF(S19="","FALTAN DATOS",IF(NOT(ISNUMBER(E19)),"FALTA PRECIO",IF(V19<0,"PIERDE",IF(W19<Parametros!$B$18,"BAJO META","OK"))))) -> OK | AA19: =IF(B19="","",IF(F19="","Tela. ","")&IF(NOT(ISNUMBER(G19)),"Kg de tela. ","")&IF(AND(F19<>"",NOT(ISNUMBER(IFERROR(INDEX(Precios!$D$5:$D$120,MATCH(F19,Precios!$A$5:$A$120,0)),"x")))),"Tela sin precio. ","")&IF(AND(H19<>"",NOT(ISNUMBER(IFERROR(INDEX(Precios!$D$5:$D$120,MATCH(H19,Precios!$A$5:$A$120,0)),"x")))),"Tela 2 sin precio. ","")&IF(J19="","Metros impresos. ","")&IF(AND(N(J19)>0,Parametros!$B$27=0),"Impresión sin costo. ","")&IF(K19="","Confección. ",IF(Q19=0,"Confección sin valor. ",""))&IF(NOT(ISNUMBER(E19)),"Precio de venta. ","")) -> Impresión sin costo.
A20: SAL-CTV-SUB-SG | B20: CORTAVIENTO SUBLIMADO | C20: Salida | D20: 62 | E20: 36050 | M20: Por confirmar | O20: =IF(B20="","",IFERROR(G20*INDEX(Precios!$D$5:$D$120,MATCH(F20,Precios!$A$5:$A$120,0)),0)+IF(H20="",0,IFERROR(I20*INDEX(Precios!$D$5:$D$120,MATCH(H20,Precios!$A$5:$A$120,0)),0))) -> 0 | P20: =IF(B20="","",N(J20)*Parametros!$B$27) -> 0 | Q20: =IF(B20="","",IFERROR(INDEX(Confeccion!$B$5:$B$100,MATCH(K20,Confeccion!$A$5:$A$100,0)),0)) -> 0 | R20: =IF(B20="","",N(L20)) -> 0 | S20: =IF(B20="","",IF(AND(F20<>"",ISNUMBER(G20),ISNUMBER(IFERROR(INDEX(Precios!$D$5:$D$120,MATCH(F20,Precios!$A$5:$A$120,0)),"x")),OR(H20="",ISNUMBER(IFERROR(INDEX(Precios!$D$5:$D$120,MATCH(H20,Precios!$A$5:$A$120,0)),"x"))),J20<>"",K20<>"",Q20>0),SUM(O20:R20),"")) | T20: =IF(AND(S20<>"",ISNUMBER(E20)),E20*Parametros!$B$12,"") | U20: =IF(AND(S20<>"",ISNUMBER(E20)),E20*Parametros!$B$13,"") | V20: =IF(AND(S20<>"",ISNUMBER(E20)),E20-S20-T20-U20,"") | W20: =IF(AND(S20<>"",ISNUMBER(E20)),V20/E20,"") | X20: =IF(OR(S20="",Parametros!$B$14>=1),"",S20/(1-Parametros!$B$14)) | Y20: =IF(OR(S20="",Parametros!$B$14+Parametros!$B$18>=1),"",S20/(1-Parametros!$B$14-Parametros!$B$18)) | Z20: =IF(B20="","",IF(S20="","FALTAN DATOS",IF(NOT(ISNUMBER(E20)),"FALTA PRECIO",IF(V20<0,"PIERDE",IF(W20<Parametros!$B$18,"BAJO META","OK"))))) -> FALTAN DATOS | AA20: =IF(B20="","",IF(F20="","Tela. ","")&IF(NOT(ISNUMBER(G20)),"Kg de tela. ","")&IF(AND(F20<>"",NOT(ISNUMBER(IFERROR(INDEX(Precios!$D$5:$D$120,MATCH(F20,Precios!$A$5:$A$120,0)),"x")))),"Tela sin precio. ","")&IF(AND(H20<>"",NOT(ISNUMBER(IFERROR(INDEX(Precios!$D$5:$D$120,MATCH(H20,Precios!$A$5:$A$120,0)),"x")))),"Tela 2 sin precio. ","")&IF(J20="","Metros impresos. ","")&IF(AND(N(J20)>0,Parametros!$B$27=0),"Impresión sin costo. ","")&IF(K20="","Confección. ",IF(Q20=0,"Confección sin valor. ",""))&IF(NOT(ISNUMBER(E20)),"Precio de venta. ","")) -> Tela. Kg de tela. Metros impresos. Confección.
A21: RUG-SHO-BAS | B21: Short Rugby Basic | C21: Juego | D21: 61 | E21: 12507 | F21: GABARDINA | G21: 0.1842 | J21: 0 | K21: Short De Rugby | M21: Por confirmar | N21: Ficha OT 205 (19 prendas). El sistema anterior usaba confección de short de fútbol ($1.700); se cambió a Short De Rugby ($2.200). | O21: =IF(B21="","",IFERROR(G21*INDEX(Precios!$D$5:$D$120,MATCH(F21,Precios!$A$5:$A$120,0)),0)+IF(H21="",0,IFERROR(I21*INDEX(Precios!$D$5:$D$120,MATCH(H21,Precios!$A$5:$A$120,0)),0))) -> 506.55 | P21: =IF(B21="","",N(J21)*Parametros!$B$27) -> 0 | Q21: =IF(B21="","",IFERROR(INDEX(Confeccion!$B$5:$B$100,MATCH(K21,Confeccion!$A$5:$A$100,0)),0)) -> 2200 | R21: =IF(B21="","",N(L21)) -> 0 | S21: =IF(B21="","",IF(AND(F21<>"",ISNUMBER(G21),ISNUMBER(IFERROR(INDEX(Precios!$D$5:$D$120,MATCH(F21,Precios!$A$5:$A$120,0)),"x")),OR(H21="",ISNUMBER(IFERROR(INDEX(Precios!$D$5:$D$120,MATCH(H21,Precios!$A$5:$A$120,0)),"x"))),J21<>"",K21<>"",Q21>0),SUM(O21:R21),"")) -> 2706.55 | T21: =IF(AND(S21<>"",ISNUMBER(E21)),E21*Parametros!$B$12,"") -> 4414.3024 | U21: =IF(AND(S21<>"",ISNUMBER(E21)),E21*Parametros!$B$13,"") -> 1584.5924 | V21: =IF(AND(S21<>"",ISNUMBER(E21)),E21-S21-T21-U21,"") -> 3801.5552 | W21: =IF(AND(S21<>"",ISNUMBER(E21)),V21/E21,"") -> 0.3039542 | X21: =IF(OR(S21="",Parametros!$B$14>=1),"",S21/(1-Parametros!$B$14)) -> 5201.3328 | Y21: =IF(OR(S21="",Parametros!$B$14+Parametros!$B$18>=1),"",S21/(1-Parametros!$B$14-Parametros!$B$18)) -> 6438.6936 | Z21: =IF(B21="","",IF(S21="","FALTAN DATOS",IF(NOT(ISNUMBER(E21)),"FALTA PRECIO",IF(V21<0,"PIERDE",IF(W21<Parametros!$B$18,"BAJO META","OK"))))) -> OK | AA21: =IF(B21="","",IF(F21="","Tela. ","")&IF(NOT(ISNUMBER(G21)),"Kg de tela. ","")&IF(AND(F21<>"",NOT(ISNUMBER(IFERROR(INDEX(Precios!$D$5:$D$120,MATCH(F21,Precios!$A$5:$A$120,0)),"x")))),"Tela sin precio. ","")&IF(AND(H21<>"",NOT(ISNUMBER(IFERROR(INDEX(Precios!$D$5:$D$120,MATCH(H21,Precios!$A$5:$A$120,0)),"x")))),"Tela 2 sin precio. ","")&IF(J21="","Metros impresos. ","")&IF(AND(N(J21)>0,Parametros!$B$27=0),"Impresión sin costo. ","")&IF(K21="","Confección. ",IF(Q21=0,"Confección sin valor. ",""))&IF(NOT(ISNUMBER(E21)),"Precio de venta. ",""))
A22: SALPTPESUB | B22: Conjunto Polerón de Entrenamiento + Pitillo | C22: Salida | D22: 60 | E22: 41933 | M22: Por confirmar | N22: Son 2 prendas: armar como kit (polerón + pantalón). | O22: =IF(B22="","",IFERROR(G22*INDEX(Precios!$D$5:$D$120,MATCH(F22,Precios!$A$5:$A$120,0)),0)+IF(H22="",0,IFERROR(I22*INDEX(Precios!$D$5:$D$120,MATCH(H22,Precios!$A$5:$A$120,0)),0))) -> 0 | P22: =IF(B22="","",N(J22)*Parametros!$B$27) -> 0 | Q22: =IF(B22="","",IFERROR(INDEX(Confeccion!$B$5:$B$100,MATCH(K22,Confeccion!$A$5:$A$100,0)),0)) -> 0 | R22: =IF(B22="","",N(L22)) -> 0 | S22: =IF(B22="","",IF(AND(F22<>"",ISNUMBER(G22),ISNUMBER(IFERROR(INDEX(Precios!$D$5:$D$120,MATCH(F22,Precios!$A$5:$A$120,0)),"x")),OR(H22="",ISNUMBER(IFERROR(INDEX(Precios!$D$5:$D$120,MATCH(H22,Precios!$A$5:$A$120,0)),"x"))),J22<>"",K22<>"",Q22>0),SUM(O22:R22),"")) | T22: =IF(AND(S22<>"",ISNUMBER(E22)),E22*Parametros!$B$12,"") | U22: =IF(AND(S22<>"",ISNUMBER(E22)),E22*Parametros!$B$13,"") | V22: =IF(AND(S22<>"",ISNUMBER(E22)),E22-S22-T22-U22,"") | W22: =IF(AND(S22<>"",ISNUMBER(E22)),V22/E22,"") | X22: =IF(OR(S22="",Parametros!$B$14>=1),"",S22/(1-Parametros!$B$14)) | Y22: =IF(OR(S22="",Parametros!$B$14+Parametros!$B$18>=1),"",S22/(1-Parametros!$B$14-Parametros!$B$18)) | Z22: =IF(B22="","",IF(S22="","FALTAN DATOS",IF(NOT(ISNUMBER(E22)),"FALTA PRECIO",IF(V22<0,"PIERDE",IF(W22<Parametros!$B$18,"BAJO META","OK"))))) -> FALTAN DATOS | AA22: =IF(B22="","",IF(F22="","Tela. ","")&IF(NOT(ISNUMBER(G22)),"Kg de tela. ","")&IF(AND(F22<>"",NOT(ISNUMBER(IFERROR(INDEX(Precios!$D$5:$D$120,MATCH(F22,Precios!$A$5:$A$120,0)),"x")))),"Tela sin precio. ","")&IF(AND(H22<>"",NOT(ISNUMBER(IFERROR(INDEX(Precios!$D$5:$D$120,MATCH(H22,Precios!$A$5:$A$120,0)),"x")))),"Tela 2 sin precio. ","")&IF(J22="","Metros impresos. ","")&IF(AND(N(J22)>0,Parametros!$B$27=0),"Impresión sin costo. ","")&IF(K22="","Confección. ",IF(Q22=0,"Confección sin valor. ",""))&IF(NOT(ISNUMBER(E22)),"Precio de venta. ","")) -> Tela. Kg de tela. Metros impresos. Confección.
A23: FUTSHOLIS | B23: Short Fútbol Playmaker Liso | C23: Juego | D23: 55 | E23: 8059 | F23: CIRE BLANCO | G23: 0.1609 | J23: 0 | K23: Short De Futbol | M23: Por confirmar | N23: Promedio OT 2547 (0,175) y OT 2588 (0,138). Liso = sin impresión (0 m): confirmar. | O23: =IF(B23="","",IFERROR(G23*INDEX(Precios!$D$5:$D$120,MATCH(F23,Precios!$A$5:$A$120,0)),0)+IF(H23="",0,IFERROR(I23*INDEX(Precios!$D$5:$D$120,MATCH(H23,Precios!$A$5:$A$120,0)),0))) -> 901.04 | P23: =IF(B23="","",N(J23)*Parametros!$B$27) -> 0 | Q23: =IF(B23="","",IFERROR(INDEX(Confeccion!$B$5:$B$100,MATCH(K23,Confeccion!$A$5:$A$100,0)),0)) -> 1700 | R23: =IF(B23="","",N(L23)) -> 0 | S23: =IF(B23="","",IF(AND(F23<>"",ISNUMBER(G23),ISNUMBER(IFERROR(INDEX(Precios!$D$5:$D$120,MATCH(F23,Precios!$A$5:$A$120,0)),"x")),OR(H23="",ISNUMBER(IFERROR(INDEX(Precios!$D$5:$D$120,MATCH(H23,Precios!$A$5:$A$120,0)),"x"))),J23<>"",K23<>"",Q23>0),SUM(O23:R23),"")) -> 2601.04 | T23: =IF(AND(S23<>"",ISNUMBER(E23)),E23*Parametros!$B$12,"") -> 2844.3962 | U23: =IF(AND(S23<>"",ISNUMBER(E23)),E23*Parametros!$B$13,"") -> 1021.0466 | V23: =IF(AND(S23<>"",ISNUMBER(E23)),E23-S23-T23-U23,"") -> 1592.5172 | W23: =IF(AND(S23<>"",ISNUMBER(E23)),V23/E23,"") -> 0.19760729 | X23: =IF(OR(S23="",Parametros!$B$14>=1),"",S23/(1-Parametros!$B$14)) -> 4998.5682 | Y23: =IF(OR(S23="",Parametros!$B$14+Parametros!$B$18>=1),"",S23/(1-Parametros!$B$14-Parametros!$B$18)) -> 6187.6926 | Z23: =IF(B23="","",IF(S23="","FALTAN DATOS",IF(NOT(ISNUMBER(E23)),"FALTA PRECIO",IF(V23<0,"PIERDE",IF(W23<Parametros!$B$18,"BAJO META","OK"))))) -> OK | AA23: =IF(B23="","",IF(F23="","Tela. ","")&IF(NOT(ISNUMBER(G23)),"Kg de tela. ","")&IF(AND(F23<>"",NOT(ISNUMBER(IFERROR(INDEX(Precios!$D$5:$D$120,MATCH(F23,Precios!$A$5:$A$120,0)),"x")))),"Tela sin precio. ","")&IF(AND(H23<>"",NOT(ISNUMBER(IFERROR(INDEX(Precios!$D$5:$D$120,MATCH(H23,Precios!$A$5:$A$120,0)),"x")))),"Tela 2 sin precio. ","")&IF(J23="","Metros impresos. ","")&IF(AND(N(J23)>0,Parametros!$B$27=0),"Impresión sin costo. ","")&IF(K23="","Confección. ",IF(Q23=0,"Confección sin valor. ",""))&IF(NOT(ISNUMBER(E23)),"Precio de venta. ",""))
A24: VOLFEMCSUBPROV | B24: Camiseta Voley fem Pro Playmaker, V | C24: Juego | D24: 50 | E24: 19244 | K24: Camiseta Voley | M24: Por confirmar | N24: Confección sugerida por el nombre: confirmar. | O24: =IF(B24="","",IFERROR(G24*INDEX(Precios!$D$5:$D$120,MATCH(F24,Precios!$A$5:$A$120,0)),0)+IF(H24="",0,IFERROR(I24*INDEX(Precios!$D$5:$D$120,MATCH(H24,Precios!$A$5:$A$120,0)),0))) -> 0 | P24: =IF(B24="","",N(J24)*Parametros!$B$27) -> 0 | Q24: =IF(B24="","",IFERROR(INDEX(Confeccion!$B$5:$B$100,MATCH(K24,Confeccion!$A$5:$A$100,0)),0)) -> 1700 | R24: =IF(B24="","",N(L24)) -> 0 | S24: =IF(B24="","",IF(AND(F24<>"",ISNUMBER(G24),ISNUMBER(IFERROR(INDEX(Precios!$D$5:$D$120,MATCH(F24,Precios!$A$5:$A$120,0)),"x")),OR(H24="",ISNUMBER(IFERROR(INDEX(Precios!$D$5:$D$120,MATCH(H24,Precios!$A$5:$A$120,0)),"x"))),J24<>"",K24<>"",Q24>0),SUM(O24:R24),"")) | T24: =IF(AND(S24<>"",ISNUMBER(E24)),E24*Parametros!$B$12,"") | U24: =IF(AND(S24<>"",ISNUMBER(E24)),E24*Parametros!$B$13,"") | V24: =IF(AND(S24<>"",ISNUMBER(E24)),E24-S24-T24-U24,"") | W24: =IF(AND(S24<>"",ISNUMBER(E24)),V24/E24,"") | X24: =IF(OR(S24="",Parametros!$B$14>=1),"",S24/(1-Parametros!$B$14)) | Y24: =IF(OR(S24="",Parametros!$B$14+Parametros!$B$18>=1),"",S24/(1-Parametros!$B$14-Parametros!$B$18)) | Z24: =IF(B24="","",IF(S24="","FALTAN DATOS",IF(NOT(ISNUMBER(E24)),"FALTA PRECIO",IF(V24<0,"PIERDE",IF(W24<Parametros!$B$18,"BAJO META","OK"))))) -> FALTAN DATOS | AA24: =IF(B24="","",IF(F24="","Tela. ","")&IF(NOT(ISNUMBER(G24)),"Kg de tela. ","")&IF(AND(F24<>"",NOT(ISNUMBER(IFERROR(INDEX(Precios!$D$5:$D$120,MATCH(F24,Precios!$A$5:$A$120,0)),"x")))),"Tela sin precio. ","")&IF(AND(H24<>"",NOT(ISNUMBER(IFERROR(INDEX(Precios!$D$5:$D$120,MATCH(H24,Precios!$A$5:$A$120,0)),"x")))),"Tela 2 sin precio. ","")&IF(J24="","Metros impresos. ","")&IF(AND(N(J24)>0,Parametros!$B$27=0),"Impresión sin costo. ","")&IF(K24="","Confección. ",IF(Q24=0,"Confección sin valor. ",""))&IF(NOT(ISNUMBER(E24)),"Precio de venta. ","")) -> Tela. Kg de tela. Metros impresos.
A25: MDPTSUB | B25: PETO ENTRENAMIENTO SUB | C25: Juego | D25: 48 | E25: 8319 | K25: Peto Entrenamiento | M25: Por confirmar | N25: Confección sugerida por el nombre: confirmar. | O25: =IF(B25="","",IFERROR(G25*INDEX(Precios!$D$5:$D$120,MATCH(F25,Precios!$A$5:$A$120,0)),0)+IF(H25="",0,IFERROR(I25*INDEX(Precios!$D$5:$D$120,MATCH(H25,Precios!$A$5:$A$120,0)),0))) -> 0 | P25: =IF(B25="","",N(J25)*Parametros!$B$27) -> 0 | Q25: =IF(B25="","",IFERROR(INDEX(Confeccion!$B$5:$B$100,MATCH(K25,Confeccion!$A$5:$A$100,0)),0)) -> 1000 | R25: =IF(B25="","",N(L25)) -> 0 | S25: =IF(B25="","",IF(AND(F25<>"",ISNUMBER(G25),ISNUMBER(IFERROR(INDEX(Precios!$D$5:$D$120,MATCH(F25,Precios!$A$5:$A$120,0)),"x")),OR(H25="",ISNUMBER(IFERROR(INDEX(Precios!$D$5:$D$120,MATCH(H25,Precios!$A$5:$A$120,0)),"x"))),J25<>"",K25<>"",Q25>0),SUM(O25:R25),"")) | T25: =IF(AND(S25<>"",ISNUMBER(E25)),E25*Parametros!$B$12,"") | U25: =IF(AND(S25<>"",ISNUMBER(E25)),E25*Parametros!$B$13,"") | V25: =IF(AND(S25<>"",ISNUMBER(E25)),E25-S25-T25-U25,"") | W25: =IF(AND(S25<>"",ISNUMBER(E25)),V25/E25,"") | X25: =IF(OR(S25="",Parametros!$B$14>=1),"",S25/(1-Parametros!$B$14)) | Y25: =IF(OR(S25="",Parametros!$B$14+Parametros!$B$18>=1),"",S25/(1-Parametros!$B$14-Parametros!$B$18)) | Z25: =IF(B25="","",IF(S25="","FALTAN DATOS",IF(NOT(ISNUMBER(E25)),"FALTA PRECIO",IF(V25<0,"PIERDE",IF(W25<Parametros!$B$18,"BAJO META","OK"))))) -> FALTAN DATOS | AA25: =IF(B25="","",IF(F25="","Tela. ","")&IF(NOT(ISNUMBER(G25)),"Kg de tela. ","")&IF(AND(F25<>"",NOT(ISNUMBER(IFERROR(INDEX(Precios!$D$5:$D$120,MATCH(F25,Precios!$A$5:$A$120,0)),"x")))),"Tela sin precio. ","")&IF(AND(H25<>"",NOT(ISNUMBER(IFERROR(INDEX(Precios!$D$5:$D$120,MATCH(H25,Precios!$A$5:$A$120,0)),"x")))),"Tela 2 sin precio. ","")&IF(J25="","Metros impresos. ","")&IF(AND(N(J25)>0,Parametros!$B$27=0),"Impresión sin costo. ","")&IF(K25="","Confección. ",IF(Q25=0,"Confección sin valor. ",""))&IF(NOT(ISNUMBER(E25)),"Precio de venta. ","")) -> Tela. Kg de tela. Metros impresos.
A26: MDCSUBOVA | B26: Polera Playmaker, Cuello Oval s/mangas | C26: Juego | D26: 48 | E26: 16723 | M26: Por confirmar | O26: =IF(B26="","",IFERROR(G26*INDEX(Precios!$D$5:$D$120,MATCH(F26,Precios!$A$5:$A$120,0)),0)+IF(H26="",0,IFERROR(I26*INDEX(Precios!$D$5:$D$120,MATCH(H26,Precios!$A$5:$A$120,0)),0))) -> 0 | P26: =IF(B26="","",N(J26)*Parametros!$B$27) -> 0 | Q26: =IF(B26="","",IFERROR(INDEX(Confeccion!$B$5:$B$100,MATCH(K26,Confeccion!$A$5:$A$100,0)),0)) -> 0 | R26: =IF(B26="","",N(L26)) -> 0 | S26: =IF(B26="","",IF(AND(F26<>"",ISNUMBER(G26),ISNUMBER(IFERROR(INDEX(Precios!$D$5:$D$120,MATCH(F26,Precios!$A$5:$A$120,0)),"x")),OR(H26="",ISNUMBER(IFERROR(INDEX(Precios!$D$5:$D$120,MATCH(H26,Precios!$A$5:$A$120,0)),"x"))),J26<>"",K26<>"",Q26>0),SUM(O26:R26),"")) | T26: =IF(AND(S26<>"",ISNUMBER(E26)),E26*Parametros!$B$12,"") | U26: =IF(AND(S26<>"",ISNUMBER(E26)),E26*Parametros!$B$13,"") | V26: =IF(AND(S26<>"",ISNUMBER(E26)),E26-S26-T26-U26,"") | W26: =IF(AND(S26<>"",ISNUMBER(E26)),V26/E26,"") | X26: =IF(OR(S26="",Parametros!$B$14>=1),"",S26/(1-Parametros!$B$14)) | Y26: =IF(OR(S26="",Parametros!$B$14+Parametros!$B$18>=1),"",S26/(1-Parametros!$B$14-Parametros!$B$18)) | Z26: =IF(B26="","",IF(S26="","FALTAN DATOS",IF(NOT(ISNUMBER(E26)),"FALTA PRECIO",IF(V26<0,"PIERDE",IF(W26<Parametros!$B$18,"BAJO META","OK"))))) -> FALTAN DATOS | AA26: =IF(B26="","",IF(F26="","Tela. ","")&IF(NOT(ISNUMBER(G26)),"Kg de tela. ","")&IF(AND(F26<>"",NOT(ISNUMBER(IFERROR(INDEX(Precios!$D$5:$D$120,MATCH(F26,Precios!$A$5:$A$120,0)),"x")))),"Tela sin precio. ","")&IF(AND(H26<>"",NOT(ISNUMBER(IFERROR(INDEX(Precios!$D$5:$D$120,MATCH(H26,Precios!$A$5:$A$120,0)),"x")))),"Tela 2 sin precio. ","")&IF(J26="","Metros impresos. ","")&IF(AND(N(J26)>0,Parametros!$B$27=0),"Impresión sin costo. ","")&IF(K26="","Confección. ",IF(Q26=0,"Confección sin valor. ",""))&IF(NOT(ISNUMBER(E26)),"Precio de venta. ","")) -> Tela. Kg de tela. Metros impresos. Confección.
A27: SALHOOLIS | B27: Polerón Hoodie Playmaker liso | C27: Salida | D27: 47 | E27: 26134 | K27: Poleron Hoodie | M27: Por confirmar | N27: Confección sugerida por el nombre: confirmar. | O27: =IF(B27="","",IFERROR(G27*INDEX(Precios!$D$5:$D$120,MATCH(F27,Precios!$A$5:$A$120,0)),0)+IF(H27="",0,IFERROR(I27*INDEX(Precios!$D$5:$D$120,MATCH(H27,Precios!$A$5:$A$120,0)),0))) -> 0 | P27: =IF(B27="","",N(J27)*Parametros!$B$27) -> 0 | Q27: =IF(B27="","",IFERROR(INDEX(Confeccion!$B$5:$B$100,MATCH(K27,Confeccion!$A$5:$A$100,0)),0)) -> 3000 | R27: =IF(B27="","",N(L27)) -> 0 | S27: =IF(B27="","",IF(AND(F27<>"",ISNUMBER(G27),ISNUMBER(IFERROR(INDEX(Precios!$D$5:$D$120,MATCH(F27,Precios!$A$5:$A$120,0)),"x")),OR(H27="",ISNUMBER(IFERROR(INDEX(Precios!$D$5:$D$120,MATCH(H27,Precios!$A$5:$A$120,0)),"x"))),J27<>"",K27<>"",Q27>0),SUM(O27:R27),"")) | T27: =IF(AND(S27<>"",ISNUMBER(E27)),E27*Parametros!$B$12,"") | U27: =IF(AND(S27<>"",ISNUMBER(E27)),E27*Parametros!$B$13,"") | V27: =IF(AND(S27<>"",ISNUMBER(E27)),E27-S27-T27-U27,"") | W27: =IF(AND(S27<>"",ISNUMBER(E27)),V27/E27,"") | X27: =IF(OR(S27="",Parametros!$B$14>=1),"",S27/(1-Parametros!$B$14)) | Y27: =IF(OR(S27="",Parametros!$B$14+Parametros!$B$18>=1),"",S27/(1-Parametros!$B$14-Parametros!$B$18)) | Z27: =IF(B27="","",IF(S27="","FALTAN DATOS",IF(NOT(ISNUMBER(E27)),"FALTA PRECIO",IF(V27<0,"PIERDE",IF(W27<Parametros!$B$18,"BAJO META","OK"))))) -> FALTAN DATOS | AA27: =IF(B27="","",IF(F27="","Tela. ","")&IF(NOT(ISNUMBER(G27)),"Kg de tela. ","")&IF(AND(F27<>"",NOT(ISNUMBER(IFERROR(INDEX(Precios!$D$5:$D$120,MATCH(F27,Precios!$A$5:$A$120,0)),"x")))),"Tela sin precio. ","")&IF(AND(H27<>"",NOT(ISNUMBER(IFERROR(INDEX(Precios!$D$5:$D$120,MATCH(H27,Precios!$A$5:$A$120,0)),"x")))),"Tela 2 sin precio. ","")&IF(J27="","Metros impresos. ","")&IF(AND(N(J27)>0,Parametros!$B$27=0),"Impresión sin costo. ","")&IF(K27="","Confección. ",IF(Q27=0,"Confección sin valor. ",""))&IF(NOT(ISNUMBER(E27)),"Precio de venta. ","")) -> Tela. Kg de tela. Metros impresos.
A28: CSUBRUGSFBLANCA | B28: CAMISETA DE RUGBY STADE FRANCAIS ANIVERSARIO (BLANCA) | C28: Juego | D28: 44 | E28: 27605 | M28: Por confirmar | O28: =IF(B28="","",IFERROR(G28*INDEX(Precios!$D$5:$D$120,MATCH(F28,Precios!$A$5:$A$120,0)),0)+IF(H28="",0,IFERROR(I28*INDEX(Precios!$D$5:$D$120,MATCH(H28,Precios!$A$5:$A$120,0)),0))) -> 0 | P28: =IF(B28="","",N(J28)*Parametros!$B$27) -> 0 | Q28: =IF(B28="","",IFERROR(INDEX(Confeccion!$B$5:$B$100,MATCH(K28,Confeccion!$A$5:$A$100,0)),0)) -> 0 | R28: =IF(B28="","",N(L28)) -> 0 | S28: =IF(B28="","",IF(AND(F28<>"",ISNUMBER(G28),ISNUMBER(IFERROR(INDEX(Precios!$D$5:$D$120,MATCH(F28,Precios!$A$5:$A$120,0)),"x")),OR(H28="",ISNUMBER(IFERROR(INDEX(Precios!$D$5:$D$120,MATCH(H28,Precios!$A$5:$A$120,0)),"x"))),J28<>"",K28<>"",Q28>0),SUM(O28:R28),"")) | T28: =IF(AND(S28<>"",ISNUMBER(E28)),E28*Parametros!$B$12,"") | U28: =IF(AND(S28<>"",ISNUMBER(E28)),E28*Parametros!$B$13,"") | V28: =IF(AND(S28<>"",ISNUMBER(E28)),E28-S28-T28-U28,"") | W28: =IF(AND(S28<>"",ISNUMBER(E28)),V28/E28,"") | X28: =IF(OR(S28="",Parametros!$B$14>=1),"",S28/(1-Parametros!$B$14)) | Y28: =IF(OR(S28="",Parametros!$B$14+Parametros!$B$18>=1),"",S28/(1-Parametros!$B$14-Parametros!$B$18)) | Z28: =IF(B28="","",IF(S28="","FALTAN DATOS",IF(NOT(ISNUMBER(E28)),"FALTA PRECIO",IF(V28<0,"PIERDE",IF(W28<Parametros!$B$18,"BAJO META","OK"))))) -> FALTAN DATOS | AA28: =IF(B28="","",IF(F28="","Tela. ","")&IF(NOT(ISNUMBER(G28)),"Kg de tela. ","")&IF(AND(F28<>"",NOT(ISNUMBER(IFERROR(INDEX(Precios!$D$5:$D$120,MATCH(F28,Precios!$A$5:$A$120,0)),"x")))),"Tela sin precio. ","")&IF(AND(H28<>"",NOT(ISNUMBER(IFERROR(INDEX(Precios!$D$5:$D$120,MATCH(H28,Precios!$A$5:$A$120,0)),"x")))),"Tela 2 sin precio. ","")&IF(J28="","Metros impresos. ","")&IF(AND(N(J28)>0,Parametros!$B$27=0),"Impresión sin costo. ","")&IF(K28="","Confección. ",IF(Q28=0,"Confección sin valor. ",""))&IF(NOT(ISNUMBER(E28)),"Precio de venta. ","")) -> Tela. Kg de tela. Metros impresos. Confección.
A29: SAL-POL-3C | B29: Polerón 3C Playmaker Algodón Cierre | C29: Salida | D29: 40 | E29: 32689 | M29: Por confirmar | O29: =IF(B29="","",IFERROR(G29*INDEX(Precios!$D$5:$D$120,MATCH(F29,Precios!$A$5:$A$120,0)),0)+IF(H29="",0,IFERROR(I29*INDEX(Precios!$D$5:$D$120,MATCH(H29,Precios!$A$5:$A$120,0)),0))) -> 0 | P29: =IF(B29="","",N(J29)*Parametros!$B$27) -> 0 | Q29: =IF(B29="","",IFERROR(INDEX(Confeccion!$B$5:$B$100,MATCH(K29,Confeccion!$A$5:$A$100,0)),0)) -> 0 | R29: =IF(B29="","",N(L29)) -> 0 | S29: =IF(B29="","",IF(AND(F29<>"",ISNUMBER(G29),ISNUMBER(IFERROR(INDEX(Precios!$D$5:$D$120,MATCH(F29,Precios!$A$5:$A$120,0)),"x")),OR(H29="",ISNUMBER(IFERROR(INDEX(Precios!$D$5:$D$120,MATCH(H29,Precios!$A$5:$A$120,0)),"x"))),J29<>"",K29<>"",Q29>0),SUM(O29:R29),"")) | T29: =IF(AND(S29<>"",ISNUMBER(E29)),E29*Parametros!$B$12,"") | U29: =IF(AND(S29<>"",ISNUMBER(E29)),E29*Parametros!$B$13,"") | V29: =IF(AND(S29<>"",ISNUMBER(E29)),E29-S29-T29-U29,"") | W29: =IF(AND(S29<>"",ISNUMBER(E29)),V29/E29,"") | X29: =IF(OR(S29="",Parametros!$B$14>=1),"",S29/(1-Parametros!$B$14)) | Y29: =IF(OR(S29="",Parametros!$B$14+Parametros!$B$18>=1),"",S29/(1-Parametros!$B$14-Parametros!$B$18)) | Z29: =IF(B29="","",IF(S29="","FALTAN DATOS",IF(NOT(ISNUMBER(E29)),"FALTA PRECIO",IF(V29<0,"PIERDE",IF(W29<Parametros!$B$18,"BAJO META","OK"))))) -> FALTAN DATOS | AA29: =IF(B29="","",IF(F29="","Tela. ","")&IF(NOT(ISNUMBER(G29)),"Kg de tela. ","")&IF(AND(F29<>"",NOT(ISNUMBER(IFERROR(INDEX(Precios!$D$5:$D$120,MATCH(F29,Precios!$A$5:$A$120,0)),"x")))),"Tela sin precio. ","")&IF(AND(H29<>"",NOT(ISNUMBER(IFERROR(INDEX(Precios!$D$5:$D$120,MATCH(H29,Precios!$A$5:$A$120,0)),"x")))),"Tela 2 sin precio. ","")&IF(J29="","Metros impresos. ","")&IF(AND(N(J29)>0,Parametros!$B$27=0),"Impresión sin costo. ","")&IF(K29="","Confección. ",IF(Q29=0,"Confección sin valor. ",""))&IF(NOT(ISNUMBER(E29)),"Precio de venta. ","")) -> Tela. Kg de tela. Metros impresos. Confección.
A30: VOLMASC-CSUB-POL-CER | B30: Camiseta Voley masc Playmaker, Polo m/cero | C30: Juego | D30: 37 | E30: 17563 | K30: Camiseta Voley | M30: Por confirmar | N30: Confección sugerida por el nombre: confirmar. | O30: =IF(B30="","",IFERROR(G30*INDEX(Precios!$D$5:$D$120,MATCH(F30,Precios!$A$5:$A$120,0)),0)+IF(H30="",0,IFERROR(I30*INDEX(Precios!$D$5:$D$120,MATCH(H30,Precios!$A$5:$A$120,0)),0))) -> 0 | P30: =IF(B30="","",N(J30)*Parametros!$B$27) -> 0 | Q30: =IF(B30="","",IFERROR(INDEX(Confeccion!$B$5:$B$100,MATCH(K30,Confeccion!$A$5:$A$100,0)),0)) -> 1700 | R30: =IF(B30="","",N(L30)) -> 0 | S30: =IF(B30="","",IF(AND(F30<>"",ISNUMBER(G30),ISNUMBER(IFERROR(INDEX(Precios!$D$5:$D$120,MATCH(F30,Precios!$A$5:$A$120,0)),"x")),OR(H30="",ISNUMBER(IFERROR(INDEX(Precios!$D$5:$D$120,MATCH(H30,Precios!$A$5:$A$120,0)),"x"))),J30<>"",K30<>"",Q30>0),SUM(O30:R30),"")) | T30: =IF(AND(S30<>"",ISNUMBER(E30)),E30*Parametros!$B$12,"") | U30: =IF(AND(S30<>"",ISNUMBER(E30)),E30*Parametros!$B$13,"") | V30: =IF(AND(S30<>"",ISNUMBER(E30)),E30-S30-T30-U30,"") | W30: =IF(AND(S30<>"",ISNUMBER(E30)),V30/E30,"") | X30: =IF(OR(S30="",Parametros!$B$14>=1),"",S30/(1-Parametros!$B$14)) | Y30: =IF(OR(S30="",Parametros!$B$14+Parametros!$B$18>=1),"",S30/(1-Parametros!$B$14-Parametros!$B$18)) | Z30: =IF(B30="","",IF(S30="","FALTAN DATOS",IF(NOT(ISNUMBER(E30)),"FALTA PRECIO",IF(V30<0,"PIERDE",IF(W30<Parametros!$B$18,"BAJO META","OK"))))) -> FALTAN DATOS | AA30: =IF(B30="","",IF(F30="","Tela. ","")&IF(NOT(ISNUMBER(G30)),"Kg de tela. ","")&IF(AND(F30<>"",NOT(ISNUMBER(IFERROR(INDEX(Precios!$D$5:$D$120,MATCH(F30,Precios!$A$5:$A$120,0)),"x")))),"Tela sin precio. ","")&IF(AND(H30<>"",NOT(ISNUMBER(IFERROR(INDEX(Precios!$D$5:$D$120,MATCH(H30,Precios!$A$5:$A$120,0)),"x")))),"Tela 2 sin precio. ","")&IF(J30="","Metros impresos. ","")&IF(AND(N(J30)>0,Parametros!$B$27=0),"Impresión sin costo. ","")&IF(K30="","Confección. ",IF(Q30=0,"Confección sin valor. ",""))&IF(NOT(ISNUMBER(E30)),"Precio de venta. ","")) -> Tela. Kg de tela. Metros impresos.
A31: SALPRKLIS | B31: Parka Lisa Playmaker | C31: Salida | D31: 37 | E31: 54022 | M31: Por confirmar | O31: =IF(B31="","",IFERROR(G31*INDEX(Precios!$D$5:$D$120,MATCH(F31,Precios!$A$5:$A$120,0)),0)+IF(H31="",0,IFERROR(I31*INDEX(Precios!$D$5:$D$120,MATCH(H31,Precios!$A$5:$A$120,0)),0))) -> 0 | P31: =IF(B31="","",N(J31)*Parametros!$B$27) -> 0 | Q31: =IF(B31="","",IFERROR(INDEX(Confeccion!$B$5:$B$100,MATCH(K31,Confeccion!$A$5:$A$100,0)),0)) -> 0 | R31: =IF(B31="","",N(L31)) -> 0 | S31: =IF(B31="","",IF(AND(F31<>"",ISNUMBER(G31),ISNUMBER(IFERROR(INDEX(Precios!$D$5:$D$120,MATCH(F31,Precios!$A$5:$A$120,0)),"x")),OR(H31="",ISNUMBER(IFERROR(INDEX(Precios!$D$5:$D$120,MATCH(H31,Precios!$A$5:$A$120,0)),"x"))),J31<>"",K31<>"",Q31>0),SUM(O31:R31),"")) | T31: =IF(AND(S31<>"",ISNUMBER(E31)),E31*Parametros!$B$12,"") | U31: =IF(AND(S31<>"",ISNUMBER(E31)),E31*Parametros!$B$13,"") | V31: =IF(AND(S31<>"",ISNUMBER(E31)),E31-S31-T31-U31,"") | W31: =IF(AND(S31<>"",ISNUMBER(E31)),V31/E31,"") | X31: =IF(OR(S31="",Parametros!$B$14>=1),"",S31/(1-Parametros!$B$14)) | Y31: =IF(OR(S31="",Parametros!$B$14+Parametros!$B$18>=1),"",S31/(1-Parametros!$B$14-Parametros!$B$18)) | Z31: =IF(B31="","",IF(S31="","FALTAN DATOS",IF(NOT(ISNUMBER(E31)),"FALTA PRECIO",IF(V31<0,"PIERDE",IF(W31<Parametros!$B$18,"BAJO META","OK"))))) -> FALTAN DATOS | AA31: =IF(B31="","",IF(F31="","Tela. ","")&IF(NOT(ISNUMBER(G31)),"Kg de tela. ","")&IF(AND(F31<>"",NOT(ISNUMBER(IFERROR(INDEX(Precios!$D$5:$D$120,MATCH(F31,Precios!$A$5:$A$120,0)),"x")))),"Tela sin precio. ","")&IF(AND(H31<>"",NOT(ISNUMBER(IFERROR(INDEX(Precios!$D$5:$D$120,MATCH(H31,Precios!$A$5:$A$120,0)),"x")))),"Tela 2 sin precio. ","")&IF(J31="","Metros impresos. ","")&IF(AND(N(J31)>0,Parametros!$B$27=0),"Impresión sin costo. ","")&IF(K31="","Confección. ",IF(Q31=0,"Confección sin valor. ",""))&IF(NOT(ISNUMBER(E31)),"Precio de venta. ","")) -> Tela. Kg de tela. Metros impresos. Confección.
A32: RUG-SHO-PRO | B32: Short Rugby Pro | C32: Juego | D32: 35 | E32: 14202 | K32: Short De Rugby | M32: Por confirmar | N32: Confección sugerida por el nombre: confirmar. | O32: =IF(B32="","",IFERROR(G32*INDEX(Precios!$D$5:$D$120,MATCH(F32,Precios!$A$5:$A$120,0)),0)+IF(H32="",0,IFERROR(I32*INDEX(Precios!$D$5:$D$120,MATCH(H32,Precios!$A$5:$A$120,0)),0))) -> 0 | P32: =IF(B32="","",N(J32)*Parametros!$B$27) -> 0 | Q32: =IF(B32="","",IFERROR(INDEX(Confeccion!$B$5:$B$100,MATCH(K32,Confeccion!$A$5:$A$100,0)),0)) -> 2200 | R32: =IF(B32="","",N(L32)) -> 0 | S32: =IF(B32="","",IF(AND(F32<>"",ISNUMBER(G32),ISNUMBER(IFERROR(INDEX(Precios!$D$5:$D$120,MATCH(F32,Precios!$A$5:$A$120,0)),"x")),OR(H32="",ISNUMBER(IFERROR(INDEX(Precios!$D$5:$D$120,MATCH(H32,Precios!$A$5:$A$120,0)),"x"))),J32<>"",K32<>"",Q32>0),SUM(O32:R32),"")) | T32: =IF(AND(S32<>"",ISNUMBER(E32)),E32*Parametros!$B$12,"") | U32: =IF(AND(S32<>"",ISNUMBER(E32)),E32*Parametros!$B$13,"") | V32: =IF(AND(S32<>"",ISNUMBER(E32)),E32-S32-T32-U32,"") | W32: =IF(AND(S32<>"",ISNUMBER(E32)),V32/E32,"") | X32: =IF(OR(S32="",Parametros!$B$14>=1),"",S32/(1-Parametros!$B$14)) | Y32: =IF(OR(S32="",Parametros!$B$14+Parametros!$B$18>=1),"",S32/(1-Parametros!$B$14-Parametros!$B$18)) | Z32: =IF(B32="","",IF(S32="","FALTAN DATOS",IF(NOT(ISNUMBER(E32)),"FALTA PRECIO",IF(V32<0,"PIERDE",IF(W32<Parametros!$B$18,"BAJO META","OK"))))) -> FALTAN DATOS | AA32: =IF(B32="","",IF(F32="","Tela. ","")&IF(NOT(ISNUMBER(G32)),"Kg de tela. ","")&IF(AND(F32<>"",NOT(ISNUMBER(IFERROR(INDEX(Precios!$D$5:$D$120,MATCH(F32,Precios!$A$5:$A$120,0)),"x")))),"Tela sin precio. ","")&IF(AND(H32<>"",NOT(ISNUMBER(IFERROR(INDEX(Precios!$D$5:$D$120,MATCH(H32,Precios!$A$5:$A$120,0)),"x")))),"Tela 2 sin precio. ","")&IF(J32="","Metros impresos. ","")&IF(AND(N(J32)>0,Parametros!$B$27=0),"Impresión sin costo. ","")&IF(K32="","Confección. ",IF(Q32=0,"Confección sin valor. ",""))&IF(NOT(ISNUMBER(E32)),"Precio de venta. ","")) -> Tela. Kg de tela. Metros impresos.
