Workbook

Sheet Datos_Maestro
B2: PLAYMAKER — DATOS MAESTRO MENSUAL
B3: Ingresa aquí los indicadores de cada mes | I3: Azul = editable | Verde = calculado auto
B6: 1. PRODUCCIÓN — Control de Ploteo (ingresar mensualmente)
B7: Mes | C7: Mts Producción | D7: Mts Reproceso | E7: Mts Moldes/Muestra | F7: Mts Total | G7: % Reproc. (auto) | H7: Base (P+R) | I7: Meta % Reproc. | J7: Mts solo reimpresión | K7: Costo reproceso (CLP)
B8: Mayo 2026 | C8: 1889.9 | D8: 133 | E8: 76.55 | F8: =IFERROR(C8+D8+E8,"—") -> 2099.45 | G8: =IFERROR(D8/(C8+D8),"—") -> 0.065747195 | H8: =IFERROR(C8+D8,"—") -> 2022.9 | I8: 0.08 | J8: 11.95 | K8: =IF(D8="",0,J8*Supuestos!$B$63+(D8-J8)*Supuestos!$B$64) -> 754980
B9: Junio 2026 | C9: 1863.85 | D9: 148.95 | E9: 180.2 | F9: =IFERROR(C9+D9+E9,"—") -> 2193 | G9: =IFERROR(D9/(C9+D9),"—") -> 0.074001391 | H9: =IFERROR(C9+D9,"—") -> 2012.8 | I9: 0.07 | J9: 9.05 | K9: =IF(D9="",0,J9*Supuestos!$B$63+(D9-J9)*Supuestos!$B$64) -> 861120
B10: Julio 2026 | C10: 1901 | D10: 245 | E10: 14 | F10: =IFERROR(C10+D10+E10,"—") -> 2160 | G10: =IFERROR(D10/(C10+D10),"—") -> 0.11416589 | H10: =IFERROR(C10+D10,"—") -> 2146 | I10: 0.06 | J10: 13.23 | K10: =IF(D10="",0,J10*Supuestos!$B$63+(D10-J10)*Supuestos!$B$64) -> 1422372
B11: Agosto 2026 | C11: 1722.03 | D11: 278.87 | E11: 143.1 | F11: =IFERROR(C11+D11+E11,"—") -> 2144 | G11: =IFERROR(D11/(C11+D11),"—") -> 0.13937228 | H11: =IFERROR(C11+D11,"—") -> 2000.9 | I11: 0.05 | J11: 10.24 | K11: =IF(D11="",0,J11*Supuestos!$B$63+(D11-J11)*Supuestos!$B$64) -> 1636356
B12: Septiembre 2026 | C12: 2097.76 | D12: 127.13 | E12: 154.28 | F12: =IFERROR(C12+D12+E12,"—") -> 2379.17 | G12: =IFERROR(D12/(C12+D12),"—") -> 0.057139904 | H12: =IFERROR(C12+D12,"—") -> 2224.89 | I12: 0.05 | J12: 5.91 | K12: =IF(D12="",0,J12*Supuestos!$B$63+(D12-J12)*Supuestos!$B$64) -> 741504
B13: Octubre 2026 | F13: =IFERROR(C13+D13+E13,"—") -> 0 | G13: =IFERROR(D13/(C13+D13),"—") -> — | H13: =IFERROR(C13+D13,"—") -> 0 | I13: 0.05 | K13: =IF(D13="",0,J13*Supuestos!$B$63+(D13-J13)*Supuestos!$B$64) -> 0
B14: Noviembre 2026 | F14: =IFERROR(C14+D14+E14,"—") -> 0 | G14: =IFERROR(D14/(C14+D14),"—") -> — | H14: =IFERROR(C14+D14,"—") -> 0 | I14: 0.05 | K14: =IF(D14="",0,J14*Supuestos!$B$63+(D14-J14)*Supuestos!$B$64) -> 0
B15: Diciembre 2026 | F15: =IFERROR(C15+D15+E15,"—") -> 0 | G15: =IFERROR(D15/(C15+D15),"—") -> — | H15: =IFERROR(C15+D15,"—") -> 0 | I15: 0.05 | K15: =IF(D15="",0,J15*Supuestos!$B$63+(D15-J15)*Supuestos!$B$64) -> 0
B16: TOTAL / PROMEDIO | C16: =IFERROR(SUM(C8:C15),"—") -> 9474.54 | D16: =IFERROR(SUM(D8:D15),"—") -> 932.95 | E16: =IFERROR(SUM(E8:E15),"—") -> 568.13 | F16: =IFERROR(SUM(F8:F15),"—") -> 10975.62 | G16: =IFERROR(D16/(C16+D16),"—") -> 0.089642171 | H16: =IFERROR(C16+D16,"—") -> 10407.49 | J16: =IFERROR(SUM(J8:J15),"—") -> 50.38 | K16: =IFERROR(SUM(K8:K15),"—") -> 5416332
B18: 2. DEFECTOS — Control WhatsApp PENDIENTES PMK (auto desde hoja Resumen_Mensual)
B19: Mes | C19: Eventos Defecto | D19: Prendas Defect. | E19: Proyectos únicos | F19: Costo (por etapa) | G19: Motivo Principal | H19: Eventos Mot.Princ. | I19: % sobre total ev.
B20: Mayo 2026 | C20: =IFERROR(Resumen_Mensual!B2,"—") -> 25 | D20: =IFERROR(Resumen_Mensual!C2,"—") -> 50 | E20: =IFERROR(Resumen_Mensual!E2,"—") -> 0 | F20: =IFERROR(K8,"—") -> 754980 | G20: Mesa / Rollo | H20: 52 | I20: =IFERROR(H20/C20,"—") -> 2.08
B21: Junio 2026 | C21: =IFERROR(Resumen_Mensual!B3,"—") -> 55 | D21: =IFERROR(Resumen_Mensual!C3,"—") -> 157 | E21: =IFERROR(Resumen_Mensual!E3,"—") -> 0 | F21: =IFERROR(K9,"—") -> 861120 | G21: Mesa / Rollo | H21: 52 | I21: =IFERROR(H21/C21,"—") -> 0.94545455
B22: Julio 2026 | C22: =IFERROR(Resumen_Mensual!B4,"—") -> 48 | D22: =IFERROR(Resumen_Mensual!C4,"—") -> 286 | E22: =IFERROR(Resumen_Mensual!E4,"—") -> 0 | F22: =IFERROR(K10,"—") -> 1422372 | G22: Mesa / Rollo | H22: 52 | I22: =IFERROR(H22/C22,"—") -> 1.0833333
B23: Agosto 2026 | C23: =IFERROR(Resumen_Mensual!B5,"—") -> 57 | D23: =IFERROR(Resumen_Mensual!C5,"—") -> 198 | E23: =IFERROR(Resumen_Mensual!E5,"—") -> 0 | F23: =IFERROR(K11,"—") -> 1636356 | G23: Mesa / Rollo | H23: 52 | I23: =IFERROR(H23/C23,"—") -> 0.9122807
B24: Septiembre 2026 | C24: =IFERROR(Resumen_Mensual!B6,"—") -> 51 | D24: =IFERROR(Resumen_Mensual!C6,"—") -> 354 | E24: =IFERROR(Resumen_Mensual!E6,"—") -> 0 | F24: =IFERROR(K12,"—") -> 741504 | G24: Sublimación | H24: 12 | I24: =IFERROR(H24/C24,"—") -> 0.23529412
B25: Octubre 2026 | C25: =IFERROR(Resumen_Mensual!B7,"—") -> 0 | D25: =IFERROR(Resumen_Mensual!C7,"—") -> 0 | E25: =IFERROR(Resumen_Mensual!E7,"—") -> 0 | F25: =IFERROR(K13,"—") -> 0 | I25: =IFERROR(H25/C25,"—") -> —
B26: Noviembre 2026 | C26: =IFERROR(Resumen_Mensual!B8,"—") -> 0 | D26: =IFERROR(Resumen_Mensual!C8,"—") -> 0 | E26: =IFERROR(Resumen_Mensual!E8,"—") -> 0 | F26: =IFERROR(K14,"—") -> 0 | I26: =IFERROR(H26/C26,"—") -> —
B27: Diciembre 2026 | C27: =IFERROR(Resumen_Mensual!B9,"—") -> 0 | D27: =IFERROR(Resumen_Mensual!C9,"—") -> 0 | E27: =IFERROR(Resumen_Mensual!E9,"—") -> 0 | F27: =IFERROR(K15,"—") -> 0 | I27: =IFERROR(H27/C27,"—") -> —
B28: TOTAL / ACUMULADO | C28: =IFERROR(SUM(C20:C27),"—") -> 236 | D28: =IFERROR(SUM(D20:D27),"—") -> 1045 | F28: =IFERROR(SUM(F20:F27),"—") -> 5416332
B30: 3. VENTAS MENSUALES Y KPIs FINANCIEROS (ingresar mensualmente)
B31: Mes | C31: Venta Neta (CLP) | D31: Costo Reproceso | E31: % Pérdida /Venta | F31: Costo si todo fuera completo | G31: Costo Total Reproc. | H31: % Costo Total/Venta | I31: Meta % Pérdida
B32: Mayo 2026 | C32: 0 | D32: =IFERROR(K8,0) -> 754980 | E32: =IFERROR(D32/C32,"—") -> — | F32: =IFERROR(D8*Supuestos!$B$64,0) -> 798000 | G32: =IFERROR(D32,0) -> 754980 | H32: =IFERROR(G32/C32,"—") -> — | I32: 0.03
B33: Junio 2026 | C33: 0 | D33: =IFERROR(K9,0) -> 861120 | E33: =IFERROR(D33/C33,"—") -> — | F33: =IFERROR(D9*Supuestos!$B$64,0) -> 893700 | G33: =IFERROR(D33,0) -> 861120 | H33: =IFERROR(G33/C33,"—") -> — | I33: 0.03
B34: Julio 2026 | C34: 0 | D34: =IFERROR(K10,0) -> 1422372 | E34: =IFERROR(D34/C34,"—") -> — | F34: =IFERROR(D10*Supuestos!$B$64,0) -> 1470000 | G34: =IFERROR(D34,0) -> 1422372 | H34: =IFERROR(G34/C34,"—") -> — | I34: 0.03
B35: Agosto 2026 | C35: 0 | D35: =IFERROR(K11,0) -> 1636356 | E35: =IFERROR(D35/C35,"—") -> — | F35: =IFERROR(D11*Supuestos!$B$64,0) -> 1673220 | G35: =IFERROR(D35,0) -> 1636356 | H35: =IFERROR(G35/C35,"—") -> — | I35: 0.03
B36: Septiembre 2026 | D36: =IFERROR(K12,0) -> 741504 | E36: =IFERROR(D36/C36,"—") -> — | F36: =IFERROR(D12*Supuestos!$B$64,0) -> 762780 | G36: =IFERROR(D36,0) -> 741504 | H36: =IFERROR(G36/C36,"—") -> — | I36: 0.03
B37: Octubre 2026 | D37: =IFERROR(K13,0) -> 0 | E37: =IFERROR(D37/C37,"—") -> — | F37: =IFERROR(D13*Supuestos!$B$64,0) -> 0 | G37: =IFERROR(D37,0) -> 0 | H37: =IFERROR(G37/C37,"—") -> — | I37: 0.03
B38: Noviembre 2026 | D38: =IFERROR(K14,0) -> 0 | E38: =IFERROR(D38/C38,"—") -> — | F38: =IFERROR(D14*Supuestos!$B$64,0) -> 0 | G38: =IFERROR(D38,0) -> 0 | H38: =IFERROR(G38/C38,"—") -> — | I38: 0.03
B39: Diciembre 2026 | D39: =IFERROR(K15,0) -> 0 | E39: =IFERROR(D39/C39,"—") -> — | F39: =IFERROR(D15*Supuestos!$B$64,0) -> 0 | G39: =IFERROR(D39,0) -> 0 | H39: =IFERROR(G39/C39,"—") -> — | I39: 0.03
B40: TOTAL PERÍODO | C40: =IFERROR(SUM(C32:C39),0) -> 0 | D40: =IFERROR(SUM(D32:D39),0) -> 5416332 | E40: =IFERROR(D40/C40,"—") -> — | F40: =IFERROR(SUM(F32:F39),0) -> 5597700 | G40: =IFERROR(SUM(G32:G39),0) -> 5416332 | H40: =IFERROR(G40/C40,"—") -> —
B42: GUÍA DE USO MENSUAL
B43: SECCIÓN 1 — Ploteo | C43: Ingresa Mts Producción, Mts Reproceso, Mts Moldes/Muestra y Mts solo reimpresión (bloque "Costo de reproceso por etapa" del Dashboard del Control de Ploteo). El % y el costo se calculan solos.
B44: SECCIÓN 2 — Defectos | C44: Se actualiza sola desde el chat WA procesado. Solo confirma el Motivo Principal y sus eventos.
B45: SECCIÓN 3 — Ventas | C45: Ingresa la venta neta mensual (CLP). El % pérdida/venta y el costo total se calculan solos.
B46: COLORES | C46: Azul+amarillo = campo editable. Verde = calculado automático. NO editar celdas verdes.
...

Sheet Dashboard
B2: PLAYMAKER — Control de Defectos de Producción
B3: Dashboard resumen mensual | H3: Playmaker © 2026
B5: TOTAL EVENTOS | E5: PRENDAS AFECTADAS | I5: COSTO REPROCESO
B6: =COUNTA(Datos!B2:B1000) -> 236 | E6: =SUM(Datos!G2:G1000) -> 1045 | I6: =Datos_Maestro!K16 -> 5416332
B7: eventos registrados | E7: prendas | I7: =IF(SUM(Resumen_Mensual!F2:F6)=0,"Costo por etapa (metros de ploteo)",TEXT(Datos_Maestro!K16/SUM(Resumen_Mensual!F2:F6),"0.0%")&" sobre venta") -> Costo por etapa (metros de ploteo)
B11: Resumen por Motivo de Defecto
B12: Motivo | D12: Eventos | F12: Prendas | H12: Costo aprox. (prendas) | J12: % Eventos
B13: =Resumen_Motivos!A2 -> Mesa / Rollo / Papel | D13: =Resumen_Motivos!B2 -> 78 | F13: =Resumen_Motivos!C2 -> 437 | H13: =Resumen_Motivos!D2 -> 2601750 | J13: =IF(SUM(Resumen_Motivos!D$2:D$9)=0,0,Resumen_Motivos!D2/SUM(Resumen_Motivos!D$2:D$9)) -> 0.37941595
B14: =Resumen_Motivos!A3 -> Sublimación | D14: =Resumen_Motivos!B3 -> 62 | F14: =Resumen_Motivos!C3 -> 131 | H14: =Resumen_Motivos!D3 -> 884250 | J14: =IF(SUM(Resumen_Motivos!D$2:D$9)=0,0,Resumen_Motivos!D3/SUM(Resumen_Motivos!D$2:D$9)) -> 0.12895111
B15: =Resumen_Motivos!A4 -> Pendiente sub. | D15: =Resumen_Motivos!B4 -> 29 | F15: =Resumen_Motivos!C4 -> 63 | H15: =Resumen_Motivos!D4 -> 421200 | J15: =IF(SUM(Resumen_Motivos!D$2:D$9)=0,0,Resumen_Motivos!D4/SUM(Resumen_Motivos!D$2:D$9)) -> 0.06142404
B16: =Resumen_Motivos!A5 -> Corte | D16: =Resumen_Motivos!B5 -> 20 | F16: =Resumen_Motivos!C5 -> 141 | H16: =Resumen_Motivos!D5 -> 951750 | J16: =IF(SUM(Resumen_Motivos!D$2:D$9)=0,0,Resumen_Motivos!D5/SUM(Resumen_Motivos!D$2:D$9)) -> 0.13879471
B17: =Resumen_Motivos!A6 -> Faltó impresión | D17: =Resumen_Motivos!B6 -> 12 | F17: =Resumen_Motivos!C6 -> 34 | H17: =Resumen_Motivos!D6 -> 91800 | J17: =IF(SUM(Resumen_Motivos!D$2:D$9)=0,0,Resumen_Motivos!D6/SUM(Resumen_Motivos!D$2:D$9)) -> 0.013387291
B18: =Resumen_Motivos!A7 -> Confección | D18: =Resumen_Motivos!B7 -> 18 | F18: =Resumen_Motivos!C7 -> 61 | H18: =Resumen_Motivos!D7 -> 411750 | J18: =IF(SUM(Resumen_Motivos!D$2:D$9)=0,0,Resumen_Motivos!D7/SUM(Resumen_Motivos!D$2:D$9)) -> 0.060045937
B19: =Resumen_Motivos!A8 -> Diseño / Ficha | D19: =Resumen_Motivos!B8 -> 15 | F19: =Resumen_Motivos!C8 -> 175 | H19: =Resumen_Motivos!D8 -> 1181250 | J19: =IF(SUM(Resumen_Motivos!D$2:D$9)=0,0,Resumen_Motivos!D8/SUM(Resumen_Motivos!D$2:D$9)) -> 0.17226293
B20: =Resumen_Motivos!A9 -> Otro / Cambio ficha | D20: =Resumen_Motivos!B9 -> 2 | F20: =Resumen_Motivos!C9 -> 3 | H20: =Resumen_Motivos!D9 -> 313500 | J20: =IF(SUM(Resumen_Motivos!D$2:D$9)=0,0,Resumen_Motivos!D9/SUM(Resumen_Motivos!D$2:D$9)) -> 0.045718036
B21: TOTAL | D21: =SUM(Resumen_Motivos!B2:B9) -> 236 | F21: =SUM(Resumen_Motivos!C2:C9) -> 1045 | H21: =SUM(Resumen_Motivos!D2:D9) -> 6857250 | J21: "100%"
B24: Evolución Mensual
B25: Mes | D25: Eventos | F25: Prendas | H25: Costo Est. (CLP) | J25: Proyectos únicos
B26: =Resumen_Mensual!A2 -> Mayo 2026 | D26: =Resumen_Mensual!B2 -> 25 | F26: =Resumen_Mensual!C2 -> 50 | H26: =Datos_Maestro!K8 -> 754980 | J26: =Resumen_Mensual!E2 -> 0
B27: =Resumen_Mensual!A3 -> Junio 2026 | D27: =Resumen_Mensual!B3 -> 55 | F27: =Resumen_Mensual!C3 -> 157 | H27: =Datos_Maestro!K9 -> 861120 | J27: =Resumen_Mensual!E3 -> 0
B28: =Resumen_Mensual!A4 -> Julio 2026 | D28: =Resumen_Mensual!B4 -> 48 | F28: =Resumen_Mensual!C4 -> 286 | H28: =Datos_Maestro!K10 -> 1422372 | J28: =Resumen_Mensual!E4 -> 0
B29: =Resumen_Mensual!A5 -> Agosto 2026 | D29: =Resumen_Mensual!B5 -> 57 | F29: =Resumen_Mensual!C5 -> 198 | H29: =Datos_Maestro!K11 -> 1636356 | J29: =Resumen_Mensual!E5 -> 0
B30: =Resumen_Mensual!A6 -> Septiembre 2026 | D30: =Resumen_Mensual!B6 -> 51 | F30: =Resumen_Mensual!C6 -> 354 | H30: =Datos_Maestro!K12 -> 741504 | J30: =Resumen_Mensual!E6 -> 0
B33: ⚠ Nota: Los costos de reproceso se configuran en la hoja 'Supuestos'. Ingresa el costo CLP por prenda según motivo para activar los totales.
B34: Los campos en azul en la hoja 'Datos' (columna G) y los amarillos en 'Supuestos' son editables. Todo se recalcula automáticamente.
B38: Evolución Mensual — Gráfico

Sheet Datos
B1: Fecha | C1: Proyecto | D1: Referencia | E1: Detalle Prendas | F1: Motivo | G1: Prendas Defectuosas | H1: Costo Estimado (CLP) | I1: Mes | J1: Reportado por | K1: Etapa detectada
B2: 19/05/26 | C2: CSI "4 Equipos" | D2: 575 | E2: Espalda talla L arquero. Sin número en espalda. | F2: Mesa / Ploteo | G2: 1 | H2: =G2*IF(K2="Antes de sublimar",Supuestos!$B$63*1.125,IFERROR(VLOOKUP(F2,Supuestos!$A$29:$B$56,2,0),Supuestos!$C$17)) -> 6750 | I2: Mayo 2026 | J2: Yuli M. | K2: Después de sublimar
B3: 20/05/26 | C3: Sportwear FC | D3: 668 | E3: Camiseta XL corta N°1+9 (Cesar King) / Short XL N°1+9 | F3: Cambio ficha | G3: 2 | H3: =G3*IF(K3="Antes de sublimar",Supuestos!$B$63*1.125,IFERROR(VLOOKUP(F3,Supuestos!$A$29:$B$56,2,0),Supuestos!$C$17)) -> 13500 | I3: Mayo 2026 | J3: Cristina R. | K3: Después de sublimar
B4: 20/05/26 | C4: Los Compadres | D4: 220 | E4: 2 completas talla L #80 ambas | F4: Faltó impresión | G4: 2 | H4: =G4*IF(K4="Antes de sublimar",Supuestos!$B$63*1.125,IFERROR(VLOOKUP(F4,Supuestos!$A$29:$B$56,2,0),Supuestos!$C$17)) -> 5400 | I4: Mayo 2026 | J4: Sebas PMK | K4: Antes de sublimar
B5: 22/05/26 | C5: Los Compadres | D5: 220 | E5: Short TL — 1 trasero izq / 1 frente derecho | F5: Sublimación | G5: 2 | H5: =G5*IF(K5="Antes de sublimar",Supuestos!$B$63*1.125,IFERROR(VLOOKUP(F5,Supuestos!$A$29:$B$56,2,0),Supuestos!$C$17)) -> 13500 | I5: Mayo 2026 | J5: Cristina R. | K5: Después de sublimar
B6: 22/05/26 | C6: CSI 4 Equipos | D6: 575 | E6: Short TS completo N°8 (4to equipo, talla L) | F6: Sublimación | G6: 1 | H6: =G6*IF(K6="Antes de sublimar",Supuestos!$B$63*1.125,IFERROR(VLOOKUP(F6,Supuestos!$A$29:$B$56,2,0),Supuestos!$C$17)) -> 6750 | I6: Mayo 2026 | J6: Cristina R. | K6: Después de sublimar
B7: 25/05/26 | C7: Stade Preventa 5 | D7: 1333 | E7: 1 completa talla L | F7: No venía en rollo | G7: 1 | H7: =G7*IF(K7="Antes de sublimar",Supuestos!$B$63*1.125,IFERROR(VLOOKUP(F7,Supuestos!$A$29:$B$56,2,0),Supuestos!$C$17)) -> 2700 | I7: Mayo 2026 | J7: Sebas PMK | K7: Antes de sublimar
B8: 25/05/26 | C8: Evolution Training | D8: 322 | E8: 2 completas talla XL/F | F8: No venía en rollo | G8: 2 | H8: =G8*IF(K8="Antes de sublimar",Supuestos!$B$63*1.125,IFERROR(VLOOKUP(F8,Supuestos!$A$29:$B$56,2,0),Supuestos!$C$17)) -> 5400 | I8: Mayo 2026 | J8: Sebas PMK | K8: Antes de sublimar
B9: 25/05/26 | C9: Colegio La Cruz Docentes | D9: 496 | E9: 1 DEL L PMK | F9: Sublimación | G9: 1 | H9: =G9*IF(K9="Antes de sublimar",Supuestos!$B$63*1.125,IFERROR(VLOOKUP(F9,Supuestos!$A$29:$B$56,2,0),Supuestos!$C$17)) -> 6750 | I9: Mayo 2026 | J9: Sebas PMK | K9: Después de sublimar
B10: 25/05/26 | C10: Colegio La Cruz Docentes | D10: 496 | E10: Pieza para dos patas y 4 bolsillos (ambas tallas) | F10: Faltó impresión | G10: 1 | H10: =G10*IF(K10="Antes de sublimar",Supuestos!$B$63*1.125,IFERROR(VLOOKUP(F10,Supuestos!$A$29:$B$56,2,0),Supuestos!$C$17)) -> 2700 | I10: Mayo 2026 | J10: Sebas PMK | K10: Antes de sublimar
B11: 26/05/26 | C11: Colegio San Francisco FEM | D11: 591 | E11: Paño burdeo para cuellos V | F11: Corte | G11: 1 | H11: =G11*IF(K11="Antes de sublimar",Supuestos!$B$63*1.125,IFERROR(VLOOKUP(F11,Supuestos!$A$29:$B$56,2,0),Supuestos!$C$17)) -> 6750 | I11: Mayo 2026 | J11: Cristina R. | K11: Después de sublimar
B12: 26/05/26 | C12: Colegio La Cruz Local | D12: 496 | E12: Frente L (M. Training) | F12: Confección | G12: 1 | H12: =G12*IF(K12="Antes de sublimar",Supuestos!$B$63*1.125,IFERROR(VLOOKUP(F12,Supuestos!$A$29:$B$56,2,0),Supuestos!$C$17)) -> 6750 | I12: Mayo 2026 | J12: Cristina R. | K12: Después de sublimar
B13: 26/05/26 | C13: Colegio La Cruz Docentes | D13: 496 | E13: 1 DEL L PMK — no salió en pendientes | F13: Faltó impresión | G13: 1 | H13: =G13*IF(K13="Antes de sublimar",Supuestos!$B$63*1.125,IFERROR(VLOOKUP(F13,Supuestos!$A$29:$B$56,2,0),Supuestos!$C$17)) -> 2700 | I13: Mayo 2026 | J13: Cristina R. | K13: Antes de sublimar
... B87: 01-07-26 | C87: EVOLUTION TRAINNING | D87: 322 | E87: Prendas — papel entró mal | F87: Mesa / Papel | G87: 2 | H87: =G87*IF(K87="Antes de sublimar",Supuestos!$B$63*1.125,IFERROR(VLOOKUP(F87,Supuestos!$A$29:$B$56,2,0),Supuestos!$C$17)) -> 13500 | I87: Julio 2026 | J87: Sebas | K87: Después de sublimar
B88: 03-07-26 | C88: CLUB MANQUEHUE | D88: S/R | E88: Reimpresión DTF — costo total área producción | F88: Reimpresión DTF | G88: 1 | H88: 300000 | I88: Junio 2026 | J88: Cristina R. | K88: Después de sublimar
B89: 01-07-26 | C89: PUC | D89: S/R | E89: 1 Delantero XXL Rojo #18 / 1 Manga Con diseño roja M | F89: Mesa | G89: 2 | H89: =G89*IF(K89="Antes de sublimar",Supuestos!$B$63*1.125,IFERROR(VLOOKUP(F89,Supuestos!$A$29:$B$56,2,0),Supuestos!$C$17)) -> 13500 | I89: Julio 2026 | J89: Yuli | K89: Después de sublimar
B90: 01-07-26 | C90: PUC | D90: S/R | E90: 1 Delantero M rojo #1 | F90: Sublimación | G90: 1 | H90: =G90*IF(K90="Antes de sublimar",Supuestos!$B$63*1.125,IFERROR(VLOOKUP(F90,Supuestos!$A$29:$B$56,2,0),Supuestos!$C$17)) -> 6750 | I90: Julio 2026 | J90: Yuli | K90: Después de sublimar
B91: 01-07-26 | C91: EVOLUTION TRAINNING | D91: 322 | E91: 1 Del M/F — papel había entrado mal | F91: Mesa / Papel | G91: 1 | H91: =G91*IF(K91="Antes de sublimar",Supuestos!$B$63*1.125,IFERROR(VLOOKUP(F91,Supuestos!$A$29:$B$56,2,0),Supuestos!$C$17)) -> 6750 | I91: Julio 2026 | J91: Sebas | K91: Después de sublimar
B92: 03-07-26 | C92: 357 BRAND | D92: 1379/1572 | E92: Cuellos todas las tallas — error de confección por falta de muestra | F92: Confección | G92: 6 | H92: =G92*IF(K92="Antes de sublimar",Supuestos!$B$63*1.125,IFERROR(VLOOKUP(F92,Supuestos!$A$29:$B$56,2,0),Supuestos!$C$17)) -> 40500 | I92: Julio 2026 | J92: Cristina | K92: Después de sublimar
B93: 03-07-26 | C93: CONDORES AMPUTADOS | D93: 1425 | E93: Short arquero Dis1 — paño amarillo XL | F93: Mesa / Ploteo | G93: 1 | H93: =G93*IF(K93="Antes de sublimar",Supuestos!$B$63*1.125,IFERROR(VLOOKUP(F93,Supuestos!$A$29:$B$56,2,0),Supuestos!$C$17)) -> 6750 | I93: Julio 2026 | J93: Cristina | K93: Después de sublimar
B94: 03-07-26 | C94: CORRE CON FELIPE ARANDA | D94: 1416 | E94: Camisetas sin mangas: 1 talla S / 2 talla Sfem | F94: Pendiente sub. | G94: 3 | H94: =G94*IF(K94="Antes de sublimar",Supuestos!$B$63*1.125,IFERROR(VLOOKUP(F94,Supuestos!$A$29:$B$56,2,0),Supuestos!$C$17)) -> 20250 | I94: Julio 2026 | J94: Yuli | K94: Después de sublimar
B95: 03-07-26 | C95: ATLETICO BARRANCAS | D95: 1732 | E95: Delanteros masc: 1 frente M / 2 frentes L / 1 frente XL — cortados como cuello V | F95: Corte | G95: 4 | H95: =G95*IF(K95="Antes de sublimar",Supuestos!$B$63*1.125,IFERROR(VLOOKUP(F95,Supuestos!$A$29:$B$56,2,0),Supuestos!$C$17)) -> 27000 | I95: Julio 2026 | J95: Yuli | K95: Después de sublimar
B96: 03-07-26 | C96: NOMADES RC | D96: 1123 | E96: 2 cuellos XXL — no venían en mesa | F96: Mesa / Rollo | G96: 2 | H96: =G96*IF(K96="Antes de sublimar",Supuestos!$B$63*1.125,IFERROR(VLOOKUP(F96,Supuestos!$A$29:$B$56,2,0),Supuestos!$C$17)) -> 5400 | I96: Julio 2026 | J96: Yuli | K96: Antes de sublimar
B97: 03-07-26 | C97: COLEGIO ADVENTISTA VILLARRICA VOLEY | D97: 1490 | E97: Par de mangas largas masc — se imprimió como femenina | F97: Diseño | G97: 2 | H97: =G97*IF(K97="Antes de sublimar",Supuestos!$B$63*1.125,IFERROR(VLOOKUP(F97,Supuestos!$A$29:$B$56,2,0),Supuestos!$C$17)) -> 13500 | I97: Julio 2026 | J97: Yuli | K97: Después de sublimar
B98: 03-07-26 | C98: ACADEMIA FUT TRAINING | D98: 1490 | E98: Mangas largas arquero — no estaba el corte | F98: Corte | G98: 2 | H98: =G98*IF(K98="Antes de sublimar",Supuestos!$B$63*1.125,IFERROR(VLOOKUP(F98,Supuestos!$A$29:$B$56,2,0),Supuestos!$C$17)) -> 13500 | I98: Julio 2026 | J98: Yuli | K98: Después de sublimar
B99: 03-07-26 | C99: CD ALIANZA CORONEL | D99: 1480 | E99: Cuello para 6 camisetas — mala sublimación | F99: Sublimación | G99: 6 | H99: =G99*IF(K99="Antes de sublimar",Supuestos!$B$63*1.125,IFERROR(VLOOKUP(F99,Supuestos!$A$29:$B$56,2,0),Supuestos!$C$17)) -> 40500 | I99: Julio 2026 | J99: Yuli | K99: Después de sublimar
B100: 03-07-26 | C100: PUC VOLEY | D100: 1272 | E100: Azules: 2 Del L / Blancas: 6 Del L / Rojas: 3 Del L — pintitas en impresión | F100: Mesa / Ploteo | G100: 11 | H100: =G100*IF(K100="Antes de sublimar",Supuestos!$B$63*1.125,IFERROR(VLOOKUP(F100,Supuestos!$A$29:$B$56,2,0),Supuestos!$C$17)) -> 74250 | I100: Julio 2026 | J100: Sebas | K100: Después de sublimar
... B237: 29-09-26 | C237: FINTUAL C LEVEL | D237: 2581 | E237: M — 1 manga — pendiente de taller | F237: Pendiente sub. | G237: 1 | H237: =G237*IF(K237="Antes de sublimar",Supuestos!$B$63*1.125,IFERROR(VLOOKUP(F237,Supuestos!$A$29:$B$56,2,0),Supuestos!$C$17)) -> 6750 | I237: Septiembre 2026 | J237: Cristina | K237: Después de sublimar

Sheet Supuestos
A1: Supuestos de Costo — Reproceso por Metro Lineal
A3: Base de cálculo
A4: Costo por metro lineal (CLP) | B4: 6000 | C4: 1 metro lineal sublimado = $6.000 CLP
A5: Piezas por metro lineal | B5: 4 | C5: Espalda + frente + manga izq + manga der
A6: Costo por pieza (CLP) | B6: =B4/B5 -> 1500 | C6: Calculado automáticamente
A8: Equivalencia por tipo de pieza / prenda
A9: Tipo de pieza / prenda | B9: Piezas equiv. | C9: Costo unitario (CLP) | D9: Descripción
A10: Espalda (1 pieza) | B10: 0.5 | C10: =$B$4*0.5 -> 3000 | D10: En 1m caben 2 espaldas
A11: Frente camiseta (1 pieza) | B11: 0.5 | C11: =$B$4*0.5 -> 3000 | D11: En 1m caben 2 frentes
A12: Manga (1 pieza) | B12: 0.125 | C12: =$B$4*0.125 -> 750 | D12: En 1m caben 8 mangas
A13: Cuello / puño (1 pieza) | B13: 0.05 | C13: =$B$4*0.05 -> 300 | D13: En 1m caben 20 cuellos
A14: Frente short (1 pieza) | B14: 0.5 | C14: =$B$4*0.5 -> 3000 | D14: En 1m caben 2 frentes de short
A15: Trasero short (1 pieza) | B15: 0.5 | C15: =$B$4*0.5 -> 3000 | D15: En 1m caben 2 traseros de short
A16: Pierna pantalón (1 pieza) | B16: 1 | C16: =$B$4*1 -> 6000 | D16: 1 pierna ocupa 1 metro completo
A17: Prenda completa (F+E+2M+C) | B17: 1.125 | C17: =$B$4*1.125 -> 6750 | D17: 0.5+0.5+0.125×2+0.05×? — aprox 1.125m
A18: Short completo (F+T) | B18: 1 | C18: =$B$4*1 -> 6000 | D18: 0.5m frente + 0.5m trasero
A19: Par de mangas | B19: 0.25 | C19: =$B$4*0.25 -> 1500 | D19: 2 × 0.125m
A20: Par de costados / laterales | B20: 0.25 | C20: =$B$4*0.25 -> 1500 | D20: Similar a par de mangas
A21: Pantalón completo (2 piernas) | B21: 2 | C21: =$B$4*2 -> 12000 | D21: 2 piernas × 1m
A23: ⚠ Solo edita B4 (costo/metro) y B5 (piezas/metro). El resto se recalcula automáticamente.
A27: Costo por Motivo (para cálculo automático col H en Datos)
A28: Motivo | B28: Costo unitario (CLP) | C28: Base de cálculo | D28: Nota
A29: Mesa / Rollo | B29: =Supuestos!$C$17 -> 6750 | C29: Prenda completa promedio | D29: Ajustable
A30: Mesa / Sublimación | B30: =Supuestos!$C$17 -> 6750 | C30: Prenda completa promedio | D30: Ajustable
A31: Mesa / Ploteo | B31: =Supuestos!$C$17 -> 6750 | C31: Prenda completa promedio | D31: Ajustable
A32: Mesa / Diseño | B32: =Supuestos!$C$17 -> 6750 | C32: Prenda completa promedio | D32: Ajustable
A33: Mesa / Diseño (molde incorrecto) | B33: =Supuestos!$C$17 -> 6750 | C33: Prenda completa | D33: Ajustable
A34: No venía en rollo | B34: =Supuestos!$C$17 -> 6750 | C34: Prenda completa promedio | D34: Ajustable
A35: Mesa (talla incorrecta) | B35: =Supuestos!$C$17 -> 6750 | C35: Prenda completa promedio | D35: Ajustable
A36: Mesa (texto girado en cuello) | B36: =Supuestos!$C$13*10 -> 3000 | C36: ~10 cuellos promedio | D36: Ajustable
A37: Mesa incorrecta | B37: =Supuestos!$C$17 -> 6750 | C37: Prenda completa promedio | D37: Ajustable
A38: Mesa | B38: =Supuestos!$C$17 -> 6750 | C38: Prenda completa promedio | D38: Ajustable
A39: Sublimación | B39: =Supuestos!$C$17 -> 6750 | C39: Prenda completa promedio | D39: Ajustable
A40: Sublimación (negro en papel) | B40: =Supuestos!$C$10 -> 3000 | C40: Pieza suelta promedio | D40: Ajustable
A41: Mal sublimado | B41: =Supuestos!$C$17 -> 6750 | C41: Prenda completa promedio | D41: Ajustable
A42: manchitas en la sublimación | B42: =Supuestos!$C$10 -> 3000 | C42: Pieza suelta promedio | D42: Ajustable
A43: Pendiente sub. | B43: =Supuestos!$C$17 -> 6750 | C43: Prenda completa promedio | D43: Ajustable
A44: Pendiente de taller | B44: =Supuestos!$C$17 -> 6750 | C44: Prenda completa promedio | D44: Ajustable
A45: Confección | B45: =Supuestos!$C$17 -> 6750 | C45: Prenda completa promedio | D45: Ajustable
A46: Confección / Mesa | B46: =Supuestos!$C$17 -> 6750 | C46: Prenda completa promedio | D46: Ajustable
...

Sheet Resumen_Motivos
A1: Motivo | B1: Eventos | C1: Prendas | D1: Costo Est.
A2: Mesa / Rollo / Papel | B2: =COUNTIF(Datos!F2:F1000,"Mesa / Rollo")+COUNTIF(Datos!F2:F1000,"Mesa / Sublimación")+COUNTIF(Datos!F2:F1000,"Mesa / Ploteo")+COUNTIF(Datos!F2:F1000,"Mesa / Diseño")+COUNTIF(Datos!F2:F1000,"Mesa / Diseño (molde incorrecto)")+COUNTIF(Datos!F2:F1000,"Mesa (talla incorrecta)")+COUNTIF(Datos!F2:F1000,"Mesa (texto girado en cuello)")+COUNTIF(Datos!F2:F1000,"Mesa incorrecta")+COUNTIF(Datos!F2:F1000,"Mesa")+COUNTIF(Datos!F2:F1000,"No venía en rollo")+COUNTIF(Datos!F2:F1000,"Falta de paño")+COUNTIF(Datos!F2:F1000,"Error en mesa")+COUNTIF(Datos!F2:F1000,"Mesa / Papel") -> 78 | C2: =SUMIF(Datos!F2:F1000,"Mesa / Rollo",Datos!G2:G1000)+SUMIF(Datos!F2:F1000,"Mesa / Sublimación",Datos!G2:G1000)+SUMIF(Datos!F2:F1000,"Mesa / Ploteo",Datos!G2:G1000)+SUMIF(Datos!F2:F1000,"Mesa / Diseño",Datos!G2:G1000)+SUMIF(Datos!F2:F1000,"Mesa / Diseño (molde incorrecto)",Datos!G2:G1000)+SUMIF(Datos!F2:F1000,"Mesa (talla incorrecta)",Datos!G2:G1000)+SUMIF(Datos!F2:F1000,"Mesa (texto girado en cuello)",Datos!G2:G1000)+SUMIF(Datos!F2:F1000,"Mesa incorrecta",Datos!G2:G1000)+SUMIF(Datos!F2:F1000,"Mesa",Datos!G2:G1000)+SUMIF(Datos!F2:F1000,"No venía en rollo",Datos!G2:G1000)+SUMIF(Datos!F2:F1000,"Falta de paño",Datos!G2:G1000)+SUMIF(Datos!F2:F1000,"Error en mesa",Datos!G2:G1000)+SUMIF(Datos!F2:F1000,"Mesa / Papel",Datos!G2:G1000) -> 437 | D2: =SUMIF(Datos!F2:F1000,"Mesa / Rollo",Datos!H2:H1000)+SUMIF(Datos!F2:F1000,"Mesa / Sublimación",Datos!H2:H1000)+SUMIF(Datos!F2:F1000,"Mesa / Ploteo",Datos!H2:H1000)+SUMIF(Datos!F2:F1000,"Mesa / Diseño",Datos!H2:H1000)+SUMIF(Datos!F2:F1000,"Mesa / Diseño (molde incorrecto)",Datos!H2:H1000)+SUMIF(Datos!F2:F1000,"Mesa (talla incorrecta)",Datos!H2:H1000)+SUMIF(Datos!F2:F1000,"Mesa (texto girado en cuello)",Datos!H2:H1000)+SUMIF(Datos!F2:F1000,"Mesa incorrecta",Datos!H2:H1000)+SUMIF(Datos!F2:F1000,"Mesa",Datos!H2:H1000)+SUMIF(Datos!F2:F1000,"No venía en rollo",Datos!H2:H1000)+SUMIF(Datos!F2:F1000,"Falta de paño",Datos!H2:H1000)+SUMIF(Datos!F2:F1000,"Error en mesa",Datos!H2:H1000)+SUMIF(Datos!F2:F1000,"Mesa / Papel",Datos!H2:H1000) -> 2601750
A3: Sublimación | B3: =COUNTIF(Datos!F2:F1000,"Sublimación")+COUNTIF(Datos!F2:F1000,"Mal sublimado")+COUNTIF(Datos!F2:F1000,"Sublimación (negro en papel)")+COUNTIF(Datos!F2:F1000,"manchitas en la sublimación")+COUNTIF(Datos!F2:F1000,"Sublimación con estrías") -> 62 | C3: =SUMIF(Datos!F2:F1000,"Sublimación",Datos!G2:G1000)+SUMIF(Datos!F2:F1000,"Mal sublimado",Datos!G2:G1000)+SUMIF(Datos!F2:F1000,"Sublimación (negro en papel)",Datos!G2:G1000)+SUMIF(Datos!F2:F1000,"manchitas en la sublimación",Datos!G2:G1000)+SUMIF(Datos!F2:F1000,"Sublimación con estrías",Datos!G2:G1000) -> 131 | D3: =SUMIF(Datos!F2:F1000,"Sublimación",Datos!H2:H1000)+SUMIF(Datos!F2:F1000,"Mal sublimado",Datos!H2:H1000)+SUMIF(Datos!F2:F1000,"Sublimación (negro en papel)",Datos!H2:H1000)+SUMIF(Datos!F2:F1000,"manchitas en la sublimación",Datos!H2:H1000)+SUMIF(Datos!F2:F1000,"Sublimación con estrías",Datos!H2:H1000) -> 884250
A4: Pendiente sub. | B4: =COUNTIF(Datos!F2:F1000,"Pendiente sub.")+COUNTIF(Datos!F2:F1000,"Pendiente de taller")+COUNTIF(Datos!F2:F1000,"Pendiente de sublimación/taller") -> 29 | C4: =SUMIF(Datos!F2:F1000,"Pendiente sub.",Datos!G2:G1000)+SUMIF(Datos!F2:F1000,"Pendiente de taller",Datos!G2:G1000)+SUMIF(Datos!F2:F1000,"Pendiente de sublimación/taller",Datos!G2:G1000) -> 63 | D4: =SUMIF(Datos!F2:F1000,"Pendiente sub.",Datos!H2:H1000)+SUMIF(Datos!F2:F1000,"Pendiente de taller",Datos!H2:H1000)+SUMIF(Datos!F2:F1000,"Pendiente de sublimación/taller",Datos!H2:H1000) -> 421200
A5: Corte | B5: =COUNTIF(Datos!F2:F1000,"Corte")+COUNTIF(Datos!F2:F1000,"Error de corte") -> 20 | C5: =SUMIF(Datos!F2:F1000,"Corte",Datos!G2:G1000)+SUMIF(Datos!F2:F1000,"Error de corte",Datos!G2:G1000) -> 141 | D5: =SUMIF(Datos!F2:F1000,"Corte",Datos!H2:H1000)+SUMIF(Datos!F2:F1000,"Error de corte",Datos!H2:H1000) -> 951750
A6: Faltó impresión | B6: =COUNTIF(Datos!F2:F1000,"Faltó impresión")+COUNTIF(Datos!F2:F1000,"No venían en impresión")+COUNTIF(Datos!F2:F1000,"No venia en la impresión") -> 12 | C6: =SUMIF(Datos!F2:F1000,"Faltó impresión",Datos!G2:G1000)+SUMIF(Datos!F2:F1000,"No venían en impresión",Datos!G2:G1000)+SUMIF(Datos!F2:F1000,"No venia en la impresión",Datos!G2:G1000) -> 34 | D6: =SUMIF(Datos!F2:F1000,"Faltó impresión",Datos!H2:H1000)+SUMIF(Datos!F2:F1000,"No venían en impresión",Datos!H2:H1000)+SUMIF(Datos!F2:F1000,"No venia en la impresión",Datos!H2:H1000) -> 91800
A7: Confección | B7: =COUNTIF(Datos!F2:F1000,"Confección")+COUNTIF(Datos!F2:F1000,"Confección / Mesa")+COUNTIF(Datos!F2:F1000,"Error de confección")+COUNTIF(Datos!F2:F1000,"ERROR DE CONFECCIÓN POR FALTA DE MUESTRA") -> 18 | C7: =SUMIF(Datos!F2:F1000,"Confección",Datos!G2:G1000)+SUMIF(Datos!F2:F1000,"Confección / Mesa",Datos!G2:G1000)+SUMIF(Datos!F2:F1000,"Error de confección",Datos!G2:G1000)+SUMIF(Datos!F2:F1000,"ERROR DE CONFECCIÓN POR FALTA DE MUESTRA",Datos!G2:G1000) -> 61 | D7: =SUMIF(Datos!F2:F1000,"Confección",Datos!H2:H1000)+SUMIF(Datos!F2:F1000,"Confección / Mesa",Datos!H2:H1000)+SUMIF(Datos!F2:F1000,"Error de confección",Datos!H2:H1000)+SUMIF(Datos!F2:F1000,"ERROR DE CONFECCIÓN POR FALTA DE MUESTRA",Datos!H2:H1000) -> 411750
A8: Diseño / Ficha | B8: =COUNTIF(Datos!F2:F1000,"Diseño")+COUNTIF(Datos!F2:F1000,"Diseño / Ficha")+COUNTIF(Datos!F2:F1000,"Error de ficha")+COUNTIF(Datos!F2:F1000,"Error de diseño") -> 15 | C8: =SUMIF(Datos!F2:F1000,"Diseño",Datos!G2:G1000)+SUMIF(Datos!F2:F1000,"Diseño / Ficha",Datos!G2:G1000)+SUMIF(Datos!F2:F1000,"Error de ficha",Datos!G2:G1000)+SUMIF(Datos!F2:F1000,"Error de diseño",Datos!G2:G1000) -> 175 | D8: =SUMIF(Datos!F2:F1000,"Diseño",Datos!H2:H1000)+SUMIF(Datos!F2:F1000,"Diseño / Ficha",Datos!H2:H1000)+SUMIF(Datos!F2:F1000,"Error de ficha",Datos!H2:H1000)+SUMIF(Datos!F2:F1000,"Error de diseño",Datos!H2:H1000) -> 1181250
A9: Otro / Cambio ficha | B9: =COUNTIF(Datos!F2:F1000,"Cambio ficha")+COUNTIF(Datos!F2:F1000,"Reimpresión DTF")+COUNTIF(Datos!F2:F1000,"Otro") -> 2 | C9: =SUMIF(Datos!F2:F1000,"Cambio ficha",Datos!G2:G1000)+SUMIF(Datos!F2:F1000,"Reimpresión DTF",Datos!G2:G1000)+SUMIF(Datos!F2:F1000,"Otro",Datos!G2:G1000) -> 3 | D9: =SUMIF(Datos!F2:F1000,"Cambio ficha",Datos!H2:H1000)+SUMIF(Datos!F2:F1000,"Reimpresión DTF",Datos!H2:H1000)+SUMIF(Datos!F2:F1000,"Otro",Datos!H2:H1000) -> 313500

Sheet Resumen_Mensual
A1: Mes | B1: Eventos | C1: Prendas | D1: Costo Est. | E1: Proyectos únicos | F1: Venta Mensual (CLP) | G1: % Pérdida / Venta
A2: Mayo 2026 | B2: =COUNTIF(Datos!I2:I1000,"Mayo 2026") -> 25 | C2: =SUMIF(Datos!I2:I1000,"Mayo 2026",Datos!G2:G1000) -> 50 | D2: =SUMIF(Datos!I2:I1000,"Mayo 2026",Datos!H2:H1000) -> 309150 | E2: =IFERROR(SUMPRODUCT((Datos!I2:I1000="Mayo 2026")/COUNTIFS(Datos!C2:C1000,Datos!C2:C1000,Datos!I2:I1000,"Mayo 2026")),0) -> 0 | F2: 0 | G2: =IF(F2=0,"—",D2/F2) -> —
A3: Junio 2026 | B3: =COUNTIF(Datos!I2:I1000,"Junio 2026") -> 55 | C3: =SUMIF(Datos!I2:I1000,"Junio 2026",Datos!G2:G1000) -> 157 | D3: =SUMIF(Datos!I2:I1000,"Junio 2026",Datos!H2:H1000) -> 1288500 | E3: =IFERROR(SUMPRODUCT((Datos!I2:I1000="Junio 2026")/COUNTIFS(Datos!C2:C1000,Datos!C2:C1000,Datos!I2:I1000,"Junio 2026")),0) -> 0 | F3: 0 | G3: =IF(F3=0,"—",D3/F3) -> —
A4: Julio 2026 | B4: =COUNTIF(Datos!I2:I1000,"Julio 2026") -> 48 | C4: =SUMIF(Datos!I2:I1000,"Julio 2026",Datos!G2:G1000) -> 286 | D4: =SUMIF(Datos!I2:I1000,"Julio 2026",Datos!H2:H1000) -> 1723950 | E4: =IFERROR(SUMPRODUCT((Datos!I2:I1000="Julio 2026")/COUNTIFS(Datos!C2:C1000,Datos!C2:C1000,Datos!I2:I1000,"Julio 2026")),0) -> 0 | F4: 0 | G4: =IF(F4=0,"—",D4/F4) -> —
A5: Agosto 2026 | B5: =COUNTIF(Datos!I2:I1000,"Agosto 2026") -> 57 | C5: =SUMIF(Datos!I2:I1000,"Agosto 2026",Datos!G2:G1000) -> 198 | D5: =SUMIF(Datos!I2:I1000,"Agosto 2026",Datos!H2:H1000) -> 1231200 | E5: =IFERROR(SUMPRODUCT((Datos!I2:I1000="Agosto 2026")/COUNTIFS(Datos!C2:C1000,Datos!C2:C1000,Datos!I2:I1000,"Agosto 2026")),0) -> 0 | F5: 0 | G5: =IF(F5=0,"—",D5/F5) -> —
A6: Septiembre 2026 | B6: =COUNTIF(Datos!I2:I1000,"Septiembre 2026") -> 51 | C6: =SUMIF(Datos!I2:I1000,"Septiembre 2026",Datos!G2:G1000) -> 354 | D6: =SUMIF(Datos!I2:I1000,"Septiembre 2026",Datos!H2:H1000) -> 2304450 | E6: =IFERROR(SUMPRODUCT((Datos!I2:I1000="Septiembre 2026")/COUNTIFS(Datos!C2:C1000,Datos!C2:C1000,Datos!I2:I1000,"Septiembre 2026")),0) -> 0 | F6: 0 | G6: =IF(F6=0,"—",D6/F6) -> —
A7: Octubre 2026 | B7: =COUNTIF(Datos!I2:I1000,"Octubre 2026") -> 0 | C7: =SUMIF(Datos!I2:I1000,"Octubre 2026",Datos!G2:G1000) -> 0 | D7: =SUMIF(Datos!I2:I1000,"Octubre 2026",Datos!H2:H1000) -> 0 | E7: =IFERROR(SUMPRODUCT((Datos!I2:I1000="Octubre 2026")/COUNTIFS(Datos!C2:C1000,Datos!C2:C1000,Datos!I2:I1000,"Octubre 2026")),0) -> 0 | F7: 0 | G7: =IF(F7=0,"—",D7/F7) -> —
A8: Noviembre 2026 | B8: =COUNTIF(Datos!I2:I1000,"Noviembre 2026") -> 0 | C8: =SUMIF(Datos!I2:I1000,"Noviembre 2026",Datos!G2:G1000) -> 0 | D8: =SUMIF(Datos!I2:I1000,"Noviembre 2026",Datos!H2:H1000) -> 0 | E8: =IFERROR(SUMPRODUCT((Datos!I2:I1000="Noviembre 2026")/COUNTIFS(Datos!C2:C1000,Datos!C2:C1000,Datos!I2:I1000,"Noviembre 2026")),0) -> 0 | F8: 0 | G8: =IF(F8=0,"—",D8/F8) -> —
A9: Diciembre 2026 | B9: =COUNTIF(Datos!I2:I1000,"Diciembre 2026") -> 0 | C9: =SUMIF(Datos!I2:I1000,"Diciembre 2026",Datos!G2:G1000) -> 0 | D9: =SUMIF(Datos!I2:I1000,"Diciembre 2026",Datos!H2:H1000) -> 0 | E9: =IFERROR(SUMPRODUCT((Datos!I2:I1000="Diciembre 2026")/COUNTIFS(Datos!C2:C1000,Datos!C2:C1000,Datos!I2:I1000,"Diciembre 2026")),0) -> 0 | F9: 0 | G9: =IF(F9=0,"—",D9/F9) -> —
