Workbook

Sheet Ficha_costo
A1: FICHA DE COSTO — elige el molde y la tela de cada pieza
A2: Celdas azules = eliges tú. La tela vacía usa la de siempre del molde. El costo de cada pieza aparece al lado y el resumen abajo.
A3: Al cambiar de molde, borra las telas que elegiste en la columna "TELA (elige)" para partir con las de siempre.
A4: MOLDE ▶ | B4: 14 · FUTHOMU01PRO | F4: =IFERROR(INDEX(Recetas!$B$6:$B$115,MATCH($B$4,Recetas!$A$6:$A$115,0))&" · "&INDEX(Recetas!$D$6:$D$115,MATCH($B$4,Recetas!$A$6:$A$115,0))&" "&INDEX(Recetas!$E$6:$E$115,MATCH($B$4,Recetas!$A$6:$A$115,0)),"Elige un molde de la lista") -> Fútbol, pro, cuello redondo · Camiseta Masculino
A5: Consumo según: | B5: =IFERROR(IF(COUNTIFS(Mediciones!$C$6:$C$305,$B$4)>0,"Promedio de "&COUNTIFS(Mediciones!$C$6:$C$305,$B$4)&" medición(es) real(es) de corte, repartido por pieza según el despiece","Despiece"&IF(N(Parametros!$B$22)>0," + "&TEXT(Parametros!$B$22,"0%")&" de merma","")),"") -> Promedio de 2 medición(es) real(es) de corte, repartido por pieza según el despiece
A7: Pieza | B7: Cant. | C7: Grupo de tela | D7: Proceso | E7: TELA (elige) vacío = la de siempre | F7: Tela usada | G7: Metros por prenda | H7: $ por metro | I7: $ COSTO TELA de la pieza | J7: Aviso
A8: =IFERROR(INDEX(Despiece!$B$6:$B$705,MATCH($B$4&"|"&1,Despiece!$H$6:$H$705,0)),"") -> Delantero | B8: =IF(A8="","",INDEX(Despiece!$C$6:$C$705,MATCH($B$4&"|"&1,Despiece!$H$6:$H$705,0))) -> 1 | C8: =IF(A8="","",INDEX(Despiece!$D$6:$D$705,MATCH($B$4&"|"&1,Despiece!$H$6:$H$705,0))) -> Tela principal | D8: =IF(A8="","",INDEX(Despiece!$E$6:$E$705,MATCH($B$4&"|"&1,Despiece!$H$6:$H$705,0))) -> Sublimada | F8: =IF(A8="","",IF(E8<>"",E8,IFERROR(IF($C8="Tela principal",INDEX(Recetas!$K$6:$K$115,MATCH($B$4,Recetas!$A$6:$A$115,0))&"",IF($C8="Tela 2",INDEX(Recetas!$L$6:$L$115,MATCH($B$4,Recetas!$A$6:$A$115,0))&"",IF(INDEX(Recetas!$M$6:$M$115,MATCH($B$4,Recetas!$A$6:$A$115,0))&""="",INDEX(Recetas!$K$6:$K$115,MATCH($B$4,Recetas!$A$6:$A$115,0))&"",INDEX(Recetas!$M$6:$M$115,MATCH($B$4,Recetas!$A$6:$A$115,0))&""))),""))) -> MONTESIMONE TRAINING (fut pro) | G8: =IF(A8="","",IF(N(INDEX(Despiece!$F$6:$F$705,MATCH($B$4&"|"&1,Despiece!$H$6:$H$705,0)))>0,INDEX(Despiece!$F$6:$F$705,MATCH($B$4&"|"&1,Despiece!$H$6:$H$705,0))*IFERROR(IF($C8="Tela principal",INDEX(Recetas!$Q$6:$Q$115,MATCH($B$4,Recetas!$A$6:$A$115,0)),IF($C8="Tela 2",INDEX(Recetas!$T$6:$T$115,MATCH($B$4,Recetas!$A$6:$A$115,0)),INDEX(Recetas!$W$6:$W$115,MATCH($B$4,Recetas!$A$6:$A$115,0))))/IF($C8="Tela principal",INDEX(Recetas!$O$6:$O$115,MATCH($B$4,Recetas!$A$6:$A$115,0)),IF($C8="Tela 2",INDEX(Recetas!$R$6:$R$115,MATCH($B$4,Recetas!$A$6:$A$115,0)),INDEX(Recetas!$U$6:$U$115,MATCH($B$4,Recetas!$A$6:$A$115,0)))),1+Parametros!$B$22),"")) | H8: =IF(OR(A8="",F8=""),"",IFERROR(IF(N(INDEX(Telas!$I$6:$I$105,MATCH(F8,Telas!$A$6:$A$105,0)))>0,INDEX(Telas!$I$6:$I$105,MATCH(F8,Telas!$A$6:$A$105,0)),""),"")) -> 695.607 | I8: =IF(AND(ISNUMBER(G8),ISNUMBER(H8)),G8*H8,"") | J8: =IF(A8="","",IF(ISNUMBER(I8),"",IF(NOT(ISNUMBER(G8)),"Faltan los metros de esta pieza (hoja Despiece). ","")&IF(F8="","Elige la tela. ",IF(NOT(ISNUMBER(H8)),"Falta precio o peso de 1 m de "&F8&" (hoja Telas). ","")))) -> Faltan los metros de esta pieza (hoja Despiece).
A9: =IFERROR(INDEX(Despiece!$B$6:$B$705,MATCH($B$4&"|"&2,Despiece!$H$6:$H$705,0)),"") -> Espalda | B9: =IF(A9="","",INDEX(Despiece!$C$6:$C$705,MATCH($B$4&"|"&2,Despiece!$H$6:$H$705,0))) -> 1 | C9: =IF(A9="","",INDEX(Despiece!$D$6:$D$705,MATCH($B$4&"|"&2,Despiece!$H$6:$H$705,0))) -> Tela principal | D9: =IF(A9="","",INDEX(Despiece!$E$6:$E$705,MATCH($B$4&"|"&2,Despiece!$H$6:$H$705,0))) -> Sublimada | F9: =IF(A9="","",IF(E9<>"",E9,IFERROR(IF($C9="Tela principal",INDEX(Recetas!$K$6:$K$115,MATCH($B$4,Recetas!$A$6:$A$115,0))&"",IF($C9="Tela 2",INDEX(Recetas!$L$6:$L$115,MATCH($B$4,Recetas!$A$6:$A$115,0))&"",IF(INDEX(Recetas!$M$6:$M$115,MATCH($B$4,Recetas!$A$6:$A$115,0))&""="",INDEX(Recetas!$K$6:$K$115,MATCH($B$4,Recetas!$A$6:$A$115,0))&"",INDEX(Recetas!$M$6:$M$115,MATCH($B$4,Recetas!$A$6:$A$115,0))&""))),""))) -> MONTESIMONE TRAINING (fut pro) | G9: =IF(A9="","",IF(N(INDEX(Despiece!$F$6:$F$705,MATCH($B$4&"|"&2,Despiece!$H$6:$H$705,0)))>0,INDEX(Despiece!$F$6:$F$705,MATCH($B$4&"|"&2,Despiece!$H$6:$H$705,0))*IFERROR(IF($C9="Tela principal",INDEX(Recetas!$Q$6:$Q$115,MATCH($B$4,Recetas!$A$6:$A$115,0)),IF($C9="Tela 2",INDEX(Recetas!$T$6:$T$115,MATCH($B$4,Recetas!$A$6:$A$115,0)),INDEX(Recetas!$W$6:$W$115,MATCH($B$4,Recetas!$A$6:$A$115,0))))/IF($C9="Tela principal",INDEX(Recetas!$O$6:$O$115,MATCH($B$4,Recetas!$A$6:$A$115,0)),IF($C9="Tela 2",INDEX(Recetas!$R$6:$R$115,MATCH($B$4,Recetas!$A$6:$A$115,0)),INDEX(Recetas!$U$6:$U$115,MATCH($B$4,Recetas!$A$6:$A$115,0)))),1+Parametros!$B$22),"")) | H9: =IF(OR(A9="",F9=""),"",IFERROR(IF(N(INDEX(Telas!$I$6:$I$105,MATCH(F9,Telas!$A$6:$A$105,0)))>0,INDEX(Telas!$I$6:$I$105,MATCH(F9,Telas!$A$6:$A$105,0)),""),"")) -> 695.607 | I9: =IF(AND(ISNUMBER(G9),ISNUMBER(H9)),G9*H9,"") | J9: =IF(A9="","",IF(ISNUMBER(I9),"",IF(NOT(ISNUMBER(G9)),"Faltan los metros de esta pieza (hoja Despiece). ","")&IF(F9="","Elige la tela. ",IF(NOT(ISNUMBER(H9)),"Falta precio o peso de 1 m de "&F9&" (hoja Telas). ","")))) -> Faltan los metros de esta pieza (hoja Despiece).
A10: =IFERROR(INDEX(Despiece!$B$6:$B$705,MATCH($B$4&"|"&3,Despiece!$H$6:$H$705,0)),"") -> Manga | B10: =IF(A10="","",INDEX(Despiece!$C$6:$C$705,MATCH($B$4&"|"&3,Despiece!$H$6:$H$705,0))) -> 2 | C10: =IF(A10="","",INDEX(Despiece!$D$6:$D$705,MATCH($B$4&"|"&3,Despiece!$H$6:$H$705,0))) -> Tela principal | D10: =IF(A10="","",INDEX(Despiece!$E$6:$E$705,MATCH($B$4&"|"&3,Despiece!$H$6:$H$705,0))) -> Sublimada | F10: =IF(A10="","",IF(E10<>"",E10,IFERROR(IF($C10="Tela principal",INDEX(Recetas!$K$6:$K$115,MATCH($B$4,Recetas!$A$6:$A$115,0))&"",IF($C10="Tela 2",INDEX(Recetas!$L$6:$L$115,MATCH($B$4,Recetas!$A$6:$A$115,0))&"",IF(INDEX(Recetas!$M$6:$M$115,MATCH($B$4,Recetas!$A$6:$A$115,0))&""="",INDEX(Recetas!$K$6:$K$115,MATCH($B$4,Recetas!$A$6:$A$115,0))&"",INDEX(Recetas!$M$6:$M$115,MATCH($B$4,Recetas!$A$6:$A$115,0))&""))),""))) -> MONTESIMONE TRAINING (fut pro) | G10: =IF(A10="","",IF(N(INDEX(Despiece!$F$6:$F$705,MATCH($B$4&"|"&3,Despiece!$H$6:$H$705,0)))>0,INDEX(Despiece!$F$6:$F$705,MATCH($B$4&"|"&3,Despiece!$H$6:$H$705,0))*IFERROR(IF($C10="Tela principal",INDEX(Recetas!$Q$6:$Q$115,MATCH($B$4,Recetas!$A$6:$A$115,0)),IF($C10="Tela 2",INDEX(Recetas!$T$6:$T$115,MATCH($B$4,Recetas!$A$6:$A$115,0)),INDEX(Recetas!$W$6:$W$115,MATCH($B$4,Recetas!$A$6:$A$115,0))))/IF($C10="Tela principal",INDEX(Recetas!$O$6:$O$115,MATCH($B$4,Recetas!$A$6:$A$115,0)),IF($C10="Tela 2",INDEX(Recetas!$R$6:$R$115,MATCH($B$4,Recetas!$A$6:$A$115,0)),INDEX(Recetas!$U$6:$U$115,MATCH($B$4,Recetas!$A$6:$A$115,0)))),1+Parametros!$B$22),"")) | H10: =IF(OR(A10="",F10=""),"",IFERROR(IF(N(INDEX(Telas!$I$6:$I$105,MATCH(F10,Telas!$A$6:$A$105,0)))>0,INDEX(Telas!$I$6:$I$105,MATCH(F10,Telas!$A$6:$A$105,0)),""),"")) -> 695.607 | I10: =IF(AND(ISNUMBER(G10),ISNUMBER(H10)),G10*H10,"") | J10: =IF(A10="","",IF(ISNUMBER(I10),"",IF(NOT(ISNUMBER(G10)),"Faltan los metros de esta pieza (hoja Despiece). ","")&IF(F10="","Elige la tela. ",IF(NOT(ISNUMBER(H10)),"Falta precio o peso de 1 m de "&F10&" (hoja Telas). ","")))) -> Faltan los metros de esta pieza (hoja Despiece).
A11: =IFERROR(INDEX(Despiece!$B$6:$B$705,MATCH($B$4&"|"&4,Despiece!$H$6:$H$705,0)),"") -> Tira de cuello | B11: =IF(A11="","",INDEX(Despiece!$C$6:$C$705,MATCH($B$4&"|"&4,Despiece!$H$6:$H$705,0))) -> 1 | C11: =IF(A11="","",INDEX(Despiece!$D$6:$D$705,MATCH($B$4&"|"&4,Despiece!$H$6:$H$705,0))) -> Tela principal | D11: =IF(A11="","",INDEX(Despiece!$E$6:$E$705,MATCH($B$4&"|"&4,Despiece!$H$6:$H$705,0))) -> Sublimada | F11: =IF(A11="","",IF(E11<>"",E11,IFERROR(IF($C11="Tela principal",INDEX(Recetas!$K$6:$K$115,MATCH($B$4,Recetas!$A$6:$A$115,0))&"",IF($C11="Tela 2",INDEX(Recetas!$L$6:$L$115,MATCH($B$4,Recetas!$A$6:$A$115,0))&"",IF(INDEX(Recetas!$M$6:$M$115,MATCH($B$4,Recetas!$A$6:$A$115,0))&""="",INDEX(Recetas!$K$6:$K$115,MATCH($B$4,Recetas!$A$6:$A$115,0))&"",INDEX(Recetas!$M$6:$M$115,MATCH($B$4,Recetas!$A$6:$A$115,0))&""))),""))) -> MONTESIMONE TRAINING (fut pro) | G11: =IF(A11="","",IF(N(INDEX(Despiece!$F$6:$F$705,MATCH($B$4&"|"&4,Despiece!$H$6:$H$705,0)))>0,INDEX(Despiece!$F$6:$F$705,MATCH($B$4&"|"&4,Despiece!$H$6:$H$705,0))*IFERROR(IF($C11="Tela principal",INDEX(Recetas!$Q$6:$Q$115,MATCH($B$4,Recetas!$A$6:$A$115,0)),IF($C11="Tela 2",INDEX(Recetas!$T$6:$T$115,MATCH($B$4,Recetas!$A$6:$A$115,0)),INDEX(Recetas!$W$6:$W$115,MATCH($B$4,Recetas!$A$6:$A$115,0))))/IF($C11="Tela principal",INDEX(Recetas!$O$6:$O$115,MATCH($B$4,Recetas!$A$6:$A$115,0)),IF($C11="Tela 2",INDEX(Recetas!$R$6:$R$115,MATCH($B$4,Recetas!$A$6:$A$115,0)),INDEX(Recetas!$U$6:$U$115,MATCH($B$4,Recetas!$A$6:$A$115,0)))),1+Parametros!$B$22),"")) | H11: =IF(OR(A11="",F11=""),"",IFERROR(IF(N(INDEX(Telas!$I$6:$I$105,MATCH(F11,Telas!$A$6:$A$105,0)))>0,INDEX(Telas!$I$6:$I$105,MATCH(F11,Telas!$A$6:$A$105,0)),""),"")) -> 695.607 | I11: =IF(AND(ISNUMBER(G11),ISNUMBER(H11)),G11*H11,"") | J11: =IF(A11="","",IF(ISNUMBER(I11),"",IF(NOT(ISNUMBER(G11)),"Faltan los metros de esta pieza (hoja Despiece). ","")&IF(F11="","Elige la tela. ",IF(NOT(ISNUMBER(H11)),"Falta precio o peso de 1 m de "&F11&" (hoja Telas). ","")))) -> Faltan los metros de esta pieza (hoja Despiece).
A12: =IFERROR(INDEX(Despiece!$B$6:$B$705,MATCH($B$4&"|"&5,Despiece!$H$6:$H$705,0)),"") -> Paneles laterales | B12: =IF(A12="","",INDEX(Despiece!$C$6:$C$705,MATCH($B$4&"|"&5,Despiece!$H$6:$H$705,0))) -> 2 | C12: =IF(A12="","",INDEX(Despiece!$D$6:$D$705,MATCH($B$4&"|"&5,Despiece!$H$6:$H$705,0))) -> Tela 2 | D12: =IF(A12="","",INDEX(Despiece!$E$6:$E$705,MATCH($B$4&"|"&5,Despiece!$H$6:$H$705,0))) -> Sublimada | F12: =IF(A12="","",IF(E12<>"",E12,IFERROR(IF($C12="Tela principal",INDEX(Recetas!$K$6:$K$115,MATCH($B$4,Recetas!$A$6:$A$115,0))&"",IF($C12="Tela 2",INDEX(Recetas!$L$6:$L$115,MATCH($B$4,Recetas!$A$6:$A$115,0))&"",IF(INDEX(Recetas!$M$6:$M$115,MATCH($B$4,Recetas!$A$6:$A$115,0))&""="",INDEX(Recetas!$K$6:$K$115,MATCH($B$4,Recetas!$A$6:$A$115,0))&"",INDEX(Recetas!$M$6:$M$115,MATCH($B$4,Recetas!$A$6:$A$115,0))&""))),""))) -> MESH | G12: =IF(A12="","",IF(N(INDEX(Despiece!$F$6:$F$705,MATCH($B$4&"|"&5,Despiece!$H$6:$H$705,0)))>0,INDEX(Despiece!$F$6:$F$705,MATCH($B$4&"|"&5,Despiece!$H$6:$H$705,0))*IFERROR(IF($C12="Tela principal",INDEX(Recetas!$Q$6:$Q$115,MATCH($B$4,Recetas!$A$6:$A$115,0)),IF($C12="Tela 2",INDEX(Recetas!$T$6:$T$115,MATCH($B$4,Recetas!$A$6:$A$115,0)),INDEX(Recetas!$W$6:$W$115,MATCH($B$4,Recetas!$A$6:$A$115,0))))/IF($C12="Tela principal",INDEX(Recetas!$O$6:$O$115,MATCH($B$4,Recetas!$A$6:$A$115,0)),IF($C12="Tela 2",INDEX(Recetas!$R$6:$R$115,MATCH($B$4,Recetas!$A$6:$A$115,0)),INDEX(Recetas!$U$6:$U$115,MATCH($B$4,Recetas!$A$6:$A$115,0)))),1+Parametros!$B$22),"")) | H12: =IF(OR(A12="",F12=""),"",IFERROR(IF(N(INDEX(Telas!$I$6:$I$105,MATCH(F12,Telas!$A$6:$A$105,0)))>0,INDEX(Telas!$I$6:$I$105,MATCH(F12,Telas!$A$6:$A$105,0)),""),"")) | I12: =IF(AND(ISNUMBER(G12),ISNUMBER(H12)),G12*H12,"") | J12: =IF(A12="","",IF(ISNUMBER(I12),"",IF(NOT(ISNUMBER(G12)),"Faltan los metros de esta pieza (hoja Despiece). ","")&IF(F12="","Elige la tela. ",IF(NOT(ISNUMBER(H12)),"Falta precio o peso de 1 m de "&F12&" (hoja Telas). ","")))) -> Faltan los metros de esta pieza (hoja Despiece). Falta precio o peso de 1 m de MESH (hoja Telas).
A13: =IFERROR(INDEX(Despiece!$B$6:$B$705,MATCH($B$4&"|"&6,Despiece!$H$6:$H$705,0)),"") | B13: =IF(A13="","",INDEX(Despiece!$C$6:$C$705,MATCH($B$4&"|"&6,Despiece!$H$6:$H$705,0))) | C13: =IF(A13="","",INDEX(Despiece!$D$6:$D$705,MATCH($B$4&"|"&6,Despiece!$H$6:$H$705,0))) | D13: =IF(A13="","",INDEX(Despiece!$E$6:$E$705,MATCH($B$4&"|"&6,Despiece!$H$6:$H$705,0))) | F13: =IF(A13="","",IF(E13<>"",E13,IFERROR(IF($C13="Tela principal",INDEX(Recetas!$K$6:$K$115,MATCH($B$4,Recetas!$A$6:$A$115,0))&"",IF($C13="Tela 2",INDEX(Recetas!$L$6:$L$115,MATCH($B$4,Recetas!$A$6:$A$115,0))&"",IF(INDEX(Recetas!$M$6:$M$115,MATCH($B$4,Recetas!$A$6:$A$115,0))&""="",INDEX(Recetas!$K$6:$K$115,MATCH($B$4,Recetas!$A$6:$A$115,0))&"",INDEX(Recetas!$M$6:$M$115,MATCH($B$4,Recetas!$A$6:$A$115,0))&""))),""))) | G13: =IF(A13="","",IF(N(INDEX(Despiece!$F$6:$F$705,MATCH($B$4&"|"&6,Despiece!$H$6:$H$705,0)))>0,INDEX(Despiece!$F$6:$F$705,MATCH($B$4&"|"&6,Despiece!$H$6:$H$705,0))*IFERROR(IF($C13="Tela principal",INDEX(Recetas!$Q$6:$Q$115,MATCH($B$4,Recetas!$A$6:$A$115,0)),IF($C13="Tela 2",INDEX(Recetas!$T$6:$T$115,MATCH($B$4,Recetas!$A$6:$A$115,0)),INDEX(Recetas!$W$6:$W$115,MATCH($B$4,Recetas!$A$6:$A$115,0))))/IF($C13="Tela principal",INDEX(Recetas!$O$6:$O$115,MATCH($B$4,Recetas!$A$6:$A$115,0)),IF($C13="Tela 2",INDEX(Recetas!$R$6:$R$115,MATCH($B$4,Recetas!$A$6:$A$115,0)),INDEX(Recetas!$U$6:$U$115,MATCH($B$4,Recetas!$A$6:$A$115,0)))),1+Parametros!$B$22),"")) | H13: =IF(OR(A13="",F13=""),"",IFERROR(IF(N(INDEX(Telas!$I$6:$I$105,MATCH(F13,Telas!$A$6:$A$105,0)))>0,INDEX(Telas!$I$6:$I$105,MATCH(F13,Telas!$A$6:$A$105,0)),""),"")) | I13: =IF(AND(ISNUMBER(G13),ISNUMBER(H13)),G13*H13,"") | J13: =IF(A13="","",IF(ISNUMBER(I13),"",IF(NOT(ISNUMBER(G13)),"Faltan los metros de esta pieza (hoja Despiece). ","")&IF(F13="","Elige la tela. ",IF(NOT(ISNUMBER(H13)),"Falta precio o peso de 1 m de "&F13&" (hoja Telas). ",""))))
A14: =IFERROR(INDEX(Despiece!$B$6:$B$705,MATCH($B$4&"|"&7,Despiece!$H$6:$H$705,0)),"") | B14: =IF(A14="","",INDEX(Despiece!$C$6:$C$705,MATCH($B$4&"|"&7,Despiece!$H$6:$H$705,0))) | C14: =IF(A14="","",INDEX(Despiece!$D$6:$D$705,MATCH($B$4&"|"&7,Despiece!$H$6:$H$705,0))) | D14: =IF(A14="","",INDEX(Despiece!$E$6:$E$705,MATCH($B$4&"|"&7,Despiece!$H$6:$H$705,0))) | F14: =IF(A14="","",IF(E14<>"",E14,IFERROR(IF($C14="Tela principal",INDEX(Recetas!$K$6:$K$115,MATCH($B$4,Recetas!$A$6:$A$115,0))&"",IF($C14="Tela 2",INDEX(Recetas!$L$6:$L$115,MATCH($B$4,Recetas!$A$6:$A$115,0))&"",IF(INDEX(Recetas!$M$6:$M$115,MATCH($B$4,Recetas!$A$6:$A$115,0))&""="",INDEX(Recetas!$K$6:$K$115,MATCH($B$4,Recetas!$A$6:$A$115,0))&"",INDEX(Recetas!$M$6:$M$115,MATCH($B$4,Recetas!$A$6:$A$115,0))&""))),""))) | G14: =IF(A14="","",IF(N(INDEX(Despiece!$F$6:$F$705,MATCH($B$4&"|"&7,Despiece!$H$6:$H$705,0)))>0,INDEX(Despiece!$F$6:$F$705,MATCH($B$4&"|"&7,Despiece!$H$6:$H$705,0))*IFERROR(IF($C14="Tela principal",INDEX(Recetas!$Q$6:$Q$115,MATCH($B$4,Recetas!$A$6:$A$115,0)),IF($C14="Tela 2",INDEX(Recetas!$T$6:$T$115,MATCH($B$4,Recetas!$A$6:$A$115,0)),INDEX(Recetas!$W$6:$W$115,MATCH($B$4,Recetas!$A$6:$A$115,0))))/IF($C14="Tela principal",INDEX(Recetas!$O$6:$O$115,MATCH($B$4,Recetas!$A$6:$A$115,0)),IF($C14="Tela 2",INDEX(Recetas!$R$6:$R$115,MATCH($B$4,Recetas!$A$6:$A$115,0)),INDEX(Recetas!$U$6:$U$115,MATCH($B$4,Recetas!$A$6:$A$115,0)))),1+Parametros!$B$22),"")) | H14: =IF(OR(A14="",F14=""),"",IFERROR(IF(N(INDEX(Telas!$I$6:$I$105,MATCH(F14,Telas!$A$6:$A$105,0)))>0,INDEX(Telas!$I$6:$I$105,MATCH(F14,Telas!$A$6:$A$105,0)),""),"")) | I14: =IF(AND(ISNUMBER(G14),ISNUMBER(H14)),G14*H14,"") | J14: =IF(A14="","",IF(ISNUMBER(I14),"",IF(NOT(ISNUMBER(G14)),"Faltan los metros de esta pieza (hoja Despiece). ","")&IF(F14="","Elige la tela. ",IF(NOT(ISNUMBER(H14)),"Falta precio o peso de 1 m de "&F14&" (hoja Telas). ",""))))
A15: =IFERROR(INDEX(Despiece!$B$6:$B$705,MATCH($B$4&"|"&8,Despiece!$H$6:$H$705,0)),"") | B15: =IF(A15="","",INDEX(Despiece!$C$6:$C$705,MATCH($B$4&"|"&8,Despiece!$H$6:$H$705,0))) | C15: =IF(A15="","",INDEX(Despiece!$D$6:$D$705,MATCH($B$4&"|"&8,Despiece!$H$6:$H$705,0))) | D15: =IF(A15="","",INDEX(Despiece!$E$6:$E$705,MATCH($B$4&"|"&8,Despiece!$H$6:$H$705,0))) | F15: =IF(A15="","",IF(E15<>"",E15,IFERROR(IF($C15="Tela principal",INDEX(Recetas!$K$6:$K$115,MATCH($B$4,Recetas!$A$6:$A$115,0))&"",IF($C15="Tela 2",INDEX(Recetas!$L$6:$L$115,MATCH($B$4,Recetas!$A$6:$A$115,0))&"",IF(INDEX(Recetas!$M$6:$M$115,MATCH($B$4,Recetas!$A$6:$A$115,0))&""="",INDEX(Recetas!$K$6:$K$115,MATCH($B$4,Recetas!$A$6:$A$115,0))&"",INDEX(Recetas!$M$6:$M$115,MATCH($B$4,Recetas!$A$6:$A$115,0))&""))),""))) | G15: =IF(A15="","",IF(N(INDEX(Despiece!$F$6:$F$705,MATCH($B$4&"|"&8,Despiece!$H$6:$H$705,0)))>0,INDEX(Despiece!$F$6:$F$705,MATCH($B$4&"|"&8,Despiece!$H$6:$H$705,0))*IFERROR(IF($C15="Tela principal",INDEX(Recetas!$Q$6:$Q$115,MATCH($B$4,Recetas!$A$6:$A$115,0)),IF($C15="Tela 2",INDEX(Recetas!$T$6:$T$115,MATCH($B$4,Recetas!$A$6:$A$115,0)),INDEX(Recetas!$W$6:$W$115,MATCH($B$4,Recetas!$A$6:$A$115,0))))/IF($C15="Tela principal",INDEX(Recetas!$O$6:$O$115,MATCH($B$4,Recetas!$A$6:$A$115,0)),IF($C15="Tela 2",INDEX(Recetas!$R$6:$R$115,MATCH($B$4,Recetas!$A$6:$A$115,0)),INDEX(Recetas!$U$6:$U$115,MATCH($B$4,Recetas!$A$6:$A$115,0)))),1+Parametros!$B$22),"")) | H15: =IF(OR(A15="",F15=""),"",IFERROR(IF(N(INDEX(Telas!$I$6:$I$105,MATCH(F15,Telas!$A$6:$A$105,0)))>0,INDEX(Telas!$I$6:$I$105,MATCH(F15,Telas!$A$6:$A$105,0)),""),"")) | I15: =IF(AND(ISNUMBER(G15),ISNUMBER(H15)),G15*H15,"") | J15: =IF(A15="","",IF(ISNUMBER(I15),"",IF(NOT(ISNUMBER(G15)),"Faltan los metros de esta pieza (hoja Despiece). ","")&IF(F15="","Elige la tela. ",IF(NOT(ISNUMBER(H15)),"Falta precio o peso de 1 m de "&F15&" (hoja Telas). ",""))))
A16: =IFERROR(INDEX(Despiece!$B$6:$B$705,MATCH($B$4&"|"&9,Despiece!$H$6:$H$705,0)),"") | B16: =IF(A16="","",INDEX(Despiece!$C$6:$C$705,MATCH($B$4&"|"&9,Despiece!$H$6:$H$705,0))) | C16: =IF(A16="","",INDEX(Despiece!$D$6:$D$705,MATCH($B$4&"|"&9,Despiece!$H$6:$H$705,0))) | D16: =IF(A16="","",INDEX(Despiece!$E$6:$E$705,MATCH($B$4&"|"&9,Despiece!$H$6:$H$705,0))) | F16: =IF(A16="","",IF(E16<>"",E16,IFERROR(IF($C16="Tela principal",INDEX(Recetas!$K$6:$K$115,MATCH($B$4,Recetas!$A$6:$A$115,0))&"",IF($C16="Tela 2",INDEX(Recetas!$L$6:$L$115,MATCH($B$4,Recetas!$A$6:$A$115,0))&"",IF(INDEX(Recetas!$M$6:$M$115,MATCH($B$4,Recetas!$A$6:$A$115,0))&""="",INDEX(Recetas!$K$6:$K$115,MATCH($B$4,Recetas!$A$6:$A$115,0))&"",INDEX(Recetas!$M$6:$M$115,MATCH($B$4,Recetas!$A$6:$A$115,0))&""))),""))) | G16: =IF(A16="","",IF(N(INDEX(Despiece!$F$6:$F$705,MATCH($B$4&"|"&9,Despiece!$H$6:$H$705,0)))>0,INDEX(Despiece!$F$6:$F$705,MATCH($B$4&"|"&9,Despiece!$H$6:$H$705,0))*IFERROR(IF($C16="Tela principal",INDEX(Recetas!$Q$6:$Q$115,MATCH($B$4,Recetas!$A$6:$A$115,0)),IF($C16="Tela 2",INDEX(Recetas!$T$6:$T$115,MATCH($B$4,Recetas!$A$6:$A$115,0)),INDEX(Recetas!$W$6:$W$115,MATCH($B$4,Recetas!$A$6:$A$115,0))))/IF($C16="Tela principal",INDEX(Recetas!$O$6:$O$115,MATCH($B$4,Recetas!$A$6:$A$115,0)),IF($C16="Tela 2",INDEX(Recetas!$R$6:$R$115,MATCH($B$4,Recetas!$A$6:$A$115,0)),INDEX(Recetas!$U$6:$U$115,MATCH($B$4,Recetas!$A$6:$A$115,0)))),1+Parametros!$B$22),"")) | H16: =IF(OR(A16="",F16=""),"",IFERROR(IF(N(INDEX(Telas!$I$6:$I$105,MATCH(F16,Telas!$A$6:$A$105,0)))>0,INDEX(Telas!$I$6:$I$105,MATCH(F16,Telas!$A$6:$A$105,0)),""),"")) | I16: =IF(AND(ISNUMBER(G16),ISNUMBER(H16)),G16*H16,"") | J16: =IF(A16="","",IF(ISNUMBER(I16),"",IF(NOT(ISNUMBER(G16)),"Faltan los metros de esta pieza (hoja Despiece). ","")&IF(F16="","Elige la tela. ",IF(NOT(ISNUMBER(H16)),"Falta precio o peso de 1 m de "&F16&" (hoja Telas). ",""))))
A17: =IFERROR(INDEX(Despiece!$B$6:$B$705,MATCH($B$4&"|"&10,Despiece!$H$6:$H$705,0)),"") | B17: =IF(A17="","",INDEX(Despiece!$C$6:$C$705,MATCH($B$4&"|"&10,Despiece!$H$6:$H$705,0))) | C17: =IF(A17="","",INDEX(Despiece!$D$6:$D$705,MATCH($B$4&"|"&10,Despiece!$H$6:$H$705,0))) | D17: =IF(A17="","",INDEX(Despiece!$E$6:$E$705,MATCH($B$4&"|"&10,Despiece!$H$6:$H$705,0))) | F17: =IF(A17="","",IF(E17<>"",E17,IFERROR(IF($C17="Tela principal",INDEX(Recetas!$K$6:$K$115,MATCH($B$4,Recetas!$A$6:$A$115,0))&"",IF($C17="Tela 2",INDEX(Recetas!$L$6:$L$115,MATCH($B$4,Recetas!$A$6:$A$115,0))&"",IF(INDEX(Recetas!$M$6:$M$115,MATCH($B$4,Recetas!$A$6:$A$115,0))&""="",INDEX(Recetas!$K$6:$K$115,MATCH($B$4,Recetas!$A$6:$A$115,0))&"",INDEX(Recetas!$M$6:$M$115,MATCH($B$4,Recetas!$A$6:$A$115,0))&""))),""))) | G17: =IF(A17="","",IF(N(INDEX(Despiece!$F$6:$F$705,MATCH($B$4&"|"&10,Despiece!$H$6:$H$705,0)))>0,INDEX(Despiece!$F$6:$F$705,MATCH($B$4&"|"&10,Despiece!$H$6:$H$705,0))*IFERROR(IF($C17="Tela principal",INDEX(Recetas!$Q$6:$Q$115,MATCH($B$4,Recetas!$A$6:$A$115,0)),IF($C17="Tela 2",INDEX(Recetas!$T$6:$T$115,MATCH($B$4,Recetas!$A$6:$A$115,0)),INDEX(Recetas!$W$6:$W$115,MATCH($B$4,Recetas!$A$6:$A$115,0))))/IF($C17="Tela principal",INDEX(Recetas!$O$6:$O$115,MATCH($B$4,Recetas!$A$6:$A$115,0)),IF($C17="Tela 2",INDEX(Recetas!$R$6:$R$115,MATCH($B$4,Recetas!$A$6:$A$115,0)),INDEX(Recetas!$U$6:$U$115,MATCH($B$4,Recetas!$A$6:$A$115,0)))),1+Parametros!$B$22),"")) | H17: =IF(OR(A17="",F17=""),"",IFERROR(IF(N(INDEX(Telas!$I$6:$I$105,MATCH(F17,Telas!$A$6:$A$105,0)))>0,INDEX(Telas!$I$6:$I$105,MATCH(F17,Telas!$A$6:$A$105,0)),""),"")) | I17: =IF(AND(ISNUMBER(G17),ISNUMBER(H17)),G17*H17,"") | J17: =IF(A17="","",IF(ISNUMBER(I17),"",IF(NOT(ISNUMBER(G17)),"Faltan los metros de esta pieza (hoja Despiece). ","")&IF(F17="","Elige la tela. ",IF(NOT(ISNUMBER(H17)),"Falta precio o peso de 1 m de "&F17&" (hoja Telas). ",""))))
A18: =IFERROR(INDEX(Despiece!$B$6:$B$705,MATCH($B$4&"|"&11,Despiece!$H$6:$H$705,0)),"") | B18: =IF(A18="","",INDEX(Despiece!$C$6:$C$705,MATCH($B$4&"|"&11,Despiece!$H$6:$H$705,0))) | C18: =IF(A18="","",INDEX(Despiece!$D$6:$D$705,MATCH($B$4&"|"&11,Despiece!$H$6:$H$705,0))) | D18: =IF(A18="","",INDEX(Despiece!$E$6:$E$705,MATCH($B$4&"|"&11,Despiece!$H$6:$H$705,0))) | F18: =IF(A18="","",IF(E18<>"",E18,IFERROR(IF($C18="Tela principal",INDEX(Recetas!$K$6:$K$115,MATCH($B$4,Recetas!$A$6:$A$115,0))&"",IF($C18="Tela 2",INDEX(Recetas!$L$6:$L$115,MATCH($B$4,Recetas!$A$6:$A$115,0))&"",IF(INDEX(Recetas!$M$6:$M$115,MATCH($B$4,Recetas!$A$6:$A$115,0))&""="",INDEX(Recetas!$K$6:$K$115,MATCH($B$4,Recetas!$A$6:$A$115,0))&"",INDEX(Recetas!$M$6:$M$115,MATCH($B$4,Recetas!$A$6:$A$115,0))&""))),""))) | G18: =IF(A18="","",IF(N(INDEX(Despiece!$F$6:$F$705,MATCH($B$4&"|"&11,Despiece!$H$6:$H$705,0)))>0,INDEX(Despiece!$F$6:$F$705,MATCH($B$4&"|"&11,Despiece!$H$6:$H$705,0))*IFERROR(IF($C18="Tela principal",INDEX(Recetas!$Q$6:$Q$115,MATCH($B$4,Recetas!$A$6:$A$115,0)),IF($C18="Tela 2",INDEX(Recetas!$T$6:$T$115,MATCH($B$4,Recetas!$A$6:$A$115,0)),INDEX(Recetas!$W$6:$W$115,MATCH($B$4,Recetas!$A$6:$A$115,0))))/IF($C18="Tela principal",INDEX(Recetas!$O$6:$O$115,MATCH($B$4,Recetas!$A$6:$A$115,0)),IF($C18="Tela 2",INDEX(Recetas!$R$6:$R$115,MATCH($B$4,Recetas!$A$6:$A$115,0)),INDEX(Recetas!$U$6:$U$115,MATCH($B$4,Recetas!$A$6:$A$115,0)))),1+Parametros!$B$22),"")) | H18: =IF(OR(A18="",F18=""),"",IFERROR(IF(N(INDEX(Telas!$I$6:$I$105,MATCH(F18,Telas!$A$6:$A$105,0)))>0,INDEX(Telas!$I$6:$I$105,MATCH(F18,Telas!$A$6:$A$105,0)),""),"")) | I18: =IF(AND(ISNUMBER(G18),ISNUMBER(H18)),G18*H18,"") | J18: =IF(A18="","",IF(ISNUMBER(I18),"",IF(NOT(ISNUMBER(G18)),"Faltan los metros de esta pieza (hoja Despiece). ","")&IF(F18="","Elige la tela. ",IF(NOT(ISNUMBER(H18)),"Falta precio o peso de 1 m de "&F18&" (hoja Telas). ",""))))
A19: =IFERROR(INDEX(Despiece!$B$6:$B$705,MATCH($B$4&"|"&12,Despiece!$H$6:$H$705,0)),"") | B19: =IF(A19="","",INDEX(Despiece!$C$6:$C$705,MATCH($B$4&"|"&12,Despiece!$H$6:$H$705,0))) | C19: =IF(A19="","",INDEX(Despiece!$D$6:$D$705,MATCH($B$4&"|"&12,Despiece!$H$6:$H$705,0))) | D19: =IF(A19="","",INDEX(Despiece!$E$6:$E$705,MATCH($B$4&"|"&12,Despiece!$H$6:$H$705,0))) | F19: =IF(A19="","",IF(E19<>"",E19,IFERROR(IF($C19="Tela principal",INDEX(Recetas!$K$6:$K$115,MATCH($B$4,Recetas!$A$6:$A$115,0))&"",IF($C19="Tela 2",INDEX(Recetas!$L$6:$L$115,MATCH($B$4,Recetas!$A$6:$A$115,0))&"",IF(INDEX(Recetas!$M$6:$M$115,MATCH($B$4,Recetas!$A$6:$A$115,0))&""="",INDEX(Recetas!$K$6:$K$115,MATCH($B$4,Recetas!$A$6:$A$115,0))&"",INDEX(Recetas!$M$6:$M$115,MATCH($B$4,Recetas!$A$6:$A$115,0))&""))),""))) | G19: =IF(A19="","",IF(N(INDEX(Despiece!$F$6:$F$705,MATCH($B$4&"|"&12,Despiece!$H$6:$H$705,0)))>0,INDEX(Despiece!$F$6:$F$705,MATCH($B$4&"|"&12,Despiece!$H$6:$H$705,0))*IFERROR(IF($C19="Tela principal",INDEX(Recetas!$Q$6:$Q$115,MATCH($B$4,Recetas!$A$6:$A$115,0)),IF($C19="Tela 2",INDEX(Recetas!$T$6:$T$115,MATCH($B$4,Recetas!$A$6:$A$115,0)),INDEX(Recetas!$W$6:$W$115,MATCH($B$4,Recetas!$A$6:$A$115,0))))/IF($C19="Tela principal",INDEX(Recetas!$O$6:$O$115,MATCH($B$4,Recetas!$A$6:$A$115,0)),IF($C19="Tela 2",INDEX(Recetas!$R$6:$R$115,MATCH($B$4,Recetas!$A$6:$A$115,0)),INDEX(Recetas!$U$6:$U$115,MATCH($B$4,Recetas!$A$6:$A$115,0)))),1+Parametros!$B$22),"")) | H19: =IF(OR(A19="",F19=""),"",IFERROR(IF(N(INDEX(Telas!$I$6:$I$105,MATCH(F19,Telas!$A$6:$A$105,0)))>0,INDEX(Telas!$I$6:$I$105,MATCH(F19,Telas!$A$6:$A$105,0)),""),"")) | I19: =IF(AND(ISNUMBER(G19),ISNUMBER(H19)),G19*H19,"") | J19: =IF(A19="","",IF(ISNUMBER(I19),"",IF(NOT(ISNUMBER(G19)),"Faltan los metros de esta pieza (hoja Despiece). ","")&IF(F19="","Elige la tela. ",IF(NOT(ISNUMBER(H19)),"Falta precio o peso de 1 m de "&F19&" (hoja Telas). ",""))))
A20: =IFERROR(INDEX(Despiece!$B$6:$B$705,MATCH($B$4&"|"&13,Despiece!$H$6:$H$705,0)),"") | B20: =IF(A20="","",INDEX(Despiece!$C$6:$C$705,MATCH($B$4&"|"&13,Despiece!$H$6:$H$705,0))) | C20: =IF(A20="","",INDEX(Despiece!$D$6:$D$705,MATCH($B$4&"|"&13,Despiece!$H$6:$H$705,0))) | D20: =IF(A20="","",INDEX(Despiece!$E$6:$E$705,MATCH($B$4&"|"&13,Despiece!$H$6:$H$705,0))) | F20: =IF(A20="","",IF(E20<>"",E20,IFERROR(IF($C20="Tela principal",INDEX(Recetas!$K$6:$K$115,MATCH($B$4,Recetas!$A$6:$A$115,0))&"",IF($C20="Tela 2",INDEX(Recetas!$L$6:$L$115,MATCH($B$4,Recetas!$A$6:$A$115,0))&"",IF(INDEX(Recetas!$M$6:$M$115,MATCH($B$4,Recetas!$A$6:$A$115,0))&""="",INDEX(Recetas!$K$6:$K$115,MATCH($B$4,Recetas!$A$6:$A$115,0))&"",INDEX(Recetas!$M$6:$M$115,MATCH($B$4,Recetas!$A$6:$A$115,0))&""))),""))) | G20: =IF(A20="","",IF(N(INDEX(Despiece!$F$6:$F$705,MATCH($B$4&"|"&13,Despiece!$H$6:$H$705,0)))>0,INDEX(Despiece!$F$6:$F$705,MATCH($B$4&"|"&13,Despiece!$H$6:$H$705,0))*IFERROR(IF($C20="Tela principal",INDEX(Recetas!$Q$6:$Q$115,MATCH($B$4,Recetas!$A$6:$A$115,0)),IF($C20="Tela 2",INDEX(Recetas!$T$6:$T$115,MATCH($B$4,Recetas!$A$6:$A$115,0)),INDEX(Recetas!$W$6:$W$115,MATCH($B$4,Recetas!$A$6:$A$115,0))))/IF($C20="Tela principal",INDEX(Recetas!$O$6:$O$115,MATCH($B$4,Recetas!$A$6:$A$115,0)),IF($C20="Tela 2",INDEX(Recetas!$R$6:$R$115,MATCH($B$4,Recetas!$A$6:$A$115,0)),INDEX(Recetas!$U$6:$U$115,MATCH($B$4,Recetas!$A$6:$A$115,0)))),1+Parametros!$B$22),"")) | H20: =IF(OR(A20="",F20=""),"",IFERROR(IF(N(INDEX(Telas!$I$6:$I$105,MATCH(F20,Telas!$A$6:$A$105,0)))>0,INDEX(Telas!$I$6:$I$105,MATCH(F20,Telas!$A$6:$A$105,0)),""),"")) | I20: =IF(AND(ISNUMBER(G20),ISNUMBER(H20)),G20*H20,"") | J20: =IF(A20="","",IF(ISNUMBER(I20),"",IF(NOT(ISNUMBER(G20)),"Faltan los metros de esta pieza (hoja Despiece). ","")&IF(F20="","Elige la tela. ",IF(NOT(ISNUMBER(H20)),"Falta precio o peso de 1 m de "&F20&" (hoja Telas). ",""))))
A21: =IFERROR(INDEX(Despiece!$B$6:$B$705,MATCH($B$4&"|"&14,Despiece!$H$6:$H$705,0)),"") | B21: =IF(A21="","",INDEX(Despiece!$C$6:$C$705,MATCH($B$4&"|"&14,Despiece!$H$6:$H$705,0))) | C21: =IF(A21="","",INDEX(Despiece!$D$6:$D$705,MATCH($B$4&"|"&14,Despiece!$H$6:$H$705,0))) | D21: =IF(A21="","",INDEX(Despiece!$E$6:$E$705,MATCH($B$4&"|"&14,Despiece!$H$6:$H$705,0))) | F21: =IF(A21="","",IF(E21<>"",E21,IFERROR(IF($C21="Tela principal",INDEX(Recetas!$K$6:$K$115,MATCH($B$4,Recetas!$A$6:$A$115,0))&"",IF($C21="Tela 2",INDEX(Recetas!$L$6:$L$115,MATCH($B$4,Recetas!$A$6:$A$115,0))&"",IF(INDEX(Recetas!$M$6:$M$115,MATCH($B$4,Recetas!$A$6:$A$115,0))&""="",INDEX(Recetas!$K$6:$K$115,MATCH($B$4,Recetas!$A$6:$A$115,0))&"",INDEX(Recetas!$M$6:$M$115,MATCH($B$4,Recetas!$A$6:$A$115,0))&""))),""))) | G21: =IF(A21="","",IF(N(INDEX(Despiece!$F$6:$F$705,MATCH($B$4&"|"&14,Despiece!$H$6:$H$705,0)))>0,INDEX(Despiece!$F$6:$F$705,MATCH($B$4&"|"&14,Despiece!$H$6:$H$705,0))*IFERROR(IF($C21="Tela principal",INDEX(Recetas!$Q$6:$Q$115,MATCH($B$4,Recetas!$A$6:$A$115,0)),IF($C21="Tela 2",INDEX(Recetas!$T$6:$T$115,MATCH($B$4,Recetas!$A$6:$A$115,0)),INDEX(Recetas!$W$6:$W$115,MATCH($B$4,Recetas!$A$6:$A$115,0))))/IF($C21="Tela principal",INDEX(Recetas!$O$6:$O$115,MATCH($B$4,Recetas!$A$6:$A$115,0)),IF($C21="Tela 2",INDEX(Recetas!$R$6:$R$115,MATCH($B$4,Recetas!$A$6:$A$115,0)),INDEX(Recetas!$U$6:$U$115,MATCH($B$4,Recetas!$A$6:$A$115,0)))),1+Parametros!$B$22),"")) | H21: =IF(OR(A21="",F21=""),"",IFERROR(IF(N(INDEX(Telas!$I$6:$I$105,MATCH(F21,Telas!$A$6:$A$105,0)))>0,INDEX(Telas!$I$6:$I$105,MATCH(F21,Telas!$A$6:$A$105,0)),""),"")) | I21: =IF(AND(ISNUMBER(G21),ISNUMBER(H21)),G21*H21,"") | J21: =IF(A21="","",IF(ISNUMBER(I21),"",IF(NOT(ISNUMBER(G21)),"Faltan los metros de esta pieza (hoja Despiece). ","")&IF(F21="","Elige la tela. ",IF(NOT(ISNUMBER(H21)),"Falta precio o peso de 1 m de "&F21&" (hoja Telas). ",""))))
A22: =IFERROR(INDEX(Despiece!$B$6:$B$705,MATCH($B$4&"|"&15,Despiece!$H$6:$H$705,0)),"") | B22: =IF(A22="","",INDEX(Despiece!$C$6:$C$705,MATCH($B$4&"|"&15,Despiece!$H$6:$H$705,0))) | C22: =IF(A22="","",INDEX(Despiece!$D$6:$D$705,MATCH($B$4&"|"&15,Despiece!$H$6:$H$705,0))) | D22: =IF(A22="","",INDEX(Despiece!$E$6:$E$705,MATCH($B$4&"|"&15,Despiece!$H$6:$H$705,0))) | F22: =IF(A22="","",IF(E22<>"",E22,IFERROR(IF($C22="Tela principal",INDEX(Recetas!$K$6:$K$115,MATCH($B$4,Recetas!$A$6:$A$115,0))&"",IF($C22="Tela 2",INDEX(Recetas!$L$6:$L$115,MATCH($B$4,Recetas!$A$6:$A$115,0))&"",IF(INDEX(Recetas!$M$6:$M$115,MATCH($B$4,Recetas!$A$6:$A$115,0))&""="",INDEX(Recetas!$K$6:$K$115,MATCH($B$4,Recetas!$A$6:$A$115,0))&"",INDEX(Recetas!$M$6:$M$115,MATCH($B$4,Recetas!$A$6:$A$115,0))&""))),""))) | G22: =IF(A22="","",IF(N(INDEX(Despiece!$F$6:$F$705,MATCH($B$4&"|"&15,Despiece!$H$6:$H$705,0)))>0,INDEX(Despiece!$F$6:$F$705,MATCH($B$4&"|"&15,Despiece!$H$6:$H$705,0))*IFERROR(IF($C22="Tela principal",INDEX(Recetas!$Q$6:$Q$115,MATCH($B$4,Recetas!$A$6:$A$115,0)),IF($C22="Tela 2",INDEX(Recetas!$T$6:$T$115,MATCH($B$4,Recetas!$A$6:$A$115,0)),INDEX(Recetas!$W$6:$W$115,MATCH($B$4,Recetas!$A$6:$A$115,0))))/IF($C22="Tela principal",INDEX(Recetas!$O$6:$O$115,MATCH($B$4,Recetas!$A$6:$A$115,0)),IF($C22="Tela 2",INDEX(Recetas!$R$6:$R$115,MATCH($B$4,Recetas!$A$6:$A$115,0)),INDEX(Recetas!$U$6:$U$115,MATCH($B$4,Recetas!$A$6:$A$115,0)))),1+Parametros!$B$22),"")) | H22: =IF(OR(A22="",F22=""),"",IFERROR(IF(N(INDEX(Telas!$I$6:$I$105,MATCH(F22,Telas!$A$6:$A$105,0)))>0,INDEX(Telas!$I$6:$I$105,MATCH(F22,Telas!$A$6:$A$105,0)),""),"")) | I22: =IF(AND(ISNUMBER(G22),ISNUMBER(H22)),G22*H22,"") | J22: =IF(A22="","",IF(ISNUMBER(I22),"",IF(NOT(ISNUMBER(G22)),"Faltan los metros de esta pieza (hoja Despiece). ","")&IF(F22="","Elige la tela. ",IF(NOT(ISNUMBER(H22)),"Falta precio o peso de 1 m de "&F22&" (hoja Telas). ",""))))
A24: RESUMEN — COSTO DE PRODUCCIÓN DE UNA PRENDA (neto, sin IVA)
A25: Tela (suma de las piezas) | I25: =IF(COUNTA(A8:A22)-COUNTBLANK(A8:A22)=0,"",IF(SUMPRODUCT((A8:A22<>"")*NOT(ISNUMBER(I8:I22)))>0,"Faltan datos ↑",SUM(I8:I22))) -> Faltan datos ↑
A26: Papel y tinta de sublimación | I26: =IFERROR(INDEX(Recetas!$AA$6:$AA$115,MATCH($B$4,Recetas!$A$6:$A$115,0))*1,"Faltan metros impresos") -> 0 | J26: =IFERROR(TEXT(INDEX(Recetas!$Y$6:$Y$115,MATCH($B$4,Recetas!$A$6:$A$115,0)),"0.00")&" m impresos × "&TEXT(Parametros!$B$19,"$#,##0")&" por metro"&IF(N(Parametros!$B$19)=0," ← OJO: costo de impresión en $0 (Parametros)",""),"") -> 1.90 m impresos × $0 por metro ← OJO: costo de impresión en $0 (Parametros)
A27: Confección (taller, a trato) | I27: =IFERROR(INDEX(Recetas!$AB$6:$AB$115,MATCH($B$4,Recetas!$A$6:$A$115,0))*1,"Falta tipo/precio de confección") -> 2000 | J27: =IFERROR(INDEX(Recetas!$F$6:$F$115,MATCH($B$4,Recetas!$A$6:$A$115,0))&"","") -> Camiseta De Futbol
A28: Avíos | I28: =IFERROR(INDEX(Recetas!$AC$6:$AC$115,MATCH($B$4,Recetas!$A$6:$A$115,0))*1,0) -> 0 | J28: =IFERROR(IF(INDEX(Recetas!$G$6:$G$115,MATCH($B$4,Recetas!$A$6:$A$115,0))&""="","Sin avíos",INDEX(Recetas!$G$6:$G$115,MATCH($B$4,Recetas!$A$6:$A$115,0))&" × "&INDEX(Recetas!$H$6:$H$115,MATCH($B$4,Recetas!$A$6:$A$115,0))&IF(INDEX(Recetas!$I$6:$I$115,MATCH($B$4,Recetas!$A$6:$A$115,0))&""="",""," + "&INDEX(Recetas!$I$6:$I$115,MATCH($B$4,Recetas!$A$6:$A$115,0))&" × "&INDEX(Recetas!$J$6:$J$115,MATCH($B$4,Recetas!$A$6:$A$115,0)))),"") -> Sin avíos
A29: Extras (escribe: bordado, DTF, escudo…) | J29: Por prenda
A30: COSTO DE PRODUCCIÓN | I30: =IFERROR(I25+I26+I27+I28+N(I29),"Completa los datos ↑") -> Completa los datos ↑
A32: PRECIO Y GANANCIA
A33: ="Precio mínimo de venta (neto): costo × "&TEXT(Parametros!$B$12,"0.00")&" (gastos generales "&TEXT(Parametros!$B$8,"0.0%")&" + ganancia "&TEXT(Parametros!$B$11,"0%")&")" -> Precio mínimo de venta (neto): costo × 2.40 (gastos generales 43.4% + ganancia 15%) | I33: =IF(ISNUMBER(I30),I30*Parametros!$B$12,"")
A34: Precio de venta actual, neto (escribe)
A35: Gastos generales que paga esta prenda | I35: =IF(N(I34)>0,I34*Parametros!$B$8,"")
A36: GANANCIA POR PRENDA | I36: =IF(AND(ISNUMBER(I30),N(I34)>0),I34-I30-I35,"") | J36: =IF(ISNUMBER(I36),TEXT(I36/I34,"0.0%")&" del precio"&IF(I36<0," ← PIERDE PLATA",IF(I36/I34<Parametros!$B$11," ← bajo la meta","")),"")
A38: Corte, ploteo, sublimado y estampado (mano de obra con sueldo) NO van aquí: están en los gastos generales que cobra el sistema de ventas. Si se sumaran, se cobrarían dos veces.

Sheet Como_usar
A1: RECETAS DE COSTO — PLAYMAKER v8
B3: QUÉ ES
B4: El COSTO DE PRODUCCIÓN de cada prenda: tela + papel y tinta + confección + avíos, todo neto (sin IVA). No lleva gastos generales: esos los aplica el sistema de ventas como % del precio.
B5: IDEA CLAVE
B6: Un molde gasta los MISMOS METROS con cualquier tela, y el taller cobra lo MISMO con cualquier tela. Lo único que cambia al cambiar de tela es el $ por metro. Por eso el consumo se guarda por molde, en metros, y la tela se elige aparte.
B7: EMPIEZA AQUÍ
B8: Hoja "Ficha_costo": eliges el molde, ves sus piezas, eliges la tela de cada pieza y al lado sale el costo de esa pieza. Abajo, el costo de producción completo y el precio mínimo.
B9: 1. Telas
B10: Una fila por tela: precio por kg (neto, o el de la factura con IVA) y el PESO DE 1 METRO (cortar 1 m de ancho completo y pesarlo). Sin el peso por metro no se puede pasar de kg a metros.
B11: 2. Despiece
B12: Las piezas de cada molde y en qué grupo de tela va cada una (Tela principal / Tela 2 / Tela 3). Para poner las mangas en otra tela, cambia su grupo a "Tela 2". Metros por prenda: de la marcada (tizado) del plotter.
B13: 3. Mediciones
B14: El consumo REAL: después de cada corte, anota tela, prendas cortadas y kg usados. Se pasa solo a metros por prenda y la receta usa el promedio. Mientras más cortes anotes, más exacto. Ya incluye la merma real.
... B26: Pesar 1 metro de cada tela · metros por pieza del despiece (tizado) · papel: metros por rollo · tinta: ml por metro · confirmar precios de confección · meta de ganancia.

Sheet Recetas
A1: RECETAS POR MOLDE — costo de producción de UNA prenda (neto, sin gastos generales)
A2: Consumo en metros: sale del promedio de las Mediciones reales; si no hay, del Despiece (+ merma). Las telas de aquí son las de siempre: para probar otras, usa "Comparar telas" o "Productos".
A3: ="Recetas listas: "&COUNTIF(AG6:AG115,"Lista*")&" de "&COUNTA(A6:A115)&" · Precio mínimo = costo × "&TEXT(Parametros!B12,"0.00")&" (gastos generales "&TEXT(Parametros!B8,"0.0%")&" + meta "&TEXT(Parametros!B11,"0%")&")" -> Recetas listas: 1 de 58 · Precio mínimo = costo × 2.40 (gastos generales 43.4% + meta 15%)
A4: MOLDE | F4: LO ESCRIBES TÚ | O4: CONSUMO TELA PRINCIPAL | R4: CONSUMO TELA 2 | U4: CONSUMO TELA 3 | X4: IMPRESIÓN | Z4: COSTO DE PRODUCCIÓN POR PRENDA ($, neto)
A5: Molde | B5: Descripción | C5: Deporte | D5: Prenda | E5: Calce | F5: Confección (tipo) | G5: Avío 1 | H5: Cant. | I5: Avío 2 | J5: Cant. | K5: Tela principal (la de siempre) | L5: Tela 2 | M5: Tela 3 | N5: Consumo según (vacío = automático) | O5: Despiece (m) | P5: Real medido (m) | Q5: USADO (m) | R5: Despiece (m) | S5: Real medido (m) | T5: USADO (m) | U5: Despiece (m) | V5: Real medido (m) | W5: USADO (m) | X5: Metros impresos (si lo mides) | Y5: METROS IMPRESOS | Z5: $ Tela | AA5: $ Papel y tinta | AB5: $ Confección | AC5: $ Avíos | AD5: COSTO DE PRODUCCIÓN | AE5: Precio mínimo (referencia) | AF5: Prendas por kg (tela principal) | AG5: Qué falta | AH5: Notas
A6: 01 · FUTMUJU01 | B6: Fútbol, cuello redondo | C6: Fútbol | D6: Camiseta | E6: Femenino | F6: Camiseta De Futbol | O6: =IF($A6="","",IF(COUNTIFS(Despiece!$A$6:$A$705,$A6,Despiece!$D$6:$D$705,"Tela principal",Despiece!$F$6:$F$705,">0")=0,"",SUMIFS(Despiece!$F$6:$F$705,Despiece!$A$6:$A$705,$A6,Despiece!$D$6:$D$705,"Tela principal"))) | P6: =IF($A6="","",IFERROR(AVERAGEIFS(Mediciones!$K$6:$K$305,Mediciones!$C$6:$C$305,$A6,Mediciones!$D$6:$D$305,"Tela principal"),"")) | Q6: =IF($A6="","",IF(N(IF($N6="Despiece",IF(ISNUMBER(O6),O6*(1+Parametros!$B$22),IF(COUNTIFS(Despiece!$A$6:$A$705,$A6,Despiece!$D$6:$D$705,"Tela principal")>0,"",0)),IF($N6="Medición real",IF(ISNUMBER(P6),P6,IF(COUNTIFS(Mediciones!$C$6:$C$305,$A6,Mediciones!$D$6:$D$305,"Tela principal")>0,"",0)),IF(ISNUMBER(P6),P6,IF(ISNUMBER(O6),O6*(1+Parametros!$B$22),IF(OR(COUNTIFS(Despiece!$A$6:$A$705,$A6,Despiece!$D$6:$D$705,"Tela principal")>0,COUNTIFS(Mediciones!$C$6:$C$305,$A6,Mediciones!$D$6:$D$305,"Tela principal")>0),"",0))))))=0,"",IF($N6="Despiece",IF(ISNUMBER(O6),O6*(1+Parametros!$B$22),IF(COUNTIFS(Despiece!$A$6:$A$705,$A6,Despiece!$D$6:$D$705,"Tela principal")>0,"",0)),IF($N6="Medición real",IF(ISNUMBER(P6),P6,IF(COUNTIFS(Mediciones!$C$6:$C$305,$A6,Mediciones!$D$6:$D$305,"Tela principal")>0,"",0)),IF(ISNUMBER(P6),P6,IF(ISNUMBER(O6),O6*(1+Parametros!$B$22),IF(OR(COUNTIFS(Despiece!$A$6:$A$705,$A6,Despiece!$D$6:$D$705,"Tela principal")>0,COUNTIFS(Mediciones!$C$6:$C$305,$A6,Mediciones!$D$6:$D$305,"Tela principal")>0),"",0))))))) | R6: =IF($A6="","",IF(COUNTIFS(Despiece!$A$6:$A$705,$A6,Despiece!$D$6:$D$705,"Tela 2",Despiece!$F$6:$F$705,">0")=0,"",SUMIFS(Despiece!$F$6:$F$705,Despiece!$A$6:$A$705,$A6,Despiece!$D$6:$D$705,"Tela 2"))) | S6: =IF($A6="","",IFERROR(AVERAGEIFS(Mediciones!$K$6:$K$305,Mediciones!$C$6:$C$305,$A6,Mediciones!$D$6:$D$305,"Tela 2"),"")) | T6: =IF($A6="","",IF($N6="Despiece",IF(ISNUMBER(R6),R6*(1+Parametros!$B$22),IF(COUNTIFS(Despiece!$A$6:$A$705,$A6,Despiece!$D$6:$D$705,"Tela 2")>0,"",0)),IF($N6="Medición real",IF(ISNUMBER(S6),S6,IF(COUNTIFS(Mediciones!$C$6:$C$305,$A6,Mediciones!$D$6:$D$305,"Tela 2")>0,"",0)),IF(ISNUMBER(S6),S6,IF(ISNUMBER(R6),R6*(1+Parametros!$B$22),IF(OR(COUNTIFS(Despiece!$A$6:$A$705,$A6,Despiece!$D$6:$D$705,"Tela 2")>0,COUNTIFS(Mediciones!$C$6:$C$305,$A6,Mediciones!$D$6:$D$305,"Tela 2")>0),"",0)))))) -> 0 | U6: =IF($A6="","",IF(COUNTIFS(Despiece!$A$6:$A$705,$A6,Despiece!$D$6:$D$705,"Tela 3",Despiece!$F$6:$F$705,">0")=0,"",SUMIFS(Despiece!$F$6:$F$705,Despiece!$A$6:$A$705,$A6,Despiece!$D$6:$D$705,"Tela 3"))) | V6: =IF($A6="","",IFERROR(AVERAGEIFS(Mediciones!$K$6:$K$305,Mediciones!$C$6:$C$305,$A6,Mediciones!$D$6:$D$305,"Tela 3"),"")) | W6: =IF($A6="","",IF($N6="Despiece",IF(ISNUMBER(U6),U6*(1+Parametros!$B$22),IF(COUNTIFS(Despiece!$A$6:$A$705,$A6,Despiece!$D$6:$D$705,"Tela 3")>0,"",0)),IF($N6="Medición real",IF(ISNUMBER(V6),V6,IF(COUNTIFS(Mediciones!$C$6:$C$305,$A6,Mediciones!$D$6:$D$305,"Tela 3")>0,"",0)),IF(ISNUMBER(V6),V6,IF(ISNUMBER(U6),U6*(1+Parametros!$B$22),IF(OR(COUNTIFS(Despiece!$A$6:$A$705,$A6,Despiece!$D$6:$D$705,"Tela 3")>0,COUNTIFS(Mediciones!$C$6:$C$305,$A6,Mediciones!$D$6:$D$305,"Tela 3")>0),"",0)))))) -> 0 | Y6: =IF($A6="","",IF(ISNUMBER(X6),X6,IF(COUNTIFS(Despiece!$A$6:$A$705,$A6,Despiece!$E$6:$E$705,"Sublimada",Despiece!$F$6:$F$705,">0")>0,SUMIFS(Despiece!$F$6:$F$705,Despiece!$A$6:$A$705,$A6,Despiece!$E$6:$E$705,"Sublimada")*(1+Parametros!$B$22),IF(COUNTIFS(Despiece!$A$6:$A$705,$A6,Despiece!$E$6:$E$705,"Sublimada")=0,0,"")))) | Z6: =IF($A6="","",IFERROR(IF(ISNUMBER(Q6),IF(Q6=0,0,Q6*INDEX(Telas!$I$6:$I$105,MATCH(K6,Telas!$A$6:$A$105,0))),NA())+IF(ISNUMBER(T6),IF(T6=0,0,T6*INDEX(Telas!$I$6:$I$105,MATCH(L6,Telas!$A$6:$A$105,0))),NA())+IF(ISNUMBER(W6),IF(W6=0,0,W6*INDEX(Telas!$I$6:$I$105,MATCH(IF(M6="",K6,M6),Telas!$A$6:$A$105,0))),NA()),"")) | AA6: =IF($A6="","",IF(ISNUMBER(Y6),Y6*Parametros!$B$19,"")) | AB6: =IF(OR($A6="",F6=""),"",IFERROR(INDEX(Confeccion!$B$6:$B$125,MATCH(F6,Confeccion!$A$6:$A$125,0)),"")) -> 2000 | AC6: =IF($A6="","",IFERROR(N(H6)*IF(G6="",0,INDEX(Avios!$C$6:$C$65,MATCH(G6,Avios!$A$6:$A$65,0)))+N(J6)*IF(I6="",0,INDEX(Avios!$C$6:$C$65,MATCH(I6,Avios!$A$6:$A$65,0))),"")) -> 0 | AD6: =IF($A6="","",IFERROR(Z6+AA6+AB6+AC6,"")) | AE6: =IF(ISNUMBER(AD6),AD6*Parametros!$B$12,"") | AF6: =IF(AND(ISNUMBER(Q6),K6<>""),IFERROR(1/(Q6*INDEX(Telas!$G$6:$G$105,MATCH(K6,Telas!$A$6:$A$105,0))),""),"") | AG6: =IF($A6="","",IF(ISNUMBER(AD6),IF(AND(N(Y6)>0,N(Parametros!$B$19)=0),"Lista, pero sin costo de impresión (Parametros)","Lista"),IF(Q6="","Consumo tela principal (Despiece o Mediciones). ","")&IF(COUNTIFS(Mediciones!$C$6:$C$305,$A6,Mediciones!$K$6:$K$305,"")>0,"Pesar 1 m de la tela medida (Telas, kg por metro). ","")&IF(T6="","Consumo Tela 2. ","")&IF(W6="","Consumo Tela 3. ","")&IF(K6="","Elegir tela principal. ",IF(ISERROR(INDEX(Telas!$I$6:$I$105,MATCH(K6,Telas!$A$6:$A$105,0))*1),"Precio o peso por metro de "&K6&". ",""))&IF(AND(N(T6)>0,L6=""),"Elegir Tela 2. ",IF(AND(N(T6)>0,ISERROR(INDEX(Telas!$I$6:$I$105,MATCH(L6,Telas!$A$6:$A$105,0))*1)),"Precio o peso por metro de "&L6&". ",""))&IF(Y6="","Metros impresos. ","")&IF(F6="","Tipo de confección. ",IF(AB6="","Precio de confección. ","")))) -> Consumo tela principal (Despiece o Mediciones). Elegir tela principal. Metros impresos. | AH6: Confección sugerida por el tipo de molde: confirmar. Falta ficha de corte.
A7: 02 · FUTHOMU01 | B7: Fútbol, cuello redondo | C7: Fútbol | D7: Camiseta | E7: Masculino | F7: Camiseta De Futbol | O7: =IF($A7="","",IF(COUNTIFS(Despiece!$A$6:$A$705,$A7,Despiece!$D$6:$D$705,"Tela principal",Despiece!$F$6:$F$705,">0")=0,"",SUMIFS(Despiece!$F$6:$F$705,Despiece!$A$6:$A$705,$A7,Despiece!$D$6:$D$705,"Tela principal"))) | P7: =IF($A7="","",IFERROR(AVERAGEIFS(Mediciones!$K$6:$K$305,Mediciones!$C$6:$C$305,$A7,Mediciones!$D$6:$D$305,"Tela principal"),"")) | Q7: =IF($A7="","",IF(N(IF($N7="Despiece",IF(ISNUMBER(O7),O7*(1+Parametros!$B$22),IF(COUNTIFS(Despiece!$A$6:$A$705,$A7,Despiece!$D$6:$D$705,"Tela principal")>0,"",0)),IF($N7="Medición real",IF(ISNUMBER(P7),P7,IF(COUNTIFS(Mediciones!$C$6:$C$305,$A7,Mediciones!$D$6:$D$305,"Tela principal")>0,"",0)),IF(ISNUMBER(P7),P7,IF(ISNUMBER(O7),O7*(1+Parametros!$B$22),IF(OR(COUNTIFS(Despiece!$A$6:$A$705,$A7,Despiece!$D$6:$D$705,"Tela principal")>0,COUNTIFS(Mediciones!$C$6:$C$305,$A7,Mediciones!$D$6:$D$305,"Tela principal")>0),"",0))))))=0,"",IF($N7="Despiece",IF(ISNUMBER(O7),O7*(1+Parametros!$B$22),IF(COUNTIFS(Despiece!$A$6:$A$705,$A7,Despiece!$D$6:$D$705,"Tela principal")>0,"",0)),IF($N7="Medición real",IF(ISNUMBER(P7),P7,IF(COUNTIFS(Mediciones!$C$6:$C$305,$A7,Mediciones!$D$6:$D$305,"Tela principal")>0,"",0)),IF(ISNUMBER(P7),P7,IF(ISNUMBER(O7),O7*(1+Parametros!$B$22),IF(OR(COUNTIFS(Despiece!$A$6:$A$705,$A7,Despiece!$D$6:$D$705,"Tela principal")>0,COUNTIFS(Mediciones!$C$6:$C$305,$A7,Mediciones!$D$6:$D$305,"Tela principal")>0),"",0))))))) | R7: =IF($A7="","",IF(COUNTIFS(Despiece!$A$6:$A$705,$A7,Despiece!$D$6:$D$705,"Tela 2",Despiece!$F$6:$F$705,">0")=0,"",SUMIFS(Despiece!$F$6:$F$705,Despiece!$A$6:$A$705,$A7,Despiece!$D$6:$D$705,"Tela 2"))) | S7: =IF($A7="","",IFERROR(AVERAGEIFS(Mediciones!$K$6:$K$305,Mediciones!$C$6:$C$305,$A7,Mediciones!$D$6:$D$305,"Tela 2"),"")) | T7: =IF($A7="","",IF($N7="Despiece",IF(ISNUMBER(R7),R7*(1+Parametros!$B$22),IF(COUNTIFS(Despiece!$A$6:$A$705,$A7,Despiece!$D$6:$D$705,"Tela 2")>0,"",0)),IF($N7="Medición real",IF(ISNUMBER(S7),S7,IF(COUNTIFS(Mediciones!$C$6:$C$305,$A7,Mediciones!$D$6:$D$305,"Tela 2")>0,"",0)),IF(ISNUMBER(S7),S7,IF(ISNUMBER(R7),R7*(1+Parametros!$B$22),IF(OR(COUNTIFS(Despiece!$A$6:$A$705,$A7,Despiece!$D$6:$D$705,"Tela 2")>0,COUNTIFS(Mediciones!$C$6:$C$305,$A7,Mediciones!$D$6:$D$305,"Tela 2")>0),"",0)))))) -> 0 | U7: =IF($A7="","",IF(COUNTIFS(Despiece!$A$6:$A$705,$A7,Despiece!$D$6:$D$705,"Tela 3",Despiece!$F$6:$F$705,">0")=0,"",SUMIFS(Despiece!$F$6:$F$705,Despiece!$A$6:$A$705,$A7,Despiece!$D$6:$D$705,"Tela 3"))) | V7: =IF($A7="","",IFERROR(AVERAGEIFS(Mediciones!$K$6:$K$305,Mediciones!$C$6:$C$305,$A7,Mediciones!$D$6:$D$305,"Tela 3"),"")) | W7: =IF($A7="","",IF($N7="Despiece",IF(ISNUMBER(U7),U7*(1+Parametros!$B$22),IF(COUNTIFS(Despiece!$A$6:$A$705,$A7,Despiece!$D$6:$D$705,"Tela 3")>0,"",0)),IF($N7="Medición real",IF(ISNUMBER(V7),V7,IF(COUNTIFS(Mediciones!$C$6:$C$305,$A7,Mediciones!$D$6:$D$305,"Tela 3")>0,"",0)),IF(ISNUMBER(V7),V7,IF(ISNUMBER(U7),U7*(1+Parametros!$B$22),IF(OR(COUNTIFS(Despiece!$A$6:$A$705,$A7,Despiece!$D$6:$D$705,"Tela 3")>0,COUNTIFS(Mediciones!$C$6:$C$305,$A7,Mediciones!$D$6:$D$305,"Tela 3")>0),"",0)))))) -> 0 | Y7: =IF($A7="","",IF(ISNUMBER(X7),X7,IF(COUNTIFS(Despiece!$A$6:$A$705,$A7,Despiece!$E$6:$E$705,"Sublimada",Despiece!$F$6:$F$705,">0")>0,SUMIFS(Despiece!$F$6:$F$705,Despiece!$A$6:$A$705,$A7,Despiece!$E$6:$E$705,"Sublimada")*(1+Parametros!$B$22),IF(COUNTIFS(Despiece!$A$6:$A$705,$A7,Despiece!$E$6:$E$705,"Sublimada")=0,0,"")))) | Z7: =IF($A7="","",IFERROR(IF(ISNUMBER(Q7),IF(Q7=0,0,Q7*INDEX(Telas!$I$6:$I$105,MATCH(K7,Telas!$A$6:$A$105,0))),NA())+IF(ISNUMBER(T7),IF(T7=0,0,T7*INDEX(Telas!$I$6:$I$105,MATCH(L7,Telas!$A$6:$A$105,0))),NA())+IF(ISNUMBER(W7),IF(W7=0,0,W7*INDEX(Telas!$I$6:$I$105,MATCH(IF(M7="",K7,M7),Telas!$A$6:$A$105,0))),NA()),"")) | AA7: =IF($A7="","",IF(ISNUMBER(Y7),Y7*Parametros!$B$19,"")) | AB7: =IF(OR($A7="",F7=""),"",IFERROR(INDEX(Confeccion!$B$6:$B$125,MATCH(F7,Confeccion!$A$6:$A$125,0)),"")) -> 2000 | AC7: =IF($A7="","",IFERROR(N(H7)*IF(G7="",0,INDEX(Avios!$C$6:$C$65,MATCH(G7,Avios!$A$6:$A$65,0)))+N(J7)*IF(I7="",0,INDEX(Avios!$C$6:$C$65,MATCH(I7,Avios!$A$6:$A$65,0))),"")) -> 0 | AD7: =IF($A7="","",IFERROR(Z7+AA7+AB7+AC7,"")) | AE7: =IF(ISNUMBER(AD7),AD7*Parametros!$B$12,"") | AF7: =IF(AND(ISNUMBER(Q7),K7<>""),IFERROR(1/(Q7*INDEX(Telas!$G$6:$G$105,MATCH(K7,Telas!$A$6:$A$105,0))),""),"") | AG7: =IF($A7="","",IF(ISNUMBER(AD7),IF(AND(N(Y7)>0,N(Parametros!$B$19)=0),"Lista, pero sin costo de impresión (Parametros)","Lista"),IF(Q7="","Consumo tela principal (Despiece o Mediciones). ","")&IF(COUNTIFS(Mediciones!$C$6:$C$305,$A7,Mediciones!$K$6:$K$305,"")>0,"Pesar 1 m de la tela medida (Telas, kg por metro). ","")&IF(T7="","Consumo Tela 2. ","")&IF(W7="","Consumo Tela 3. ","")&IF(K7="","Elegir tela principal. ",IF(ISERROR(INDEX(Telas!$I$6:$I$105,MATCH(K7,Telas!$A$6:$A$105,0))*1),"Precio o peso por metro de "&K7&". ",""))&IF(AND(N(T7)>0,L7=""),"Elegir Tela 2. ",IF(AND(N(T7)>0,ISERROR(INDEX(Telas!$I$6:$I$105,MATCH(L7,Telas!$A$6:$A$105,0))*1)),"Precio o peso por metro de "&L7&". ",""))&IF(Y7="","Metros impresos. ","")&IF(F7="","Tipo de confección. ",IF(AB7="","Precio de confección. ","")))) -> Consumo tela principal (Despiece o Mediciones). Elegir tela principal. Metros impresos. | AH7: Confección sugerida por el tipo de molde: confirmar. Falta ficha de corte.
A8: 03 · FUTINMUJU01 | B8: Fútbol infantil, cuello redondo | C8: Fútbol | D8: Camiseta | E8: Infantil Femenino | F8: Camiseta De Futbol | O8: =IF($A8="","",IF(COUNTIFS(Despiece!$A$6:$A$705,$A8,Despiece!$D$6:$D$705,"Tela principal",Despiece!$F$6:$F$705,">0")=0,"",SUMIFS(Despiece!$F$6:$F$705,Despiece!$A$6:$A$705,$A8,Despiece!$D$6:$D$705,"Tela principal"))) | P8: =IF($A8="","",IFERROR(AVERAGEIFS(Mediciones!$K$6:$K$305,Mediciones!$C$6:$C$305,$A8,Mediciones!$D$6:$D$305,"Tela principal"),"")) | Q8: =IF($A8="","",IF(N(IF($N8="Despiece",IF(ISNUMBER(O8),O8*(1+Parametros!$B$22),IF(COUNTIFS(Despiece!$A$6:$A$705,$A8,Despiece!$D$6:$D$705,"Tela principal")>0,"",0)),IF($N8="Medición real",IF(ISNUMBER(P8),P8,IF(COUNTIFS(Mediciones!$C$6:$C$305,$A8,Mediciones!$D$6:$D$305,"Tela principal")>0,"",0)),IF(ISNUMBER(P8),P8,IF(ISNUMBER(O8),O8*(1+Parametros!$B$22),IF(OR(COUNTIFS(Despiece!$A$6:$A$705,$A8,Despiece!$D$6:$D$705,"Tela principal")>0,COUNTIFS(Mediciones!$C$6:$C$305,$A8,Mediciones!$D$6:$D$305,"Tela principal")>0),"",0))))))=0,"",IF($N8="Despiece",IF(ISNUMBER(O8),O8*(1+Parametros!$B$22),IF(COUNTIFS(Despiece!$A$6:$A$705,$A8,Despiece!$D$6:$D$705,"Tela principal")>0,"",0)),IF($N8="Medición real",IF(ISNUMBER(P8),P8,IF(COUNTIFS(Mediciones!$C$6:$C$305,$A8,Mediciones!$D$6:$D$305,"Tela principal")>0,"",0)),IF(ISNUMBER(P8),P8,IF(ISNUMBER(O8),O8*(1+Parametros!$B$22),IF(OR(COUNTIFS(Despiece!$A$6:$A$705,$A8,Despiece!$D$6:$D$705,"Tela principal")>0,COUNTIFS(Mediciones!$C$6:$C$305,$A8,Mediciones!$D$6:$D$305,"Tela principal")>0),"",0))))))) | R8: =IF($A8="","",IF(COUNTIFS(Despiece!$A$6:$A$705,$A8,Despiece!$D$6:$D$705,"Tela 2",Despiece!$F$6:$F$705,">0")=0,"",SUMIFS(Despiece!$F$6:$F$705,Despiece!$A$6:$A$705,$A8,Despiece!$D$6:$D$705,"Tela 2"))) | S8: =IF($A8="","",IFERROR(AVERAGEIFS(Mediciones!$K$6:$K$305,Mediciones!$C$6:$C$305,$A8,Mediciones!$D$6:$D$305,"Tela 2"),"")) | T8: =IF($A8="","",IF($N8="Despiece",IF(ISNUMBER(R8),R8*(1+Parametros!$B$22),IF(COUNTIFS(Despiece!$A$6:$A$705,$A8,Despiece!$D$6:$D$705,"Tela 2")>0,"",0)),IF($N8="Medición real",IF(ISNUMBER(S8),S8,IF(COUNTIFS(Mediciones!$C$6:$C$305,$A8,Mediciones!$D$6:$D$305,"Tela 2")>0,"",0)),IF(ISNUMBER(S8),S8,IF(ISNUMBER(R8),R8*(1+Parametros!$B$22),IF(OR(COUNTIFS(Despiece!$A$6:$A$705,$A8,Despiece!$D$6:$D$705,"Tela 2")>0,COUNTIFS(Mediciones!$C$6:$C$305,$A8,Mediciones!$D$6:$D$305,"Tela 2")>0),"",0)))))) -> 0 | U8: =IF($A8="","",IF(COUNTIFS(Despiece!$A$6:$A$705,$A8,Despiece!$D$6:$D$705,"Tela 3",Despiece!$F$6:$F$705,">0")=0,"",SUMIFS(Despiece!$F$6:$F$705,Despiece!$A$6:$A$705,$A8,Despiece!$D$6:$D$705,"Tela 3"))) | V8: =IF($A8="","",IFERROR(AVERAGEIFS(Mediciones!$K$6:$K$305,Mediciones!$C$6:$C$305,$A8,Mediciones!$D$6:$D$305,"Tela 3"),"")) | W8: =IF($A8="","",IF($N8="Despiece",IF(ISNUMBER(U8),U8*(1+Parametros!$B$22),IF(COUNTIFS(Despiece!$A$6:$A$705,$A8,Despiece!$D$6:$D$705,"Tela 3")>0,"",0)),IF($N8="Medición real",IF(ISNUMBER(V8),V8,IF(COUNTIFS(Mediciones!$C$6:$C$305,$A8,Mediciones!$D$6:$D$305,"Tela 3")>0,"",0)),IF(ISNUMBER(V8),V8,IF(ISNUMBER(U8),U8*(1+Parametros!$B$22),IF(OR(COUNTIFS(Despiece!$A$6:$A$705,$A8,Despiece!$D$6:$D$705,"Tela 3")>0,COUNTIFS(Mediciones!$C$6:$C$305,$A8,Mediciones!$D$6:$D$305,"Tela 3")>0),"",0)))))) -> 0 | Y8: =IF($A8="","",IF(ISNUMBER(X8),X8,IF(COUNTIFS(Despiece!$A$6:$A$705,$A8,Despiece!$E$6:$E$705,"Sublimada",Despiece!$F$6:$F$705,">0")>0,SUMIFS(Despiece!$F$6:$F$705,Despiece!$A$6:$A$705,$A8,Despiece!$E$6:$E$705,"Sublimada")*(1+Parametros!$B$22),IF(COUNTIFS(Despiece!$A$6:$A$705,$A8,Despiece!$E$6:$E$705,"Sublimada")=0,0,"")))) | Z8: =IF($A8="","",IFERROR(IF(ISNUMBER(Q8),IF(Q8=0,0,Q8*INDEX(Telas!$I$6:$I$105,MATCH(K8,Telas!$A$6:$A$105,0))),NA())+IF(ISNUMBER(T8),IF(T8=0,0,T8*INDEX(Telas!$I$6:$I$105,MATCH(L8,Telas!$A$6:$A$105,0))),NA())+IF(ISNUMBER(W8),IF(W8=0,0,W8*INDEX(Telas!$I$6:$I$105,MATCH(IF(M8="",K8,M8),Telas!$A$6:$A$105,0))),NA()),"")) | AA8: =IF($A8="","",IF(ISNUMBER(Y8),Y8*Parametros!$B$19,"")) | AB8: =IF(OR($A8="",F8=""),"",IFERROR(INDEX(Confeccion!$B$6:$B$125,MATCH(F8,Confeccion!$A$6:$A$125,0)),"")) -> 2000 | AC8: =IF($A8="","",IFERROR(N(H8)*IF(G8="",0,INDEX(Avios!$C$6:$C$65,MATCH(G8,Avios!$A$6:$A$65,0)))+N(J8)*IF(I8="",0,INDEX(Avios!$C$6:$C$65,MATCH(I8,Avios!$A$6:$A$65,0))),"")) -> 0 | AD8: =IF($A8="","",IFERROR(Z8+AA8+AB8+AC8,"")) | AE8: =IF(ISNUMBER(AD8),AD8*Parametros!$B$12,"") | AF8: =IF(AND(ISNUMBER(Q8),K8<>""),IFERROR(1/(Q8*INDEX(Telas!$G$6:$G$105,MATCH(K8,Telas!$A$6:$A$105,0))),""),"") | AG8: =IF($A8="","",IF(ISNUMBER(AD8),IF(AND(N(Y8)>0,N(Parametros!$B$19)=0),"Lista, pero sin costo de impresión (Parametros)","Lista"),IF(Q8="","Consumo tela principal (Despiece o Mediciones). ","")&IF(COUNTIFS(Mediciones!$C$6:$C$305,$A8,Mediciones!$K$6:$K$305,"")>0,"Pesar 1 m de la tela medida (Telas, kg por metro). ","")&IF(T8="","Consumo Tela 2. ","")&IF(W8="","Consumo Tela 3. ","")&IF(K8="","Elegir tela principal. ",IF(ISERROR(INDEX(Telas!$I$6:$I$105,MATCH(K8,Telas!$A$6:$A$105,0))*1),"Precio o peso por metro de "&K8&". ",""))&IF(AND(N(T8)>0,L8=""),"Elegir Tela 2. ",IF(AND(N(T8)>0,ISERROR(INDEX(Telas!$I$6:$I$105,MATCH(L8,Telas!$A$6:$A$105,0))*1)),"Precio o peso por metro de "&L8&". ",""))&IF(Y8="","Metros impresos. ","")&IF(F8="","Tipo de confección. ",IF(AB8="","Precio de confección. ","")))) -> Consumo tela principal (Despiece o Mediciones). Elegir tela principal. Metros impresos. | AH8: Confección sugerida por el tipo de molde: confirmar. Falta ficha de corte.
A9: 04 · FUTINHOMU01 | B9: Fútbol infantil, cuello redondo | C9: Fútbol | D9: Camiseta | E9: Infantil Masculino | F9: Camiseta De Futbol | K9: CIRE BLANCO | L9: MESH | O9: =IF($A9="","",IF(COUNTIFS(Despiece!$A$6:$A$705,$A9,Despiece!$D$6:$D$705,"Tela principal",Despiece!$F$6:$F$705,">0")=0,"",SUMIFS(Despiece!$F$6:$F$705,Despiece!$A$6:$A$705,$A9,Despiece!$D$6:$D$705,"Tela principal"))) | P9: =IF($A9="","",IFERROR(AVERAGEIFS(Mediciones!$K$6:$K$305,Mediciones!$C$6:$C$305,$A9,Mediciones!$D$6:$D$305,"Tela principal"),"")) | Q9: =IF($A9="","",IF(N(IF($N9="Despiece",IF(ISNUMBER(O9),O9*(1+Parametros!$B$22),IF(COUNTIFS(Despiece!$A$6:$A$705,$A9,Despiece!$D$6:$D$705,"Tela principal")>0,"",0)),IF($N9="Medición real",IF(ISNUMBER(P9),P9,IF(COUNTIFS(Mediciones!$C$6:$C$305,$A9,Mediciones!$D$6:$D$305,"Tela principal")>0,"",0)),IF(ISNUMBER(P9),P9,IF(ISNUMBER(O9),O9*(1+Parametros!$B$22),IF(OR(COUNTIFS(Despiece!$A$6:$A$705,$A9,Despiece!$D$6:$D$705,"Tela principal")>0,COUNTIFS(Mediciones!$C$6:$C$305,$A9,Mediciones!$D$6:$D$305,"Tela principal")>0),"",0))))))=0,"",IF($N9="Despiece",IF(ISNUMBER(O9),O9*(1+Parametros!$B$22),IF(COUNTIFS(Despiece!$A$6:$A$705,$A9,Despiece!$D$6:$D$705,"Tela principal")>0,"",0)),IF($N9="Medición real",IF(ISNUMBER(P9),P9,IF(COUNTIFS(Mediciones!$C$6:$C$305,$A9,Mediciones!$D$6:$D$305,"Tela principal")>0,"",0)),IF(ISNUMBER(P9),P9,IF(ISNUMBER(O9),O9*(1+Parametros!$B$22),IF(OR(COUNTIFS(Despiece!$A$6:$A$705,$A9,Despiece!$D$6:$D$705,"Tela principal")>0,COUNTIFS(Mediciones!$C$6:$C$305,$A9,Mediciones!$D$6:$D$305,"Tela principal")>0),"",0))))))) | R9: =IF($A9="","",IF(COUNTIFS(Despiece!$A$6:$A$705,$A9,Despiece!$D$6:$D$705,"Tela 2",Despiece!$F$6:$F$705,">0")=0,"",SUMIFS(Despiece!$F$6:$F$705,Despiece!$A$6:$A$705,$A9,Despiece!$D$6:$D$705,"Tela 2"))) | S9: =IF($A9="","",IFERROR(AVERAGEIFS(Mediciones!$K$6:$K$305,Mediciones!$C$6:$C$305,$A9,Mediciones!$D$6:$D$305,"Tela 2"),"")) | T9: =IF($A9="","",IF($N9="Despiece",IF(ISNUMBER(R9),R9*(1+Parametros!$B$22),IF(COUNTIFS(Despiece!$A$6:$A$705,$A9,Despiece!$D$6:$D$705,"Tela 2")>0,"",0)),IF($N9="Medición real",IF(ISNUMBER(S9),S9,IF(COUNTIFS(Mediciones!$C$6:$C$305,$A9,Mediciones!$D$6:$D$305,"Tela 2")>0,"",0)),IF(ISNUMBER(S9),S9,IF(ISNUMBER(R9),R9*(1+Parametros!$B$22),IF(OR(COUNTIFS(Despiece!$A$6:$A$705,$A9,Despiece!$D$6:$D$705,"Tela 2")>0,COUNTIFS(Mediciones!$C$6:$C$305,$A9,Mediciones!$D$6:$D$305,"Tela 2")>0),"",0)))))) | U9: =IF($A9="","",IF(COUNTIFS(Despiece!$A$6:$A$705,$A9,Despiece!$D$6:$D$705,"Tela 3",Despiece!$F$6:$F$705,">0")=0,"",SUMIFS(Despiece!$F$6:$F$705,Despiece!$A$6:$A$705,$A9,Despiece!$D$6:$D$705,"Tela 3"))) | V9: =IF($A9="","",IFERROR(AVERAGEIFS(Mediciones!$K$6:$K$305,Mediciones!$C$6:$C$305,$A9,Mediciones!$D$6:$D$305,"Tela 3"),"")) | W9: =IF($A9="","",IF($N9="Despiece",IF(ISNUMBER(U9),U9*(1+Parametros!$B$22),IF(COUNTIFS(Despiece!$A$6:$A$705,$A9,Despiece!$D$6:$D$705,"Tela 3")>0,"",0)),IF($N9="Medición real",IF(ISNUMBER(V9),V9,IF(COUNTIFS(Mediciones!$C$6:$C$305,$A9,Mediciones!$D$6:$D$305,"Tela 3")>0,"",0)),IF(ISNUMBER(V9),V9,IF(ISNUMBER(U9),U9*(1+Parametros!$B$22),IF(OR(COUNTIFS(Despiece!$A$6:$A$705,$A9,Despiece!$D$6:$D$705,"Tela 3")>0,COUNTIFS(Mediciones!$C$6:$C$305,$A9,Mediciones!$D$6:$D$305,"Tela 3")>0),"",0)))))) -> 0 | Y9: =IF($A9="","",IF(ISNUMBER(X9),X9,IF(COUNTIFS(Despiece!$A$6:$A$705,$A9,Despiece!$E$6:$E$705,"Sublimada",Despiece!$F$6:$F$705,">0")>0,SUMIFS(Despiece!$F$6:$F$705,Despiece!$A$6:$A$705,$A9,Despiece!$E$6:$E$705,"Sublimada")*(1+Parametros!$B$22),IF(COUNTIFS(Despiece!$A$6:$A$705,$A9,Despiece!$E$6:$E$705,"Sublimada")=0,0,"")))) | Z9: =IF($A9="","",IFERROR(IF(ISNUMBER(Q9),IF(Q9=0,0,Q9*INDEX(Telas!$I$6:$I$105,MATCH(K9,Telas!$A$6:$A$105,0))),NA())+IF(ISNUMBER(T9),IF(T9=0,0,T9*INDEX(Telas!$I$6:$I$105,MATCH(L9,Telas!$A$6:$A$105,0))),NA())+IF(ISNUMBER(W9),IF(W9=0,0,W9*INDEX(Telas!$I$6:$I$105,MATCH(IF(M9="",K9,M9),Telas!$A$6:$A$105,0))),NA()),"")) | AA9: =IF($A9="","",IF(ISNUMBER(Y9),Y9*Parametros!$B$19,"")) | AB9: =IF(OR($A9="",F9=""),"",IFERROR(INDEX(Confeccion!$B$6:$B$125,MATCH(F9,Confeccion!$A$6:$A$125,0)),"")) -> 2000 | AC9: =IF($A9="","",IFERROR(N(H9)*IF(G9="",0,INDEX(Avios!$C$6:$C$65,MATCH(G9,Avios!$A$6:$A$65,0)))+N(J9)*IF(I9="",0,INDEX(Avios!$C$6:$C$65,MATCH(I9,Avios!$A$6:$A$65,0))),"")) -> 0 | AD9: =IF($A9="","",IFERROR(Z9+AA9+AB9+AC9,"")) | AE9: =IF(ISNUMBER(AD9),AD9*Parametros!$B$12,"") | AF9: =IF(AND(ISNUMBER(Q9),K9<>""),IFERROR(1/(Q9*INDEX(Telas!$G$6:$G$105,MATCH(K9,Telas!$A$6:$A$105,0))),""),"") | AG9: =IF($A9="","",IF(ISNUMBER(AD9),IF(AND(N(Y9)>0,N(Parametros!$B$19)=0),"Lista, pero sin costo de impresión (Parametros)","Lista"),IF(Q9="","Consumo tela principal (Despiece o Mediciones). ","")&IF(COUNTIFS(Mediciones!$C$6:$C$305,$A9,Mediciones!$K$6:$K$305,"")>0,"Pesar 1 m de la tela medida (Telas, kg por metro). ","")&IF(T9="","Consumo Tela 2. ","")&IF(W9="","Consumo Tela 3. ","")&IF(K9="","Elegir tela principal. ",IF(ISERROR(INDEX(Telas!$I$6:$I$105,MATCH(K9,Telas!$A$6:$A$105,0))*1),"Precio o peso por metro de "&K9&". ",""))&IF(AND(N(T9)>0,L9=""),"Elegir Tela 2. ",IF(AND(N(T9)>0,ISERROR(INDEX(Telas!$I$6:$I$105,MATCH(L9,Telas!$A$6:$A$105,0))*1)),"Precio o peso por metro de "&L9&". ",""))&IF(Y9="","Metros impresos. ","")&IF(F9="","Tipo de confección. ",IF(AB9="","Precio de confección. ","")))) -> Consumo tela principal (Despiece o Mediciones). Pesar 1 m de la tela medida (Telas, kg por metro). Consumo Tela 2. Precio o peso por metro de CIRE BLANCO. Metros impresos. | AH9: Ficha OT 2369 (48 camisetas infantiles). Falta metros impresos.
