Workbook

Sheet Ficha
A1: FICHA DE COSTO DE PRODUCCIÓN
A2: Elige el molde y, si quieres, otra tela para cada pieza. Vacío = tela por defecto. Todo neto, sin IVA y sin gastos generales.
B3: Al cambiar de molde, borra las telas elegidas (columna azul) para volver a las de siempre.
B4: MOLDE ▶ | C4: 14 · FUTHOMU01PRO | F4: =IFERROR(INDEX(Moldes!$B$5:$B$154,MATCH($C$4,Moldes!$A$5:$A$154,0))&" · "&INDEX(Moldes!$C$5:$C$154,MATCH($C$4,Moldes!$A$5:$A$154,0))&" "&INDEX(Moldes!$D$5:$D$154,MATCH($C$4,Moldes!$A$5:$A$154,0)),"← elige un molde") -> Fútbol, pro, cuello redondo · Camiseta Masculino
B5: =IFERROR("Consumo: despiece + "&TEXT(IF(ISNUMBER(INDEX(Moldes!$K$5:$K$154,MATCH($C$4,Moldes!$A$5:$A$154,0))),INDEX(Moldes!$K$5:$K$154,MATCH($C$4,Moldes!$A$5:$A$154,0)),Precios!$Q$12),"0%")&IF(ISNUMBER(INDEX(Moldes!$K$5:$K$154,MATCH($C$4,Moldes!$A$5:$A$154,0)))," (ajuste por consumo real de este molde)"," (merma general)"),"") -> Consumo: despiece + 0% (merma general)
A7: # | B7: Pieza | C7: Cant. | D7: Metros por prenda | E7: TELA (elige) vacío = por defecto | F7: Tela usada | G7: $ por metro | H7: $ Tela | I7: $ Impresión | J7: TOTAL PIEZA | K7: Aviso
A8: =IF(B8="","",1) -> 1 | B8: =IFERROR(INDEX(Despiece!$B$5:$B$1004,MATCH($C$4&"|"&1,Despiece!$H$5:$H$1004,0)),"") -> Delantero | C8: =IF(B8="","",INDEX(Despiece!$C$5:$C$1004,MATCH($C$4&"|"&1,Despiece!$H$5:$H$1004,0))) -> 1 | D8: =IF(B8="","",IF(N(INDEX(Despiece!$D$5:$D$1004,MATCH($C$4&"|"&1,Despiece!$H$5:$H$1004,0)))>0,INDEX(Despiece!$D$5:$D$1004,MATCH($C$4&"|"&1,Despiece!$H$5:$H$1004,0))*(1+IFERROR(IF(ISNUMBER(INDEX(Moldes!$K$5:$K$154,MATCH($C$4,Moldes!$A$5:$A$154,0))),INDEX(Moldes!$K$5:$K$154,MATCH($C$4,Moldes!$A$5:$A$154,0)),Precios!$Q$12),Precios!$Q$12)),"")) | F8: =IF(B8="","",IF(E8<>"",E8,INDEX(Despiece!$E$5:$E$1004,MATCH($C$4&"|"&1,Despiece!$H$5:$H$1004,0))&"")) -> MONTESIMONE TRAINING (fut pro) | G8: =IF(OR(B8="",F8=""),"",IFERROR(INDEX(Precios!$F$5:$F$124,MATCH(F8,Precios!$A$5:$A$124,0))*1,"")) -> 695.607 | H8: =IF(AND(ISNUMBER(D8),ISNUMBER(G8)),D8*G8,"") | I8: =IF(OR(B8="",NOT(ISNUMBER(D8))),"",IF(INDEX(Despiece!$F$5:$F$1004,MATCH($C$4&"|"&1,Despiece!$H$5:$H$1004,0))="Sí",D8*Precios!$Q$10,0)) | J8: =IF(AND(ISNUMBER(H8),ISNUMBER(I8)),H8+I8,"") | K8: =IF(B8="","",IF(ISNUMBER(J8),IF(INDEX(Despiece!$F$5:$F$1004,MATCH($C$4&"|"&1,Despiece!$H$5:$H$1004,0))="Sí","Sublimada",""),IF(NOT(ISNUMBER(D8)),"Faltan metros (Despiece). ","")&IF(F8="","Elige tela. ",IF(NOT(ISNUMBER(G8)),"Falta precio o peso de 1 m (Precios). ","")))) -> Faltan metros (Despiece).
A9: =IF(B9="","",2) -> 2 | B9: =IFERROR(INDEX(Despiece!$B$5:$B$1004,MATCH($C$4&"|"&2,Despiece!$H$5:$H$1004,0)),"") -> Espalda | C9: =IF(B9="","",INDEX(Despiece!$C$5:$C$1004,MATCH($C$4&"|"&2,Despiece!$H$5:$H$1004,0))) -> 1 | D9: =IF(B9="","",IF(N(INDEX(Despiece!$D$5:$D$1004,MATCH($C$4&"|"&2,Despiece!$H$5:$H$1004,0)))>0,INDEX(Despiece!$D$5:$D$1004,MATCH($C$4&"|"&2,Despiece!$H$5:$H$1004,0))*(1+IFERROR(IF(ISNUMBER(INDEX(Moldes!$K$5:$K$154,MATCH($C$4,Moldes!$A$5:$A$154,0))),INDEX(Moldes!$K$5:$K$154,MATCH($C$4,Moldes!$A$5:$A$154,0)),Precios!$Q$12),Precios!$Q$12)),"")) | F9: =IF(B9="","",IF(E9<>"",E9,INDEX(Despiece!$E$5:$E$1004,MATCH($C$4&"|"&2,Despiece!$H$5:$H$1004,0))&"")) -> MONTESIMONE TRAINING (fut pro) | G9: =IF(OR(B9="",F9=""),"",IFERROR(INDEX(Precios!$F$5:$F$124,MATCH(F9,Precios!$A$5:$A$124,0))*1,"")) -> 695.607 | H9: =IF(AND(ISNUMBER(D9),ISNUMBER(G9)),D9*G9,"") | I9: =IF(OR(B9="",NOT(ISNUMBER(D9))),"",IF(INDEX(Despiece!$F$5:$F$1004,MATCH($C$4&"|"&2,Despiece!$H$5:$H$1004,0))="Sí",D9*Precios!$Q$10,0)) | J9: =IF(AND(ISNUMBER(H9),ISNUMBER(I9)),H9+I9,"") | K9: =IF(B9="","",IF(ISNUMBER(J9),IF(INDEX(Despiece!$F$5:$F$1004,MATCH($C$4&"|"&2,Despiece!$H$5:$H$1004,0))="Sí","Sublimada",""),IF(NOT(ISNUMBER(D9)),"Faltan metros (Despiece). ","")&IF(F9="","Elige tela. ",IF(NOT(ISNUMBER(G9)),"Falta precio o peso de 1 m (Precios). ","")))) -> Faltan metros (Despiece).
A10: =IF(B10="","",3) -> 3 | B10: =IFERROR(INDEX(Despiece!$B$5:$B$1004,MATCH($C$4&"|"&3,Despiece!$H$5:$H$1004,0)),"") -> Manga | C10: =IF(B10="","",INDEX(Despiece!$C$5:$C$1004,MATCH($C$4&"|"&3,Despiece!$H$5:$H$1004,0))) -> 2 | D10: =IF(B10="","",IF(N(INDEX(Despiece!$D$5:$D$1004,MATCH($C$4&"|"&3,Despiece!$H$5:$H$1004,0)))>0,INDEX(Despiece!$D$5:$D$1004,MATCH($C$4&"|"&3,Despiece!$H$5:$H$1004,0))*(1+IFERROR(IF(ISNUMBER(INDEX(Moldes!$K$5:$K$154,MATCH($C$4,Moldes!$A$5:$A$154,0))),INDEX(Moldes!$K$5:$K$154,MATCH($C$4,Moldes!$A$5:$A$154,0)),Precios!$Q$12),Precios!$Q$12)),"")) | F10: =IF(B10="","",IF(E10<>"",E10,INDEX(Despiece!$E$5:$E$1004,MATCH($C$4&"|"&3,Despiece!$H$5:$H$1004,0))&"")) -> MONTESIMONE TRAINING (fut pro) | G10: =IF(OR(B10="",F10=""),"",IFERROR(INDEX(Precios!$F$5:$F$124,MATCH(F10,Precios!$A$5:$A$124,0))*1,"")) -> 695.607 | H10: =IF(AND(ISNUMBER(D10),ISNUMBER(G10)),D10*G10,"") | I10: =IF(OR(B10="",NOT(ISNUMBER(D10))),"",IF(INDEX(Despiece!$F$5:$F$1004,MATCH($C$4&"|"&3,Despiece!$H$5:$H$1004,0))="Sí",D10*Precios!$Q$10,0)) | J10: =IF(AND(ISNUMBER(H10),ISNUMBER(I10)),H10+I10,"") | K10: =IF(B10="","",IF(ISNUMBER(J10),IF(INDEX(Despiece!$F$5:$F$1004,MATCH($C$4&"|"&3,Despiece!$H$5:$H$1004,0))="Sí","Sublimada",""),IF(NOT(ISNUMBER(D10)),"Faltan metros (Despiece). ","")&IF(F10="","Elige tela. ",IF(NOT(ISNUMBER(G10)),"Falta precio o peso de 1 m (Precios). ","")))) -> Faltan metros (Despiece).
A11: =IF(B11="","",4) -> 4 | B11: =IFERROR(INDEX(Despiece!$B$5:$B$1004,MATCH($C$4&"|"&4,Despiece!$H$5:$H$1004,0)),"") -> Tira de cuello | C11: =IF(B11="","",INDEX(Despiece!$C$5:$C$1004,MATCH($C$4&"|"&4,Despiece!$H$5:$H$1004,0))) -> 1 | D11: =IF(B11="","",IF(N(INDEX(Despiece!$D$5:$D$1004,MATCH($C$4&"|"&4,Despiece!$H$5:$H$1004,0)))>0,INDEX(Despiece!$D$5:$D$1004,MATCH($C$4&"|"&4,Despiece!$H$5:$H$1004,0))*(1+IFERROR(IF(ISNUMBER(INDEX(Moldes!$K$5:$K$154,MATCH($C$4,Moldes!$A$5:$A$154,0))),INDEX(Moldes!$K$5:$K$154,MATCH($C$4,Moldes!$A$5:$A$154,0)),Precios!$Q$12),Precios!$Q$12)),"")) | F11: =IF(B11="","",IF(E11<>"",E11,INDEX(Despiece!$E$5:$E$1004,MATCH($C$4&"|"&4,Despiece!$H$5:$H$1004,0))&"")) -> MONTESIMONE TRAINING (fut pro) | G11: =IF(OR(B11="",F11=""),"",IFERROR(INDEX(Precios!$F$5:$F$124,MATCH(F11,Precios!$A$5:$A$124,0))*1,"")) -> 695.607 | H11: =IF(AND(ISNUMBER(D11),ISNUMBER(G11)),D11*G11,"") | I11: =IF(OR(B11="",NOT(ISNUMBER(D11))),"",IF(INDEX(Despiece!$F$5:$F$1004,MATCH($C$4&"|"&4,Despiece!$H$5:$H$1004,0))="Sí",D11*Precios!$Q$10,0)) | J11: =IF(AND(ISNUMBER(H11),ISNUMBER(I11)),H11+I11,"") | K11: =IF(B11="","",IF(ISNUMBER(J11),IF(INDEX(Despiece!$F$5:$F$1004,MATCH($C$4&"|"&4,Despiece!$H$5:$H$1004,0))="Sí","Sublimada",""),IF(NOT(ISNUMBER(D11)),"Faltan metros (Despiece). ","")&IF(F11="","Elige tela. ",IF(NOT(ISNUMBER(G11)),"Falta precio o peso de 1 m (Precios). ","")))) -> Faltan metros (Despiece).
A12: =IF(B12="","",5) -> 5 | B12: =IFERROR(INDEX(Despiece!$B$5:$B$1004,MATCH($C$4&"|"&5,Despiece!$H$5:$H$1004,0)),"") -> Paneles laterales | C12: =IF(B12="","",INDEX(Despiece!$C$5:$C$1004,MATCH($C$4&"|"&5,Despiece!$H$5:$H$1004,0))) -> 2 | D12: =IF(B12="","",IF(N(INDEX(Despiece!$D$5:$D$1004,MATCH($C$4&"|"&5,Despiece!$H$5:$H$1004,0)))>0,INDEX(Despiece!$D$5:$D$1004,MATCH($C$4&"|"&5,Despiece!$H$5:$H$1004,0))*(1+IFERROR(IF(ISNUMBER(INDEX(Moldes!$K$5:$K$154,MATCH($C$4,Moldes!$A$5:$A$154,0))),INDEX(Moldes!$K$5:$K$154,MATCH($C$4,Moldes!$A$5:$A$154,0)),Precios!$Q$12),Precios!$Q$12)),"")) | F12: =IF(B12="","",IF(E12<>"",E12,INDEX(Despiece!$E$5:$E$1004,MATCH($C$4&"|"&5,Despiece!$H$5:$H$1004,0))&"")) -> MESH | G12: =IF(OR(B12="",F12=""),"",IFERROR(INDEX(Precios!$F$5:$F$124,MATCH(F12,Precios!$A$5:$A$124,0))*1,"")) | H12: =IF(AND(ISNUMBER(D12),ISNUMBER(G12)),D12*G12,"") | I12: =IF(OR(B12="",NOT(ISNUMBER(D12))),"",IF(INDEX(Despiece!$F$5:$F$1004,MATCH($C$4&"|"&5,Despiece!$H$5:$H$1004,0))="Sí",D12*Precios!$Q$10,0)) | J12: =IF(AND(ISNUMBER(H12),ISNUMBER(I12)),H12+I12,"") | K12: =IF(B12="","",IF(ISNUMBER(J12),IF(INDEX(Despiece!$F$5:$F$1004,MATCH($C$4&"|"&5,Despiece!$H$5:$H$1004,0))="Sí","Sublimada",""),IF(NOT(ISNUMBER(D12)),"Faltan metros (Despiece). ","")&IF(F12="","Elige tela. ",IF(NOT(ISNUMBER(G12)),"Falta precio o peso de 1 m (Precios). ","")))) -> Faltan metros (Despiece). Falta precio o peso de 1 m (Precios).
A13: =IF(B13="","",6) | B13: =IFERROR(INDEX(Despiece!$B$5:$B$1004,MATCH($C$4&"|"&6,Despiece!$H$5:$H$1004,0)),"") | C13: =IF(B13="","",INDEX(Despiece!$C$5:$C$1004,MATCH($C$4&"|"&6,Despiece!$H$5:$H$1004,0))) | D13: =IF(B13="","",IF(N(INDEX(Despiece!$D$5:$D$1004,MATCH($C$4&"|"&6,Despiece!$H$5:$H$1004,0)))>0,INDEX(Despiece!$D$5:$D$1004,MATCH($C$4&"|"&6,Despiece!$H$5:$H$1004,0))*(1+IFERROR(IF(ISNUMBER(INDEX(Moldes!$K$5:$K$154,MATCH($C$4,Moldes!$A$5:$A$154,0))),INDEX(Moldes!$K$5:$K$154,MATCH($C$4,Moldes!$A$5:$A$154,0)),Precios!$Q$12),Precios!$Q$12)),"")) | F13: =IF(B13="","",IF(E13<>"",E13,INDEX(Despiece!$E$5:$E$1004,MATCH($C$4&"|"&6,Despiece!$H$5:$H$1004,0))&"")) | G13: =IF(OR(B13="",F13=""),"",IFERROR(INDEX(Precios!$F$5:$F$124,MATCH(F13,Precios!$A$5:$A$124,0))*1,"")) | H13: =IF(AND(ISNUMBER(D13),ISNUMBER(G13)),D13*G13,"") | I13: =IF(OR(B13="",NOT(ISNUMBER(D13))),"",IF(INDEX(Despiece!$F$5:$F$1004,MATCH($C$4&"|"&6,Despiece!$H$5:$H$1004,0))="Sí",D13*Precios!$Q$10,0)) | J13: =IF(AND(ISNUMBER(H13),ISNUMBER(I13)),H13+I13,"") | K13: =IF(B13="","",IF(ISNUMBER(J13),IF(INDEX(Despiece!$F$5:$F$1004,MATCH($C$4&"|"&6,Despiece!$H$5:$H$1004,0))="Sí","Sublimada",""),IF(NOT(ISNUMBER(D13)),"Faltan metros (Despiece). ","")&IF(F13="","Elige tela. ",IF(NOT(ISNUMBER(G13)),"Falta precio o peso de 1 m (Precios). ",""))))
A14: =IF(B14="","",7) | B14: =IFERROR(INDEX(Despiece!$B$5:$B$1004,MATCH($C$4&"|"&7,Despiece!$H$5:$H$1004,0)),"") | C14: =IF(B14="","",INDEX(Despiece!$C$5:$C$1004,MATCH($C$4&"|"&7,Despiece!$H$5:$H$1004,0))) | D14: =IF(B14="","",IF(N(INDEX(Despiece!$D$5:$D$1004,MATCH($C$4&"|"&7,Despiece!$H$5:$H$1004,0)))>0,INDEX(Despiece!$D$5:$D$1004,MATCH($C$4&"|"&7,Despiece!$H$5:$H$1004,0))*(1+IFERROR(IF(ISNUMBER(INDEX(Moldes!$K$5:$K$154,MATCH($C$4,Moldes!$A$5:$A$154,0))),INDEX(Moldes!$K$5:$K$154,MATCH($C$4,Moldes!$A$5:$A$154,0)),Precios!$Q$12),Precios!$Q$12)),"")) | F14: =IF(B14="","",IF(E14<>"",E14,INDEX(Despiece!$E$5:$E$1004,MATCH($C$4&"|"&7,Despiece!$H$5:$H$1004,0))&"")) | G14: =IF(OR(B14="",F14=""),"",IFERROR(INDEX(Precios!$F$5:$F$124,MATCH(F14,Precios!$A$5:$A$124,0))*1,"")) | H14: =IF(AND(ISNUMBER(D14),ISNUMBER(G14)),D14*G14,"") | I14: =IF(OR(B14="",NOT(ISNUMBER(D14))),"",IF(INDEX(Despiece!$F$5:$F$1004,MATCH($C$4&"|"&7,Despiece!$H$5:$H$1004,0))="Sí",D14*Precios!$Q$10,0)) | J14: =IF(AND(ISNUMBER(H14),ISNUMBER(I14)),H14+I14,"") | K14: =IF(B14="","",IF(ISNUMBER(J14),IF(INDEX(Despiece!$F$5:$F$1004,MATCH($C$4&"|"&7,Despiece!$H$5:$H$1004,0))="Sí","Sublimada",""),IF(NOT(ISNUMBER(D14)),"Faltan metros (Despiece). ","")&IF(F14="","Elige tela. ",IF(NOT(ISNUMBER(G14)),"Falta precio o peso de 1 m (Precios). ",""))))
A15: =IF(B15="","",8) | B15: =IFERROR(INDEX(Despiece!$B$5:$B$1004,MATCH($C$4&"|"&8,Despiece!$H$5:$H$1004,0)),"") | C15: =IF(B15="","",INDEX(Despiece!$C$5:$C$1004,MATCH($C$4&"|"&8,Despiece!$H$5:$H$1004,0))) | D15: =IF(B15="","",IF(N(INDEX(Despiece!$D$5:$D$1004,MATCH($C$4&"|"&8,Despiece!$H$5:$H$1004,0)))>0,INDEX(Despiece!$D$5:$D$1004,MATCH($C$4&"|"&8,Despiece!$H$5:$H$1004,0))*(1+IFERROR(IF(ISNUMBER(INDEX(Moldes!$K$5:$K$154,MATCH($C$4,Moldes!$A$5:$A$154,0))),INDEX(Moldes!$K$5:$K$154,MATCH($C$4,Moldes!$A$5:$A$154,0)),Precios!$Q$12),Precios!$Q$12)),"")) | F15: =IF(B15="","",IF(E15<>"",E15,INDEX(Despiece!$E$5:$E$1004,MATCH($C$4&"|"&8,Despiece!$H$5:$H$1004,0))&"")) | G15: =IF(OR(B15="",F15=""),"",IFERROR(INDEX(Precios!$F$5:$F$124,MATCH(F15,Precios!$A$5:$A$124,0))*1,"")) | H15: =IF(AND(ISNUMBER(D15),ISNUMBER(G15)),D15*G15,"") | I15: =IF(OR(B15="",NOT(ISNUMBER(D15))),"",IF(INDEX(Despiece!$F$5:$F$1004,MATCH($C$4&"|"&8,Despiece!$H$5:$H$1004,0))="Sí",D15*Precios!$Q$10,0)) | J15: =IF(AND(ISNUMBER(H15),ISNUMBER(I15)),H15+I15,"") | K15: =IF(B15="","",IF(ISNUMBER(J15),IF(INDEX(Despiece!$F$5:$F$1004,MATCH($C$4&"|"&8,Despiece!$H$5:$H$1004,0))="Sí","Sublimada",""),IF(NOT(ISNUMBER(D15)),"Faltan metros (Despiece). ","")&IF(F15="","Elige tela. ",IF(NOT(ISNUMBER(G15)),"Falta precio o peso de 1 m (Precios). ",""))))
A16: =IF(B16="","",9) | B16: =IFERROR(INDEX(Despiece!$B$5:$B$1004,MATCH($C$4&"|"&9,Despiece!$H$5:$H$1004,0)),"") | C16: =IF(B16="","",INDEX(Despiece!$C$5:$C$1004,MATCH($C$4&"|"&9,Despiece!$H$5:$H$1004,0))) | D16: =IF(B16="","",IF(N(INDEX(Despiece!$D$5:$D$1004,MATCH($C$4&"|"&9,Despiece!$H$5:$H$1004,0)))>0,INDEX(Despiece!$D$5:$D$1004,MATCH($C$4&"|"&9,Despiece!$H$5:$H$1004,0))*(1+IFERROR(IF(ISNUMBER(INDEX(Moldes!$K$5:$K$154,MATCH($C$4,Moldes!$A$5:$A$154,0))),INDEX(Moldes!$K$5:$K$154,MATCH($C$4,Moldes!$A$5:$A$154,0)),Precios!$Q$12),Precios!$Q$12)),"")) | F16: =IF(B16="","",IF(E16<>"",E16,INDEX(Despiece!$E$5:$E$1004,MATCH($C$4&"|"&9,Despiece!$H$5:$H$1004,0))&"")) | G16: =IF(OR(B16="",F16=""),"",IFERROR(INDEX(Precios!$F$5:$F$124,MATCH(F16,Precios!$A$5:$A$124,0))*1,"")) | H16: =IF(AND(ISNUMBER(D16),ISNUMBER(G16)),D16*G16,"") | I16: =IF(OR(B16="",NOT(ISNUMBER(D16))),"",IF(INDEX(Despiece!$F$5:$F$1004,MATCH($C$4&"|"&9,Despiece!$H$5:$H$1004,0))="Sí",D16*Precios!$Q$10,0)) | J16: =IF(AND(ISNUMBER(H16),ISNUMBER(I16)),H16+I16,"") | K16: =IF(B16="","",IF(ISNUMBER(J16),IF(INDEX(Despiece!$F$5:$F$1004,MATCH($C$4&"|"&9,Despiece!$H$5:$H$1004,0))="Sí","Sublimada",""),IF(NOT(ISNUMBER(D16)),"Faltan metros (Despiece). ","")&IF(F16="","Elige tela. ",IF(NOT(ISNUMBER(G16)),"Falta precio o peso de 1 m (Precios). ",""))))
A17: =IF(B17="","",10) | B17: =IFERROR(INDEX(Despiece!$B$5:$B$1004,MATCH($C$4&"|"&10,Despiece!$H$5:$H$1004,0)),"") | C17: =IF(B17="","",INDEX(Despiece!$C$5:$C$1004,MATCH($C$4&"|"&10,Despiece!$H$5:$H$1004,0))) | D17: =IF(B17="","",IF(N(INDEX(Despiece!$D$5:$D$1004,MATCH($C$4&"|"&10,Despiece!$H$5:$H$1004,0)))>0,INDEX(Despiece!$D$5:$D$1004,MATCH($C$4&"|"&10,Despiece!$H$5:$H$1004,0))*(1+IFERROR(IF(ISNUMBER(INDEX(Moldes!$K$5:$K$154,MATCH($C$4,Moldes!$A$5:$A$154,0))),INDEX(Moldes!$K$5:$K$154,MATCH($C$4,Moldes!$A$5:$A$154,0)),Precios!$Q$12),Precios!$Q$12)),"")) | F17: =IF(B17="","",IF(E17<>"",E17,INDEX(Despiece!$E$5:$E$1004,MATCH($C$4&"|"&10,Despiece!$H$5:$H$1004,0))&"")) | G17: =IF(OR(B17="",F17=""),"",IFERROR(INDEX(Precios!$F$5:$F$124,MATCH(F17,Precios!$A$5:$A$124,0))*1,"")) | H17: =IF(AND(ISNUMBER(D17),ISNUMBER(G17)),D17*G17,"") | I17: =IF(OR(B17="",NOT(ISNUMBER(D17))),"",IF(INDEX(Despiece!$F$5:$F$1004,MATCH($C$4&"|"&10,Despiece!$H$5:$H$1004,0))="Sí",D17*Precios!$Q$10,0)) | J17: =IF(AND(ISNUMBER(H17),ISNUMBER(I17)),H17+I17,"") | K17: =IF(B17="","",IF(ISNUMBER(J17),IF(INDEX(Despiece!$F$5:$F$1004,MATCH($C$4&"|"&10,Despiece!$H$5:$H$1004,0))="Sí","Sublimada",""),IF(NOT(ISNUMBER(D17)),"Faltan metros (Despiece). ","")&IF(F17="","Elige tela. ",IF(NOT(ISNUMBER(G17)),"Falta precio o peso de 1 m (Precios). ",""))))
A18: =IF(B18="","",11) | B18: =IFERROR(INDEX(Despiece!$B$5:$B$1004,MATCH($C$4&"|"&11,Despiece!$H$5:$H$1004,0)),"") | C18: =IF(B18="","",INDEX(Despiece!$C$5:$C$1004,MATCH($C$4&"|"&11,Despiece!$H$5:$H$1004,0))) | D18: =IF(B18="","",IF(N(INDEX(Despiece!$D$5:$D$1004,MATCH($C$4&"|"&11,Despiece!$H$5:$H$1004,0)))>0,INDEX(Despiece!$D$5:$D$1004,MATCH($C$4&"|"&11,Despiece!$H$5:$H$1004,0))*(1+IFERROR(IF(ISNUMBER(INDEX(Moldes!$K$5:$K$154,MATCH($C$4,Moldes!$A$5:$A$154,0))),INDEX(Moldes!$K$5:$K$154,MATCH($C$4,Moldes!$A$5:$A$154,0)),Precios!$Q$12),Precios!$Q$12)),"")) | F18: =IF(B18="","",IF(E18<>"",E18,INDEX(Despiece!$E$5:$E$1004,MATCH($C$4&"|"&11,Despiece!$H$5:$H$1004,0))&"")) | G18: =IF(OR(B18="",F18=""),"",IFERROR(INDEX(Precios!$F$5:$F$124,MATCH(F18,Precios!$A$5:$A$124,0))*1,"")) | H18: =IF(AND(ISNUMBER(D18),ISNUMBER(G18)),D18*G18,"") | I18: =IF(OR(B18="",NOT(ISNUMBER(D18))),"",IF(INDEX(Despiece!$F$5:$F$1004,MATCH($C$4&"|"&11,Despiece!$H$5:$H$1004,0))="Sí",D18*Precios!$Q$10,0)) | J18: =IF(AND(ISNUMBER(H18),ISNUMBER(I18)),H18+I18,"") | K18: =IF(B18="","",IF(ISNUMBER(J18),IF(INDEX(Despiece!$F$5:$F$1004,MATCH($C$4&"|"&11,Despiece!$H$5:$H$1004,0))="Sí","Sublimada",""),IF(NOT(ISNUMBER(D18)),"Faltan metros (Despiece). ","")&IF(F18="","Elige tela. ",IF(NOT(ISNUMBER(G18)),"Falta precio o peso de 1 m (Precios). ",""))))
A19: =IF(B19="","",12) | B19: =IFERROR(INDEX(Despiece!$B$5:$B$1004,MATCH($C$4&"|"&12,Despiece!$H$5:$H$1004,0)),"") | C19: =IF(B19="","",INDEX(Despiece!$C$5:$C$1004,MATCH($C$4&"|"&12,Despiece!$H$5:$H$1004,0))) | D19: =IF(B19="","",IF(N(INDEX(Despiece!$D$5:$D$1004,MATCH($C$4&"|"&12,Despiece!$H$5:$H$1004,0)))>0,INDEX(Despiece!$D$5:$D$1004,MATCH($C$4&"|"&12,Despiece!$H$5:$H$1004,0))*(1+IFERROR(IF(ISNUMBER(INDEX(Moldes!$K$5:$K$154,MATCH($C$4,Moldes!$A$5:$A$154,0))),INDEX(Moldes!$K$5:$K$154,MATCH($C$4,Moldes!$A$5:$A$154,0)),Precios!$Q$12),Precios!$Q$12)),"")) | F19: =IF(B19="","",IF(E19<>"",E19,INDEX(Despiece!$E$5:$E$1004,MATCH($C$4&"|"&12,Despiece!$H$5:$H$1004,0))&"")) | G19: =IF(OR(B19="",F19=""),"",IFERROR(INDEX(Precios!$F$5:$F$124,MATCH(F19,Precios!$A$5:$A$124,0))*1,"")) | H19: =IF(AND(ISNUMBER(D19),ISNUMBER(G19)),D19*G19,"") | I19: =IF(OR(B19="",NOT(ISNUMBER(D19))),"",IF(INDEX(Despiece!$F$5:$F$1004,MATCH($C$4&"|"&12,Despiece!$H$5:$H$1004,0))="Sí",D19*Precios!$Q$10,0)) | J19: =IF(AND(ISNUMBER(H19),ISNUMBER(I19)),H19+I19,"") | K19: =IF(B19="","",IF(ISNUMBER(J19),IF(INDEX(Despiece!$F$5:$F$1004,MATCH($C$4&"|"&12,Despiece!$H$5:$H$1004,0))="Sí","Sublimada",""),IF(NOT(ISNUMBER(D19)),"Faltan metros (Despiece). ","")&IF(F19="","Elige tela. ",IF(NOT(ISNUMBER(G19)),"Falta precio o peso de 1 m (Precios). ",""))))
A20: =IF(B20="","",13) | B20: =IFERROR(INDEX(Despiece!$B$5:$B$1004,MATCH($C$4&"|"&13,Despiece!$H$5:$H$1004,0)),"") | C20: =IF(B20="","",INDEX(Despiece!$C$5:$C$1004,MATCH($C$4&"|"&13,Despiece!$H$5:$H$1004,0))) | D20: =IF(B20="","",IF(N(INDEX(Despiece!$D$5:$D$1004,MATCH($C$4&"|"&13,Despiece!$H$5:$H$1004,0)))>0,INDEX(Despiece!$D$5:$D$1004,MATCH($C$4&"|"&13,Despiece!$H$5:$H$1004,0))*(1+IFERROR(IF(ISNUMBER(INDEX(Moldes!$K$5:$K$154,MATCH($C$4,Moldes!$A$5:$A$154,0))),INDEX(Moldes!$K$5:$K$154,MATCH($C$4,Moldes!$A$5:$A$154,0)),Precios!$Q$12),Precios!$Q$12)),"")) | F20: =IF(B20="","",IF(E20<>"",E20,INDEX(Despiece!$E$5:$E$1004,MATCH($C$4&"|"&13,Despiece!$H$5:$H$1004,0))&"")) | G20: =IF(OR(B20="",F20=""),"",IFERROR(INDEX(Precios!$F$5:$F$124,MATCH(F20,Precios!$A$5:$A$124,0))*1,"")) | H20: =IF(AND(ISNUMBER(D20),ISNUMBER(G20)),D20*G20,"") | I20: =IF(OR(B20="",NOT(ISNUMBER(D20))),"",IF(INDEX(Despiece!$F$5:$F$1004,MATCH($C$4&"|"&13,Despiece!$H$5:$H$1004,0))="Sí",D20*Precios!$Q$10,0)) | J20: =IF(AND(ISNUMBER(H20),ISNUMBER(I20)),H20+I20,"") | K20: =IF(B20="","",IF(ISNUMBER(J20),IF(INDEX(Despiece!$F$5:$F$1004,MATCH($C$4&"|"&13,Despiece!$H$5:$H$1004,0))="Sí","Sublimada",""),IF(NOT(ISNUMBER(D20)),"Faltan metros (Despiece). ","")&IF(F20="","Elige tela. ",IF(NOT(ISNUMBER(G20)),"Falta precio o peso de 1 m (Precios). ",""))))
A21: =IF(B21="","",14) | B21: =IFERROR(INDEX(Despiece!$B$5:$B$1004,MATCH($C$4&"|"&14,Despiece!$H$5:$H$1004,0)),"") | C21: =IF(B21="","",INDEX(Despiece!$C$5:$C$1004,MATCH($C$4&"|"&14,Despiece!$H$5:$H$1004,0))) | D21: =IF(B21="","",IF(N(INDEX(Despiece!$D$5:$D$1004,MATCH($C$4&"|"&14,Despiece!$H$5:$H$1004,0)))>0,INDEX(Despiece!$D$5:$D$1004,MATCH($C$4&"|"&14,Despiece!$H$5:$H$1004,0))*(1+IFERROR(IF(ISNUMBER(INDEX(Moldes!$K$5:$K$154,MATCH($C$4,Moldes!$A$5:$A$154,0))),INDEX(Moldes!$K$5:$K$154,MATCH($C$4,Moldes!$A$5:$A$154,0)),Precios!$Q$12),Precios!$Q$12)),"")) | F21: =IF(B21="","",IF(E21<>"",E21,INDEX(Despiece!$E$5:$E$1004,MATCH($C$4&"|"&14,Despiece!$H$5:$H$1004,0))&"")) | G21: =IF(OR(B21="",F21=""),"",IFERROR(INDEX(Precios!$F$5:$F$124,MATCH(F21,Precios!$A$5:$A$124,0))*1,"")) | H21: =IF(AND(ISNUMBER(D21),ISNUMBER(G21)),D21*G21,"") | I21: =IF(OR(B21="",NOT(ISNUMBER(D21))),"",IF(INDEX(Despiece!$F$5:$F$1004,MATCH($C$4&"|"&14,Despiece!$H$5:$H$1004,0))="Sí",D21*Precios!$Q$10,0)) | J21: =IF(AND(ISNUMBER(H21),ISNUMBER(I21)),H21+I21,"") | K21: =IF(B21="","",IF(ISNUMBER(J21),IF(INDEX(Despiece!$F$5:$F$1004,MATCH($C$4&"|"&14,Despiece!$H$5:$H$1004,0))="Sí","Sublimada",""),IF(NOT(ISNUMBER(D21)),"Faltan metros (Despiece). ","")&IF(F21="","Elige tela. ",IF(NOT(ISNUMBER(G21)),"Falta precio o peso de 1 m (Precios). ",""))))
A22: =IF(B22="","",15) | B22: =IFERROR(INDEX(Despiece!$B$5:$B$1004,MATCH($C$4&"|"&15,Despiece!$H$5:$H$1004,0)),"") | C22: =IF(B22="","",INDEX(Despiece!$C$5:$C$1004,MATCH($C$4&"|"&15,Despiece!$H$5:$H$1004,0))) | D22: =IF(B22="","",IF(N(INDEX(Despiece!$D$5:$D$1004,MATCH($C$4&"|"&15,Despiece!$H$5:$H$1004,0)))>0,INDEX(Despiece!$D$5:$D$1004,MATCH($C$4&"|"&15,Despiece!$H$5:$H$1004,0))*(1+IFERROR(IF(ISNUMBER(INDEX(Moldes!$K$5:$K$154,MATCH($C$4,Moldes!$A$5:$A$154,0))),INDEX(Moldes!$K$5:$K$154,MATCH($C$4,Moldes!$A$5:$A$154,0)),Precios!$Q$12),Precios!$Q$12)),"")) | F22: =IF(B22="","",IF(E22<>"",E22,INDEX(Despiece!$E$5:$E$1004,MATCH($C$4&"|"&15,Despiece!$H$5:$H$1004,0))&"")) | G22: =IF(OR(B22="",F22=""),"",IFERROR(INDEX(Precios!$F$5:$F$124,MATCH(F22,Precios!$A$5:$A$124,0))*1,"")) | H22: =IF(AND(ISNUMBER(D22),ISNUMBER(G22)),D22*G22,"") | I22: =IF(OR(B22="",NOT(ISNUMBER(D22))),"",IF(INDEX(Despiece!$F$5:$F$1004,MATCH($C$4&"|"&15,Despiece!$H$5:$H$1004,0))="Sí",D22*Precios!$Q$10,0)) | J22: =IF(AND(ISNUMBER(H22),ISNUMBER(I22)),H22+I22,"") | K22: =IF(B22="","",IF(ISNUMBER(J22),IF(INDEX(Despiece!$F$5:$F$1004,MATCH($C$4&"|"&15,Despiece!$H$5:$H$1004,0))="Sí","Sublimada",""),IF(NOT(ISNUMBER(D22)),"Faltan metros (Despiece). ","")&IF(F22="","Elige tela. ",IF(NOT(ISNUMBER(G22)),"Falta precio o peso de 1 m (Precios). ",""))))
A23: =IF(B23="","",16) | B23: =IFERROR(INDEX(Despiece!$B$5:$B$1004,MATCH($C$4&"|"&16,Despiece!$H$5:$H$1004,0)),"") | C23: =IF(B23="","",INDEX(Despiece!$C$5:$C$1004,MATCH($C$4&"|"&16,Despiece!$H$5:$H$1004,0))) | D23: =IF(B23="","",IF(N(INDEX(Despiece!$D$5:$D$1004,MATCH($C$4&"|"&16,Despiece!$H$5:$H$1004,0)))>0,INDEX(Despiece!$D$5:$D$1004,MATCH($C$4&"|"&16,Despiece!$H$5:$H$1004,0))*(1+IFERROR(IF(ISNUMBER(INDEX(Moldes!$K$5:$K$154,MATCH($C$4,Moldes!$A$5:$A$154,0))),INDEX(Moldes!$K$5:$K$154,MATCH($C$4,Moldes!$A$5:$A$154,0)),Precios!$Q$12),Precios!$Q$12)),"")) | F23: =IF(B23="","",IF(E23<>"",E23,INDEX(Despiece!$E$5:$E$1004,MATCH($C$4&"|"&16,Despiece!$H$5:$H$1004,0))&"")) | G23: =IF(OR(B23="",F23=""),"",IFERROR(INDEX(Precios!$F$5:$F$124,MATCH(F23,Precios!$A$5:$A$124,0))*1,"")) | H23: =IF(AND(ISNUMBER(D23),ISNUMBER(G23)),D23*G23,"") | I23: =IF(OR(B23="",NOT(ISNUMBER(D23))),"",IF(INDEX(Despiece!$F$5:$F$1004,MATCH($C$4&"|"&16,Despiece!$H$5:$H$1004,0))="Sí",D23*Precios!$Q$10,0)) | J23: =IF(AND(ISNUMBER(H23),ISNUMBER(I23)),H23+I23,"") | K23: =IF(B23="","",IF(ISNUMBER(J23),IF(INDEX(Despiece!$F$5:$F$1004,MATCH($C$4&"|"&16,Despiece!$H$5:$H$1004,0))="Sí","Sublimada",""),IF(NOT(ISNUMBER(D23)),"Faltan metros (Despiece). ","")&IF(F23="","Elige tela. ",IF(NOT(ISNUMBER(G23)),"Falta precio o peso de 1 m (Precios). ",""))))
B25: RESUMEN POR PRENDA
B26: Tela | J26: =IF(SUMPRODUCT((B8:B23<>"")*NOT(ISNUMBER(J8:J23)))=0,SUM(H8:H23),"Faltan datos ↑") -> Faltan datos ↑ | K26: Suma de las piezas
B27: Papel y tinta de sublimación | J27: =IF(SUMPRODUCT((B8:B23<>"")*NOT(ISNUMBER(J8:J23)))=0,SUM(I8:I23),"Faltan datos ↑") -> Faltan datos ↑ | K27: =IF(N(Precios!$Q$10)=0,"OJO: costo de impresión en $0 (hoja Precios)",TEXT(SUMIF(I8:I23,">0",D8:D23),"0.00")&" m impresos × "&TEXT(Precios!$Q$10,"$#,##0")) -> OJO: costo de impresión en $0 (hoja Precios)
B28: Confección (taller) | J28: =IFERROR(INDEX(Moldes!$M$5:$M$154,MATCH($C$4,Moldes!$A$5:$A$154,0))*1,"Falta tipo de confección (Moldes)") -> 2000 | K28: =IFERROR(INDEX(Moldes!$E$5:$E$154,MATCH($C$4,Moldes!$A$5:$A$154,0))&"","") -> Camiseta De Futbol
B29: Avíos | J29: =IFERROR(INDEX(Moldes!$N$5:$N$154,MATCH($C$4,Moldes!$A$5:$A$154,0))*1,0) -> 0 | K29: =IFERROR(IF(INDEX(Moldes!$F$5:$F$154,MATCH($C$4,Moldes!$A$5:$A$154,0))&""="","Sin avíos",INDEX(Moldes!$F$5:$F$154,MATCH($C$4,Moldes!$A$5:$A$154,0))&" × "&INDEX(Moldes!$G$5:$G$154,MATCH($C$4,Moldes!$A$5:$A$154,0))&IF(INDEX(Moldes!$H$5:$H$154,MATCH($C$4,Moldes!$A$5:$A$154,0))&""="",""," + "&INDEX(Moldes!$H$5:$H$154,MATCH($C$4,Moldes!$A$5:$A$154,0))&" × "&INDEX(Moldes!$I$5:$I$154,MATCH($C$4,Moldes!$A$5:$A$154,0)))),"") -> Sin avíos
B30: Extras (bordado, DTF, escudo…) — escribe | K30: Por prenda
B31: COSTO DE PRODUCCIÓN | J31: =IFERROR(J26+J27+J28+J29+N(J30),"Completa los datos ↑") -> Completa los datos ↑
B33: ="Precio mínimo de venta (neto) = costo × "&TEXT(Precios!$Q$16,"0.00")&" (gastos generales "&TEXT(Precios!$Q$14,"0.0%")&" + ganancia "&TEXT(Precios!$Q$15,"0%")&")" -> Precio mínimo de venta (neto) = costo × 2.40 (gastos generales 43.4% + ganancia 15%) | J33: =IF(ISNUMBER(J31),J31*Precios!$Q$16,"")
B34: Tu precio de venta actual, neto — escribe
B35: Ganancia por prenda (después de costo y gastos generales) | J35: =IF(AND(ISNUMBER(J31),N(J34)>0),J34-J31-J34*Precios!$Q$14,"") | K35: =IF(ISNUMBER(J35),TEXT(J35/J34,"0.0%")&" del precio"&IF(J35<0," ← PIERDE PLATA",IF(J35/J34<Precios!$Q$15," ← bajo la meta","")),"")
B37: AJUSTAR CON UN CORTE REAL (opcional)
B38: Después de cortar este molde: qué tela, cuántas prendas y cuántos kg se usaron. Te dice el % de ajuste para anotar en Moldes.
B39: Tela cortada
B40: Prendas cortadas
B41: Kg usados
B42: Metros reales por prenda | J42: =IFERROR(J41/INDEX(Precios!$E$5:$E$124,MATCH(J39,Precios!$A$5:$A$124,0))/J40,"")
B43: Metros del despiece en esa tela (sin merma) | J43: =IF(J39="","",SUMIF(F8:F23,J39,D8:D23)/(1+IFERROR(IF(ISNUMBER(INDEX(Moldes!$K$5:$K$154,MATCH($C$4,Moldes!$A$5:$A$154,0))),INDEX(Moldes!$K$5:$K$154,MATCH($C$4,Moldes!$A$5:$A$154,0)),Precios!$Q$12),Precios!$Q$12)))
B44: AJUSTE A ANOTAR EN MOLDES (columna K) | J44: =IF(AND(ISNUMBER(J42),N(J43)>0),J42/J43-1,"")
...

Sheet Moldes
A1: MOLDES — catálogo con su costo de producción (telas por defecto)
A2: Una fila por molde. Lo que va por prenda y no depende de la tela: confección y avíos. Para probar otras telas, usa la Ficha.
A3: ="Moldes con costo completo: "&COUNTIF(P5:P154,"Lista*")&" de "&COUNTA(A5:A154) -> Moldes con costo completo: 0 de 58
A4: Molde | B4: Descripción | C4: Prenda | D4: Calce | E4: Tipo de confección | F4: Avío 1 | G4: Cant. | H4: Avío 2 | I4: Cant. | J4: Piezas en despiece | K4: Ajuste por consumo real (%) — vacío = merma general | L4: $ Tela + impresión | M4: $ Confección | N4: $ Avíos | O4: COSTO DE PRODUCCIÓN | P4: Qué falta | Q4: Notas
A5: 01 · FUTMUJU01 | B5: Fútbol, cuello redondo | C5: Camiseta | D5: Femenino | E5: Camiseta De Futbol | J5: =IF(A5="","",COUNTIF(Despiece!$A$5:$A$1004,A5)) -> 4 | L5: =IF(A5="","",IF(COUNTIFS(Despiece!$A$5:$A$1004,A5,Despiece!$D$5:$D$1004,">0")<J5,"",IF(COUNTIFS(Despiece!$A$5:$A$1004,A5,Despiece!$G$5:$G$1004,"falta*")>0,"",SUMIFS(Despiece!$G$5:$G$1004,Despiece!$A$5:$A$1004,A5)))) | M5: =IF(OR(A5="",E5=""),"",IFERROR(INDEX(Precios!$K$5:$K$84,MATCH(E5,Precios!$J$5:$J$84,0)),"")) -> 2000 | N5: =IF(A5="","",IFERROR(N(G5)*IF(F5="",0,INDEX(Precios!$N$5:$N$64,MATCH(F5,Precios!$M$5:$M$64,0)))+N(I5)*IF(H5="",0,INDEX(Precios!$N$5:$N$64,MATCH(H5,Precios!$M$5:$M$64,0))),"")) -> 0 | O5: =IF(A5="","",IFERROR(L5+M5+N5,"")) | P5: =IF(A5="","",IF(ISNUMBER(O5),"Lista"&IF(N(Precios!$Q$10)=0," (impresión en $0)",""),IF(J5=0,"Agregar piezas en Despiece. ",IF(COUNTIFS(Despiece!$A$5:$A$1004,A5,Despiece!$D$5:$D$1004,">0")<J5,"Metros de "&(J5-COUNTIFS(Despiece!$A$5:$A$1004,A5,Despiece!$D$5:$D$1004,">0"))&" pieza(s). ",""))&IF(COUNTIFS(Despiece!$A$5:$A$1004,A5,Despiece!$G$5:$G$1004,"falta*")>0,"Precio o peso de 1 m de alguna tela. ","")&IF(M5="","Tipo/precio de confección. ",""))) -> Metros de 4 pieza(s).
A6: 02 · FUTHOMU01 | B6: Fútbol, cuello redondo | C6: Camiseta | D6: Masculino | E6: Camiseta De Futbol | J6: =IF(A6="","",COUNTIF(Despiece!$A$5:$A$1004,A6)) -> 4 | L6: =IF(A6="","",IF(COUNTIFS(Despiece!$A$5:$A$1004,A6,Despiece!$D$5:$D$1004,">0")<J6,"",IF(COUNTIFS(Despiece!$A$5:$A$1004,A6,Despiece!$G$5:$G$1004,"falta*")>0,"",SUMIFS(Despiece!$G$5:$G$1004,Despiece!$A$5:$A$1004,A6)))) | M6: =IF(OR(A6="",E6=""),"",IFERROR(INDEX(Precios!$K$5:$K$84,MATCH(E6,Precios!$J$5:$J$84,0)),"")) -> 2000 | N6: =IF(A6="","",IFERROR(N(G6)*IF(F6="",0,INDEX(Precios!$N$5:$N$64,MATCH(F6,Precios!$M$5:$M$64,0)))+N(I6)*IF(H6="",0,INDEX(Precios!$N$5:$N$64,MATCH(H6,Precios!$M$5:$M$64,0))),"")) -> 0 | O6: =IF(A6="","",IFERROR(L6+M6+N6,"")) | P6: =IF(A6="","",IF(ISNUMBER(O6),"Lista"&IF(N(Precios!$Q$10)=0," (impresión en $0)",""),IF(J6=0,"Agregar piezas en Despiece. ",IF(COUNTIFS(Despiece!$A$5:$A$1004,A6,Despiece!$D$5:$D$1004,">0")<J6,"Metros de "&(J6-COUNTIFS(Despiece!$A$5:$A$1004,A6,Despiece!$D$5:$D$1004,">0"))&" pieza(s). ",""))&IF(COUNTIFS(Despiece!$A$5:$A$1004,A6,Despiece!$G$5:$G$1004,"falta*")>0,"Precio o peso de 1 m de alguna tela. ","")&IF(M6="","Tipo/precio de confección. ",""))) -> Metros de 4 pieza(s).
A7: 03 · FUTINMUJU01 | B7: Fútbol infantil, cuello redondo | C7: Camiseta | D7: Infantil Femenino | E7: Camiseta De Futbol | J7: =IF(A7="","",COUNTIF(Despiece!$A$5:$A$1004,A7)) -> 4 | L7: =IF(A7="","",IF(COUNTIFS(Despiece!$A$5:$A$1004,A7,Despiece!$D$5:$D$1004,">0")<J7,"",IF(COUNTIFS(Despiece!$A$5:$A$1004,A7,Despiece!$G$5:$G$1004,"falta*")>0,"",SUMIFS(Despiece!$G$5:$G$1004,Despiece!$A$5:$A$1004,A7)))) | M7: =IF(OR(A7="",E7=""),"",IFERROR(INDEX(Precios!$K$5:$K$84,MATCH(E7,Precios!$J$5:$J$84,0)),"")) -> 2000 | N7: =IF(A7="","",IFERROR(N(G7)*IF(F7="",0,INDEX(Precios!$N$5:$N$64,MATCH(F7,Precios!$M$5:$M$64,0)))+N(I7)*IF(H7="",0,INDEX(Precios!$N$5:$N$64,MATCH(H7,Precios!$M$5:$M$64,0))),"")) -> 0 | O7: =IF(A7="","",IFERROR(L7+M7+N7,"")) | P7: =IF(A7="","",IF(ISNUMBER(O7),"Lista"&IF(N(Precios!$Q$10)=0," (impresión en $0)",""),IF(J7=0,"Agregar piezas en Despiece. ",IF(COUNTIFS(Despiece!$A$5:$A$1004,A7,Despiece!$D$5:$D$1004,">0")<J7,"Metros de "&(J7-COUNTIFS(Despiece!$A$5:$A$1004,A7,Despiece!$D$5:$D$1004,">0"))&" pieza(s). ",""))&IF(COUNTIFS(Despiece!$A$5:$A$1004,A7,Despiece!$G$5:$G$1004,"falta*")>0,"Precio o peso de 1 m de alguna tela. ","")&IF(M7="","Tipo/precio de confección. ",""))) -> Metros de 4 pieza(s).
A8: 04 · FUTINHOMU01 | B8: Fútbol infantil, cuello redondo | C8: Camiseta | D8: Infantil Masculino | E8: Camiseta De Futbol | J8: =IF(A8="","",COUNTIF(Despiece!$A$5:$A$1004,A8)) -> 4 | L8: =IF(A8="","",IF(COUNTIFS(Despiece!$A$5:$A$1004,A8,Despiece!$D$5:$D$1004,">0")<J8,"",IF(COUNTIFS(Despiece!$A$5:$A$1004,A8,Despiece!$G$5:$G$1004,"falta*")>0,"",SUMIFS(Despiece!$G$5:$G$1004,Despiece!$A$5:$A$1004,A8)))) | M8: =IF(OR(A8="",E8=""),"",IFERROR(INDEX(Precios!$K$5:$K$84,MATCH(E8,Precios!$J$5:$J$84,0)),"")) -> 2000 | N8: =IF(A8="","",IFERROR(N(G8)*IF(F8="",0,INDEX(Precios!$N$5:$N$64,MATCH(F8,Precios!$M$5:$M$64,0)))+N(I8)*IF(H8="",0,INDEX(Precios!$N$5:$N$64,MATCH(H8,Precios!$M$5:$M$64,0))),"")) -> 0 | O8: =IF(A8="","",IFERROR(L8+M8+N8,"")) | P8: =IF(A8="","",IF(ISNUMBER(O8),"Lista"&IF(N(Precios!$Q$10)=0," (impresión en $0)",""),IF(J8=0,"Agregar piezas en Despiece. ",IF(COUNTIFS(Despiece!$A$5:$A$1004,A8,Despiece!$D$5:$D$1004,">0")<J8,"Metros de "&(J8-COUNTIFS(Despiece!$A$5:$A$1004,A8,Despiece!$D$5:$D$1004,">0"))&" pieza(s). ",""))&IF(COUNTIFS(Despiece!$A$5:$A$1004,A8,Despiece!$G$5:$G$1004,"falta*")>0,"Precio o peso de 1 m de alguna tela. ","")&IF(M8="","Tipo/precio de confección. ",""))) -> Metros de 4 pieza(s). | Q8: Corte OT 2369: 0,0375 kg Cire + 0,024 kg Mesh por prenda.
A9: 05 · FUTMUJV01 | B9: Fútbol, cuello v | C9: Camiseta | D9: Femenino | E9: Camiseta De Futbol | J9: =IF(A9="","",COUNTIF(Despiece!$A$5:$A$1004,A9)) -> 4 | L9: =IF(A9="","",IF(COUNTIFS(Despiece!$A$5:$A$1004,A9,Despiece!$D$5:$D$1004,">0")<J9,"",IF(COUNTIFS(Despiece!$A$5:$A$1004,A9,Despiece!$G$5:$G$1004,"falta*")>0,"",SUMIFS(Despiece!$G$5:$G$1004,Despiece!$A$5:$A$1004,A9)))) | M9: =IF(OR(A9="",E9=""),"",IFERROR(INDEX(Precios!$K$5:$K$84,MATCH(E9,Precios!$J$5:$J$84,0)),"")) -> 2000 | N9: =IF(A9="","",IFERROR(N(G9)*IF(F9="",0,INDEX(Precios!$N$5:$N$64,MATCH(F9,Precios!$M$5:$M$64,0)))+N(I9)*IF(H9="",0,INDEX(Precios!$N$5:$N$64,MATCH(H9,Precios!$M$5:$M$64,0))),"")) -> 0 | O9: =IF(A9="","",IFERROR(L9+M9+N9,"")) | P9: =IF(A9="","",IF(ISNUMBER(O9),"Lista"&IF(N(Precios!$Q$10)=0," (impresión en $0)",""),IF(J9=0,"Agregar piezas en Despiece. ",IF(COUNTIFS(Despiece!$A$5:$A$1004,A9,Despiece!$D$5:$D$1004,">0")<J9,"Metros de "&(J9-COUNTIFS(Despiece!$A$5:$A$1004,A9,Despiece!$D$5:$D$1004,">0"))&" pieza(s). ",""))&IF(COUNTIFS(Despiece!$A$5:$A$1004,A9,Despiece!$G$5:$G$1004,"falta*")>0,"Precio o peso de 1 m de alguna tela. ","")&IF(M9="","Tipo/precio de confección. ",""))) -> Metros de 4 pieza(s).
A10: 06 · FUTHOMV01 | B10: Fútbol, cuello v | C10: Camiseta | D10: Masculino | E10: Camiseta De Futbol | J10: =IF(A10="","",COUNTIF(Despiece!$A$5:$A$1004,A10)) -> 4 | L10: =IF(A10="","",IF(COUNTIFS(Despiece!$A$5:$A$1004,A10,Despiece!$D$5:$D$1004,">0")<J10,"",IF(COUNTIFS(Despiece!$A$5:$A$1004,A10,Despiece!$G$5:$G$1004,"falta*")>0,"",SUMIFS(Despiece!$G$5:$G$1004,Despiece!$A$5:$A$1004,A10)))) | M10: =IF(OR(A10="",E10=""),"",IFERROR(INDEX(Precios!$K$5:$K$84,MATCH(E10,Precios!$J$5:$J$84,0)),"")) -> 2000 | N10: =IF(A10="","",IFERROR(N(G10)*IF(F10="",0,INDEX(Precios!$N$5:$N$64,MATCH(F10,Precios!$M$5:$M$64,0)))+N(I10)*IF(H10="",0,INDEX(Precios!$N$5:$N$64,MATCH(H10,Precios!$M$5:$M$64,0))),"")) -> 0 | O10: =IF(A10="","",IFERROR(L10+M10+N10,"")) | P10: =IF(A10="","",IF(ISNUMBER(O10),"Lista"&IF(N(Precios!$Q$10)=0," (impresión en $0)",""),IF(J10=0,"Agregar piezas en Despiece. ",IF(COUNTIFS(Despiece!$A$5:$A$1004,A10,Despiece!$D$5:$D$1004,">0")<J10,"Metros de "&(J10-COUNTIFS(Despiece!$A$5:$A$1004,A10,Despiece!$D$5:$D$1004,">0"))&" pieza(s). ",""))&IF(COUNTIFS(Despiece!$A$5:$A$1004,A10,Despiece!$G$5:$G$1004,"falta*")>0,"Precio o peso de 1 m de alguna tela. ","")&IF(M10="","Tipo/precio de confección. ",""))) -> Metros de 4 pieza(s).
A11: 07 · FUTINMUJV01 | B11: Fútbol infantil, cuello v | C11: Camiseta | D11: Infantil Femenino | E11: Camiseta De Futbol | J11: =IF(A11="","",COUNTIF(Despiece!$A$5:$A$1004,A11)) -> 4 | L11: =IF(A11="","",IF(COUNTIFS(Despiece!$A$5:$A$1004,A11,Despiece!$D$5:$D$1004,">0")<J11,"",IF(COUNTIFS(Despiece!$A$5:$A$1004,A11,Despiece!$G$5:$G$1004,"falta*")>0,"",SUMIFS(Despiece!$G$5:$G$1004,Despiece!$A$5:$A$1004,A11)))) | M11: =IF(OR(A11="",E11=""),"",IFERROR(INDEX(Precios!$K$5:$K$84,MATCH(E11,Precios!$J$5:$J$84,0)),"")) -> 2000 | N11: =IF(A11="","",IFERROR(N(G11)*IF(F11="",0,INDEX(Precios!$N$5:$N$64,MATCH(F11,Precios!$M$5:$M$64,0)))+N(I11)*IF(H11="",0,INDEX(Precios!$N$5:$N$64,MATCH(H11,Precios!$M$5:$M$64,0))),"")) -> 0 | O11: =IF(A11="","",IFERROR(L11+M11+N11,"")) | P11: =IF(A11="","",IF(ISNUMBER(O11),"Lista"&IF(N(Precios!$Q$10)=0," (impresión en $0)",""),IF(J11=0,"Agregar piezas en Despiece. ",IF(COUNTIFS(Despiece!$A$5:$A$1004,A11,Despiece!$D$5:$D$1004,">0")<J11,"Metros de "&(J11-COUNTIFS(Despiece!$A$5:$A$1004,A11,Despiece!$D$5:$D$1004,">0"))&" pieza(s). ",""))&IF(COUNTIFS(Despiece!$A$5:$A$1004,A11,Despiece!$G$5:$G$1004,"falta*")>0,"Precio o peso de 1 m de alguna tela. ","")&IF(M11="","Tipo/precio de confección. ",""))) -> Metros de 4 pieza(s).
A12: 08 · FUTINHOMV01 | B12: Fútbol infantil, cuello v | C12: Camiseta | D12: Infantil Masculino | E12: Camiseta De Futbol | J12: =IF(A12="","",COUNTIF(Despiece!$A$5:$A$1004,A12)) -> 4 | L12: =IF(A12="","",IF(COUNTIFS(Despiece!$A$5:$A$1004,A12,Despiece!$D$5:$D$1004,">0")<J12,"",IF(COUNTIFS(Despiece!$A$5:$A$1004,A12,Despiece!$G$5:$G$1004,"falta*")>0,"",SUMIFS(Despiece!$G$5:$G$1004,Despiece!$A$5:$A$1004,A12)))) | M12: =IF(OR(A12="",E12=""),"",IFERROR(INDEX(Precios!$K$5:$K$84,MATCH(E12,Precios!$J$5:$J$84,0)),"")) -> 2000 | N12: =IF(A12="","",IFERROR(N(G12)*IF(F12="",0,INDEX(Precios!$N$5:$N$64,MATCH(F12,Precios!$M$5:$M$64,0)))+N(I12)*IF(H12="",0,INDEX(Precios!$N$5:$N$64,MATCH(H12,Precios!$M$5:$M$64,0))),"")) -> 0 | O12: =IF(A12="","",IFERROR(L12+M12+N12,"")) | P12: =IF(A12="","",IF(ISNUMBER(O12),"Lista"&IF(N(Precios!$Q$10)=0," (impresión en $0)",""),IF(J12=0,"Agregar piezas en Despiece. ",IF(COUNTIFS(Despiece!$A$5:$A$1004,A12,Despiece!$D$5:$D$1004,">0")<J12,"Metros de "&(J12-COUNTIFS(Despiece!$A$5:$A$1004,A12,Despiece!$D$5:$D$1004,">0"))&" pieza(s). ",""))&IF(COUNTIFS(Despiece!$A$5:$A$1004,A12,Despiece!$G$5:$G$1004,"falta*")>0,"Precio o peso de 1 m de alguna tela. ","")&IF(M12="","Tipo/precio de confección. ",""))) -> Metros de 4 pieza(s).
A13: 09 · FUTMUJCC01 | B13: Fútbol, cuello camisero | C13: Camiseta | D13: Femenino | E13: Camiseta De Futbol | J13: =IF(A13="","",COUNTIF(Despiece!$A$5:$A$1004,A13)) -> 4 | L13: =IF(A13="","",IF(COUNTIFS(Despiece!$A$5:$A$1004,A13,Despiece!$D$5:$D$1004,">0")<J13,"",IF(COUNTIFS(Despiece!$A$5:$A$1004,A13,Despiece!$G$5:$G$1004,"falta*")>0,"",SUMIFS(Despiece!$G$5:$G$1004,Despiece!$A$5:$A$1004,A13)))) | M13: =IF(OR(A13="",E13=""),"",IFERROR(INDEX(Precios!$K$5:$K$84,MATCH(E13,Precios!$J$5:$J$84,0)),"")) -> 2000 | N13: =IF(A13="","",IFERROR(N(G13)*IF(F13="",0,INDEX(Precios!$N$5:$N$64,MATCH(F13,Precios!$M$5:$M$64,0)))+N(I13)*IF(H13="",0,INDEX(Precios!$N$5:$N$64,MATCH(H13,Precios!$M$5:$M$64,0))),"")) -> 0 | O13: =IF(A13="","",IFERROR(L13+M13+N13,"")) | P13: =IF(A13="","",IF(ISNUMBER(O13),"Lista"&IF(N(Precios!$Q$10)=0," (impresión en $0)",""),IF(J13=0,"Agregar piezas en Despiece. ",IF(COUNTIFS(Despiece!$A$5:$A$1004,A13,Despiece!$D$5:$D$1004,">0")<J13,"Metros de "&(J13-COUNTIFS(Despiece!$A$5:$A$1004,A13,Despiece!$D$5:$D$1004,">0"))&" pieza(s). ",""))&IF(COUNTIFS(Despiece!$A$5:$A$1004,A13,Despiece!$G$5:$G$1004,"falta*")>0,"Precio o peso de 1 m de alguna tela. ","")&IF(M13="","Tipo/precio de confección. ",""))) -> Metros de 4 pieza(s).
A14: 10 · FUTHOMCC01 | B14: Fútbol, cuello camisero | C14: Camiseta | D14: Masculino | E14: Camiseta De Futbol | J14: =IF(A14="","",COUNTIF(Despiece!$A$5:$A$1004,A14)) -> 4 | L14: =IF(A14="","",IF(COUNTIFS(Despiece!$A$5:$A$1004,A14,Despiece!$D$5:$D$1004,">0")<J14,"",IF(COUNTIFS(Despiece!$A$5:$A$1004,A14,Despiece!$G$5:$G$1004,"falta*")>0,"",SUMIFS(Despiece!$G$5:$G$1004,Despiece!$A$5:$A$1004,A14)))) | M14: =IF(OR(A14="",E14=""),"",IFERROR(INDEX(Precios!$K$5:$K$84,MATCH(E14,Precios!$J$5:$J$84,0)),"")) -> 2000 | N14: =IF(A14="","",IFERROR(N(G14)*IF(F14="",0,INDEX(Precios!$N$5:$N$64,MATCH(F14,Precios!$M$5:$M$64,0)))+N(I14)*IF(H14="",0,INDEX(Precios!$N$5:$N$64,MATCH(H14,Precios!$M$5:$M$64,0))),"")) -> 0 | O14: =IF(A14="","",IFERROR(L14+M14+N14,"")) | P14: =IF(A14="","",IF(ISNUMBER(O14),"Lista"&IF(N(Precios!$Q$10)=0," (impresión en $0)",""),IF(J14=0,"Agregar piezas en Despiece. ",IF(COUNTIFS(Despiece!$A$5:$A$1004,A14,Despiece!$D$5:$D$1004,">0")<J14,"Metros de "&(J14-COUNTIFS(Despiece!$A$5:$A$1004,A14,Despiece!$D$5:$D$1004,">0"))&" pieza(s). ",""))&IF(COUNTIFS(Despiece!$A$5:$A$1004,A14,Despiece!$G$5:$G$1004,"falta*")>0,"Precio o peso de 1 m de alguna tela. ","")&IF(M14="","Tipo/precio de confección. ",""))) -> Metros de 4 pieza(s).
A15: 11 · FUTINMUJCC01 | B15: Fútbol infantil, cuello camisero | C15: Camiseta | D15: Infantil Femenino | E15: Camiseta De Futbol | J15: =IF(A15="","",COUNTIF(Despiece!$A$5:$A$1004,A15)) -> 4 | L15: =IF(A15="","",IF(COUNTIFS(Despiece!$A$5:$A$1004,A15,Despiece!$D$5:$D$1004,">0")<J15,"",IF(COUNTIFS(Despiece!$A$5:$A$1004,A15,Despiece!$G$5:$G$1004,"falta*")>0,"",SUMIFS(Despiece!$G$5:$G$1004,Despiece!$A$5:$A$1004,A15)))) | M15: =IF(OR(A15="",E15=""),"",IFERROR(INDEX(Precios!$K$5:$K$84,MATCH(E15,Precios!$J$5:$J$84,0)),"")) -> 2000 | N15: =IF(A15="","",IFERROR(N(G15)*IF(F15="",0,INDEX(Precios!$N$5:$N$64,MATCH(F15,Precios!$M$5:$M$64,0)))+N(I15)*IF(H15="",0,INDEX(Precios!$N$5:$N$64,MATCH(H15,Precios!$M$5:$M$64,0))),"")) -> 0 | O15: =IF(A15="","",IFERROR(L15+M15+N15,"")) | P15: =IF(A15="","",IF(ISNUMBER(O15),"Lista"&IF(N(Precios!$Q$10)=0," (impresión en $0)",""),IF(J15=0,"Agregar piezas en Despiece. ",IF(COUNTIFS(Despiece!$A$5:$A$1004,A15,Despiece!$D$5:$D$1004,">0")<J15,"Metros de "&(J15-COUNTIFS(Despiece!$A$5:$A$1004,A15,Despiece!$D$5:$D$1004,">0"))&" pieza(s). ",""))&IF(COUNTIFS(Despiece!$A$5:$A$1004,A15,Despiece!$G$5:$G$1004,"falta*")>0,"Precio o peso de 1 m de alguna tela. ","")&IF(M15="","Tipo/precio de confección. ",""))) -> Metros de 4 pieza(s).
A16: 12 · FUTINHOMCC01 | B16: Fútbol infantil, cuello camisero | C16: Camiseta | D16: Infantil Masculino | E16: Camiseta De Futbol | J16: =IF(A16="","",COUNTIF(Despiece!$A$5:$A$1004,A16)) -> 4 | L16: =IF(A16="","",IF(COUNTIFS(Despiece!$A$5:$A$1004,A16,Despiece!$D$5:$D$1004,">0")<J16,"",IF(COUNTIFS(Despiece!$A$5:$A$1004,A16,Despiece!$G$5:$G$1004,"falta*")>0,"",SUMIFS(Despiece!$G$5:$G$1004,Despiece!$A$5:$A$1004,A16)))) | M16: =IF(OR(A16="",E16=""),"",IFERROR(INDEX(Precios!$K$5:$K$84,MATCH(E16,Precios!$J$5:$J$84,0)),"")) -> 2000 | N16: =IF(A16="","",IFERROR(N(G16)*IF(F16="",0,INDEX(Precios!$N$5:$N$64,MATCH(F16,Precios!$M$5:$M$64,0)))+N(I16)*IF(H16="",0,INDEX(Precios!$N$5:$N$64,MATCH(H16,Precios!$M$5:$M$64,0))),"")) -> 0 | O16: =IF(A16="","",IFERROR(L16+M16+N16,"")) | P16: =IF(A16="","",IF(ISNUMBER(O16),"Lista"&IF(N(Precios!$Q$10)=0," (impresión en $0)",""),IF(J16=0,"Agregar piezas en Despiece. ",IF(COUNTIFS(Despiece!$A$5:$A$1004,A16,Despiece!$D$5:$D$1004,">0")<J16,"Metros de "&(J16-COUNTIFS(Despiece!$A$5:$A$1004,A16,Despiece!$D$5:$D$1004,">0"))&" pieza(s). ",""))&IF(COUNTIFS(Despiece!$A$5:$A$1004,A16,Despiece!$G$5:$G$1004,"falta*")>0,"Precio o peso de 1 m de alguna tela. ","")&IF(M16="","Tipo/precio de confección. ",""))) -> Metros de 4 pieza(s).
A17: 13 · FUTMUJU01PRO | B17: Fútbol, pro, cuello redondo | C17: Camiseta | D17: Femenino | E17: Camiseta De Futbol | J17: =IF(A17="","",COUNTIF(Despiece!$A$5:$A$1004,A17)) -> 5 | L17: =IF(A17="","",IF(COUNTIFS(Despiece!$A$5:$A$1004,A17,Despiece!$D$5:$D$1004,">0")<J17,"",IF(COUNTIFS(Despiece!$A$5:$A$1004,A17,Despiece!$G$5:$G$1004,"falta*")>0,"",SUMIFS(Despiece!$G$5:$G$1004,Despiece!$A$5:$A$1004,A17)))) | M17: =IF(OR(A17="",E17=""),"",IFERROR(INDEX(Precios!$K$5:$K$84,MATCH(E17,Precios!$J$5:$J$84,0)),"")) -> 2000 | N17: =IF(A17="","",IFERROR(N(G17)*IF(F17="",0,INDEX(Precios!$N$5:$N$64,MATCH(F17,Precios!$M$5:$M$64,0)))+N(I17)*IF(H17="",0,INDEX(Precios!$N$5:$N$64,MATCH(H17,Precios!$M$5:$M$64,0))),"")) -> 0 | O17: =IF(A17="","",IFERROR(L17+M17+N17,"")) | P17: =IF(A17="","",IF(ISNUMBER(O17),"Lista"&IF(N(Precios!$Q$10)=0," (impresión en $0)",""),IF(J17=0,"Agregar piezas en Despiece. ",IF(COUNTIFS(Despiece!$A$5:$A$1004,A17,Despiece!$D$5:$D$1004,">0")<J17,"Metros de "&(J17-COUNTIFS(Despiece!$A$5:$A$1004,A17,Despiece!$D$5:$D$1004,">0"))&" pieza(s). ",""))&IF(COUNTIFS(Despiece!$A$5:$A$1004,A17,Despiece!$G$5:$G$1004,"falta*")>0,"Precio o peso de 1 m de alguna tela. ","")&IF(M17="","Tipo/precio de confección. ",""))) -> Metros de 5 pieza(s). | Q17: Corte OT 2257: 0,1225 kg Montesimone por prenda.
A18: 14 · FUTHOMU01PRO | B18: Fútbol, pro, cuello redondo | C18: Camiseta | D18: Masculino | E18: Camiseta De Futbol | J18: =IF(A18="","",COUNTIF(Despiece!$A$5:$A$1004,A18)) -> 5 | L18: =IF(A18="","",IF(COUNTIFS(Despiece!$A$5:$A$1004,A18,Despiece!$D$5:$D$1004,">0")<J18,"",IF(COUNTIFS(Despiece!$A$5:$A$1004,A18,Despiece!$G$5:$G$1004,"falta*")>0,"",SUMIFS(Despiece!$G$5:$G$1004,Despiece!$A$5:$A$1004,A18)))) | M18: =IF(OR(A18="",E18=""),"",IFERROR(INDEX(Precios!$K$5:$K$84,MATCH(E18,Precios!$J$5:$J$84,0)),"")) -> 2000 | N18: =IF(A18="","",IFERROR(N(G18)*IF(F18="",0,INDEX(Precios!$N$5:$N$64,MATCH(F18,Precios!$M$5:$M$64,0)))+N(I18)*IF(H18="",0,INDEX(Precios!$N$5:$N$64,MATCH(H18,Precios!$M$5:$M$64,0))),"")) -> 0 | O18: =IF(A18="","",IFERROR(L18+M18+N18,"")) | P18: =IF(A18="","",IF(ISNUMBER(O18),"Lista"&IF(N(Precios!$Q$10)=0," (impresión en $0)",""),IF(J18=0,"Agregar piezas en Despiece. ",IF(COUNTIFS(Despiece!$A$5:$A$1004,A18,Despiece!$D$5:$D$1004,">0")<J18,"Metros de "&(J18-COUNTIFS(Despiece!$A$5:$A$1004,A18,Despiece!$D$5:$D$1004,">0"))&" pieza(s). ",""))&IF(COUNTIFS(Despiece!$A$5:$A$1004,A18,Despiece!$G$5:$G$1004,"falta*")>0,"Precio o peso de 1 m de alguna tela. ","")&IF(M18="","Tipo/precio de confección. ",""))) -> Metros de 5 pieza(s). | Q18: Corte OT 2547: 0,12 kg Montesimone + 0,0775 kg Mesh por prenda.
A19: 15 · FUTMUJV01PRO | B19: Fútbol, pro, cuello v | C19: Camiseta | D19: Femenino | E19: Camiseta De Futbol | J19: =IF(A19="","",COUNTIF(Despiece!$A$5:$A$1004,A19)) -> 5 | L19: =IF(A19="","",IF(COUNTIFS(Despiece!$A$5:$A$1004,A19,Despiece!$D$5:$D$1004,">0")<J19,"",IF(COUNTIFS(Despiece!$A$5:$A$1004,A19,Despiece!$G$5:$G$1004,"falta*")>0,"",SUMIFS(Despiece!$G$5:$G$1004,Despiece!$A$5:$A$1004,A19)))) | M19: =IF(OR(A19="",E19=""),"",IFERROR(INDEX(Precios!$K$5:$K$84,MATCH(E19,Precios!$J$5:$J$84,0)),"")) -> 2000 | N19: =IF(A19="","",IFERROR(N(G19)*IF(F19="",0,INDEX(Precios!$N$5:$N$64,MATCH(F19,Precios!$M$5:$M$64,0)))+N(I19)*IF(H19="",0,INDEX(Precios!$N$5:$N$64,MATCH(H19,Precios!$M$5:$M$64,0))),"")) -> 0 | O19: =IF(A19="","",IFERROR(L19+M19+N19,"")) | P19: =IF(A19="","",IF(ISNUMBER(O19),"Lista"&IF(N(Precios!$Q$10)=0," (impresión en $0)",""),IF(J19=0,"Agregar piezas en Despiece. ",IF(COUNTIFS(Despiece!$A$5:$A$1004,A19,Despiece!$D$5:$D$1004,">0")<J19,"Metros de "&(J19-COUNTIFS(Despiece!$A$5:$A$1004,A19,Despiece!$D$5:$D$1004,">0"))&" pieza(s). ",""))&IF(COUNTIFS(Despiece!$A$5:$A$1004,A19,Despiece!$G$5:$G$1004,"falta*")>0,"Precio o peso de 1 m de alguna tela. ","")&IF(M19="","Tipo/precio de confección. ",""))) -> Metros de 5 pieza(s).
A20: 16 · FUTHOMV01PRO | B20: Fútbol, pro, cuello v | C20: Camiseta | D20: Masculino | E20: Camiseta De Futbol | J20: =IF(A20="","",COUNTIF(Despiece!$A$5:$A$1004,A20)) -> 5 | L20: =IF(A20="","",IF(COUNTIFS(Despiece!$A$5:$A$1004,A20,Despiece!$D$5:$D$1004,">0")<J20,"",IF(COUNTIFS(Despiece!$A$5:$A$1004,A20,Despiece!$G$5:$G$1004,"falta*")>0,"",SUMIFS(Despiece!$G$5:$G$1004,Despiece!$A$5:$A$1004,A20)))) | M20: =IF(OR(A20="",E20=""),"",IFERROR(INDEX(Precios!$K$5:$K$84,MATCH(E20,Precios!$J$5:$J$84,0)),"")) -> 2000 | N20: =IF(A20="","",IFERROR(N(G20)*IF(F20="",0,INDEX(Precios!$N$5:$N$64,MATCH(F20,Precios!$M$5:$M$64,0)))+N(I20)*IF(H20="",0,INDEX(Precios!$N$5:$N$64,MATCH(H20,Precios!$M$5:$M$64,0))),"")) -> 0 | O20: =IF(A20="","",IFERROR(L20+M20+N20,"")) | P20: =IF(A20="","",IF(ISNUMBER(O20),"Lista"&IF(N(Precios!$Q$10)=0," (impresión en $0)",""),IF(J20=0,"Agregar piezas en Despiece. ",IF(COUNTIFS(Despiece!$A$5:$A$1004,A20,Despiece!$D$5:$D$1004,">0")<J20,"Metros de "&(J20-COUNTIFS(Despiece!$A$5:$A$1004,A20,Despiece!$D$5:$D$1004,">0"))&" pieza(s). ",""))&IF(COUNTIFS(Despiece!$A$5:$A$1004,A20,Despiece!$G$5:$G$1004,"falta*")>0,"Precio o peso de 1 m de alguna tela. ","")&IF(M20="","Tipo/precio de confección. ",""))) -> Metros de 5 pieza(s).
A21: 17 · FUTMUJU02 | B21: Fútbol, raglán, cuello redondo | C21: Camiseta | D21: Femenino | E21: Camiseta Futbol Molde 2026 (Raglan) | J21: =IF(A21="","",COUNTIF(Despiece!$A$5:$A$1004,A21)) -> 4 | L21: =IF(A21="","",IF(COUNTIFS(Despiece!$A$5:$A$1004,A21,Despiece!$D$5:$D$1004,">0")<J21,"",IF(COUNTIFS(Despiece!$A$5:$A$1004,A21,Despiece!$G$5:$G$1004,"falta*")>0,"",SUMIFS(Despiece!$G$5:$G$1004,Despiece!$A$5:$A$1004,A21)))) | M21: =IF(OR(A21="",E21=""),"",IFERROR(INDEX(Precios!$K$5:$K$84,MATCH(E21,Precios!$J$5:$J$84,0)),"")) -> 2300 | N21: =IF(A21="","",IFERROR(N(G21)*IF(F21="",0,INDEX(Precios!$N$5:$N$64,MATCH(F21,Precios!$M$5:$M$64,0)))+N(I21)*IF(H21="",0,INDEX(Precios!$N$5:$N$64,MATCH(H21,Precios!$M$5:$M$64,0))),"")) -> 0 | O21: =IF(A21="","",IFERROR(L21+M21+N21,"")) | P21: =IF(A21="","",IF(ISNUMBER(O21),"Lista"&IF(N(Precios!$Q$10)=0," (impresión en $0)",""),IF(J21=0,"Agregar piezas en Despiece. ",IF(COUNTIFS(Despiece!$A$5:$A$1004,A21,Despiece!$D$5:$D$1004,">0")<J21,"Metros de "&(J21-COUNTIFS(Despiece!$A$5:$A$1004,A21,Despiece!$D$5:$D$1004,">0"))&" pieza(s). ",""))&IF(COUNTIFS(Despiece!$A$5:$A$1004,A21,Despiece!$G$5:$G$1004,"falta*")>0,"Precio o peso de 1 m de alguna tela. ","")&IF(M21="","Tipo/precio de confección. ",""))) -> Metros de 4 pieza(s).
A22: 18 · FUTHOMU02 | B22: Fútbol, raglán, cuello redondo | C22: Camiseta | D22: Masculino | E22: Camiseta Futbol Molde 2026 (Raglan) | J22: =IF(A22="","",COUNTIF(Despiece!$A$5:$A$1004,A22)) -> 4 | L22: =IF(A22="","",IF(COUNTIFS(Despiece!$A$5:$A$1004,A22,Despiece!$D$5:$D$1004,">0")<J22,"",IF(COUNTIFS(Despiece!$A$5:$A$1004,A22,Despiece!$G$5:$G$1004,"falta*")>0,"",SUMIFS(Despiece!$G$5:$G$1004,Despiece!$A$5:$A$1004,A22)))) | M22: =IF(OR(A22="",E22=""),"",IFERROR(INDEX(Precios!$K$5:$K$84,MATCH(E22,Precios!$J$5:$J$84,0)),"")) -> 2300 | N22: =IF(A22="","",IFERROR(N(G22)*IF(F22="",0,INDEX(Precios!$N$5:$N$64,MATCH(F22,Precios!$M$5:$M$64,0)))+N(I22)*IF(H22="",0,INDEX(Precios!$N$5:$N$64,MATCH(H22,Precios!$M$5:$M$64,0))),"")) -> 0 | O22: =IF(A22="","",IFERROR(L22+M22+N22,"")) | P22: =IF(A22="","",IF(ISNUMBER(O22),"Lista"&IF(N(Precios!$Q$10)=0," (impresión en $0)",""),IF(J22=0,"Agregar piezas en Despiece. ",IF(COUNTIFS(Despiece!$A$5:$A$1004,A22,Despiece!$D$5:$D$1004,">0")<J22,"Metros de "&(J22-COUNTIFS(Despiece!$A$5:$A$1004,A22,Despiece!$D$5:$D$1004,">0"))&" pieza(s). ",""))&IF(COUNTIFS(Despiece!$A$5:$A$1004,A22,Despiece!$G$5:$G$1004,"falta*")>0,"Precio o peso de 1 m de alguna tela. ","")&IF(M22="","Tipo/precio de confección. ",""))) -> Metros de 4 pieza(s).
A23: 19 · FUTINMUJU02 | B23: Fútbol infantil, raglán, cuello redondo | C23: Camiseta | D23: Infantil Femenino | E23: Camiseta Futbol Molde 2026 (Raglan) | J23: =IF(A23="","",COUNTIF(Despiece!$A$5:$A$1004,A23)) -> 4 | L23: =IF(A23="","",IF(COUNTIFS(Despiece!$A$5:$A$1004,A23,Despiece!$D$5:$D$1004,">0")<J23,"",IF(COUNTIFS(Despiece!$A$5:$A$1004,A23,Despiece!$G$5:$G$1004,"falta*")>0,"",SUMIFS(Despiece!$G$5:$G$1004,Despiece!$A$5:$A$1004,A23)))) | M23: =IF(OR(A23="",E23=""),"",IFERROR(INDEX(Precios!$K$5:$K$84,MATCH(E23,Precios!$J$5:$J$84,0)),"")) -> 2300 | N23: =IF(A23="","",IFERROR(N(G23)*IF(F23="",0,INDEX(Precios!$N$5:$N$64,MATCH(F23,Precios!$M$5:$M$64,0)))+N(I23)*IF(H23="",0,INDEX(Precios!$N$5:$N$64,MATCH(H23,Precios!$M$5:$M$64,0))),"")) -> 0 | O23: =IF(A23="","",IFERROR(L23+M23+N23,"")) | P23: =IF(A23="","",IF(ISNUMBER(O23),"Lista"&IF(N(Precios!$Q$10)=0," (impresión en $0)",""),IF(J23=0,"Agregar piezas en Despiece. ",IF(COUNTIFS(Despiece!$A$5:$A$1004,A23,Despiece!$D$5:$D$1004,">0")<J23,"Metros de "&(J23-COUNTIFS(Despiece!$A$5:$A$1004,A23,Despiece!$D$5:$D$1004,">0"))&" pieza(s). ",""))&IF(COUNTIFS(Despiece!$A$5:$A$1004,A23,Despiece!$G$5:$G$1004,"falta*")>0,"Precio o peso de 1 m de alguna tela. ","")&IF(M23="","Tipo/precio de confección. ",""))) -> Metros de 4 pieza(s).
A24: 20 · FUTINHOMU02 | B24: Fútbol infantil, raglán, cuello redondo | C24: Camiseta | D24: Infantil Masculino | E24: Camiseta Futbol Molde 2026 (Raglan) | J24: =IF(A24="","",COUNTIF(Despiece!$A$5:$A$1004,A24)) -> 4 | L24: =IF(A24="","",IF(COUNTIFS(Despiece!$A$5:$A$1004,A24,Despiece!$D$5:$D$1004,">0")<J24,"",IF(COUNTIFS(Despiece!$A$5:$A$1004,A24,Despiece!$G$5:$G$1004,"falta*")>0,"",SUMIFS(Despiece!$G$5:$G$1004,Despiece!$A$5:$A$1004,A24)))) | M24: =IF(OR(A24="",E24=""),"",IFERROR(INDEX(Precios!$K$5:$K$84,MATCH(E24,Precios!$J$5:$J$84,0)),"")) -> 2300 | N24: =IF(A24="","",IFERROR(N(G24)*IF(F24="",0,INDEX(Precios!$N$5:$N$64,MATCH(F24,Precios!$M$5:$M$64,0)))+N(I24)*IF(H24="",0,INDEX(Precios!$N$5:$N$64,MATCH(H24,Precios!$M$5:$M$64,0))),"")) -> 0 | O24: =IF(A24="","",IFERROR(L24+M24+N24,"")) | P24: =IF(A24="","",IF(ISNUMBER(O24),"Lista"&IF(N(Precios!$Q$10)=0," (impresión en $0)",""),IF(J24=0,"Agregar piezas en Despiece. ",IF(COUNTIFS(Despiece!$A$5:$A$1004,A24,Despiece!$D$5:$D$1004,">0")<J24,"Metros de "&(J24-COUNTIFS(Despiece!$A$5:$A$1004,A24,Despiece!$D$5:$D$1004,">0"))&" pieza(s). ",""))&IF(COUNTIFS(Despiece!$A$5:$A$1004,A24,Despiece!$G$5:$G$1004,"falta*")>0,"Precio o peso de 1 m de alguna tela. ","")&IF(M24="","Tipo/precio de confección. ",""))) -> Metros de 4 pieza(s).
A25: 21 · FUTMUJV02 | B25: Fútbol, raglán, cuello v | C25: Camiseta | D25: Femenino | E25: Camiseta Futbol Molde 2026 (Raglan) | J25: =IF(A25="","",COUNTIF(Despiece!$A$5:$A$1004,A25)) -> 4 | L25: =IF(A25="","",IF(COUNTIFS(Despiece!$A$5:$A$1004,A25,Despiece!$D$5:$D$1004,">0")<J25,"",IF(COUNTIFS(Despiece!$A$5:$A$1004,A25,Despiece!$G$5:$G$1004,"falta*")>0,"",SUMIFS(Despiece!$G$5:$G$1004,Despiece!$A$5:$A$1004,A25)))) | M25: =IF(OR(A25="",E25=""),"",IFERROR(INDEX(Precios!$K$5:$K$84,MATCH(E25,Precios!$J$5:$J$84,0)),"")) -> 2300 | N25: =IF(A25="","",IFERROR(N(G25)*IF(F25="",0,INDEX(Precios!$N$5:$N$64,MATCH(F25,Precios!$M$5:$M$64,0)))+N(I25)*IF(H25="",0,INDEX(Precios!$N$5:$N$64,MATCH(H25,Precios!$M$5:$M$64,0))),"")) -> 0 | O25: =IF(A25="","",IFERROR(L25+M25+N25,"")) | P25: =IF(A25="","",IF(ISNUMBER(O25),"Lista"&IF(N(Precios!$Q$10)=0," (impresión en $0)",""),IF(J25=0,"Agregar piezas en Despiece. ",IF(COUNTIFS(Despiece!$A$5:$A$1004,A25,Despiece!$D$5:$D$1004,">0")<J25,"Metros de "&(J25-COUNTIFS(Despiece!$A$5:$A$1004,A25,Despiece!$D$5:$D$1004,">0"))&" pieza(s). ",""))&IF(COUNTIFS(Despiece!$A$5:$A$1004,A25,Despiece!$G$5:$G$1004,"falta*")>0,"Precio o peso de 1 m de alguna tela. ","")&IF(M25="","Tipo/precio de confección. ",""))) -> Metros de 4 pieza(s).
A26: 22 · FUTHOMV02 | B26: Fútbol, raglán, cuello v | C26: Camiseta | D26: Masculino | E26: Camiseta Futbol Molde 2026 (Raglan) | J26: =IF(A26="","",COUNTIF(Despiece!$A$5:$A$1004,A26)) -> 4 | L26: =IF(A26="","",IF(COUNTIFS(Despiece!$A$5:$A$1004,A26,Despiece!$D$5:$D$1004,">0")<J26,"",IF(COUNTIFS(Despiece!$A$5:$A$1004,A26,Despiece!$G$5:$G$1004,"falta*")>0,"",SUMIFS(Despiece!$G$5:$G$1004,Despiece!$A$5:$A$1004,A26)))) | M26: =IF(OR(A26="",E26=""),"",IFERROR(INDEX(Precios!$K$5:$K$84,MATCH(E26,Precios!$J$5:$J$84,0)),"")) -> 2300 | N26: =IF(A26="","",IFERROR(N(G26)*IF(F26="",0,INDEX(Precios!$N$5:$N$64,MATCH(F26,Precios!$M$5:$M$64,0)))+N(I26)*IF(H26="",0,INDEX(Precios!$N$5:$N$64,MATCH(H26,Precios!$M$5:$M$64,0))),"")) -> 0 | O26: =IF(A26="","",IFERROR(L26+M26+N26,"")) | P26: =IF(A26="","",IF(ISNUMBER(O26),"Lista"&IF(N(Precios!$Q$10)=0," (impresión en $0)",""),IF(J26=0,"Agregar piezas en Despiece. ",IF(COUNTIFS(Despiece!$A$5:$A$1004,A26,Despiece!$D$5:$D$1004,">0")<J26,"Metros de "&(J26-COUNTIFS(Despiece!$A$5:$A$1004,A26,Despiece!$D$5:$D$1004,">0"))&" pieza(s). ",""))&IF(COUNTIFS(Despiece!$A$5:$A$1004,A26,Despiece!$G$5:$G$1004,"falta*")>0,"Precio o peso de 1 m de alguna tela. ","")&IF(M26="","Tipo/precio de confección. ",""))) -> Metros de 4 pieza(s).
A27: 23 · FUTINMUJV02 | B27: Fútbol infantil, raglán, cuello v | C27: Camiseta | D27: Infantil Femenino | E27: Camiseta Futbol Molde 2026 (Raglan) | J27: =IF(A27="","",COUNTIF(Despiece!$A$5:$A$1004,A27)) -> 4 | L27: =IF(A27="","",IF(COUNTIFS(Despiece!$A$5:$A$1004,A27,Despiece!$D$5:$D$1004,">0")<J27,"",IF(COUNTIFS(Despiece!$A$5:$A$1004,A27,Despiece!$G$5:$G$1004,"falta*")>0,"",SUMIFS(Despiece!$G$5:$G$1004,Despiece!$A$5:$A$1004,A27)))) | M27: =IF(OR(A27="",E27=""),"",IFERROR(INDEX(Precios!$K$5:$K$84,MATCH(E27,Precios!$J$5:$J$84,0)),"")) -> 2300 | N27: =IF(A27="","",IFERROR(N(G27)*IF(F27="",0,INDEX(Precios!$N$5:$N$64,MATCH(F27,Precios!$M$5:$M$64,0)))+N(I27)*IF(H27="",0,INDEX(Precios!$N$5:$N$64,MATCH(H27,Precios!$M$5:$M$64,0))),"")) -> 0 | O27: =IF(A27="","",IFERROR(L27+M27+N27,"")) | P27: =IF(A27="","",IF(ISNUMBER(O27),"Lista"&IF(N(Precios!$Q$10)=0," (impresión en $0)",""),IF(J27=0,"Agregar piezas en Despiece. ",IF(COUNTIFS(Despiece!$A$5:$A$1004,A27,Despiece!$D$5:$D$1004,">0")<J27,"Metros de "&(J27-COUNTIFS(Despiece!$A$5:$A$1004,A27,Despiece!$D$5:$D$1004,">0"))&" pieza(s). ",""))&IF(COUNTIFS(Despiece!$A$5:$A$1004,A27,Despiece!$G$5:$G$1004,"falta*")>0,"Precio o peso de 1 m de alguna tela. ","")&IF(M27="","Tipo/precio de confección. ",""))) -> Metros de 4 pieza(s).
A28: 24 · FUTINHOMV02 | B28: Fútbol infantil, raglán, cuello v | C28: Camiseta | D28: Infantil Masculino | E28: Camiseta Futbol Molde 2026 (Raglan) | J28: =IF(A28="","",COUNTIF(Despiece!$A$5:$A$1004,A28)) -> 4 | L28: =IF(A28="","",IF(COUNTIFS(Despiece!$A$5:$A$1004,A28,Despiece!$D$5:$D$1004,">0")<J28,"",IF(COUNTIFS(Despiece!$A$5:$A$1004,A28,Despiece!$G$5:$G$1004,"falta*")>0,"",SUMIFS(Despiece!$G$5:$G$1004,Despiece!$A$5:$A$1004,A28)))) | M28: =IF(OR(A28="",E28=""),"",IFERROR(INDEX(Precios!$K$5:$K$84,MATCH(E28,Precios!$J$5:$J$84,0)),"")) -> 2300 | N28: =IF(A28="","",IFERROR(N(G28)*IF(F28="",0,INDEX(Precios!$N$5:$N$64,MATCH(F28,Precios!$M$5:$M$64,0)))+N(I28)*IF(H28="",0,INDEX(Precios!$N$5:$N$64,MATCH(H28,Precios!$M$5:$M$64,0))),"")) -> 0 | O28: =IF(A28="","",IFERROR(L28+M28+N28,"")) | P28: =IF(A28="","",IF(ISNUMBER(O28),"Lista"&IF(N(Precios!$Q$10)=0," (impresión en $0)",""),IF(J28=0,"Agregar piezas en Despiece. ",IF(COUNTIFS(Despiece!$A$5:$A$1004,A28,Despiece!$D$5:$D$1004,">0")<J28,"Metros de "&(J28-COUNTIFS(Despiece!$A$5:$A$1004,A28,Despiece!$D$5:$D$1004,">0"))&" pieza(s). ",""))&IF(COUNTIFS(Despiece!$A$5:$A$1004,A28,Despiece!$G$5:$G$1004,"falta*")>0,"Precio o peso de 1 m de alguna tela. ","")&IF(M28="","Tipo/precio de confección. ",""))) -> Metros de 4 pieza(s).
A29: 25 · FUTMUJU02PRO | B29: Fútbol, raglán, pro, cuello redondo | C29: Camiseta | D29: Femenino | E29: Camiseta Futbol Molde 2026 (Raglan) | J29: =IF(A29="","",COUNTIF(Despiece!$A$5:$A$1004,A29)) -> 5 | L29: =IF(A29="","",IF(COUNTIFS(Despiece!$A$5:$A$1004,A29,Despiece!$D$5:$D$1004,">0")<J29,"",IF(COUNTIFS(Despiece!$A$5:$A$1004,A29,Despiece!$G$5:$G$1004,"falta*")>0,"",SUMIFS(Despiece!$G$5:$G$1004,Despiece!$A$5:$A$1004,A29)))) | M29: =IF(OR(A29="",E29=""),"",IFERROR(INDEX(Precios!$K$5:$K$84,MATCH(E29,Precios!$J$5:$J$84,0)),"")) -> 2300 | N29: =IF(A29="","",IFERROR(N(G29)*IF(F29="",0,INDEX(Precios!$N$5:$N$64,MATCH(F29,Precios!$M$5:$M$64,0)))+N(I29)*IF(H29="",0,INDEX(Precios!$N$5:$N$64,MATCH(H29,Precios!$M$5:$M$64,0))),"")) -> 0 | O29: =IF(A29="","",IFERROR(L29+M29+N29,"")) | P29: =IF(A29="","",IF(ISNUMBER(O29),"Lista"&IF(N(Precios!$Q$10)=0," (impresión en $0)",""),IF(J29=0,"Agregar piezas en Despiece. ",IF(COUNTIFS(Despiece!$A$5:$A$1004,A29,Despiece!$D$5:$D$1004,">0")<J29,"Metros de "&(J29-COUNTIFS(Despiece!$A$5:$A$1004,A29,Despiece!$D$5:$D$1004,">0"))&" pieza(s). ",""))&IF(COUNTIFS(Despiece!$A$5:$A$1004,A29,Despiece!$G$5:$G$1004,"falta*")>0,"Precio o peso de 1 m de alguna tela. ","")&IF(M29="","Tipo/precio de confección. ",""))) -> Metros de 5 pieza(s).
A30: 26 · FUTHOMU02PRO | B30: Fútbol, raglán, pro, cuello redondo | C30: Camiseta | D30: Masculino | E30: Camiseta Futbol Molde 2026 (Raglan) | J30: =IF(A30="","",COUNTIF(Despiece!$A$5:$A$1004,A30)) -> 5 | L30: =IF(A30="","",IF(COUNTIFS(Despiece!$A$5:$A$1004,A30,Despiece!$D$5:$D$1004,">0")<J30,"",IF(COUNTIFS(Despiece!$A$5:$A$1004,A30,Despiece!$G$5:$G$1004,"falta*")>0,"",SUMIFS(Despiece!$G$5:$G$1004,Despiece!$A$5:$A$1004,A30)))) | M30: =IF(OR(A30="",E30=""),"",IFERROR(INDEX(Precios!$K$5:$K$84,MATCH(E30,Precios!$J$5:$J$84,0)),"")) -> 2300 | N30: =IF(A30="","",IFERROR(N(G30)*IF(F30="",0,INDEX(Precios!$N$5:$N$64,MATCH(F30,Precios!$M$5:$M$64,0)))+N(I30)*IF(H30="",0,INDEX(Precios!$N$5:$N$64,MATCH(H30,Precios!$M$5:$M$64,0))),"")) -> 0 | O30: =IF(A30="","",IFERROR(L30+M30+N30,"")) | P30: =IF(A30="","",IF(ISNUMBER(O30),"Lista"&IF(N(Precios!$Q$10)=0," (impresión en $0)",""),IF(J30=0,"Agregar piezas en Despiece. ",IF(COUNTIFS(Despiece!$A$5:$A$1004,A30,Despiece!$D$5:$D$1004,">0")<J30,"Metros de "&(J30-COUNTIFS(Despiece!$A$5:$A$1004,A30,Despiece!$D$5:$D$1004,">0"))&" pieza(s). ",""))&IF(COUNTIFS(Despiece!$A$5:$A$1004,A30,Despiece!$G$5:$G$1004,"falta*")>0,"Precio o peso de 1 m de alguna tela. ","")&IF(M30="","Tipo/precio de confección. ",""))) -> Metros de 5 pieza(s).
