Workbook

Sheet Como_usar
A1: RECETAS DE COSTO — PLAYMAKER (v3, por molde del catálogo)
A2: Armado desde el Sistema de Costeo v2 y el catálogo de moldes vigente. Todo dato dice "Por confirmar" hasta que lo valides.
A4: CÓMO ESTÁ ORDENADO
B5: RECETAS: una por cada MOLDE del catálogo (los 54 de Fútbol y Básquetbol, los mismos de Fichas y Planificación). Es el costo de producir UNA prenda con ese molde.
B6: PRODUCTOS: lo que vendes. Cada producto elige la receta de su molde (columna E) y suma extras (cuello piqué, manga larga). Ahí ves ganancia, precio mínimo y semáforo.
B7: Así, si cambia una tela o un consumo, se actualizan solos todos los productos que usan ese molde.
A8: COLORES
B9: AZUL = lo escribes tú. GRIS = se calcula solo. Semáforo: PIERDE (rojo) · BAJO META (amarillo) · OK (verde) · gris = faltan datos.
A10: PASOS PARA COMPLETAR
B11: 1) En Recetas, completa el molde: tela (lista), kg por prenda (kg de la ficha de corte ÷ prendas cortadas), tela 2 si lleva malla, metros impresos y confección.
B12: 2) En Productos, revisa que cada producto tenga elegida la receta de su molde. Los marcados "sugerido" hay que confirmarlos.
B13: 3) Las prendas que aún no tienen molde (short de fútbol, short de rugby, running, calza) están al final de Recetas como "SM-…". Agrega más en las filas libres.
A14: CADA TRIMESTRE (próximo: diciembre 2026)
B15: En Gastos_Ventas escribe los gastos y ventas de los 3 meses más recientes. El recargo y todos los productos se actualizan solos.
A16: PENDIENTES QUE AFECTAN LOS RESULTADOS
B17: ="• Papel y tinta: "&IF(Parametros!$B$27=0,"SIN DATO → las prendas sublimadas salen más baratas de lo real.","ingresado ("&TEXT(Parametros!$B$27,"$#,##0")&" por metro).") -> • Papel y tinta: SIN DATO → las prendas sublimadas salen más baratas de lo real.
B18: ="• Recetas (moldes) completas: "&COUNTIF(Recetas!T5:T84,"Lista*")&" de "&COUNTA(Recetas!A5:A84) -> • Recetas (moldes) completas: 4 de 59
B19: ="• Productos con costo completo: "&COUNTIF(Catalogo!F6:F200,"Completa")&" · con datos faltantes: "&COUNTIF(Catalogo!F6:F200,"Faltan datos") -> • Productos con costo completo: 7 · con datos faltantes: 67
B20: • Faltan fichas de corte de casi todos los moldes: cada ficha nueva completa la receta de su molde para todos los productos que lo usan.
B21: • El short de fútbol no tiene molde en el catálogo: cuando se agregue, cambia su receta "SM-01" por el molde nuevo.
B22: • Gastos: el archivo original trae un solo mes; se repitió en los 3 meses. Reemplazar con el gasto real.

Sheet Productos
A1: PRODUCTOS — ganancia y precio mínimo de lo que vendes
A2: Cada producto usa la receta de su molde (hoja Recetas). Elige la receta en la columna E y suma los extras (cuello piqué, manga larga…). Fuente de productos y precios: 2_Catálogo (jun–sep 2026).
A3: ="Recargo usado: "&TEXT(Parametros!$B$14,"0.0%")&" del precio (fábrica "&TEXT(Parametros!$B$12,"0.0%")&" + comercial "&TEXT(Parametros!$B$13,"0.0%")&") · Meta de ganancia: "&TEXT(Parametros!$B$18,"0%")&" · Impresión: "&IF(Parametros!$B$27=0,"SIN COSTO (pendiente)",TEXT(Parametros!$B$27,"$#,##0")&" por metro") -> Recargo usado: 48.0% del precio (fábrica 35.3% + comercial 12.7%) · Meta de ganancia: 10% · Impresión: SIN COSTO (pendiente)
A4: PRODUCTO | E4: LO LLENAS TÚ | J4: RESULTADO AL PRECIO ACTUAL
A5: Código | B5: Producto | C5: Tipo | D5: Unid. vendidas jun–sep | E5: Receta (molde) | F5: Extras ($ por prenda) | G5: Precio venta neto ($) | H5: Estado | I5: Notas | J5: COSTO DE PRODUCCIÓN | K5: Gastos de fábrica | L5: Gastos comerciales | M5: GANANCIA ($) | N5: GANANCIA (%) | O5: Precio mínimo (sin perder) | P5: Precio mínimo (con meta) | Q5: Semáforo | R5: Qué falta
A6: FUTCSUBMC | B6: Camiseta Fútbol Playmaker, m/c | C6: Juego | D6: 198 | E6: 02 · FUTHOMU01 | G6: 15994 | H6: Por confirmar | I6: Molde sugerido: fútbol masculino cuello redondo. Confirmar. | J6: =IF(OR(B6="",E6=""),"",IF(IFERROR(INDEX(Recetas!$S$5:$S$84,MATCH(E6,Recetas!$A$5:$A$84,0)),"")="","",IFERROR(INDEX(Recetas!$S$5:$S$84,MATCH(E6,Recetas!$A$5:$A$84,0)),"")+N(F6))) | K6: =IF(AND(J6<>"",ISNUMBER(G6)),G6*Parametros!$B$12,"") | L6: =IF(AND(J6<>"",ISNUMBER(G6)),G6*Parametros!$B$13,"") | M6: =IF(AND(J6<>"",ISNUMBER(G6)),G6-J6-K6-L6,"") | N6: =IF(AND(J6<>"",ISNUMBER(G6)),M6/G6,"") | O6: =IF(OR(J6="",Parametros!$B$14>=1),"",J6/(1-Parametros!$B$14)) | P6: =IF(OR(J6="",Parametros!$B$14+Parametros!$B$18>=1),"",J6/(1-Parametros!$B$14-Parametros!$B$18)) | Q6: =IF(B6="","",IF(E6="","SIN RECETA",IF(J6="","FALTAN DATOS",IF(NOT(ISNUMBER(G6)),"FALTA PRECIO",IF(M6<0,"PIERDE",IF(N6<Parametros!$B$18,"BAJO META","OK")))))) -> FALTAN DATOS | R6: =IF(B6="","",IF(E6="","Elegir receta (molde).",IF(ISNA(MATCH(E6,Recetas!$A$5:$A$84,0)),"La receta no existe en Recetas.",IF(J6="","Completar la receta "&E6&": "&INDEX(Recetas!$T$5:$T$84,MATCH(E6,Recetas!$A$5:$A$84,0)),IF(NOT(ISNUMBER(G6)),"Precio de venta.",""))))) -> Completar la receta 02 · FUTHOMU01: Tela. Kg de tela. Metros impresos.
A7: FUTCSUBREDMC | B7: Camiseta Fútbol Playmaker Cuello Redondo m/c | C7: Juego | D7: 190 | E7: 02 · FUTHOMU01 | G7: 16073 | H7: Por confirmar | I7: Molde sugerido. Confirmar. | J7: =IF(OR(B7="",E7=""),"",IF(IFERROR(INDEX(Recetas!$S$5:$S$84,MATCH(E7,Recetas!$A$5:$A$84,0)),"")="","",IFERROR(INDEX(Recetas!$S$5:$S$84,MATCH(E7,Recetas!$A$5:$A$84,0)),"")+N(F7))) | K7: =IF(AND(J7<>"",ISNUMBER(G7)),G7*Parametros!$B$12,"") | L7: =IF(AND(J7<>"",ISNUMBER(G7)),G7*Parametros!$B$13,"") | M7: =IF(AND(J7<>"",ISNUMBER(G7)),G7-J7-K7-L7,"") | N7: =IF(AND(J7<>"",ISNUMBER(G7)),M7/G7,"") | O7: =IF(OR(J7="",Parametros!$B$14>=1),"",J7/(1-Parametros!$B$14)) | P7: =IF(OR(J7="",Parametros!$B$14+Parametros!$B$18>=1),"",J7/(1-Parametros!$B$14-Parametros!$B$18)) | Q7: =IF(B7="","",IF(E7="","SIN RECETA",IF(J7="","FALTAN DATOS",IF(NOT(ISNUMBER(G7)),"FALTA PRECIO",IF(M7<0,"PIERDE",IF(N7<Parametros!$B$18,"BAJO META","OK")))))) -> FALTAN DATOS | R7: =IF(B7="","",IF(E7="","Elegir receta (molde).",IF(ISNA(MATCH(E7,Recetas!$A$5:$A$84,0)),"La receta no existe en Recetas.",IF(J7="","Completar la receta "&E7&": "&INDEX(Recetas!$T$5:$T$84,MATCH(E7,Recetas!$A$5:$A$84,0)),IF(NOT(ISNUMBER(G7)),"Precio de venta.",""))))) -> Completar la receta 02 · FUTHOMU01: Tela. Kg de tela. Metros impresos.
A8: FUTCSUBPROREDMC | B8: Camiseta Fútbol Pro Playmaker Cuello Redondo m/c | C8: Juego | D8: 160 | E8: 14 · FUTHOMU01PRO | G8: 18403 | H8: Por confirmar | I8: Molde Pro cuello redondo. | J8: =IF(OR(B8="",E8=""),"",IF(IFERROR(INDEX(Recetas!$S$5:$S$84,MATCH(E8,Recetas!$A$5:$A$84,0)),"")="","",IFERROR(INDEX(Recetas!$S$5:$S$84,MATCH(E8,Recetas!$A$5:$A$84,0)),"")+N(F8))) -> 3020.47 | K8: =IF(AND(J8<>"",ISNUMBER(G8)),G8*Parametros!$B$12,"") -> 6495.2752 | L8: =IF(AND(J8<>"",ISNUMBER(G8)),G8*Parametros!$B$13,"") -> 2331.5946 | M8: =IF(AND(J8<>"",ISNUMBER(G8)),G8-J8-K8-L8,"") -> 6555.6601 | N8: =IF(AND(J8<>"",ISNUMBER(G8)),M8/G8,"") -> 0.3562278 | O8: =IF(OR(J8="",Parametros!$B$14>=1),"",J8/(1-Parametros!$B$14)) -> 5804.6109 | P8: =IF(OR(J8="",Parametros!$B$14+Parametros!$B$18>=1),"",J8/(1-Parametros!$B$14-Parametros!$B$18)) -> 7185.4873 | Q8: =IF(B8="","",IF(E8="","SIN RECETA",IF(J8="","FALTAN DATOS",IF(NOT(ISNUMBER(G8)),"FALTA PRECIO",IF(M8<0,"PIERDE",IF(N8<Parametros!$B$18,"BAJO META","OK")))))) -> OK | R8: =IF(B8="","",IF(E8="","Elegir receta (molde).",IF(ISNA(MATCH(E8,Recetas!$A$5:$A$84,0)),"La receta no existe en Recetas.",IF(J8="","Completar la receta "&E8&": "&INDEX(Recetas!$T$5:$T$84,MATCH(E8,Recetas!$A$5:$A$84,0)),IF(NOT(ISNUMBER(G8)),"Precio de venta.","")))))
A9: VOLMASC-CSUB-V-MC | B9: Camiseta Voley fem Playmaker, V m/c | C9: Juego | D9: 139 | G9: 17563 | H9: Por confirmar | I9: Sin receta: elige el molde que usa, o crea la receta en "Recetas" si aún no tiene molde. | J9: =IF(OR(B9="",E9=""),"",IF(IFERROR(INDEX(Recetas!$S$5:$S$84,MATCH(E9,Recetas!$A$5:$A$84,0)),"")="","",IFERROR(INDEX(Recetas!$S$5:$S$84,MATCH(E9,Recetas!$A$5:$A$84,0)),"")+N(F9))) | K9: =IF(AND(J9<>"",ISNUMBER(G9)),G9*Parametros!$B$12,"") | L9: =IF(AND(J9<>"",ISNUMBER(G9)),G9*Parametros!$B$13,"") | M9: =IF(AND(J9<>"",ISNUMBER(G9)),G9-J9-K9-L9,"") | N9: =IF(AND(J9<>"",ISNUMBER(G9)),M9/G9,"") | O9: =IF(OR(J9="",Parametros!$B$14>=1),"",J9/(1-Parametros!$B$14)) | P9: =IF(OR(J9="",Parametros!$B$14+Parametros!$B$18>=1),"",J9/(1-Parametros!$B$14-Parametros!$B$18)) | Q9: =IF(B9="","",IF(E9="","SIN RECETA",IF(J9="","FALTAN DATOS",IF(NOT(ISNUMBER(G9)),"FALTA PRECIO",IF(M9<0,"PIERDE",IF(N9<Parametros!$B$18,"BAJO META","OK")))))) -> SIN RECETA | R9: =IF(B9="","",IF(E9="","Elegir receta (molde).",IF(ISNA(MATCH(E9,Recetas!$A$5:$A$84,0)),"La receta no existe en Recetas.",IF(J9="","Completar la receta "&E9&": "&INDEX(Recetas!$T$5:$T$84,MATCH(E9,Recetas!$A$5:$A$84,0)),IF(NOT(ISNUMBER(G9)),"Precio de venta.",""))))) -> Elegir receta (molde).
A10: FUTCSUBPROMC | B10: Camiseta Fútbol Pro Playmaker, m/c | C10: Juego | D10: 109 | E10: 14 · FUTHOMU01PRO | G10: 18403 | H10: Por confirmar | I10: Molde Pro sugerido. Confirmar. | J10: =IF(OR(B10="",E10=""),"",IF(IFERROR(INDEX(Recetas!$S$5:$S$84,MATCH(E10,Recetas!$A$5:$A$84,0)),"")="","",IFERROR(INDEX(Recetas!$S$5:$S$84,MATCH(E10,Recetas!$A$5:$A$84,0)),"")+N(F10))) -> 3020.47 | K10: =IF(AND(J10<>"",ISNUMBER(G10)),G10*Parametros!$B$12,"") -> 6495.2752 | L10: =IF(AND(J10<>"",ISNUMBER(G10)),G10*Parametros!$B$13,"") -> 2331.5946 | M10: =IF(AND(J10<>"",ISNUMBER(G10)),G10-J10-K10-L10,"") -> 6555.6601 | N10: =IF(AND(J10<>"",ISNUMBER(G10)),M10/G10,"") -> 0.3562278 | O10: =IF(OR(J10="",Parametros!$B$14>=1),"",J10/(1-Parametros!$B$14)) -> 5804.6109 | P10: =IF(OR(J10="",Parametros!$B$14+Parametros!$B$18>=1),"",J10/(1-Parametros!$B$14-Parametros!$B$18)) -> 7185.4873 | Q10: =IF(B10="","",IF(E10="","SIN RECETA",IF(J10="","FALTAN DATOS",IF(NOT(ISNUMBER(G10)),"FALTA PRECIO",IF(M10<0,"PIERDE",IF(N10<Parametros!$B$18,"BAJO META","OK")))))) -> OK | R10: =IF(B10="","",IF(E10="","Elegir receta (molde).",IF(ISNA(MATCH(E10,Recetas!$A$5:$A$84,0)),"La receta no existe en Recetas.",IF(J10="","Completar la receta "&E10&": "&INDEX(Recetas!$T$5:$T$84,MATCH(E10,Recetas!$A$5:$A$84,0)),IF(NOT(ISNUMBER(G10)),"Precio de venta.","")))))
A11: FUTCSUBMC-V | B11: Camiseta Fútbol Playmaker, V m/c | C11: Juego | D11: 109 | E11: 06 · FUTHOMV01 | G11: 16589 | H11: Por confirmar | I11: Molde sugerido: cuello V. Confirmar. | J11: =IF(OR(B11="",E11=""),"",IF(IFERROR(INDEX(Recetas!$S$5:$S$84,MATCH(E11,Recetas!$A$5:$A$84,0)),"")="","",IFERROR(INDEX(Recetas!$S$5:$S$84,MATCH(E11,Recetas!$A$5:$A$84,0)),"")+N(F11))) | K11: =IF(AND(J11<>"",ISNUMBER(G11)),G11*Parametros!$B$12,"") | L11: =IF(AND(J11<>"",ISNUMBER(G11)),G11*Parametros!$B$13,"") | M11: =IF(AND(J11<>"",ISNUMBER(G11)),G11-J11-K11-L11,"") | N11: =IF(AND(J11<>"",ISNUMBER(G11)),M11/G11,"") | O11: =IF(OR(J11="",Parametros!$B$14>=1),"",J11/(1-Parametros!$B$14)) | P11: =IF(OR(J11="",Parametros!$B$14+Parametros!$B$18>=1),"",J11/(1-Parametros!$B$14-Parametros!$B$18)) | Q11: =IF(B11="","",IF(E11="","SIN RECETA",IF(J11="","FALTAN DATOS",IF(NOT(ISNUMBER(G11)),"FALTA PRECIO",IF(M11<0,"PIERDE",IF(N11<Parametros!$B$18,"BAJO META","OK")))))) -> FALTAN DATOS | R11: =IF(B11="","",IF(E11="","Elegir receta (molde).",IF(ISNA(MATCH(E11,Recetas!$A$5:$A$84,0)),"La receta no existe en Recetas.",IF(J11="","Completar la receta "&E11&": "&INDEX(Recetas!$T$5:$T$84,MATCH(E11,Recetas!$A$5:$A$84,0)),IF(NOT(ISNUMBER(G11)),"Precio de venta.",""))))) -> Completar la receta 06 · FUTHOMV01: Tela. Kg de tela. Metros impresos.
A12: SALPOLPRESLISA | B12: Polera de Presentación Lisa | C12: Salida | D12: 109 | G12: 17004 | H12: Por confirmar | I12: Sin receta: elige el molde que usa, o crea la receta en "Recetas" si aún no tiene molde. | J12: =IF(OR(B12="",E12=""),"",IF(IFERROR(INDEX(Recetas!$S$5:$S$84,MATCH(E12,Recetas!$A$5:$A$84,0)),"")="","",IFERROR(INDEX(Recetas!$S$5:$S$84,MATCH(E12,Recetas!$A$5:$A$84,0)),"")+N(F12))) | K12: =IF(AND(J12<>"",ISNUMBER(G12)),G12*Parametros!$B$12,"") | L12: =IF(AND(J12<>"",ISNUMBER(G12)),G12*Parametros!$B$13,"") | M12: =IF(AND(J12<>"",ISNUMBER(G12)),G12-J12-K12-L12,"") | N12: =IF(AND(J12<>"",ISNUMBER(G12)),M12/G12,"") | O12: =IF(OR(J12="",Parametros!$B$14>=1),"",J12/(1-Parametros!$B$14)) | P12: =IF(OR(J12="",Parametros!$B$14+Parametros!$B$18>=1),"",J12/(1-Parametros!$B$14-Parametros!$B$18)) | Q12: =IF(B12="","",IF(E12="","SIN RECETA",IF(J12="","FALTAN DATOS",IF(NOT(ISNUMBER(G12)),"FALTA PRECIO",IF(M12<0,"PIERDE",IF(N12<Parametros!$B$18,"BAJO META","OK")))))) -> SIN RECETA | R12: =IF(B12="","",IF(E12="","Elegir receta (molde).",IF(ISNA(MATCH(E12,Recetas!$A$5:$A$84,0)),"La receta no existe en Recetas.",IF(J12="","Completar la receta "&E12&": "&INDEX(Recetas!$T$5:$T$84,MATCH(E12,Recetas!$A$5:$A$84,0)),IF(NOT(ISNUMBER(G12)),"Precio de venta.",""))))) -> Elegir receta (molde).
A13: CSUBRUGSFROSA | B13: CAMISETA DE RUGBY STADE FRANCAIS ANIVERSARIO (ROSADA) | C13: Juego | D13: 100 | G13: 25714 | H13: Por confirmar | I13: Sin receta: elige el molde que usa, o crea la receta en "Recetas" si aún no tiene molde. | J13: =IF(OR(B13="",E13=""),"",IF(IFERROR(INDEX(Recetas!$S$5:$S$84,MATCH(E13,Recetas!$A$5:$A$84,0)),"")="","",IFERROR(INDEX(Recetas!$S$5:$S$84,MATCH(E13,Recetas!$A$5:$A$84,0)),"")+N(F13))) | K13: =IF(AND(J13<>"",ISNUMBER(G13)),G13*Parametros!$B$12,"") | L13: =IF(AND(J13<>"",ISNUMBER(G13)),G13*Parametros!$B$13,"") | M13: =IF(AND(J13<>"",ISNUMBER(G13)),G13-J13-K13-L13,"") | N13: =IF(AND(J13<>"",ISNUMBER(G13)),M13/G13,"") | O13: =IF(OR(J13="",Parametros!$B$14>=1),"",J13/(1-Parametros!$B$14)) | P13: =IF(OR(J13="",Parametros!$B$14+Parametros!$B$18>=1),"",J13/(1-Parametros!$B$14-Parametros!$B$18)) | Q13: =IF(B13="","",IF(E13="","SIN RECETA",IF(J13="","FALTAN DATOS",IF(NOT(ISNUMBER(G13)),"FALTA PRECIO",IF(M13<0,"PIERDE",IF(N13<Parametros!$B$18,"BAJO META","OK")))))) -> SIN RECETA | R13: =IF(B13="","",IF(E13="","Elegir receta (molde).",IF(ISNA(MATCH(E13,Recetas!$A$5:$A$84,0)),"La receta no existe en Recetas.",IF(J13="","Completar la receta "&E13&": "&INDEX(Recetas!$T$5:$T$84,MATCH(E13,Recetas!$A$5:$A$84,0)),IF(NOT(ISNUMBER(G13)),"Precio de venta.",""))))) -> Elegir receta (molde).
A14: SAL-PLA-SUB-MC | B14: Polera de presentación Sublim m/c | C14: Salida | D14: 99 | G14: 18729 | H14: Por confirmar | I14: Sin receta: elige el molde que usa, o crea la receta en "Recetas" si aún no tiene molde. | J14: =IF(OR(B14="",E14=""),"",IF(IFERROR(INDEX(Recetas!$S$5:$S$84,MATCH(E14,Recetas!$A$5:$A$84,0)),"")="","",IFERROR(INDEX(Recetas!$S$5:$S$84,MATCH(E14,Recetas!$A$5:$A$84,0)),"")+N(F14))) | K14: =IF(AND(J14<>"",ISNUMBER(G14)),G14*Parametros!$B$12,"") | L14: =IF(AND(J14<>"",ISNUMBER(G14)),G14*Parametros!$B$13,"") | M14: =IF(AND(J14<>"",ISNUMBER(G14)),G14-J14-K14-L14,"") | N14: =IF(AND(J14<>"",ISNUMBER(G14)),M14/G14,"") | O14: =IF(OR(J14="",Parametros!$B$14>=1),"",J14/(1-Parametros!$B$14)) | P14: =IF(OR(J14="",Parametros!$B$14+Parametros!$B$18>=1),"",J14/(1-Parametros!$B$14-Parametros!$B$18)) | Q14: =IF(B14="","",IF(E14="","SIN RECETA",IF(J14="","FALTAN DATOS",IF(NOT(ISNUMBER(G14)),"FALTA PRECIO",IF(M14<0,"PIERDE",IF(N14<Parametros!$B$18,"BAJO META","OK")))))) -> SIN RECETA | R14: =IF(B14="","",IF(E14="","Elegir receta (molde).",IF(ISNA(MATCH(E14,Recetas!$A$5:$A$84,0)),"La receta no existe en Recetas.",IF(J14="","Completar la receta "&E14&": "&INDEX(Recetas!$T$5:$T$84,MATCH(E14,Recetas!$A$5:$A$84,0)),IF(NOT(ISNUMBER(G14)),"Precio de venta.",""))))) -> Elegir receta (molde).
A15: POL-CSUB-POL-MC | B15: Polera Playmaker, Cuello Redondo m/c | C15: Juego | D15: 96 | G15: 15588 | H15: Por confirmar | I15: Sin receta: elige el molde que usa, o crea la receta en "Recetas" si aún no tiene molde. | J15: =IF(OR(B15="",E15=""),"",IF(IFERROR(INDEX(Recetas!$S$5:$S$84,MATCH(E15,Recetas!$A$5:$A$84,0)),"")="","",IFERROR(INDEX(Recetas!$S$5:$S$84,MATCH(E15,Recetas!$A$5:$A$84,0)),"")+N(F15))) | K15: =IF(AND(J15<>"",ISNUMBER(G15)),G15*Parametros!$B$12,"") | L15: =IF(AND(J15<>"",ISNUMBER(G15)),G15*Parametros!$B$13,"") | M15: =IF(AND(J15<>"",ISNUMBER(G15)),G15-J15-K15-L15,"") | N15: =IF(AND(J15<>"",ISNUMBER(G15)),M15/G15,"") | O15: =IF(OR(J15="",Parametros!$B$14>=1),"",J15/(1-Parametros!$B$14)) | P15: =IF(OR(J15="",Parametros!$B$14+Parametros!$B$18>=1),"",J15/(1-Parametros!$B$14-Parametros!$B$18)) | Q15: =IF(B15="","",IF(E15="","SIN RECETA",IF(J15="","FALTAN DATOS",IF(NOT(ISNUMBER(G15)),"FALTA PRECIO",IF(M15<0,"PIERDE",IF(N15<Parametros!$B$18,"BAJO META","OK")))))) -> SIN RECETA | R15: =IF(B15="","",IF(E15="","Elegir receta (molde).",IF(ISNA(MATCH(E15,Recetas!$A$5:$A$84,0)),"La receta no existe en Recetas.",IF(J15="","Completar la receta "&E15&": "&INDEX(Recetas!$T$5:$T$84,MATCH(E15,Recetas!$A$5:$A$84,0)),IF(NOT(ISNUMBER(G15)),"Precio de venta.",""))))) -> Elegir receta (molde).
A16: RUGCSUBPRO | B16: Camiseta Rugby Pro Pmk | C16: Juego | D16: 93 | G16: 21765 | H16: Por confirmar | I16: Sin receta: elige el molde que usa, o crea la receta en "Recetas" si aún no tiene molde. | J16: =IF(OR(B16="",E16=""),"",IF(IFERROR(INDEX(Recetas!$S$5:$S$84,MATCH(E16,Recetas!$A$5:$A$84,0)),"")="","",IFERROR(INDEX(Recetas!$S$5:$S$84,MATCH(E16,Recetas!$A$5:$A$84,0)),"")+N(F16))) | K16: =IF(AND(J16<>"",ISNUMBER(G16)),G16*Parametros!$B$12,"") | L16: =IF(AND(J16<>"",ISNUMBER(G16)),G16*Parametros!$B$13,"") | M16: =IF(AND(J16<>"",ISNUMBER(G16)),G16-J16-K16-L16,"") | N16: =IF(AND(J16<>"",ISNUMBER(G16)),M16/G16,"") | O16: =IF(OR(J16="",Parametros!$B$14>=1),"",J16/(1-Parametros!$B$14)) | P16: =IF(OR(J16="",Parametros!$B$14+Parametros!$B$18>=1),"",J16/(1-Parametros!$B$14-Parametros!$B$18)) | Q16: =IF(B16="","",IF(E16="","SIN RECETA",IF(J16="","FALTAN DATOS",IF(NOT(ISNUMBER(G16)),"FALTA PRECIO",IF(M16<0,"PIERDE",IF(N16<Parametros!$B$18,"BAJO META","OK")))))) -> SIN RECETA | R16: =IF(B16="","",IF(E16="","Elegir receta (molde).",IF(ISNA(MATCH(E16,Recetas!$A$5:$A$84,0)),"La receta no existe en Recetas.",IF(J16="","Completar la receta "&E16&": "&INDEX(Recetas!$T$5:$T$84,MATCH(E16,Recetas!$A$5:$A$84,0)),IF(NOT(ISNUMBER(G16)),"Precio de venta.",""))))) -> Elegir receta (molde).
A17: MDBZCOMENTPITSUB | B17: Conjunto Polerón de Entrenamiento + Buzo Pitillo Subl | C17: Salida | D17: 76 | G17: 44010 | H17: Por confirmar | I17: Sin receta: elige el molde que usa, o crea la receta en "Recetas" si aún no tiene molde. | J17: =IF(OR(B17="",E17=""),"",IF(IFERROR(INDEX(Recetas!$S$5:$S$84,MATCH(E17,Recetas!$A$5:$A$84,0)),"")="","",IFERROR(INDEX(Recetas!$S$5:$S$84,MATCH(E17,Recetas!$A$5:$A$84,0)),"")+N(F17))) | K17: =IF(AND(J17<>"",ISNUMBER(G17)),G17*Parametros!$B$12,"") | L17: =IF(AND(J17<>"",ISNUMBER(G17)),G17*Parametros!$B$13,"") | M17: =IF(AND(J17<>"",ISNUMBER(G17)),G17-J17-K17-L17,"") | N17: =IF(AND(J17<>"",ISNUMBER(G17)),M17/G17,"") | O17: =IF(OR(J17="",Parametros!$B$14>=1),"",J17/(1-Parametros!$B$14)) | P17: =IF(OR(J17="",Parametros!$B$14+Parametros!$B$18>=1),"",J17/(1-Parametros!$B$14-Parametros!$B$18)) | Q17: =IF(B17="","",IF(E17="","SIN RECETA",IF(J17="","FALTAN DATOS",IF(NOT(ISNUMBER(G17)),"FALTA PRECIO",IF(M17<0,"PIERDE",IF(N17<Parametros!$B$18,"BAJO META","OK")))))) -> SIN RECETA | R17: =IF(B17="","",IF(E17="","Elegir receta (molde).",IF(ISNA(MATCH(E17,Recetas!$A$5:$A$84,0)),"La receta no existe en Recetas.",IF(J17="","Completar la receta "&E17&": "&INDEX(Recetas!$T$5:$T$84,MATCH(E17,Recetas!$A$5:$A$84,0)),IF(NOT(ISNUMBER(G17)),"Precio de venta.",""))))) -> Elegir receta (molde).
A18: FUTCSUBPROPIQMC | B18: Camiseta Fútbol Pro Playmaker, Piqué m/c | C18: Juego | D18: 66 | G18: 21554 | H18: Por confirmar | I18: Sin receta: elige el molde que usa, o crea la receta en "Recetas" si aún no tiene molde. | J18: =IF(OR(B18="",E18=""),"",IF(IFERROR(INDEX(Recetas!$S$5:$S$84,MATCH(E18,Recetas!$A$5:$A$84,0)),"")="","",IFERROR(INDEX(Recetas!$S$5:$S$84,MATCH(E18,Recetas!$A$5:$A$84,0)),"")+N(F18))) | K18: =IF(AND(J18<>"",ISNUMBER(G18)),G18*Parametros!$B$12,"") | L18: =IF(AND(J18<>"",ISNUMBER(G18)),G18*Parametros!$B$13,"") | M18: =IF(AND(J18<>"",ISNUMBER(G18)),G18-J18-K18-L18,"") | N18: =IF(AND(J18<>"",ISNUMBER(G18)),M18/G18,"") | O18: =IF(OR(J18="",Parametros!$B$14>=1),"",J18/(1-Parametros!$B$14)) | P18: =IF(OR(J18="",Parametros!$B$14+Parametros!$B$18>=1),"",J18/(1-Parametros!$B$14-Parametros!$B$18)) | Q18: =IF(B18="","",IF(E18="","SIN RECETA",IF(J18="","FALTAN DATOS",IF(NOT(ISNUMBER(G18)),"FALTA PRECIO",IF(M18<0,"PIERDE",IF(N18<Parametros!$B$18,"BAJO META","OK")))))) -> SIN RECETA | R18: =IF(B18="","",IF(E18="","Elegir receta (molde).",IF(ISNA(MATCH(E18,Recetas!$A$5:$A$84,0)),"La receta no existe en Recetas.",IF(J18="","Completar la receta "&E18&": "&INDEX(Recetas!$T$5:$T$84,MATCH(E18,Recetas!$A$5:$A$84,0)),IF(NOT(ISNUMBER(G18)),"Precio de venta.",""))))) -> Elegir receta (molde).
A19: RUNCSUBPROSM | B19: Camiseta Running Pro s/m | C19: Juego | D19: 65 | E19: SM-03 · Camiseta Running s/m | G19: 19244 | H19: Por confirmar | J19: =IF(OR(B19="",E19=""),"",IF(IFERROR(INDEX(Recetas!$S$5:$S$84,MATCH(E19,Recetas!$A$5:$A$84,0)),"")="","",IFERROR(INDEX(Recetas!$S$5:$S$84,MATCH(E19,Recetas!$A$5:$A$84,0)),"")+N(F19))) -> 2148.008 | K19: =IF(AND(J19<>"",ISNUMBER(G19)),G19*Parametros!$B$12,"") -> 6792.1033 | L19: =IF(AND(J19<>"",ISNUMBER(G19)),G19*Parametros!$B$13,"") -> 2438.1464 | M19: =IF(AND(J19<>"",ISNUMBER(G19)),G19-J19-K19-L19,"") -> 7865.7424 | N19: =IF(AND(J19<>"",ISNUMBER(G19)),M19/G19,"") -> 0.40873739 | O19: =IF(OR(J19="",Parametros!$B$14>=1),"",J19/(1-Parametros!$B$14)) -> 4127.9505 | P19: =IF(OR(J19="",Parametros!$B$14+Parametros!$B$18>=1),"",J19/(1-Parametros!$B$14-Parametros!$B$18)) -> 5109.9611 | Q19: =IF(B19="","",IF(E19="","SIN RECETA",IF(J19="","FALTAN DATOS",IF(NOT(ISNUMBER(G19)),"FALTA PRECIO",IF(M19<0,"PIERDE",IF(N19<Parametros!$B$18,"BAJO META","OK")))))) -> OK | R19: =IF(B19="","",IF(E19="","Elegir receta (molde).",IF(ISNA(MATCH(E19,Recetas!$A$5:$A$84,0)),"La receta no existe en Recetas.",IF(J19="","Completar la receta "&E19&": "&INDEX(Recetas!$T$5:$T$84,MATCH(E19,Recetas!$A$5:$A$84,0)),IF(NOT(ISNUMBER(G19)),"Precio de venta.","")))))
A20: SAL-CTV-SUB-SG | B20: CORTAVIENTO SUBLIMADO | C20: Salida | D20: 62 | G20: 36050 | H20: Por confirmar | I20: Sin receta: elige el molde que usa, o crea la receta en "Recetas" si aún no tiene molde. | J20: =IF(OR(B20="",E20=""),"",IF(IFERROR(INDEX(Recetas!$S$5:$S$84,MATCH(E20,Recetas!$A$5:$A$84,0)),"")="","",IFERROR(INDEX(Recetas!$S$5:$S$84,MATCH(E20,Recetas!$A$5:$A$84,0)),"")+N(F20))) | K20: =IF(AND(J20<>"",ISNUMBER(G20)),G20*Parametros!$B$12,"") | L20: =IF(AND(J20<>"",ISNUMBER(G20)),G20*Parametros!$B$13,"") | M20: =IF(AND(J20<>"",ISNUMBER(G20)),G20-J20-K20-L20,"") | N20: =IF(AND(J20<>"",ISNUMBER(G20)),M20/G20,"") | O20: =IF(OR(J20="",Parametros!$B$14>=1),"",J20/(1-Parametros!$B$14)) | P20: =IF(OR(J20="",Parametros!$B$14+Parametros!$B$18>=1),"",J20/(1-Parametros!$B$14-Parametros!$B$18)) | Q20: =IF(B20="","",IF(E20="","SIN RECETA",IF(J20="","FALTAN DATOS",IF(NOT(ISNUMBER(G20)),"FALTA PRECIO",IF(M20<0,"PIERDE",IF(N20<Parametros!$B$18,"BAJO META","OK")))))) -> SIN RECETA | R20: =IF(B20="","",IF(E20="","Elegir receta (molde).",IF(ISNA(MATCH(E20,Recetas!$A$5:$A$84,0)),"La receta no existe en Recetas.",IF(J20="","Completar la receta "&E20&": "&INDEX(Recetas!$T$5:$T$84,MATCH(E20,Recetas!$A$5:$A$84,0)),IF(NOT(ISNUMBER(G20)),"Precio de venta.",""))))) -> Elegir receta (molde).
A21: RUG-SHO-BAS | B21: Short Rugby Basic | C21: Juego | D21: 61 | E21: SM-02 · Short Rugby | G21: 12507 | H21: Por confirmar | J21: =IF(OR(B21="",E21=""),"",IF(IFERROR(INDEX(Recetas!$S$5:$S$84,MATCH(E21,Recetas!$A$5:$A$84,0)),"")="","",IFERROR(INDEX(Recetas!$S$5:$S$84,MATCH(E21,Recetas!$A$5:$A$84,0)),"")+N(F21))) -> 2706.55 | K21: =IF(AND(J21<>"",ISNUMBER(G21)),G21*Parametros!$B$12,"") -> 4414.3024 | L21: =IF(AND(J21<>"",ISNUMBER(G21)),G21*Parametros!$B$13,"") -> 1584.5924 | M21: =IF(AND(J21<>"",ISNUMBER(G21)),G21-J21-K21-L21,"") -> 3801.5552 | N21: =IF(AND(J21<>"",ISNUMBER(G21)),M21/G21,"") -> 0.3039542 | O21: =IF(OR(J21="",Parametros!$B$14>=1),"",J21/(1-Parametros!$B$14)) -> 5201.3328 | P21: =IF(OR(J21="",Parametros!$B$14+Parametros!$B$18>=1),"",J21/(1-Parametros!$B$14-Parametros!$B$18)) -> 6438.6936 | Q21: =IF(B21="","",IF(E21="","SIN RECETA",IF(J21="","FALTAN DATOS",IF(NOT(ISNUMBER(G21)),"FALTA PRECIO",IF(M21<0,"PIERDE",IF(N21<Parametros!$B$18,"BAJO META","OK")))))) -> OK | R21: =IF(B21="","",IF(E21="","Elegir receta (molde).",IF(ISNA(MATCH(E21,Recetas!$A$5:$A$84,0)),"La receta no existe en Recetas.",IF(J21="","Completar la receta "&E21&": "&INDEX(Recetas!$T$5:$T$84,MATCH(E21,Recetas!$A$5:$A$84,0)),IF(NOT(ISNUMBER(G21)),"Precio de venta.","")))))
A22: SALPTPESUB | B22: Conjunto Polerón de Entrenamiento + Pitillo | C22: Salida | D22: 60 | G22: 41933 | H22: Por confirmar | I22: Sin receta: elige el molde que usa, o crea la receta en "Recetas" si aún no tiene molde. | J22: =IF(OR(B22="",E22=""),"",IF(IFERROR(INDEX(Recetas!$S$5:$S$84,MATCH(E22,Recetas!$A$5:$A$84,0)),"")="","",IFERROR(INDEX(Recetas!$S$5:$S$84,MATCH(E22,Recetas!$A$5:$A$84,0)),"")+N(F22))) | K22: =IF(AND(J22<>"",ISNUMBER(G22)),G22*Parametros!$B$12,"") | L22: =IF(AND(J22<>"",ISNUMBER(G22)),G22*Parametros!$B$13,"") | M22: =IF(AND(J22<>"",ISNUMBER(G22)),G22-J22-K22-L22,"") | N22: =IF(AND(J22<>"",ISNUMBER(G22)),M22/G22,"") | O22: =IF(OR(J22="",Parametros!$B$14>=1),"",J22/(1-Parametros!$B$14)) | P22: =IF(OR(J22="",Parametros!$B$14+Parametros!$B$18>=1),"",J22/(1-Parametros!$B$14-Parametros!$B$18)) | Q22: =IF(B22="","",IF(E22="","SIN RECETA",IF(J22="","FALTAN DATOS",IF(NOT(ISNUMBER(G22)),"FALTA PRECIO",IF(M22<0,"PIERDE",IF(N22<Parametros!$B$18,"BAJO META","OK")))))) -> SIN RECETA | R22: =IF(B22="","",IF(E22="","Elegir receta (molde).",IF(ISNA(MATCH(E22,Recetas!$A$5:$A$84,0)),"La receta no existe en Recetas.",IF(J22="","Completar la receta "&E22&": "&INDEX(Recetas!$T$5:$T$84,MATCH(E22,Recetas!$A$5:$A$84,0)),IF(NOT(ISNUMBER(G22)),"Precio de venta.",""))))) -> Elegir receta (molde).
A23: FUTSHOLIS | B23: Short Fútbol Playmaker Liso | C23: Juego | D23: 55 | E23: SM-01 · Short Fútbol | G23: 8059 | H23: Por confirmar | I23: El short de fútbol aún no tiene molde en el catálogo. | J23: =IF(OR(B23="",E23=""),"",IF(IFERROR(INDEX(Recetas!$S$5:$S$84,MATCH(E23,Recetas!$A$5:$A$84,0)),"")="","",IFERROR(INDEX(Recetas!$S$5:$S$84,MATCH(E23,Recetas!$A$5:$A$84,0)),"")+N(F23))) -> 2601.04 | K23: =IF(AND(J23<>"",ISNUMBER(G23)),G23*Parametros!$B$12,"") -> 2844.3962 | L23: =IF(AND(J23<>"",ISNUMBER(G23)),G23*Parametros!$B$13,"") -> 1021.0466 | M23: =IF(AND(J23<>"",ISNUMBER(G23)),G23-J23-K23-L23,"") -> 1592.5172 | N23: =IF(AND(J23<>"",ISNUMBER(G23)),M23/G23,"") -> 0.19760729 | O23: =IF(OR(J23="",Parametros!$B$14>=1),"",J23/(1-Parametros!$B$14)) -> 4998.5682 | P23: =IF(OR(J23="",Parametros!$B$14+Parametros!$B$18>=1),"",J23/(1-Parametros!$B$14-Parametros!$B$18)) -> 6187.6926 | Q23: =IF(B23="","",IF(E23="","SIN RECETA",IF(J23="","FALTAN DATOS",IF(NOT(ISNUMBER(G23)),"FALTA PRECIO",IF(M23<0,"PIERDE",IF(N23<Parametros!$B$18,"BAJO META","OK")))))) -> OK | R23: =IF(B23="","",IF(E23="","Elegir receta (molde).",IF(ISNA(MATCH(E23,Recetas!$A$5:$A$84,0)),"La receta no existe en Recetas.",IF(J23="","Completar la receta "&E23&": "&INDEX(Recetas!$T$5:$T$84,MATCH(E23,Recetas!$A$5:$A$84,0)),IF(NOT(ISNUMBER(G23)),"Precio de venta.","")))))
A24: VOLFEMCSUBPROV | B24: Camiseta Voley fem Pro Playmaker, V | C24: Juego | D24: 50 | G24: 19244 | H24: Por confirmar | I24: Sin receta: elige el molde que usa, o crea la receta en "Recetas" si aún no tiene molde. | J24: =IF(OR(B24="",E24=""),"",IF(IFERROR(INDEX(Recetas!$S$5:$S$84,MATCH(E24,Recetas!$A$5:$A$84,0)),"")="","",IFERROR(INDEX(Recetas!$S$5:$S$84,MATCH(E24,Recetas!$A$5:$A$84,0)),"")+N(F24))) | K24: =IF(AND(J24<>"",ISNUMBER(G24)),G24*Parametros!$B$12,"") | L24: =IF(AND(J24<>"",ISNUMBER(G24)),G24*Parametros!$B$13,"") | M24: =IF(AND(J24<>"",ISNUMBER(G24)),G24-J24-K24-L24,"") | N24: =IF(AND(J24<>"",ISNUMBER(G24)),M24/G24,"") | O24: =IF(OR(J24="",Parametros!$B$14>=1),"",J24/(1-Parametros!$B$14)) | P24: =IF(OR(J24="",Parametros!$B$14+Parametros!$B$18>=1),"",J24/(1-Parametros!$B$14-Parametros!$B$18)) | Q24: =IF(B24="","",IF(E24="","SIN RECETA",IF(J24="","FALTAN DATOS",IF(NOT(ISNUMBER(G24)),"FALTA PRECIO",IF(M24<0,"PIERDE",IF(N24<Parametros!$B$18,"BAJO META","OK")))))) -> SIN RECETA | R24: =IF(B24="","",IF(E24="","Elegir receta (molde).",IF(ISNA(MATCH(E24,Recetas!$A$5:$A$84,0)),"La receta no existe en Recetas.",IF(J24="","Completar la receta "&E24&": "&INDEX(Recetas!$T$5:$T$84,MATCH(E24,Recetas!$A$5:$A$84,0)),IF(NOT(ISNUMBER(G24)),"Precio de venta.",""))))) -> Elegir receta (molde).
A25: MDPTSUB | B25: PETO ENTRENAMIENTO SUB | C25: Juego | D25: 48 | G25: 8319 | H25: Por confirmar | I25: Sin receta: elige el molde que usa, o crea la receta en "Recetas" si aún no tiene molde. | J25: =IF(OR(B25="",E25=""),"",IF(IFERROR(INDEX(Recetas!$S$5:$S$84,MATCH(E25,Recetas!$A$5:$A$84,0)),"")="","",IFERROR(INDEX(Recetas!$S$5:$S$84,MATCH(E25,Recetas!$A$5:$A$84,0)),"")+N(F25))) | K25: =IF(AND(J25<>"",ISNUMBER(G25)),G25*Parametros!$B$12,"") | L25: =IF(AND(J25<>"",ISNUMBER(G25)),G25*Parametros!$B$13,"") | M25: =IF(AND(J25<>"",ISNUMBER(G25)),G25-J25-K25-L25,"") | N25: =IF(AND(J25<>"",ISNUMBER(G25)),M25/G25,"") | O25: =IF(OR(J25="",Parametros!$B$14>=1),"",J25/(1-Parametros!$B$14)) | P25: =IF(OR(J25="",Parametros!$B$14+Parametros!$B$18>=1),"",J25/(1-Parametros!$B$14-Parametros!$B$18)) | Q25: =IF(B25="","",IF(E25="","SIN RECETA",IF(J25="","FALTAN DATOS",IF(NOT(ISNUMBER(G25)),"FALTA PRECIO",IF(M25<0,"PIERDE",IF(N25<Parametros!$B$18,"BAJO META","OK")))))) -> SIN RECETA | R25: =IF(B25="","",IF(E25="","Elegir receta (molde).",IF(ISNA(MATCH(E25,Recetas!$A$5:$A$84,0)),"La receta no existe en Recetas.",IF(J25="","Completar la receta "&E25&": "&INDEX(Recetas!$T$5:$T$84,MATCH(E25,Recetas!$A$5:$A$84,0)),IF(NOT(ISNUMBER(G25)),"Precio de venta.",""))))) -> Elegir receta (molde).
A26: MDCSUBOVA | B26: Polera Playmaker, Cuello Oval s/mangas | C26: Juego | D26: 48 | G26: 16723 | H26: Por confirmar | I26: Sin receta: elige el molde que usa, o crea la receta en "Recetas" si aún no tiene molde. | J26: =IF(OR(B26="",E26=""),"",IF(IFERROR(INDEX(Recetas!$S$5:$S$84,MATCH(E26,Recetas!$A$5:$A$84,0)),"")="","",IFERROR(INDEX(Recetas!$S$5:$S$84,MATCH(E26,Recetas!$A$5:$A$84,0)),"")+N(F26))) | K26: =IF(AND(J26<>"",ISNUMBER(G26)),G26*Parametros!$B$12,"") | L26: =IF(AND(J26<>"",ISNUMBER(G26)),G26*Parametros!$B$13,"") | M26: =IF(AND(J26<>"",ISNUMBER(G26)),G26-J26-K26-L26,"") | N26: =IF(AND(J26<>"",ISNUMBER(G26)),M26/G26,"") | O26: =IF(OR(J26="",Parametros!$B$14>=1),"",J26/(1-Parametros!$B$14)) | P26: =IF(OR(J26="",Parametros!$B$14+Parametros!$B$18>=1),"",J26/(1-Parametros!$B$14-Parametros!$B$18)) | Q26: =IF(B26="","",IF(E26="","SIN RECETA",IF(J26="","FALTAN DATOS",IF(NOT(ISNUMBER(G26)),"FALTA PRECIO",IF(M26<0,"PIERDE",IF(N26<Parametros!$B$18,"BAJO META","OK")))))) -> SIN RECETA | R26: =IF(B26="","",IF(E26="","Elegir receta (molde).",IF(ISNA(MATCH(E26,Recetas!$A$5:$A$84,0)),"La receta no existe en Recetas.",IF(J26="","Completar la receta "&E26&": "&INDEX(Recetas!$T$5:$T$84,MATCH(E26,Recetas!$A$5:$A$84,0)),IF(NOT(ISNUMBER(G26)),"Precio de venta.",""))))) -> Elegir receta (molde).
A27: SALHOOLIS | B27: Polerón Hoodie Playmaker liso | C27: Salida | D27: 47 | G27: 26134 | H27: Por confirmar | I27: Sin receta: elige el molde que usa, o crea la receta en "Recetas" si aún no tiene molde. | J27: =IF(OR(B27="",E27=""),"",IF(IFERROR(INDEX(Recetas!$S$5:$S$84,MATCH(E27,Recetas!$A$5:$A$84,0)),"")="","",IFERROR(INDEX(Recetas!$S$5:$S$84,MATCH(E27,Recetas!$A$5:$A$84,0)),"")+N(F27))) | K27: =IF(AND(J27<>"",ISNUMBER(G27)),G27*Parametros!$B$12,"") | L27: =IF(AND(J27<>"",ISNUMBER(G27)),G27*Parametros!$B$13,"") | M27: =IF(AND(J27<>"",ISNUMBER(G27)),G27-J27-K27-L27,"") | N27: =IF(AND(J27<>"",ISNUMBER(G27)),M27/G27,"") | O27: =IF(OR(J27="",Parametros!$B$14>=1),"",J27/(1-Parametros!$B$14)) | P27: =IF(OR(J27="",Parametros!$B$14+Parametros!$B$18>=1),"",J27/(1-Parametros!$B$14-Parametros!$B$18)) | Q27: =IF(B27="","",IF(E27="","SIN RECETA",IF(J27="","FALTAN DATOS",IF(NOT(ISNUMBER(G27)),"FALTA PRECIO",IF(M27<0,"PIERDE",IF(N27<Parametros!$B$18,"BAJO META","OK")))))) -> SIN RECETA | R27: =IF(B27="","",IF(E27="","Elegir receta (molde).",IF(ISNA(MATCH(E27,Recetas!$A$5:$A$84,0)),"La receta no existe en Recetas.",IF(J27="","Completar la receta "&E27&": "&INDEX(Recetas!$T$5:$T$84,MATCH(E27,Recetas!$A$5:$A$84,0)),IF(NOT(ISNUMBER(G27)),"Precio de venta.",""))))) -> Elegir receta (molde).
A28: CSUBRUGSFBLANCA | B28: CAMISETA DE RUGBY STADE FRANCAIS ANIVERSARIO (BLANCA) | C28: Juego | D28: 44 | G28: 27605 | H28: Por confirmar | I28: Sin receta: elige el molde que usa, o crea la receta en "Recetas" si aún no tiene molde. | J28: =IF(OR(B28="",E28=""),"",IF(IFERROR(INDEX(Recetas!$S$5:$S$84,MATCH(E28,Recetas!$A$5:$A$84,0)),"")="","",IFERROR(INDEX(Recetas!$S$5:$S$84,MATCH(E28,Recetas!$A$5:$A$84,0)),"")+N(F28))) | K28: =IF(AND(J28<>"",ISNUMBER(G28)),G28*Parametros!$B$12,"") | L28: =IF(AND(J28<>"",ISNUMBER(G28)),G28*Parametros!$B$13,"") | M28: =IF(AND(J28<>"",ISNUMBER(G28)),G28-J28-K28-L28,"") | N28: =IF(AND(J28<>"",ISNUMBER(G28)),M28/G28,"") | O28: =IF(OR(J28="",Parametros!$B$14>=1),"",J28/(1-Parametros!$B$14)) | P28: =IF(OR(J28="",Parametros!$B$14+Parametros!$B$18>=1),"",J28/(1-Parametros!$B$14-Parametros!$B$18)) | Q28: =IF(B28="","",IF(E28="","SIN RECETA",IF(J28="","FALTAN DATOS",IF(NOT(ISNUMBER(G28)),"FALTA PRECIO",IF(M28<0,"PIERDE",IF(N28<Parametros!$B$18,"BAJO META","OK")))))) -> SIN RECETA | R28: =IF(B28="","",IF(E28="","Elegir receta (molde).",IF(ISNA(MATCH(E28,Recetas!$A$5:$A$84,0)),"La receta no existe en Recetas.",IF(J28="","Completar la receta "&E28&": "&INDEX(Recetas!$T$5:$T$84,MATCH(E28,Recetas!$A$5:$A$84,0)),IF(NOT(ISNUMBER(G28)),"Precio de venta.",""))))) -> Elegir receta (molde).
A29: SAL-POL-3C | B29: Polerón 3C Playmaker Algodón Cierre | C29: Salida | D29: 40 | G29: 32689 | H29: Por confirmar | I29: Sin receta: elige el molde que usa, o crea la receta en "Recetas" si aún no tiene molde. | J29: =IF(OR(B29="",E29=""),"",IF(IFERROR(INDEX(Recetas!$S$5:$S$84,MATCH(E29,Recetas!$A$5:$A$84,0)),"")="","",IFERROR(INDEX(Recetas!$S$5:$S$84,MATCH(E29,Recetas!$A$5:$A$84,0)),"")+N(F29))) | K29: =IF(AND(J29<>"",ISNUMBER(G29)),G29*Parametros!$B$12,"") | L29: =IF(AND(J29<>"",ISNUMBER(G29)),G29*Parametros!$B$13,"") | M29: =IF(AND(J29<>"",ISNUMBER(G29)),G29-J29-K29-L29,"") | N29: =IF(AND(J29<>"",ISNUMBER(G29)),M29/G29,"") | O29: =IF(OR(J29="",Parametros!$B$14>=1),"",J29/(1-Parametros!$B$14)) | P29: =IF(OR(J29="",Parametros!$B$14+Parametros!$B$18>=1),"",J29/(1-Parametros!$B$14-Parametros!$B$18)) | Q29: =IF(B29="","",IF(E29="","SIN RECETA",IF(J29="","FALTAN DATOS",IF(NOT(ISNUMBER(G29)),"FALTA PRECIO",IF(M29<0,"PIERDE",IF(N29<Parametros!$B$18,"BAJO META","OK")))))) -> SIN RECETA | R29: =IF(B29="","",IF(E29="","Elegir receta (molde).",IF(ISNA(MATCH(E29,Recetas!$A$5:$A$84,0)),"La receta no existe en Recetas.",IF(J29="","Completar la receta "&E29&": "&INDEX(Recetas!$T$5:$T$84,MATCH(E29,Recetas!$A$5:$A$84,0)),IF(NOT(ISNUMBER(G29)),"Precio de venta.",""))))) -> Elegir receta (molde).
A30: VOLMASC-CSUB-POL-CER | B30: Camiseta Voley masc Playmaker, Polo m/cero | C30: Juego | D30: 37 | G30: 17563 | H30: Por confirmar | I30: Sin receta: elige el molde que usa, o crea la receta en "Recetas" si aún no tiene molde. | J30: =IF(OR(B30="",E30=""),"",IF(IFERROR(INDEX(Recetas!$S$5:$S$84,MATCH(E30,Recetas!$A$5:$A$84,0)),"")="","",IFERROR(INDEX(Recetas!$S$5:$S$84,MATCH(E30,Recetas!$A$5:$A$84,0)),"")+N(F30))) | K30: =IF(AND(J30<>"",ISNUMBER(G30)),G30*Parametros!$B$12,"") | L30: =IF(AND(J30<>"",ISNUMBER(G30)),G30*Parametros!$B$13,"") | M30: =IF(AND(J30<>"",ISNUMBER(G30)),G30-J30-K30-L30,"") | N30: =IF(AND(J30<>"",ISNUMBER(G30)),M30/G30,"") | O30: =IF(OR(J30="",Parametros!$B$14>=1),"",J30/(1-Parametros!$B$14)) | P30: =IF(OR(J30="",Parametros!$B$14+Parametros!$B$18>=1),"",J30/(1-Parametros!$B$14-Parametros!$B$18)) | Q30: =IF(B30="","",IF(E30="","SIN RECETA",IF(J30="","FALTAN DATOS",IF(NOT(ISNUMBER(G30)),"FALTA PRECIO",IF(M30<0,"PIERDE",IF(N30<Parametros!$B$18,"BAJO META","OK")))))) -> SIN RECETA | R30: =IF(B30="","",IF(E30="","Elegir receta (molde).",IF(ISNA(MATCH(E30,Recetas!$A$5:$A$84,0)),"La receta no existe en Recetas.",IF(J30="","Completar la receta "&E30&": "&INDEX(Recetas!$T$5:$T$84,MATCH(E30,Recetas!$A$5:$A$84,0)),IF(NOT(ISNUMBER(G30)),"Precio de venta.",""))))) -> Elegir receta (molde).
A31: SALPRKLIS | B31: Parka Lisa Playmaker | C31: Salida | D31: 37 | G31: 54022 | H31: Por confirmar | I31: Sin receta: elige el molde que usa, o crea la receta en "Recetas" si aún no tiene molde. | J31: =IF(OR(B31="",E31=""),"",IF(IFERROR(INDEX(Recetas!$S$5:$S$84,MATCH(E31,Recetas!$A$5:$A$84,0)),"")="","",IFERROR(INDEX(Recetas!$S$5:$S$84,MATCH(E31,Recetas!$A$5:$A$84,0)),"")+N(F31))) | K31: =IF(AND(J31<>"",ISNUMBER(G31)),G31*Parametros!$B$12,"") | L31: =IF(AND(J31<>"",ISNUMBER(G31)),G31*Parametros!$B$13,"") | M31: =IF(AND(J31<>"",ISNUMBER(G31)),G31-J31-K31-L31,"") | N31: =IF(AND(J31<>"",ISNUMBER(G31)),M31/G31,"") | O31: =IF(OR(J31="",Parametros!$B$14>=1),"",J31/(1-Parametros!$B$14)) | P31: =IF(OR(J31="",Parametros!$B$14+Parametros!$B$18>=1),"",J31/(1-Parametros!$B$14-Parametros!$B$18)) | Q31: =IF(B31="","",IF(E31="","SIN RECETA",IF(J31="","FALTAN DATOS",IF(NOT(ISNUMBER(G31)),"FALTA PRECIO",IF(M31<0,"PIERDE",IF(N31<Parametros!$B$18,"BAJO META","OK")))))) -> SIN RECETA | R31: =IF(B31="","",IF(E31="","Elegir receta (molde).",IF(ISNA(MATCH(E31,Recetas!$A$5:$A$84,0)),"La receta no existe en Recetas.",IF(J31="","Completar la receta "&E31&": "&INDEX(Recetas!$T$5:$T$84,MATCH(E31,Recetas!$A$5:$A$84,0)),IF(NOT(ISNUMBER(G31)),"Precio de venta.",""))))) -> Elegir receta (molde).
A32: RUG-SHO-PRO | B32: Short Rugby Pro | C32: Juego | D32: 35 | E32: SM-02 · Short Rugby | G32: 14202 | H32: Por confirmar | I32: Pro puede gastar distinto: confirmar. | J32: =IF(OR(B32="",E32=""),"",IF(IFERROR(INDEX(Recetas!$S$5:$S$84,MATCH(E32,Recetas!$A$5:$A$84,0)),"")="","",IFERROR(INDEX(Recetas!$S$5:$S$84,MATCH(E32,Recetas!$A$5:$A$84,0)),"")+N(F32))) -> 2706.55 | K32: =IF(AND(J32<>"",ISNUMBER(G32)),G32*Parametros!$B$12,"") -> 5012.5468 | L32: =IF(AND(J32<>"",ISNUMBER(G32)),G32*Parametros!$B$13,"") -> 1799.3429 | M32: =IF(AND(J32<>"",ISNUMBER(G32)),G32-J32-K32-L32,"") -> 4683.5603 | N32: =IF(AND(J32<>"",ISNUMBER(G32)),M32/G32,"") -> 0.32978174 | O32: =IF(OR(J32="",Parametros!$B$14>=1),"",J32/(1-Parametros!$B$14)) -> 5201.3328 | P32: =IF(OR(J32="",Parametros!$B$14+Parametros!$B$18>=1),"",J32/(1-Parametros!$B$14-Parametros!$B$18)) -> 6438.6936 | Q32: =IF(B32="","",IF(E32="","SIN RECETA",IF(J32="","FALTAN DATOS",IF(NOT(ISNUMBER(G32)),"FALTA PRECIO",IF(M32<0,"PIERDE",IF(N32<Parametros!$B$18,"BAJO META","OK")))))) -> OK | R32: =IF(B32="","",IF(E32="","Elegir receta (molde).",IF(ISNA(MATCH(E32,Recetas!$A$5:$A$84,0)),"La receta no existe en Recetas.",IF(J32="","Completar la receta "&E32&": "&INDEX(Recetas!$T$5:$T$84,MATCH(E32,Recetas!$A$5:$A$84,0)),IF(NOT(ISNUMBER(G32)),"Precio de venta.","")))))
A33: SAL-POL-SUB | B33: Polerón Entrenamiento Sublim | C33: Salida | D33: 35 | G33: 27647 | H33: Por confirmar | I33: Sin receta: elige el molde que usa, o crea la receta en "Recetas" si aún no tiene molde. | J33: =IF(OR(B33="",E33=""),"",IF(IFERROR(INDEX(Recetas!$S$5:$S$84,MATCH(E33,Recetas!$A$5:$A$84,0)),"")="","",IFERROR(INDEX(Recetas!$S$5:$S$84,MATCH(E33,Recetas!$A$5:$A$84,0)),"")+N(F33))) | K33: =IF(AND(J33<>"",ISNUMBER(G33)),G33*Parametros!$B$12,"") | L33: =IF(AND(J33<>"",ISNUMBER(G33)),G33*Parametros!$B$13,"") | M33: =IF(AND(J33<>"",ISNUMBER(G33)),G33-J33-K33-L33,"") | N33: =IF(AND(J33<>"",ISNUMBER(G33)),M33/G33,"") | O33: =IF(OR(J33="",Parametros!$B$14>=1),"",J33/(1-Parametros!$B$14)) | P33: =IF(OR(J33="",Parametros!$B$14+Parametros!$B$18>=1),"",J33/(1-Parametros!$B$14-Parametros!$B$18)) | Q33: =IF(B33="","",IF(E33="","SIN RECETA",IF(J33="","FALTAN DATOS",IF(NOT(ISNUMBER(G33)),"FALTA PRECIO",IF(M33<0,"PIERDE",IF(N33<Parametros!$B$18,"BAJO META","OK")))))) -> SIN RECETA | R33: =IF(B33="","",IF(E33="","Elegir receta (molde).",IF(ISNA(MATCH(E33,Recetas!$A$5:$A$84,0)),"La receta no existe en Recetas.",IF(J33="","Completar la receta "&E33&": "&INDEX(Recetas!$T$5:$T$84,MATCH(E33,Recetas!$A$5:$A$84,0)),IF(NOT(ISNUMBER(G33)),"Precio de venta.",""))))) -> Elegir receta (molde).
A34: RUGCSUBPER | B34: Camiseta Rugby Performance Pmk | C34: Juego | D34: 34 | G34: 19664 | H34: Por confirmar | I34: Sin receta: elige el molde que usa, o crea la receta en "Recetas" si aún no tiene molde. | J34: =IF(OR(B34="",E34=""),"",IF(IFERROR(INDEX(Recetas!$S$5:$S$84,MATCH(E34,Recetas!$A$5:$A$84,0)),"")="","",IFERROR(INDEX(Recetas!$S$5:$S$84,MATCH(E34,Recetas!$A$5:$A$84,0)),"")+N(F34))) | K34: =IF(AND(J34<>"",ISNUMBER(G34)),G34*Parametros!$B$12,"") | L34: =IF(AND(J34<>"",ISNUMBER(G34)),G34*Parametros!$B$13,"") | M34: =IF(AND(J34<>"",ISNUMBER(G34)),G34-J34-K34-L34,"") | N34: =IF(AND(J34<>"",ISNUMBER(G34)),M34/G34,"") | O34: =IF(OR(J34="",Parametros!$B$14>=1),"",J34/(1-Parametros!$B$14)) | P34: =IF(OR(J34="",Parametros!$B$14+Parametros!$B$18>=1),"",J34/(1-Parametros!$B$14-Parametros!$B$18)) | Q34: =IF(B34="","",IF(E34="","SIN RECETA",IF(J34="","FALTAN DATOS",IF(NOT(ISNUMBER(G34)),"FALTA PRECIO",IF(M34<0,"PIERDE",IF(N34<Parametros!$B$18,"BAJO META","OK")))))) -> SIN RECETA | R34: =IF(B34="","",IF(E34="","Elegir receta (molde).",IF(ISNA(MATCH(E34,Recetas!$A$5:$A$84,0)),"La receta no existe en Recetas.",IF(J34="","Completar la receta "&E34&": "&INDEX(Recetas!$T$5:$T$84,MATCH(E34,Recetas!$A$5:$A$84,0)),IF(NOT(ISNUMBER(G34)),"Precio de venta.",""))))) -> Elegir receta (molde).
A35: FUTCSUBML | B35: Camiseta Fútbol Playmaker, m/l | C35: Juego | D35: 34 | E35: 02 · FUTHOMU01 | G35: 17563 | H35: Por confirmar | I35: Manga larga: suma su costo extra en "Extras". | J35: =IF(OR(B35="",E35=""),"",IF(IFERROR(INDEX(Recetas!$S$5:$S$84,MATCH(E35,Recetas!$A$5:$A$84,0)),"")="","",IFERROR(INDEX(Recetas!$S$5:$S$84,MATCH(E35,Recetas!$A$5:$A$84,0)),"")+N(F35))) | K35: =IF(AND(J35<>"",ISNUMBER(G35)),G35*Parametros!$B$12,"") | L35: =IF(AND(J35<>"",ISNUMBER(G35)),G35*Parametros!$B$13,"") | M35: =IF(AND(J35<>"",ISNUMBER(G35)),G35-J35-K35-L35,"") | N35: =IF(AND(J35<>"",ISNUMBER(G35)),M35/G35,"") | O35: =IF(OR(J35="",Parametros!$B$14>=1),"",J35/(1-Parametros!$B$14)) | P35: =IF(OR(J35="",Parametros!$B$14+Parametros!$B$18>=1),"",J35/(1-Parametros!$B$14-Parametros!$B$18)) | Q35: =IF(B35="","",IF(E35="","SIN RECETA",IF(J35="","FALTAN DATOS",IF(NOT(ISNUMBER(G35)),"FALTA PRECIO",IF(M35<0,"PIERDE",IF(N35<Parametros!$B$18,"BAJO META","OK")))))) -> FALTAN DATOS | R35: =IF(B35="","",IF(E35="","Elegir receta (molde).",IF(ISNA(MATCH(E35,Recetas!$A$5:$A$84,0)),"La receta no existe en Recetas.",IF(J35="","Completar la receta "&E35&": "&INDEX(Recetas!$T$5:$T$84,MATCH(E35,Recetas!$A$5:$A$84,0)),IF(NOT(ISNUMBER(G35)),"Precio de venta.",""))))) -> Completar la receta 02 · FUTHOMU01: Tela. Kg de tela. Metros impresos.
A36: SALALMLLISA | B36: Camiseta Algodón Manga Larga Lisa | C36: Juego | D36: 31 | G36: 12521 | H36: Por confirmar | I36: Sin receta: elige el molde que usa, o crea la receta en "Recetas" si aún no tiene molde. | J36: =IF(OR(B36="",E36=""),"",IF(IFERROR(INDEX(Recetas!$S$5:$S$84,MATCH(E36,Recetas!$A$5:$A$84,0)),"")="","",IFERROR(INDEX(Recetas!$S$5:$S$84,MATCH(E36,Recetas!$A$5:$A$84,0)),"")+N(F36))) | K36: =IF(AND(J36<>"",ISNUMBER(G36)),G36*Parametros!$B$12,"") | L36: =IF(AND(J36<>"",ISNUMBER(G36)),G36*Parametros!$B$13,"") | M36: =IF(AND(J36<>"",ISNUMBER(G36)),G36-J36-K36-L36,"") | N36: =IF(AND(J36<>"",ISNUMBER(G36)),M36/G36,"") | O36: =IF(OR(J36="",Parametros!$B$14>=1),"",J36/(1-Parametros!$B$14)) | P36: =IF(OR(J36="",Parametros!$B$14+Parametros!$B$18>=1),"",J36/(1-Parametros!$B$14-Parametros!$B$18)) | Q36: =IF(B36="","",IF(E36="","SIN RECETA",IF(J36="","FALTAN DATOS",IF(NOT(ISNUMBER(G36)),"FALTA PRECIO",IF(M36<0,"PIERDE",IF(N36<Parametros!$B$18,"BAJO META","OK")))))) -> SIN RECETA | R36: =IF(B36="","",IF(E36="","Elegir receta (molde).",IF(ISNA(MATCH(E36,Recetas!$A$5:$A$84,0)),"La receta no existe en Recetas.",IF(J36="","Completar la receta "&E36&": "&INDEX(Recetas!$T$5:$T$84,MATCH(E36,Recetas!$A$5:$A$84,0)),IF(NOT(ISNUMBER(G36)),"Precio de venta.",""))))) -> Elegir receta (molde).
A37: RUG-CSUB-PIQ | B37: Camiseta Rugby Playmaker, Vintage | C37: Juego | D37: 29 | G37: 21204 | H37: Por confirmar | I37: Sin receta: elige el molde que usa, o crea la receta en "Recetas" si aún no tiene molde. | J37: =IF(OR(B37="",E37=""),"",IF(IFERROR(INDEX(Recetas!$S$5:$S$84,MATCH(E37,Recetas!$A$5:$A$84,0)),"")="","",IFERROR(INDEX(Recetas!$S$5:$S$84,MATCH(E37,Recetas!$A$5:$A$84,0)),"")+N(F37))) | K37: =IF(AND(J37<>"",ISNUMBER(G37)),G37*Parametros!$B$12,"") | L37: =IF(AND(J37<>"",ISNUMBER(G37)),G37*Parametros!$B$13,"") | M37: =IF(AND(J37<>"",ISNUMBER(G37)),G37-J37-K37-L37,"") | N37: =IF(AND(J37<>"",ISNUMBER(G37)),M37/G37,"") | O37: =IF(OR(J37="",Parametros!$B$14>=1),"",J37/(1-Parametros!$B$14)) | P37: =IF(OR(J37="",Parametros!$B$14+Parametros!$B$18>=1),"",J37/(1-Parametros!$B$14-Parametros!$B$18)) | Q37: =IF(B37="","",IF(E37="","SIN RECETA",IF(J37="","FALTAN DATOS",IF(NOT(ISNUMBER(G37)),"FALTA PRECIO",IF(M37<0,"PIERDE",IF(N37<Parametros!$B$18,"BAJO META","OK")))))) -> SIN RECETA | R37: =IF(B37="","",IF(E37="","Elegir receta (molde).",IF(ISNA(MATCH(E37,Recetas!$A$5:$A$84,0)),"La receta no existe en Recetas.",IF(J37="","Completar la receta "&E37&": "&INDEX(Recetas!$T$5:$T$84,MATCH(E37,Recetas!$A$5:$A$84,0)),IF(NOT(ISNUMBER(G37)),"Precio de venta.",""))))) -> Elegir receta (molde).
A38: VOL-CSUB-SAL-MC | B38: Camiseta Salida de Cancha Voley m/c | C38: Salida | D38: 29 | G38: 22605 | H38: Por confirmar | I38: Sin receta: elige el molde que usa, o crea la receta en "Recetas" si aún no tiene molde. | J38: =IF(OR(B38="",E38=""),"",IF(IFERROR(INDEX(Recetas!$S$5:$S$84,MATCH(E38,Recetas!$A$5:$A$84,0)),"")="","",IFERROR(INDEX(Recetas!$S$5:$S$84,MATCH(E38,Recetas!$A$5:$A$84,0)),"")+N(F38))) | K38: =IF(AND(J38<>"",ISNUMBER(G38)),G38*Parametros!$B$12,"") | L38: =IF(AND(J38<>"",ISNUMBER(G38)),G38*Parametros!$B$13,"") | M38: =IF(AND(J38<>"",ISNUMBER(G38)),G38-J38-K38-L38,"") | N38: =IF(AND(J38<>"",ISNUMBER(G38)),M38/G38,"") | O38: =IF(OR(J38="",Parametros!$B$14>=1),"",J38/(1-Parametros!$B$14)) | P38: =IF(OR(J38="",Parametros!$B$14+Parametros!$B$18>=1),"",J38/(1-Parametros!$B$14-Parametros!$B$18)) | Q38: =IF(B38="","",IF(E38="","SIN RECETA",IF(J38="","FALTAN DATOS",IF(NOT(ISNUMBER(G38)),"FALTA PRECIO",IF(M38<0,"PIERDE",IF(N38<Parametros!$B$18,"BAJO META","OK")))))) -> SIN RECETA | R38: =IF(B38="","",IF(E38="","Elegir receta (molde).",IF(ISNA(MATCH(E38,Recetas!$A$5:$A$84,0)),"La receta no existe en Recetas.",IF(J38="","Completar la receta "&E38&": "&INDEX(Recetas!$T$5:$T$84,MATCH(E38,Recetas!$A$5:$A$84,0)),IF(NOT(ISNUMBER(G38)),"Precio de venta.",""))))) -> Elegir receta (molde).
A39: CSUBVOLFEMVSM | B39: CAMISETA VOLEY FEM V S/M PLAYMAKER | C39: Juego | D39: 29 | G39: 16723 | H39: Por confirmar | I39: Sin receta: elige el molde que usa, o crea la receta en "Recetas" si aún no tiene molde. | J39: =IF(OR(B39="",E39=""),"",IF(IFERROR(INDEX(Recetas!$S$5:$S$84,MATCH(E39,Recetas!$A$5:$A$84,0)),"")="","",IFERROR(INDEX(Recetas!$S$5:$S$84,MATCH(E39,Recetas!$A$5:$A$84,0)),"")+N(F39))) | K39: =IF(AND(J39<>"",ISNUMBER(G39)),G39*Parametros!$B$12,"") | L39: =IF(AND(J39<>"",ISNUMBER(G39)),G39*Parametros!$B$13,"") | M39: =IF(AND(J39<>"",ISNUMBER(G39)),G39-J39-K39-L39,"") | N39: =IF(AND(J39<>"",ISNUMBER(G39)),M39/G39,"") | O39: =IF(OR(J39="",Parametros!$B$14>=1),"",J39/(1-Parametros!$B$14)) | P39: =IF(OR(J39="",Parametros!$B$14+Parametros!$B$18>=1),"",J39/(1-Parametros!$B$14-Parametros!$B$18)) | Q39: =IF(B39="","",IF(E39="","SIN RECETA",IF(J39="","FALTAN DATOS",IF(NOT(ISNUMBER(G39)),"FALTA PRECIO",IF(M39<0,"PIERDE",IF(N39<Parametros!$B$18,"BAJO META","OK")))))) -> SIN RECETA | R39: =IF(B39="","",IF(E39="","Elegir receta (molde).",IF(ISNA(MATCH(E39,Recetas!$A$5:$A$84,0)),"La receta no existe en Recetas.",IF(J39="","Completar la receta "&E39&": "&INDEX(Recetas!$T$5:$T$84,MATCH(E39,Recetas!$A$5:$A$84,0)),IF(NOT(ISNUMBER(G39)),"Precio de venta.",""))))) -> Elegir receta (molde).
A40: RUG-CSUB-LIC | B40: Camiseta Rugby Playmaker, Low Profile | C40: Juego | D40: 26 | G40: 23488 | H40: Por confirmar | I40: Sin receta: elige el molde que usa, o crea la receta en "Recetas" si aún no tiene molde. | J40: =IF(OR(B40="",E40=""),"",IF(IFERROR(INDEX(Recetas!$S$5:$S$84,MATCH(E40,Recetas!$A$5:$A$84,0)),"")="","",IFERROR(INDEX(Recetas!$S$5:$S$84,MATCH(E40,Recetas!$A$5:$A$84,0)),"")+N(F40))) | K40: =IF(AND(J40<>"",ISNUMBER(G40)),G40*Parametros!$B$12,"") | L40: =IF(AND(J40<>"",ISNUMBER(G40)),G40*Parametros!$B$13,"") | M40: =IF(AND(J40<>"",ISNUMBER(G40)),G40-J40-K40-L40,"") | N40: =IF(AND(J40<>"",ISNUMBER(G40)),M40/G40,"") | O40: =IF(OR(J40="",Parametros!$B$14>=1),"",J40/(1-Parametros!$B$14)) | P40: =IF(OR(J40="",Parametros!$B$14+Parametros!$B$18>=1),"",J40/(1-Parametros!$B$14-Parametros!$B$18)) | Q40: =IF(B40="","",IF(E40="","SIN RECETA",IF(J40="","FALTAN DATOS",IF(NOT(ISNUMBER(G40)),"FALTA PRECIO",IF(M40<0,"PIERDE",IF(N40<Parametros!$B$18,"BAJO META","OK")))))) -> SIN RECETA | R40: =IF(B40="","",IF(E40="","Elegir receta (molde).",IF(ISNA(MATCH(E40,Recetas!$A$5:$A$84,0)),"La receta no existe en Recetas.",IF(J40="","Completar la receta "&E40&": "&INDEX(Recetas!$T$5:$T$84,MATCH(E40,Recetas!$A$5:$A$84,0)),IF(NOT(ISNUMBER(G40)),"Precio de venta.",""))))) -> Elegir receta (molde).
...

Sheet Recetas
A1: RECETAS POR MOLDE — costo de producción de una prenda
A2: Una fila = un molde del catálogo (los mismos del panel de Fichas y de Planificación). Llena las columnas azules. Abajo: prendas que aún no tienen molde.
A4: Receta (molde) | B4: Descripción | C4: Deporte | D4: Prenda | E4: Calce | F4: Tela principal | G4: Kg tela por prenda | H4: Tela 2 (malla, etc.) | I4: Kg tela 2 por prenda | J4: Metros impresos por prenda | K4: Confección (tipo) | L4: Avíos ($ por prenda) | M4: Estado del dato | N4: Notas | O4: $ Telas | P4: $ Papel y tinta | Q4: $ Confección | R4: $ Avíos | S4: COSTO DE PRODUCCIÓN | T4: Qué falta
A5: 01 · FUTMUJU01 | B5: Fútbol, cuello redondo | C5: Fútbol | D5: Camiseta | E5: Femenino | K5: Camiseta De Futbol | M5: Por confirmar | N5: Confección sugerida por el tipo de molde: confirmar. | O5: =IF(A5="","",IFERROR(G5*INDEX(Precios!$D$5:$D$120,MATCH(F5,Precios!$A$5:$A$120,0)),0)+IF(H5="",0,IFERROR(I5*INDEX(Precios!$D$5:$D$120,MATCH(H5,Precios!$A$5:$A$120,0)),0))) -> 0 | P5: =IF(A5="","",N(J5)*Parametros!$B$27) -> 0 | Q5: =IF(A5="","",IFERROR(INDEX(Confeccion!$B$5:$B$100,MATCH(K5,Confeccion!$A$5:$A$100,0)),0)) -> 2000 | R5: =IF(A5="","",N(L5)) -> 0 | S5: =IF(A5="","",IF(AND(F5<>"",ISNUMBER(G5),ISNUMBER(IFERROR(INDEX(Precios!$D$5:$D$120,MATCH(F5,Precios!$A$5:$A$120,0)),"x")),OR(H5="",ISNUMBER(IFERROR(INDEX(Precios!$D$5:$D$120,MATCH(H5,Precios!$A$5:$A$120,0)),"x"))),J5<>"",K5<>"",Q5>0),SUM(O5:R5),"")) | T5: =IF(A5="","",IF(S5<>"",IF(AND(N(J5)>0,Parametros!$B$27=0),"Lista (sin costo de impresión)","Lista"),IF(F5="","Tela. ","")&IF(NOT(ISNUMBER(G5)),"Kg de tela. ","")&IF(AND(F5<>"",NOT(ISNUMBER(IFERROR(INDEX(Precios!$D$5:$D$120,MATCH(F5,Precios!$A$5:$A$120,0)),"x")))),"Tela sin precio. ","")&IF(J5="","Metros impresos. ","")&IF(K5="","Confección. ",IF(Q5=0,"Confección sin valor. ","")))) -> Tela. Kg de tela. Metros impresos.
A6: 02 · FUTHOMU01 | B6: Fútbol, cuello redondo | C6: Fútbol | D6: Camiseta | E6: Masculino | K6: Camiseta De Futbol | M6: Por confirmar | N6: Confección sugerida por el tipo de molde: confirmar. | O6: =IF(A6="","",IFERROR(G6*INDEX(Precios!$D$5:$D$120,MATCH(F6,Precios!$A$5:$A$120,0)),0)+IF(H6="",0,IFERROR(I6*INDEX(Precios!$D$5:$D$120,MATCH(H6,Precios!$A$5:$A$120,0)),0))) -> 0 | P6: =IF(A6="","",N(J6)*Parametros!$B$27) -> 0 | Q6: =IF(A6="","",IFERROR(INDEX(Confeccion!$B$5:$B$100,MATCH(K6,Confeccion!$A$5:$A$100,0)),0)) -> 2000 | R6: =IF(A6="","",N(L6)) -> 0 | S6: =IF(A6="","",IF(AND(F6<>"",ISNUMBER(G6),ISNUMBER(IFERROR(INDEX(Precios!$D$5:$D$120,MATCH(F6,Precios!$A$5:$A$120,0)),"x")),OR(H6="",ISNUMBER(IFERROR(INDEX(Precios!$D$5:$D$120,MATCH(H6,Precios!$A$5:$A$120,0)),"x"))),J6<>"",K6<>"",Q6>0),SUM(O6:R6),"")) | T6: =IF(A6="","",IF(S6<>"",IF(AND(N(J6)>0,Parametros!$B$27=0),"Lista (sin costo de impresión)","Lista"),IF(F6="","Tela. ","")&IF(NOT(ISNUMBER(G6)),"Kg de tela. ","")&IF(AND(F6<>"",NOT(ISNUMBER(IFERROR(INDEX(Precios!$D$5:$D$120,MATCH(F6,Precios!$A$5:$A$120,0)),"x")))),"Tela sin precio. ","")&IF(J6="","Metros impresos. ","")&IF(K6="","Confección. ",IF(Q6=0,"Confección sin valor. ","")))) -> Tela. Kg de tela. Metros impresos.
A7: 03 · FUTINMUJU01 | B7: Fútbol infantil, cuello redondo | C7: Fútbol | D7: Camiseta | E7: Infantil Femenino | K7: Camiseta De Futbol | M7: Por confirmar | N7: Confección sugerida por el tipo de molde: confirmar. | O7: =IF(A7="","",IFERROR(G7*INDEX(Precios!$D$5:$D$120,MATCH(F7,Precios!$A$5:$A$120,0)),0)+IF(H7="",0,IFERROR(I7*INDEX(Precios!$D$5:$D$120,MATCH(H7,Precios!$A$5:$A$120,0)),0))) -> 0 | P7: =IF(A7="","",N(J7)*Parametros!$B$27) -> 0 | Q7: =IF(A7="","",IFERROR(INDEX(Confeccion!$B$5:$B$100,MATCH(K7,Confeccion!$A$5:$A$100,0)),0)) -> 2000 | R7: =IF(A7="","",N(L7)) -> 0 | S7: =IF(A7="","",IF(AND(F7<>"",ISNUMBER(G7),ISNUMBER(IFERROR(INDEX(Precios!$D$5:$D$120,MATCH(F7,Precios!$A$5:$A$120,0)),"x")),OR(H7="",ISNUMBER(IFERROR(INDEX(Precios!$D$5:$D$120,MATCH(H7,Precios!$A$5:$A$120,0)),"x"))),J7<>"",K7<>"",Q7>0),SUM(O7:R7),"")) | T7: =IF(A7="","",IF(S7<>"",IF(AND(N(J7)>0,Parametros!$B$27=0),"Lista (sin costo de impresión)","Lista"),IF(F7="","Tela. ","")&IF(NOT(ISNUMBER(G7)),"Kg de tela. ","")&IF(AND(F7<>"",NOT(ISNUMBER(IFERROR(INDEX(Precios!$D$5:$D$120,MATCH(F7,Precios!$A$5:$A$120,0)),"x")))),"Tela sin precio. ","")&IF(J7="","Metros impresos. ","")&IF(K7="","Confección. ",IF(Q7=0,"Confección sin valor. ","")))) -> Tela. Kg de tela. Metros impresos.
A8: 04 · FUTINHOMU01 | B8: Fútbol infantil, cuello redondo | C8: Fútbol | D8: Camiseta | E8: Infantil Masculino | F8: CIRE BLANCO | G8: 0.0375 | H8: MESH | I8: 0.024 | K8: Camiseta De Futbol | M8: Por confirmar | N8: Ficha OT 2369 (48 camisetas infantiles). Falta metros impresos. | O8: =IF(A8="","",IFERROR(G8*INDEX(Precios!$D$5:$D$120,MATCH(F8,Precios!$A$5:$A$120,0)),0)+IF(H8="",0,IFERROR(I8*INDEX(Precios!$D$5:$D$120,MATCH(H8,Precios!$A$5:$A$120,0)),0))) -> 394.8 | P8: =IF(A8="","",N(J8)*Parametros!$B$27) -> 0 | Q8: =IF(A8="","",IFERROR(INDEX(Confeccion!$B$5:$B$100,MATCH(K8,Confeccion!$A$5:$A$100,0)),0)) -> 2000 | R8: =IF(A8="","",N(L8)) -> 0 | S8: =IF(A8="","",IF(AND(F8<>"",ISNUMBER(G8),ISNUMBER(IFERROR(INDEX(Precios!$D$5:$D$120,MATCH(F8,Precios!$A$5:$A$120,0)),"x")),OR(H8="",ISNUMBER(IFERROR(INDEX(Precios!$D$5:$D$120,MATCH(H8,Precios!$A$5:$A$120,0)),"x"))),J8<>"",K8<>"",Q8>0),SUM(O8:R8),"")) | T8: =IF(A8="","",IF(S8<>"",IF(AND(N(J8)>0,Parametros!$B$27=0),"Lista (sin costo de impresión)","Lista"),IF(F8="","Tela. ","")&IF(NOT(ISNUMBER(G8)),"Kg de tela. ","")&IF(AND(F8<>"",NOT(ISNUMBER(IFERROR(INDEX(Precios!$D$5:$D$120,MATCH(F8,Precios!$A$5:$A$120,0)),"x")))),"Tela sin precio. ","")&IF(J8="","Metros impresos. ","")&IF(K8="","Confección. ",IF(Q8=0,"Confección sin valor. ","")))) -> Metros impresos.
A9: 05 · FUTMUJV01 | B9: Fútbol, cuello v | C9: Fútbol | D9: Camiseta | E9: Femenino | K9: Camiseta De Futbol | M9: Por confirmar | N9: Confección sugerida por el tipo de molde: confirmar. | O9: =IF(A9="","",IFERROR(G9*INDEX(Precios!$D$5:$D$120,MATCH(F9,Precios!$A$5:$A$120,0)),0)+IF(H9="",0,IFERROR(I9*INDEX(Precios!$D$5:$D$120,MATCH(H9,Precios!$A$5:$A$120,0)),0))) -> 0 | P9: =IF(A9="","",N(J9)*Parametros!$B$27) -> 0 | Q9: =IF(A9="","",IFERROR(INDEX(Confeccion!$B$5:$B$100,MATCH(K9,Confeccion!$A$5:$A$100,0)),0)) -> 2000 | R9: =IF(A9="","",N(L9)) -> 0 | S9: =IF(A9="","",IF(AND(F9<>"",ISNUMBER(G9),ISNUMBER(IFERROR(INDEX(Precios!$D$5:$D$120,MATCH(F9,Precios!$A$5:$A$120,0)),"x")),OR(H9="",ISNUMBER(IFERROR(INDEX(Precios!$D$5:$D$120,MATCH(H9,Precios!$A$5:$A$120,0)),"x"))),J9<>"",K9<>"",Q9>0),SUM(O9:R9),"")) | T9: =IF(A9="","",IF(S9<>"",IF(AND(N(J9)>0,Parametros!$B$27=0),"Lista (sin costo de impresión)","Lista"),IF(F9="","Tela. ","")&IF(NOT(ISNUMBER(G9)),"Kg de tela. ","")&IF(AND(F9<>"",NOT(ISNUMBER(IFERROR(INDEX(Precios!$D$5:$D$120,MATCH(F9,Precios!$A$5:$A$120,0)),"x")))),"Tela sin precio. ","")&IF(J9="","Metros impresos. ","")&IF(K9="","Confección. ",IF(Q9=0,"Confección sin valor. ","")))) -> Tela. Kg de tela. Metros impresos.
A10: 06 · FUTHOMV01 | B10: Fútbol, cuello v | C10: Fútbol | D10: Camiseta | E10: Masculino | K10: Camiseta De Futbol | M10: Por confirmar | N10: Confección sugerida por el tipo de molde: confirmar. | O10: =IF(A10="","",IFERROR(G10*INDEX(Precios!$D$5:$D$120,MATCH(F10,Precios!$A$5:$A$120,0)),0)+IF(H10="",0,IFERROR(I10*INDEX(Precios!$D$5:$D$120,MATCH(H10,Precios!$A$5:$A$120,0)),0))) -> 0 | P10: =IF(A10="","",N(J10)*Parametros!$B$27) -> 0 | Q10: =IF(A10="","",IFERROR(INDEX(Confeccion!$B$5:$B$100,MATCH(K10,Confeccion!$A$5:$A$100,0)),0)) -> 2000 | R10: =IF(A10="","",N(L10)) -> 0 | S10: =IF(A10="","",IF(AND(F10<>"",ISNUMBER(G10),ISNUMBER(IFERROR(INDEX(Precios!$D$5:$D$120,MATCH(F10,Precios!$A$5:$A$120,0)),"x")),OR(H10="",ISNUMBER(IFERROR(INDEX(Precios!$D$5:$D$120,MATCH(H10,Precios!$A$5:$A$120,0)),"x"))),J10<>"",K10<>"",Q10>0),SUM(O10:R10),"")) | T10: =IF(A10="","",IF(S10<>"",IF(AND(N(J10)>0,Parametros!$B$27=0),"Lista (sin costo de impresión)","Lista"),IF(F10="","Tela. ","")&IF(NOT(ISNUMBER(G10)),"Kg de tela. ","")&IF(AND(F10<>"",NOT(ISNUMBER(IFERROR(INDEX(Precios!$D$5:$D$120,MATCH(F10,Precios!$A$5:$A$120,0)),"x")))),"Tela sin precio. ","")&IF(J10="","Metros impresos. ","")&IF(K10="","Confección. ",IF(Q10=0,"Confección sin valor. ","")))) -> Tela. Kg de tela. Metros impresos.
A11: 07 · FUTINMUJV01 | B11: Fútbol infantil, cuello v | C11: Fútbol | D11: Camiseta | E11: Infantil Femenino | K11: Camiseta De Futbol | M11: Por confirmar | N11: Confección sugerida por el tipo de molde: confirmar. | O11: =IF(A11="","",IFERROR(G11*INDEX(Precios!$D$5:$D$120,MATCH(F11,Precios!$A$5:$A$120,0)),0)+IF(H11="",0,IFERROR(I11*INDEX(Precios!$D$5:$D$120,MATCH(H11,Precios!$A$5:$A$120,0)),0))) -> 0 | P11: =IF(A11="","",N(J11)*Parametros!$B$27) -> 0 | Q11: =IF(A11="","",IFERROR(INDEX(Confeccion!$B$5:$B$100,MATCH(K11,Confeccion!$A$5:$A$100,0)),0)) -> 2000 | R11: =IF(A11="","",N(L11)) -> 0 | S11: =IF(A11="","",IF(AND(F11<>"",ISNUMBER(G11),ISNUMBER(IFERROR(INDEX(Precios!$D$5:$D$120,MATCH(F11,Precios!$A$5:$A$120,0)),"x")),OR(H11="",ISNUMBER(IFERROR(INDEX(Precios!$D$5:$D$120,MATCH(H11,Precios!$A$5:$A$120,0)),"x"))),J11<>"",K11<>"",Q11>0),SUM(O11:R11),"")) | T11: =IF(A11="","",IF(S11<>"",IF(AND(N(J11)>0,Parametros!$B$27=0),"Lista (sin costo de impresión)","Lista"),IF(F11="","Tela. ","")&IF(NOT(ISNUMBER(G11)),"Kg de tela. ","")&IF(AND(F11<>"",NOT(ISNUMBER(IFERROR(INDEX(Precios!$D$5:$D$120,MATCH(F11,Precios!$A$5:$A$120,0)),"x")))),"Tela sin precio. ","")&IF(J11="","Metros impresos. ","")&IF(K11="","Confección. ",IF(Q11=0,"Confección sin valor. ","")))) -> Tela. Kg de tela. Metros impresos.
