Workbook

Sheet Como_usar
A1: RECETAS DE COSTO — PLAYMAKER (v5: consumos por molde, costo por tela y resultado mensual)
A2: La receta de un molde guarda solo CONSUMOS. El costo sale al elegir la tela de cada producto. Todo dato dice "Por confirmar" hasta que lo valides.
A4: LA IDEA
B5: Un mismo molde se puede producir en distintas telas: los CONSUMOS son los mismos (metros de tela, metros impresos, confección, avíos), pero el COSTO cambia según la tela.
B6: Por eso el consumo se mide en METROS (no en kg): los mismos metros pesan distinto en cada tela. Cada tela tiene su rendimiento (metros por kg) y de ahí sale su $ por metro.
A7: LAS HOJAS
B8: Recetas — una por molde del catálogo (54) + prendas sin molde. SOLO CONSUMOS. Si tu ficha de corte está en kg, escribe los kg y la tela con que se midió: se convierte solo a metros.
B9: Productos — lo que vendes: eliges el molde, la tela principal y la tela 2 (si lleva). Aquí se calcula el costo, la ganancia, el precio mínimo y el semáforo.
B10: Resultado_mensual — ventas, margen de contribución, gastos fijos, reprocesos, ganancia y punto de equilibrio de cada mes. La hoja para saber si el negocio está ganando.
B11: Precios — precio por kg y RENDIMIENTO (metros por kg) de cada tela → $ por metro. Avíos por unidad.
B12: Confeccion — valor del taller por tipo de prenda. Parametros / Gastos_Ventas — recargo de gastos fijos y meta. Catalogo — cobertura.
A13: CÓMO SACAR EL RENDIMIENTO DE UNA TELA (metros por kg)
B14: Toma un rollo: metros del rollo ÷ kg del rollo. Ej: rollo de 25 kg con 127 metros → 127 ÷ 25 = 5,08 m/kg. Muchas veces viene en la ficha del proveedor.
B15: Ojo: los metros por prenda se miden con el ancho de tela habitual. Si una tela es mucho más angosta o ancha, la tizada cambia: en ese caso conviene una receta aparte.
A16: CÓMO SACAR EL CONSUMO DE UN MOLDE
B17: De la ficha de corte: metros (o kg) de tela usados ÷ prendas cortadas. Si mides en metros, escríbelo en "Metros por prenda (directo)" y tiene prioridad sobre los kg.
A18: PENDIENTES QUE AFECTAN LOS RESULTADOS
B19: ="• Papel y tinta: "&IF(Parametros!$B$27=0,"SIN DATO → las prendas sublimadas salen más baratas de lo real.","ingresado ("&TEXT(Parametros!$B$27,"$#,##0")&" por metro).") -> • Papel y tinta: SIN DATO → las prendas sublimadas salen más baratas de lo real.
B20: ="• Telas con rendimiento cargado: "&COUNT(Precios!E5:E120)&" de "&COUNTIF(Precios!B5:B120,"Tela")&". Sin rendimiento, una tela no tiene $ por metro." -> • Telas con rendimiento cargado: 4 de 33. Sin rendimiento, una tela no tiene $ por metro.
B21: ="• Recetas (moldes) listas: "&COUNTIF(Recetas!T5:T84,"Lista")&" de "&COUNTA(Recetas!A5:A84) -> • Recetas (moldes) listas: 1 de 59
B22: ="• Productos con costo completo: "&COUNTIF(Catalogo!F6:F200,"Completa")&" · con datos faltantes: "&COUNTIF(Catalogo!F6:F200,"Faltan datos") -> • Productos con costo completo: 1 · con datos faltantes: 73
B23: • Gastos: el archivo original trae un solo mes; se repitió en los 3 meses. Reemplazar con el gasto real.

Sheet Resultado_mensual
A1: RESULTADO MENSUAL — ¿el negocio está ganando?
A2: Ventas − costo variable = margen de contribución. Margen − gastos fijos − reprocesos = ganancia del mes. Llena las celdas azules de cada mes.
A4: Concepto | B4: Jun-2026 | C4: Jul-2026 | D4: Ago-2026 | E4: Sep-2026 | F4: Oct-2026 | G4: Nov-2026 | H4: Dic-2026 | I4: Promedio (meses con ventas) | J4: De dónde sale
A5: Ventas netas ($) | B5: 32768213 | C5: 38874120 | D5: 33942186 | I5: =IFERROR(AVERAGEIF(B5:H5,">0",B5:H5),"") -> 35194840 | J5: Export de Parrotfy (Neto $). Septiembre: completar (el export llegaba solo hasta el día 5).
A6: Unidades vendidas | B6: 2176 | C6: 2037 | D6: 2034 | I6: =IFERROR(AVERAGEIF(B5:H5,">0",B6:H6),"") -> 2082.3333 | J6: Opcional. Jun–ago: líneas del export (incluye adicionales como escudos y cuellos).
A7: Costo variable REAL del mes ($) — opcional | I7: =IFERROR(AVERAGEIF(B5:H5,">0",B7:H7),"") | J7: Si sabes lo gastado en tela, papel, tinta, talleres y avíos del mes, escríbelo. Si no, se estima con el % de abajo.
A8: Costo variable usado ($) | B8: =IF(ISNUMBER(B7),B7,IF(AND(ISNUMBER(B5),ISNUMBER($B$24)),B5*$B$24,"")) | C8: =IF(ISNUMBER(C7),C7,IF(AND(ISNUMBER(C5),ISNUMBER($B$24)),C5*$B$24,"")) | D8: =IF(ISNUMBER(D7),D7,IF(AND(ISNUMBER(D5),ISNUMBER($B$24)),D5*$B$24,"")) | E8: =IF(ISNUMBER(E7),E7,IF(AND(ISNUMBER(E5),ISNUMBER($B$24)),E5*$B$24,"")) | F8: =IF(ISNUMBER(F7),F7,IF(AND(ISNUMBER(F5),ISNUMBER($B$24)),F5*$B$24,"")) | G8: =IF(ISNUMBER(G7),G7,IF(AND(ISNUMBER(G5),ISNUMBER($B$24)),G5*$B$24,"")) | H8: =IF(ISNUMBER(H7),H7,IF(AND(ISNUMBER(H5),ISNUMBER($B$24)),H5*$B$24,"")) | I8: =IFERROR(AVERAGEIF(B5:H5,">0",B8:H8),"") | J8: Real si lo escribiste; si no, ventas × costo variable promedio (fila 24). Vacío = todavía no hay un costo variable confiable.
A9: MARGEN DE CONTRIBUCIÓN ($) | B9: =IF(AND(ISNUMBER(B5),ISNUMBER(B8)),B5-B8,"") | C9: =IF(AND(ISNUMBER(C5),ISNUMBER(C8)),C5-C8,"") | D9: =IF(AND(ISNUMBER(D5),ISNUMBER(D8)),D5-D8,"") | E9: =IF(AND(ISNUMBER(E5),ISNUMBER(E8)),E5-E8,"") | F9: =IF(AND(ISNUMBER(F5),ISNUMBER(F8)),F5-F8,"") | G9: =IF(AND(ISNUMBER(G5),ISNUMBER(G8)),G5-G8,"") | H9: =IF(AND(ISNUMBER(H5),ISNUMBER(H8)),H5-H8,"") | I9: =IFERROR(AVERAGEIF(B5:H5,">0",B9:H9),"") | J9: Lo que dejan las ventas para pagar los gastos fijos.
A10: Margen de contribución (%) | B10: =IF(AND(N(B5)>0,ISNUMBER(B9)),B9/B5,"") | C10: =IF(AND(N(C5)>0,ISNUMBER(C9)),C9/C5,"") | D10: =IF(AND(N(D5)>0,ISNUMBER(D9)),D9/D5,"") | E10: =IF(AND(N(E5)>0,ISNUMBER(E9)),E9/E5,"") | F10: =IF(AND(N(F5)>0,ISNUMBER(F9)),F9/F5,"") | G10: =IF(AND(N(G5)>0,ISNUMBER(G9)),G9/G5,"") | H10: =IF(AND(N(H5)>0,ISNUMBER(H9)),H9/H5,"") | I10: =IFERROR(AVERAGEIF(B5:H5,">0",B10:H10),"")
A11: Gastos fijos del mes ($) | B11: 16880958 | C11: 16880958 | D11: 16880958 | I11: =IFERROR(AVERAGEIF(B5:H5,">0",B11:H11),"") -> 16880958 | J11: Jun–ago: hoja Gastos_Ventas (un solo mes repetido: reemplazar con el real). Desde septiembre: escribir el del mes.
A12: Reprocesos del mes ($) | B12: 1288500 | C12: 1723950 | D12: 1231200 | E12: 2304450 | I12: =IFERROR(AVERAGEIF(B5:H5,">0",B12:H12),"") -> 1414550 | J12: PMK_Maestro_2026, hoja Resumen_Mensual (costo estimado de reprocesos).
A13: Reprocesos (% de las ventas) | B13: =IF(AND(N(B5)>0,ISNUMBER(B12)),B12/B5,"") -> 0.039321644 | C13: =IF(AND(N(C5)>0,ISNUMBER(C12)),C12/C5,"") -> 0.044346985 | D13: =IF(AND(N(D5)>0,ISNUMBER(D12)),D12/D5,"") -> 0.036273444 | E13: =IF(AND(N(E5)>0,ISNUMBER(E12)),E12/E5,"") | F13: =IF(AND(N(F5)>0,ISNUMBER(F12)),F12/F5,"") | G13: =IF(AND(N(G5)>0,ISNUMBER(G12)),G12/G5,"") | H13: =IF(AND(N(H5)>0,ISNUMBER(H12)),H12/H5,"") | I13: =IFERROR(AVERAGEIF(B5:H5,">0",B13:H13),"") -> 0.039980691 | J13: Plata que se pierde por rehacer. Meta sugerida: bajo 2%.
A14: GANANCIA DEL MES ($) | B14: =IF(AND(ISNUMBER(B9),ISNUMBER(B11)),B9-B11-N(B12),"") | C14: =IF(AND(ISNUMBER(C9),ISNUMBER(C11)),C9-C11-N(C12),"") | D14: =IF(AND(ISNUMBER(D9),ISNUMBER(D11)),D9-D11-N(D12),"") | E14: =IF(AND(ISNUMBER(E9),ISNUMBER(E11)),E9-E11-N(E12),"") | F14: =IF(AND(ISNUMBER(F9),ISNUMBER(F11)),F9-F11-N(F12),"") | G14: =IF(AND(ISNUMBER(G9),ISNUMBER(G11)),G9-G11-N(G12),"") | H14: =IF(AND(ISNUMBER(H9),ISNUMBER(H11)),H9-H11-N(H12),"") | I14: =IFERROR(AVERAGEIF(B5:H5,">0",B14:H14),"") | J14: Margen de contribución − gastos fijos − reprocesos.
A15: Ganancia (% de las ventas) | B15: =IF(AND(N(B5)>0,ISNUMBER(B14)),B14/B5,"") | C15: =IF(AND(N(C5)>0,ISNUMBER(C14)),C14/C5,"") | D15: =IF(AND(N(D5)>0,ISNUMBER(D14)),D14/D5,"") | E15: =IF(AND(N(E5)>0,ISNUMBER(E14)),E14/E5,"") | F15: =IF(AND(N(F5)>0,ISNUMBER(F14)),F14/F5,"") | G15: =IF(AND(N(G5)>0,ISNUMBER(G14)),G14/G5,"") | H15: =IF(AND(N(H5)>0,ISNUMBER(H14)),H14/H5,"") | I15: =IFERROR(AVERAGEIF(B5:H5,">0",B15:H15),"")
A16: PUNTO DE EQUILIBRIO ($ de venta) | B16: =IF(AND(ISNUMBER(B11),ISNUMBER(B10)),IF(B10>0,(B11+N(B12))/B10,""),"") | C16: =IF(AND(ISNUMBER(C11),ISNUMBER(C10)),IF(C10>0,(C11+N(C12))/C10,""),"") | D16: =IF(AND(ISNUMBER(D11),ISNUMBER(D10)),IF(D10>0,(D11+N(D12))/D10,""),"") | E16: =IF(AND(ISNUMBER(E11),ISNUMBER(E10)),IF(E10>0,(E11+N(E12))/E10,""),"") | F16: =IF(AND(ISNUMBER(F11),ISNUMBER(F10)),IF(F10>0,(F11+N(F12))/F10,""),"") | G16: =IF(AND(ISNUMBER(G11),ISNUMBER(G10)),IF(G10>0,(G11+N(G12))/G10,""),"") | H16: =IF(AND(ISNUMBER(H11),ISNUMBER(H10)),IF(H10>0,(H11+N(H12))/H10,""),"") | I16: =IFERROR(AVERAGEIF(B5:H5,">0",B16:H16),"") | J16: Lo que hay que vender en el mes para no perder (gastos fijos + reprocesos ÷ margen %).
A17: Ventas sobre (o bajo) el equilibrio ($) | B17: =IF(AND(ISNUMBER(B5),ISNUMBER(B16)),B5-B16,"") | C17: =IF(AND(ISNUMBER(C5),ISNUMBER(C16)),C5-C16,"") | D17: =IF(AND(ISNUMBER(D5),ISNUMBER(D16)),D5-D16,"") | E17: =IF(AND(ISNUMBER(E5),ISNUMBER(E16)),E5-E16,"") | F17: =IF(AND(ISNUMBER(F5),ISNUMBER(F16)),F5-F16,"") | G17: =IF(AND(ISNUMBER(G5),ISNUMBER(G16)),G5-G16,"") | H17: =IF(AND(ISNUMBER(H5),ISNUMBER(H16)),H5-H16,"") | I17: =IFERROR(AVERAGEIF(B5:H5,">0",B17:H17),"") | J17: Positivo = vendiste más de lo necesario para cubrir todo.
A18: Resultado | B18: =IF(ISNUMBER(B14),IF(B14>=0,"GANA","PIERDE"),"") | C18: =IF(ISNUMBER(C14),IF(C14>=0,"GANA","PIERDE"),"") | D18: =IF(ISNUMBER(D14),IF(D14>=0,"GANA","PIERDE"),"") | E18: =IF(ISNUMBER(E14),IF(E14>=0,"GANA","PIERDE"),"") | F18: =IF(ISNUMBER(F14),IF(F14>=0,"GANA","PIERDE"),"") | G18: =IF(ISNUMBER(G14),IF(G14>=0,"GANA","PIERDE"),"") | H18: =IF(ISNUMBER(H14),IF(H14>=0,"GANA","PIERDE"),"") | I18: =IF(ISNUMBER(I14),IF(I14>=0,"GANA","PIERDE"),"")
A20: COSTO VARIABLE PROMEDIO (% de la venta) — se usa cuando no escribes el costo variable real del mes
A21: Calculado desde Productos | B21: =IFERROR(SUM(Productos!$Y$6:$Y$110)/SUM(Productos!$Z$6:$Z$110),"") -> 0.11161962 | C21: Costo de producción ÷ precio de venta, ponderado por unidades vendidas, de los productos que ya tienen costo completo.
A22: Unidades vendidas que cubre el cálculo | B22: =IFERROR(SUM(Productos!$AA$6:$AA$110)/SUM(Productos!$D$6:$D$110),0) -> 0.022011514 | C22: Mientras más alto, más confiable. Bajo 50% el promedio todavía no representa bien al negocio.
A23: Costo variable fijado a mano (opcional) | C23: Si tienes una estimación mejor (ej: 25%), escríbela aquí: tiene prioridad sobre el calculado.
A24: COSTO VARIABLE USADO (%) | B24: =IF(ISNUMBER(B23),B23,IF(AND(ISNUMBER(B21),B22>=0.5),B21,"")) | C24: =IF(ISNUMBER(B23),"Usando el valor fijado a mano.",IF(B22<0.5,"⚠ TODAVÍA NO HAY UN COSTO VARIABLE CONFIABLE: el cálculo cubre solo "&TEXT(B22,"0%")&" de las unidades vendidas (necesita 50%) y no incluye papel y tinta. Escribe el costo real del mes (fila 7) o una estimación (fila 23). Mientras, mira la tabla ¿Y si…? de abajo.","Calculado desde Productos (cubre "&TEXT(B22,"0%")&" de lo vendido).")) -> ⚠ TODAVÍA NO HAY UN COSTO VARIABLE CONFIABLE: el cálculo cubre solo 2% de las unidades vendidas (necesita 50%) y no incluye papel y tinta. Escribe el costo real del mes (fila 7) o una estimación (fila 23). Mientras, mira la tabla ¿Y si…? de abajo.
A26: ¿Y SI EL COSTO VARIABLE FUERA…? (mes promedio: ventas, gastos fijos y reprocesos de los meses con datos)
A27: Costo variable (% de la venta) | B27: Margen de contribución | C27: Ganancia del mes | D27: Ganancia (%) | E27: Punto de equilibrio
A28: 0.15 | B28: =IF(ISNUMBER($I$5),$I$5*(1-A28),"") -> 29915614 | C28: =IF(ISNUMBER($I$5),$I$5*(1-A28)-N($I$11)-N($I$12),"") -> 11620106 | D28: =IF(N($I$5)>0,C28/$I$5,"") -> 0.33016504 | E28: =IF(A28<1,(N($I$11)+N($I$12))/(1-A28),"") -> 21524127
A29: 0.2 | B29: =IF(ISNUMBER($I$5),$I$5*(1-A29),"") -> 28155872 | C29: =IF(ISNUMBER($I$5),$I$5*(1-A29)-N($I$11)-N($I$12),"") -> 9860363.7 | D29: =IF(N($I$5)>0,C29/$I$5,"") -> 0.28016504 | E29: =IF(A29<1,(N($I$11)+N($I$12))/(1-A29),"") -> 22869385
A30: 0.25 | B30: =IF(ISNUMBER($I$5),$I$5*(1-A30),"") -> 26396130 | C30: =IF(ISNUMBER($I$5),$I$5*(1-A30)-N($I$11)-N($I$12),"") -> 8100621.8 | D30: =IF(N($I$5)>0,C30/$I$5,"") -> 0.23016504 | E30: =IF(A30<1,(N($I$11)+N($I$12))/(1-A30),"") -> 24394011
A31: 0.3 | B31: =IF(ISNUMBER($I$5),$I$5*(1-A31),"") -> 24636388 | C31: =IF(ISNUMBER($I$5),$I$5*(1-A31)-N($I$11)-N($I$12),"") -> 6340879.8 | D31: =IF(N($I$5)>0,C31/$I$5,"") -> 0.18016504 | E31: =IF(A31<1,(N($I$11)+N($I$12))/(1-A31),"") -> 26136440
A32: 0.35 | B32: =IF(ISNUMBER($I$5),$I$5*(1-A32),"") -> 22876646 | C32: =IF(ISNUMBER($I$5),$I$5*(1-A32)-N($I$11)-N($I$12),"") -> 4581137.8 | D32: =IF(N($I$5)>0,C32/$I$5,"") -> 0.13016504 | E32: =IF(A32<1,(N($I$11)+N($I$12))/(1-A32),"") -> 28146935
A33: 0.4 | B33: =IF(ISNUMBER($I$5),$I$5*(1-A33),"") -> 21116904 | C33: =IF(ISNUMBER($I$5),$I$5*(1-A33)-N($I$11)-N($I$12),"") -> 2821395.8 | D33: =IF(N($I$5)>0,C33/$I$5,"") -> 0.080165042 | E33: =IF(A33<1,(N($I$11)+N($I$12))/(1-A33),"") -> 30492513
A34: 0.45 | B34: =IF(ISNUMBER($I$5),$I$5*(1-A34),"") -> 19357162 | C34: =IF(ISNUMBER($I$5),$I$5*(1-A34)-N($I$11)-N($I$12),"") -> 1061653.8 | D34: =IF(N($I$5)>0,C34/$I$5,"") -> 0.030165042 | E34: =IF(A34<1,(N($I$11)+N($I$12))/(1-A34),"") -> 33264560
A35: Puedes cambiar los % de la primera columna. Con las recetas completas (o el costo real del mes) sabrás en qué fila está el negocio.
A37: CÓMO LEER ESTA HOJA
A38: • MARGEN DE CONTRIBUCIÓN: lo que dejan las ventas después de pagar lo que se gasta por prenda (tela, papel, tinta, taller, avíos). Con él se pagan los gastos fijos.
A39: • PUNTO DE EQUILIBRIO: lo que necesitas vender en el mes para no perder. Si vendes más, el margen de lo que sobra es ganancia.
A40: • REPROCESOS: lo que cuesta rehacer prendas. Sale directo de la ganancia.
A41: • COSTO VARIABLE REAL DEL MES (fila 7): la forma más exacta es sumar las compras del mes de tela, papel, tinta y avíos, más lo pagado a los talleres de confección.
A42: • Para decidir un descuento: mientras el precio cubra el costo variable de la prenda y deje margen, el pedido ayuda a pagar los gastos fijos.

Sheet Productos
A1: PRODUCTOS — costo según el molde y la tela que elijas
A2: Cada producto toma los CONSUMOS de su molde (hoja Recetas) y los valoriza con la TELA que elijas aquí (precio por metro de la hoja Precios). Un mismo molde puede costar distinto según la tela.
A3: ="Recargo usado: "&TEXT(Parametros!$B$14,"0.0%")&" del precio (fábrica "&TEXT(Parametros!$B$12,"0.0%")&" + comercial "&TEXT(Parametros!$B$13,"0.0%")&") · Meta de ganancia: "&TEXT(Parametros!$B$18,"0%")&" · Impresión: "&IF(Parametros!$B$27=0,"SIN COSTO (pendiente)",TEXT(Parametros!$B$27,"$#,##0")&" por metro") -> Recargo usado: 48.0% del precio (fábrica 35.3% + comercial 12.7%) · Meta de ganancia: 10% · Impresión: SIN COSTO (pendiente)
A4: PRODUCTO | E4: LO ELIGES TÚ: molde, tela y precio | L4: COSTO DE PRODUCCIÓN ($ por prenda) | Q4: RESULTADO AL PRECIO ACTUAL
A5: Código | B5: Producto | C5: Tipo | D5: Unid. vendidas jun–sep | E5: Receta (molde) | F5: Tela principal | G5: Tela 2 (si el molde lleva) | H5: Extras ($ por prenda) | I5: Precio venta neto ($) | J5: Estado | K5: Notas | L5: $ Tela | M5: $ Papel y tinta | N5: $ Confección | O5: $ Avíos | P5: COSTO DE PRODUCCIÓN | Q5: Gastos de fábrica | R5: Gastos comerciales | S5: GANANCIA ($) | T5: GANANCIA (%) | U5: Precio mínimo (sin perder) | V5: Precio mínimo (con meta) | W5: Semáforo | X5: Qué falta | Y5: Aux: costo × unid. | Z5: Aux: venta × unid. | AA5: Aux: unid. con costo
A6: FUTCSUBMC | B6: Camiseta Fútbol Playmaker, m/c | C6: Juego | D6: 198 | E6: 02 · FUTHOMU01 | I6: 15994 | J6: Por confirmar | K6: Molde sugerido: fútbol masculino cuello redondo. Confirmar molde y elegir tela. | L6: =IF(OR(B6="",E6=""),"",IFERROR(INDEX(Recetas!$R$5:$R$84,MATCH($E6,Recetas!$A$5:$A$84,0))*IFERROR(INDEX(Precios!$F$5:$F$120,MATCH(F6,Precios!$A$5:$A$120,0)),"")+IF(N(INDEX(Recetas!$S$5:$S$84,MATCH($E6,Recetas!$A$5:$A$84,0)))=0,0,INDEX(Recetas!$S$5:$S$84,MATCH($E6,Recetas!$A$5:$A$84,0))*IFERROR(INDEX(Precios!$F$5:$F$120,MATCH(G6,Precios!$A$5:$A$120,0)),"")),"")) | M6: =IF(OR(B6="",E6=""),"",IFERROR(N(INDEX(Recetas!$L$5:$L$84,MATCH($E6,Recetas!$A$5:$A$84,0)))*Parametros!$B$27,"")) -> 0 | N6: =IF(OR(B6="",E6=""),"",IFERROR(INDEX(Confeccion!$B$5:$B$100,MATCH(INDEX(Recetas!$M$5:$M$84,MATCH($E6,Recetas!$A$5:$A$84,0)),Confeccion!$A$5:$A$100,0)),"")) -> 2000 | O6: =IF(OR(B6="",E6=""),"",IFERROR(N(INDEX(Recetas!$O$5:$O$84,MATCH($E6,Recetas!$A$5:$A$84,0)))*INDEX(Precios!$D$5:$D$120,MATCH(INDEX(Recetas!$N$5:$N$84,MATCH($E6,Recetas!$A$5:$A$84,0)),Precios!$A$5:$A$120,0)),0)) -> 0 | P6: =IF(OR(B6="",E6=""),"",IF(AND(IFERROR(INDEX(Recetas!$T$5:$T$84,MATCH($E6,Recetas!$A$5:$A$84,0))="Lista",FALSE()),ISNUMBER(L6),ISNUMBER(M6),ISNUMBER(N6),N(N6)>0),L6+M6+N6+N(O6)+N(H6),"")) | Q6: =IF(AND(ISNUMBER(P6),ISNUMBER(I6)),I6*Parametros!$B$12,"") | R6: =IF(AND(ISNUMBER(P6),ISNUMBER(I6)),I6*Parametros!$B$13,"") | S6: =IF(AND(ISNUMBER(P6),ISNUMBER(I6)),I6-P6-Q6-R6,"") | T6: =IF(AND(ISNUMBER(P6),ISNUMBER(I6)),S6/I6,"") | U6: =IF(OR(NOT(ISNUMBER(P6)),Parametros!$B$14>=1),"",P6/(1-Parametros!$B$14)) | V6: =IF(OR(NOT(ISNUMBER(P6)),Parametros!$B$14+Parametros!$B$18>=1),"",P6/(1-Parametros!$B$14-Parametros!$B$18)) | W6: =IF(B6="","",IF(E6="","SIN RECETA",IF(NOT(ISNUMBER(P6)),"FALTAN DATOS",IF(NOT(ISNUMBER(I6)),"FALTA PRECIO",IF(S6<0,"PIERDE",IF(T6<Parametros!$B$18,"BAJO META","OK")))))) -> FALTAN DATOS | X6: =IF(B6="","",IF(E6="","Elegir receta (molde). ",IF(ISNA(MATCH(E6,Recetas!$A$5:$A$84,0)),"La receta no existe. ",IF(IFERROR(INDEX(Recetas!$T$5:$T$84,MATCH($E6,Recetas!$A$5:$A$84,0))="Lista",FALSE()),"","Receta "&E6&": "&INDEX(Recetas!$T$5:$T$84,MATCH($E6,Recetas!$A$5:$A$84,0)))))&IF(F6="","Elegir tela. ",IF(IFERROR(INDEX(Precios!$F$5:$F$120,MATCH(F6,Precios!$A$5:$A$120,0)),"")="","Tela sin $/metro (falta rendimiento o precio). ",""))&IF(AND(E6<>"",N(IFERROR(INDEX(Recetas!$S$5:$S$84,MATCH($E6,Recetas!$A$5:$A$84,0)),0))>0,G6=""),"Elegir tela 2. ","")&IF(NOT(ISNUMBER(I6)),"Precio de venta.","")) -> Receta 02 · FUTHOMU01: Consumo de tela. Metros impresos. Elegir tela. | Y6: =IF(AND(ISNUMBER(P6),ISNUMBER(I6),ISNUMBER(D6)),P6*D6,0) -> 0 | Z6: =IF(AND(ISNUMBER(P6),ISNUMBER(I6),ISNUMBER(D6)),I6*D6,0) -> 0 | AA6: =IF(AND(ISNUMBER(P6),ISNUMBER(I6),ISNUMBER(D6)),D6,0) -> 0
A7: FUTCSUBREDMC | B7: Camiseta Fútbol Playmaker Cuello Redondo m/c | C7: Juego | D7: 190 | E7: 02 · FUTHOMU01 | I7: 16073 | J7: Por confirmar | K7: Molde sugerido. Elegir tela. | L7: =IF(OR(B7="",E7=""),"",IFERROR(INDEX(Recetas!$R$5:$R$84,MATCH($E7,Recetas!$A$5:$A$84,0))*IFERROR(INDEX(Precios!$F$5:$F$120,MATCH(F7,Precios!$A$5:$A$120,0)),"")+IF(N(INDEX(Recetas!$S$5:$S$84,MATCH($E7,Recetas!$A$5:$A$84,0)))=0,0,INDEX(Recetas!$S$5:$S$84,MATCH($E7,Recetas!$A$5:$A$84,0))*IFERROR(INDEX(Precios!$F$5:$F$120,MATCH(G7,Precios!$A$5:$A$120,0)),"")),"")) | M7: =IF(OR(B7="",E7=""),"",IFERROR(N(INDEX(Recetas!$L$5:$L$84,MATCH($E7,Recetas!$A$5:$A$84,0)))*Parametros!$B$27,"")) -> 0 | N7: =IF(OR(B7="",E7=""),"",IFERROR(INDEX(Confeccion!$B$5:$B$100,MATCH(INDEX(Recetas!$M$5:$M$84,MATCH($E7,Recetas!$A$5:$A$84,0)),Confeccion!$A$5:$A$100,0)),"")) -> 2000 | O7: =IF(OR(B7="",E7=""),"",IFERROR(N(INDEX(Recetas!$O$5:$O$84,MATCH($E7,Recetas!$A$5:$A$84,0)))*INDEX(Precios!$D$5:$D$120,MATCH(INDEX(Recetas!$N$5:$N$84,MATCH($E7,Recetas!$A$5:$A$84,0)),Precios!$A$5:$A$120,0)),0)) -> 0 | P7: =IF(OR(B7="",E7=""),"",IF(AND(IFERROR(INDEX(Recetas!$T$5:$T$84,MATCH($E7,Recetas!$A$5:$A$84,0))="Lista",FALSE()),ISNUMBER(L7),ISNUMBER(M7),ISNUMBER(N7),N(N7)>0),L7+M7+N7+N(O7)+N(H7),"")) | Q7: =IF(AND(ISNUMBER(P7),ISNUMBER(I7)),I7*Parametros!$B$12,"") | R7: =IF(AND(ISNUMBER(P7),ISNUMBER(I7)),I7*Parametros!$B$13,"") | S7: =IF(AND(ISNUMBER(P7),ISNUMBER(I7)),I7-P7-Q7-R7,"") | T7: =IF(AND(ISNUMBER(P7),ISNUMBER(I7)),S7/I7,"") | U7: =IF(OR(NOT(ISNUMBER(P7)),Parametros!$B$14>=1),"",P7/(1-Parametros!$B$14)) | V7: =IF(OR(NOT(ISNUMBER(P7)),Parametros!$B$14+Parametros!$B$18>=1),"",P7/(1-Parametros!$B$14-Parametros!$B$18)) | W7: =IF(B7="","",IF(E7="","SIN RECETA",IF(NOT(ISNUMBER(P7)),"FALTAN DATOS",IF(NOT(ISNUMBER(I7)),"FALTA PRECIO",IF(S7<0,"PIERDE",IF(T7<Parametros!$B$18,"BAJO META","OK")))))) -> FALTAN DATOS | X7: =IF(B7="","",IF(E7="","Elegir receta (molde). ",IF(ISNA(MATCH(E7,Recetas!$A$5:$A$84,0)),"La receta no existe. ",IF(IFERROR(INDEX(Recetas!$T$5:$T$84,MATCH($E7,Recetas!$A$5:$A$84,0))="Lista",FALSE()),"","Receta "&E7&": "&INDEX(Recetas!$T$5:$T$84,MATCH($E7,Recetas!$A$5:$A$84,0)))))&IF(F7="","Elegir tela. ",IF(IFERROR(INDEX(Precios!$F$5:$F$120,MATCH(F7,Precios!$A$5:$A$120,0)),"")="","Tela sin $/metro (falta rendimiento o precio). ",""))&IF(AND(E7<>"",N(IFERROR(INDEX(Recetas!$S$5:$S$84,MATCH($E7,Recetas!$A$5:$A$84,0)),0))>0,G7=""),"Elegir tela 2. ","")&IF(NOT(ISNUMBER(I7)),"Precio de venta.","")) -> Receta 02 · FUTHOMU01: Consumo de tela. Metros impresos. Elegir tela. | Y7: =IF(AND(ISNUMBER(P7),ISNUMBER(I7),ISNUMBER(D7)),P7*D7,0) -> 0 | Z7: =IF(AND(ISNUMBER(P7),ISNUMBER(I7),ISNUMBER(D7)),I7*D7,0) -> 0 | AA7: =IF(AND(ISNUMBER(P7),ISNUMBER(I7),ISNUMBER(D7)),D7,0) -> 0
A8: FUTCSUBPROREDMC | B8: Camiseta Fútbol Pro Playmaker Cuello Redondo m/c | C8: Juego | D8: 160 | E8: 14 · FUTHOMU01PRO | F8: MONTESIMONE TRAINING (fut pro) | G8: MESH | I8: 18403 | J8: Por confirmar | K8: Tela de la ficha OT 2547. | L8: =IF(OR(B8="",E8=""),"",IFERROR(INDEX(Recetas!$R$5:$R$84,MATCH($E8,Recetas!$A$5:$A$84,0))*IFERROR(INDEX(Precios!$F$5:$F$120,MATCH(F8,Precios!$A$5:$A$120,0)),"")+IF(N(INDEX(Recetas!$S$5:$S$84,MATCH($E8,Recetas!$A$5:$A$84,0)))=0,0,INDEX(Recetas!$S$5:$S$84,MATCH($E8,Recetas!$A$5:$A$84,0))*IFERROR(INDEX(Precios!$F$5:$F$120,MATCH(G8,Precios!$A$5:$A$120,0)),"")),"")) -> 423.72 | M8: =IF(OR(B8="",E8=""),"",IFERROR(N(INDEX(Recetas!$L$5:$L$84,MATCH($E8,Recetas!$A$5:$A$84,0)))*Parametros!$B$27,"")) -> 0 | N8: =IF(OR(B8="",E8=""),"",IFERROR(INDEX(Confeccion!$B$5:$B$100,MATCH(INDEX(Recetas!$M$5:$M$84,MATCH($E8,Recetas!$A$5:$A$84,0)),Confeccion!$A$5:$A$100,0)),"")) -> 2000 | O8: =IF(OR(B8="",E8=""),"",IFERROR(N(INDEX(Recetas!$O$5:$O$84,MATCH($E8,Recetas!$A$5:$A$84,0)))*INDEX(Precios!$D$5:$D$120,MATCH(INDEX(Recetas!$N$5:$N$84,MATCH($E8,Recetas!$A$5:$A$84,0)),Precios!$A$5:$A$120,0)),0)) -> 0 | P8: =IF(OR(B8="",E8=""),"",IF(AND(IFERROR(INDEX(Recetas!$T$5:$T$84,MATCH($E8,Recetas!$A$5:$A$84,0))="Lista",FALSE()),ISNUMBER(L8),ISNUMBER(M8),ISNUMBER(N8),N(N8)>0),L8+M8+N8+N(O8)+N(H8),"")) | Q8: =IF(AND(ISNUMBER(P8),ISNUMBER(I8)),I8*Parametros!$B$12,"") | R8: =IF(AND(ISNUMBER(P8),ISNUMBER(I8)),I8*Parametros!$B$13,"") | S8: =IF(AND(ISNUMBER(P8),ISNUMBER(I8)),I8-P8-Q8-R8,"") | T8: =IF(AND(ISNUMBER(P8),ISNUMBER(I8)),S8/I8,"") | U8: =IF(OR(NOT(ISNUMBER(P8)),Parametros!$B$14>=1),"",P8/(1-Parametros!$B$14)) | V8: =IF(OR(NOT(ISNUMBER(P8)),Parametros!$B$14+Parametros!$B$18>=1),"",P8/(1-Parametros!$B$14-Parametros!$B$18)) | W8: =IF(B8="","",IF(E8="","SIN RECETA",IF(NOT(ISNUMBER(P8)),"FALTAN DATOS",IF(NOT(ISNUMBER(I8)),"FALTA PRECIO",IF(S8<0,"PIERDE",IF(T8<Parametros!$B$18,"BAJO META","OK")))))) -> FALTAN DATOS | X8: =IF(B8="","",IF(E8="","Elegir receta (molde). ",IF(ISNA(MATCH(E8,Recetas!$A$5:$A$84,0)),"La receta no existe. ",IF(IFERROR(INDEX(Recetas!$T$5:$T$84,MATCH($E8,Recetas!$A$5:$A$84,0))="Lista",FALSE()),"","Receta "&E8&": "&INDEX(Recetas!$T$5:$T$84,MATCH($E8,Recetas!$A$5:$A$84,0)))))&IF(F8="","Elegir tela. ",IF(IFERROR(INDEX(Precios!$F$5:$F$120,MATCH(F8,Precios!$A$5:$A$120,0)),"")="","Tela sin $/metro (falta rendimiento o precio). ",""))&IF(AND(E8<>"",N(IFERROR(INDEX(Recetas!$S$5:$S$84,MATCH($E8,Recetas!$A$5:$A$84,0)),0))>0,G8=""),"Elegir tela 2. ","")&IF(NOT(ISNUMBER(I8)),"Precio de venta.","")) -> Receta 14 · FUTHOMU01PRO: Rendimiento de MESH (m/kg) en Precios. | Y8: =IF(AND(ISNUMBER(P8),ISNUMBER(I8),ISNUMBER(D8)),P8*D8,0) -> 0 | Z8: =IF(AND(ISNUMBER(P8),ISNUMBER(I8),ISNUMBER(D8)),I8*D8,0) -> 0 | AA8: =IF(AND(ISNUMBER(P8),ISNUMBER(I8),ISNUMBER(D8)),D8,0) -> 0
A9: VOLMASC-CSUB-V-MC | B9: Camiseta Voley fem Playmaker, V m/c | C9: Juego | D9: 139 | I9: 17563 | J9: Por confirmar | K9: Sin receta: elige el molde que usa (o crea su receta en "Recetas") y la tela. | L9: =IF(OR(B9="",E9=""),"",IFERROR(INDEX(Recetas!$R$5:$R$84,MATCH($E9,Recetas!$A$5:$A$84,0))*IFERROR(INDEX(Precios!$F$5:$F$120,MATCH(F9,Precios!$A$5:$A$120,0)),"")+IF(N(INDEX(Recetas!$S$5:$S$84,MATCH($E9,Recetas!$A$5:$A$84,0)))=0,0,INDEX(Recetas!$S$5:$S$84,MATCH($E9,Recetas!$A$5:$A$84,0))*IFERROR(INDEX(Precios!$F$5:$F$120,MATCH(G9,Precios!$A$5:$A$120,0)),"")),"")) | M9: =IF(OR(B9="",E9=""),"",IFERROR(N(INDEX(Recetas!$L$5:$L$84,MATCH($E9,Recetas!$A$5:$A$84,0)))*Parametros!$B$27,"")) | N9: =IF(OR(B9="",E9=""),"",IFERROR(INDEX(Confeccion!$B$5:$B$100,MATCH(INDEX(Recetas!$M$5:$M$84,MATCH($E9,Recetas!$A$5:$A$84,0)),Confeccion!$A$5:$A$100,0)),"")) | O9: =IF(OR(B9="",E9=""),"",IFERROR(N(INDEX(Recetas!$O$5:$O$84,MATCH($E9,Recetas!$A$5:$A$84,0)))*INDEX(Precios!$D$5:$D$120,MATCH(INDEX(Recetas!$N$5:$N$84,MATCH($E9,Recetas!$A$5:$A$84,0)),Precios!$A$5:$A$120,0)),0)) | P9: =IF(OR(B9="",E9=""),"",IF(AND(IFERROR(INDEX(Recetas!$T$5:$T$84,MATCH($E9,Recetas!$A$5:$A$84,0))="Lista",FALSE()),ISNUMBER(L9),ISNUMBER(M9),ISNUMBER(N9),N(N9)>0),L9+M9+N9+N(O9)+N(H9),"")) | Q9: =IF(AND(ISNUMBER(P9),ISNUMBER(I9)),I9*Parametros!$B$12,"") | R9: =IF(AND(ISNUMBER(P9),ISNUMBER(I9)),I9*Parametros!$B$13,"") | S9: =IF(AND(ISNUMBER(P9),ISNUMBER(I9)),I9-P9-Q9-R9,"") | T9: =IF(AND(ISNUMBER(P9),ISNUMBER(I9)),S9/I9,"") | U9: =IF(OR(NOT(ISNUMBER(P9)),Parametros!$B$14>=1),"",P9/(1-Parametros!$B$14)) | V9: =IF(OR(NOT(ISNUMBER(P9)),Parametros!$B$14+Parametros!$B$18>=1),"",P9/(1-Parametros!$B$14-Parametros!$B$18)) | W9: =IF(B9="","",IF(E9="","SIN RECETA",IF(NOT(ISNUMBER(P9)),"FALTAN DATOS",IF(NOT(ISNUMBER(I9)),"FALTA PRECIO",IF(S9<0,"PIERDE",IF(T9<Parametros!$B$18,"BAJO META","OK")))))) -> SIN RECETA | X9: =IF(B9="","",IF(E9="","Elegir receta (molde). ",IF(ISNA(MATCH(E9,Recetas!$A$5:$A$84,0)),"La receta no existe. ",IF(IFERROR(INDEX(Recetas!$T$5:$T$84,MATCH($E9,Recetas!$A$5:$A$84,0))="Lista",FALSE()),"","Receta "&E9&": "&INDEX(Recetas!$T$5:$T$84,MATCH($E9,Recetas!$A$5:$A$84,0)))))&IF(F9="","Elegir tela. ",IF(IFERROR(INDEX(Precios!$F$5:$F$120,MATCH(F9,Precios!$A$5:$A$120,0)),"")="","Tela sin $/metro (falta rendimiento o precio). ",""))&IF(AND(E9<>"",N(IFERROR(INDEX(Recetas!$S$5:$S$84,MATCH($E9,Recetas!$A$5:$A$84,0)),0))>0,G9=""),"Elegir tela 2. ","")&IF(NOT(ISNUMBER(I9)),"Precio de venta.","")) -> Elegir receta (molde). Elegir tela. | Y9: =IF(AND(ISNUMBER(P9),ISNUMBER(I9),ISNUMBER(D9)),P9*D9,0) -> 0 | Z9: =IF(AND(ISNUMBER(P9),ISNUMBER(I9),ISNUMBER(D9)),I9*D9,0) -> 0 | AA9: =IF(AND(ISNUMBER(P9),ISNUMBER(I9),ISNUMBER(D9)),D9,0) -> 0
A10: FUTCSUBPROMC | B10: Camiseta Fútbol Pro Playmaker, m/c | C10: Juego | D10: 109 | E10: 14 · FUTHOMU01PRO | F10: MONTESIMONE TRAINING (fut pro) | G10: MESH | I10: 18403 | J10: Por confirmar | K10: Molde Pro sugerido. Tela de la ficha OT 2547. | L10: =IF(OR(B10="",E10=""),"",IFERROR(INDEX(Recetas!$R$5:$R$84,MATCH($E10,Recetas!$A$5:$A$84,0))*IFERROR(INDEX(Precios!$F$5:$F$120,MATCH(F10,Precios!$A$5:$A$120,0)),"")+IF(N(INDEX(Recetas!$S$5:$S$84,MATCH($E10,Recetas!$A$5:$A$84,0)))=0,0,INDEX(Recetas!$S$5:$S$84,MATCH($E10,Recetas!$A$5:$A$84,0))*IFERROR(INDEX(Precios!$F$5:$F$120,MATCH(G10,Precios!$A$5:$A$120,0)),"")),"")) -> 423.72 | M10: =IF(OR(B10="",E10=""),"",IFERROR(N(INDEX(Recetas!$L$5:$L$84,MATCH($E10,Recetas!$A$5:$A$84,0)))*Parametros!$B$27,"")) -> 0 | N10: =IF(OR(B10="",E10=""),"",IFERROR(INDEX(Confeccion!$B$5:$B$100,MATCH(INDEX(Recetas!$M$5:$M$84,MATCH($E10,Recetas!$A$5:$A$84,0)),Confeccion!$A$5:$A$100,0)),"")) -> 2000 | O10: =IF(OR(B10="",E10=""),"",IFERROR(N(INDEX(Recetas!$O$5:$O$84,MATCH($E10,Recetas!$A$5:$A$84,0)))*INDEX(Precios!$D$5:$D$120,MATCH(INDEX(Recetas!$N$5:$N$84,MATCH($E10,Recetas!$A$5:$A$84,0)),Precios!$A$5:$A$120,0)),0)) -> 0 | P10: =IF(OR(B10="",E10=""),"",IF(AND(IFERROR(INDEX(Recetas!$T$5:$T$84,MATCH($E10,Recetas!$A$5:$A$84,0))="Lista",FALSE()),ISNUMBER(L10),ISNUMBER(M10),ISNUMBER(N10),N(N10)>0),L10+M10+N10+N(O10)+N(H10),"")) | Q10: =IF(AND(ISNUMBER(P10),ISNUMBER(I10)),I10*Parametros!$B$12,"") | R10: =IF(AND(ISNUMBER(P10),ISNUMBER(I10)),I10*Parametros!$B$13,"") | S10: =IF(AND(ISNUMBER(P10),ISNUMBER(I10)),I10-P10-Q10-R10,"") | T10: =IF(AND(ISNUMBER(P10),ISNUMBER(I10)),S10/I10,"") | U10: =IF(OR(NOT(ISNUMBER(P10)),Parametros!$B$14>=1),"",P10/(1-Parametros!$B$14)) | V10: =IF(OR(NOT(ISNUMBER(P10)),Parametros!$B$14+Parametros!$B$18>=1),"",P10/(1-Parametros!$B$14-Parametros!$B$18)) | W10: =IF(B10="","",IF(E10="","SIN RECETA",IF(NOT(ISNUMBER(P10)),"FALTAN DATOS",IF(NOT(ISNUMBER(I10)),"FALTA PRECIO",IF(S10<0,"PIERDE",IF(T10<Parametros!$B$18,"BAJO META","OK")))))) -> FALTAN DATOS | X10: =IF(B10="","",IF(E10="","Elegir receta (molde). ",IF(ISNA(MATCH(E10,Recetas!$A$5:$A$84,0)),"La receta no existe. ",IF(IFERROR(INDEX(Recetas!$T$5:$T$84,MATCH($E10,Recetas!$A$5:$A$84,0))="Lista",FALSE()),"","Receta "&E10&": "&INDEX(Recetas!$T$5:$T$84,MATCH($E10,Recetas!$A$5:$A$84,0)))))&IF(F10="","Elegir tela. ",IF(IFERROR(INDEX(Precios!$F$5:$F$120,MATCH(F10,Precios!$A$5:$A$120,0)),"")="","Tela sin $/metro (falta rendimiento o precio). ",""))&IF(AND(E10<>"",N(IFERROR(INDEX(Recetas!$S$5:$S$84,MATCH($E10,Recetas!$A$5:$A$84,0)),0))>0,G10=""),"Elegir tela 2. ","")&IF(NOT(ISNUMBER(I10)),"Precio de venta.","")) -> Receta 14 · FUTHOMU01PRO: Rendimiento de MESH (m/kg) en Precios. | Y10: =IF(AND(ISNUMBER(P10),ISNUMBER(I10),ISNUMBER(D10)),P10*D10,0) -> 0 | Z10: =IF(AND(ISNUMBER(P10),ISNUMBER(I10),ISNUMBER(D10)),I10*D10,0) -> 0 | AA10: =IF(AND(ISNUMBER(P10),ISNUMBER(I10),ISNUMBER(D10)),D10,0) -> 0
A11: FUTCSUBMC-V | B11: Camiseta Fútbol Playmaker, V m/c | C11: Juego | D11: 109 | E11: 06 · FUTHOMV01 | I11: 16589 | J11: Por confirmar | K11: Molde sugerido: cuello V. Elegir tela. | L11: =IF(OR(B11="",E11=""),"",IFERROR(INDEX(Recetas!$R$5:$R$84,MATCH($E11,Recetas!$A$5:$A$84,0))*IFERROR(INDEX(Precios!$F$5:$F$120,MATCH(F11,Precios!$A$5:$A$120,0)),"")+IF(N(INDEX(Recetas!$S$5:$S$84,MATCH($E11,Recetas!$A$5:$A$84,0)))=0,0,INDEX(Recetas!$S$5:$S$84,MATCH($E11,Recetas!$A$5:$A$84,0))*IFERROR(INDEX(Precios!$F$5:$F$120,MATCH(G11,Precios!$A$5:$A$120,0)),"")),"")) | M11: =IF(OR(B11="",E11=""),"",IFERROR(N(INDEX(Recetas!$L$5:$L$84,MATCH($E11,Recetas!$A$5:$A$84,0)))*Parametros!$B$27,"")) -> 0 | N11: =IF(OR(B11="",E11=""),"",IFERROR(INDEX(Confeccion!$B$5:$B$100,MATCH(INDEX(Recetas!$M$5:$M$84,MATCH($E11,Recetas!$A$5:$A$84,0)),Confeccion!$A$5:$A$100,0)),"")) -> 2000 | O11: =IF(OR(B11="",E11=""),"",IFERROR(N(INDEX(Recetas!$O$5:$O$84,MATCH($E11,Recetas!$A$5:$A$84,0)))*INDEX(Precios!$D$5:$D$120,MATCH(INDEX(Recetas!$N$5:$N$84,MATCH($E11,Recetas!$A$5:$A$84,0)),Precios!$A$5:$A$120,0)),0)) -> 0 | P11: =IF(OR(B11="",E11=""),"",IF(AND(IFERROR(INDEX(Recetas!$T$5:$T$84,MATCH($E11,Recetas!$A$5:$A$84,0))="Lista",FALSE()),ISNUMBER(L11),ISNUMBER(M11),ISNUMBER(N11),N(N11)>0),L11+M11+N11+N(O11)+N(H11),"")) | Q11: =IF(AND(ISNUMBER(P11),ISNUMBER(I11)),I11*Parametros!$B$12,"") | R11: =IF(AND(ISNUMBER(P11),ISNUMBER(I11)),I11*Parametros!$B$13,"") | S11: =IF(AND(ISNUMBER(P11),ISNUMBER(I11)),I11-P11-Q11-R11,"") | T11: =IF(AND(ISNUMBER(P11),ISNUMBER(I11)),S11/I11,"") | U11: =IF(OR(NOT(ISNUMBER(P11)),Parametros!$B$14>=1),"",P11/(1-Parametros!$B$14)) | V11: =IF(OR(NOT(ISNUMBER(P11)),Parametros!$B$14+Parametros!$B$18>=1),"",P11/(1-Parametros!$B$14-Parametros!$B$18)) | W11: =IF(B11="","",IF(E11="","SIN RECETA",IF(NOT(ISNUMBER(P11)),"FALTAN DATOS",IF(NOT(ISNUMBER(I11)),"FALTA PRECIO",IF(S11<0,"PIERDE",IF(T11<Parametros!$B$18,"BAJO META","OK")))))) -> FALTAN DATOS | X11: =IF(B11="","",IF(E11="","Elegir receta (molde). ",IF(ISNA(MATCH(E11,Recetas!$A$5:$A$84,0)),"La receta no existe. ",IF(IFERROR(INDEX(Recetas!$T$5:$T$84,MATCH($E11,Recetas!$A$5:$A$84,0))="Lista",FALSE()),"","Receta "&E11&": "&INDEX(Recetas!$T$5:$T$84,MATCH($E11,Recetas!$A$5:$A$84,0)))))&IF(F11="","Elegir tela. ",IF(IFERROR(INDEX(Precios!$F$5:$F$120,MATCH(F11,Precios!$A$5:$A$120,0)),"")="","Tela sin $/metro (falta rendimiento o precio). ",""))&IF(AND(E11<>"",N(IFERROR(INDEX(Recetas!$S$5:$S$84,MATCH($E11,Recetas!$A$5:$A$84,0)),0))>0,G11=""),"Elegir tela 2. ","")&IF(NOT(ISNUMBER(I11)),"Precio de venta.","")) -> Receta 06 · FUTHOMV01: Consumo de tela. Metros impresos. Elegir tela. | Y11: =IF(AND(ISNUMBER(P11),ISNUMBER(I11),ISNUMBER(D11)),P11*D11,0) -> 0 | Z11: =IF(AND(ISNUMBER(P11),ISNUMBER(I11),ISNUMBER(D11)),I11*D11,0) -> 0 | AA11: =IF(AND(ISNUMBER(P11),ISNUMBER(I11),ISNUMBER(D11)),D11,0) -> 0
A12: SALPOLPRESLISA | B12: Polera de Presentación Lisa | C12: Salida | D12: 109 | I12: 17004 | J12: Por confirmar | K12: Sin receta: elige el molde que usa (o crea su receta en "Recetas") y la tela. | L12: =IF(OR(B12="",E12=""),"",IFERROR(INDEX(Recetas!$R$5:$R$84,MATCH($E12,Recetas!$A$5:$A$84,0))*IFERROR(INDEX(Precios!$F$5:$F$120,MATCH(F12,Precios!$A$5:$A$120,0)),"")+IF(N(INDEX(Recetas!$S$5:$S$84,MATCH($E12,Recetas!$A$5:$A$84,0)))=0,0,INDEX(Recetas!$S$5:$S$84,MATCH($E12,Recetas!$A$5:$A$84,0))*IFERROR(INDEX(Precios!$F$5:$F$120,MATCH(G12,Precios!$A$5:$A$120,0)),"")),"")) | M12: =IF(OR(B12="",E12=""),"",IFERROR(N(INDEX(Recetas!$L$5:$L$84,MATCH($E12,Recetas!$A$5:$A$84,0)))*Parametros!$B$27,"")) | N12: =IF(OR(B12="",E12=""),"",IFERROR(INDEX(Confeccion!$B$5:$B$100,MATCH(INDEX(Recetas!$M$5:$M$84,MATCH($E12,Recetas!$A$5:$A$84,0)),Confeccion!$A$5:$A$100,0)),"")) | O12: =IF(OR(B12="",E12=""),"",IFERROR(N(INDEX(Recetas!$O$5:$O$84,MATCH($E12,Recetas!$A$5:$A$84,0)))*INDEX(Precios!$D$5:$D$120,MATCH(INDEX(Recetas!$N$5:$N$84,MATCH($E12,Recetas!$A$5:$A$84,0)),Precios!$A$5:$A$120,0)),0)) | P12: =IF(OR(B12="",E12=""),"",IF(AND(IFERROR(INDEX(Recetas!$T$5:$T$84,MATCH($E12,Recetas!$A$5:$A$84,0))="Lista",FALSE()),ISNUMBER(L12),ISNUMBER(M12),ISNUMBER(N12),N(N12)>0),L12+M12+N12+N(O12)+N(H12),"")) | Q12: =IF(AND(ISNUMBER(P12),ISNUMBER(I12)),I12*Parametros!$B$12,"") | R12: =IF(AND(ISNUMBER(P12),ISNUMBER(I12)),I12*Parametros!$B$13,"") | S12: =IF(AND(ISNUMBER(P12),ISNUMBER(I12)),I12-P12-Q12-R12,"") | T12: =IF(AND(ISNUMBER(P12),ISNUMBER(I12)),S12/I12,"") | U12: =IF(OR(NOT(ISNUMBER(P12)),Parametros!$B$14>=1),"",P12/(1-Parametros!$B$14)) | V12: =IF(OR(NOT(ISNUMBER(P12)),Parametros!$B$14+Parametros!$B$18>=1),"",P12/(1-Parametros!$B$14-Parametros!$B$18)) | W12: =IF(B12="","",IF(E12="","SIN RECETA",IF(NOT(ISNUMBER(P12)),"FALTAN DATOS",IF(NOT(ISNUMBER(I12)),"FALTA PRECIO",IF(S12<0,"PIERDE",IF(T12<Parametros!$B$18,"BAJO META","OK")))))) -> SIN RECETA | X12: =IF(B12="","",IF(E12="","Elegir receta (molde). ",IF(ISNA(MATCH(E12,Recetas!$A$5:$A$84,0)),"La receta no existe. ",IF(IFERROR(INDEX(Recetas!$T$5:$T$84,MATCH($E12,Recetas!$A$5:$A$84,0))="Lista",FALSE()),"","Receta "&E12&": "&INDEX(Recetas!$T$5:$T$84,MATCH($E12,Recetas!$A$5:$A$84,0)))))&IF(F12="","Elegir tela. ",IF(IFERROR(INDEX(Precios!$F$5:$F$120,MATCH(F12,Precios!$A$5:$A$120,0)),"")="","Tela sin $/metro (falta rendimiento o precio). ",""))&IF(AND(E12<>"",N(IFERROR(INDEX(Recetas!$S$5:$S$84,MATCH($E12,Recetas!$A$5:$A$84,0)),0))>0,G12=""),"Elegir tela 2. ","")&IF(NOT(ISNUMBER(I12)),"Precio de venta.","")) -> Elegir receta (molde). Elegir tela. | Y12: =IF(AND(ISNUMBER(P12),ISNUMBER(I12),ISNUMBER(D12)),P12*D12,0) -> 0 | Z12: =IF(AND(ISNUMBER(P12),ISNUMBER(I12),ISNUMBER(D12)),I12*D12,0) -> 0 | AA12: =IF(AND(ISNUMBER(P12),ISNUMBER(I12),ISNUMBER(D12)),D12,0) -> 0
A13: CSUBRUGSFROSA | B13: CAMISETA DE RUGBY STADE FRANCAIS ANIVERSARIO (ROSADA) | C13: Juego | D13: 100 | I13: 25714 | J13: Por confirmar | K13: Sin receta: elige el molde que usa (o crea su receta en "Recetas") y la tela. | L13: =IF(OR(B13="",E13=""),"",IFERROR(INDEX(Recetas!$R$5:$R$84,MATCH($E13,Recetas!$A$5:$A$84,0))*IFERROR(INDEX(Precios!$F$5:$F$120,MATCH(F13,Precios!$A$5:$A$120,0)),"")+IF(N(INDEX(Recetas!$S$5:$S$84,MATCH($E13,Recetas!$A$5:$A$84,0)))=0,0,INDEX(Recetas!$S$5:$S$84,MATCH($E13,Recetas!$A$5:$A$84,0))*IFERROR(INDEX(Precios!$F$5:$F$120,MATCH(G13,Precios!$A$5:$A$120,0)),"")),"")) | M13: =IF(OR(B13="",E13=""),"",IFERROR(N(INDEX(Recetas!$L$5:$L$84,MATCH($E13,Recetas!$A$5:$A$84,0)))*Parametros!$B$27,"")) | N13: =IF(OR(B13="",E13=""),"",IFERROR(INDEX(Confeccion!$B$5:$B$100,MATCH(INDEX(Recetas!$M$5:$M$84,MATCH($E13,Recetas!$A$5:$A$84,0)),Confeccion!$A$5:$A$100,0)),"")) | O13: =IF(OR(B13="",E13=""),"",IFERROR(N(INDEX(Recetas!$O$5:$O$84,MATCH($E13,Recetas!$A$5:$A$84,0)))*INDEX(Precios!$D$5:$D$120,MATCH(INDEX(Recetas!$N$5:$N$84,MATCH($E13,Recetas!$A$5:$A$84,0)),Precios!$A$5:$A$120,0)),0)) | P13: =IF(OR(B13="",E13=""),"",IF(AND(IFERROR(INDEX(Recetas!$T$5:$T$84,MATCH($E13,Recetas!$A$5:$A$84,0))="Lista",FALSE()),ISNUMBER(L13),ISNUMBER(M13),ISNUMBER(N13),N(N13)>0),L13+M13+N13+N(O13)+N(H13),"")) | Q13: =IF(AND(ISNUMBER(P13),ISNUMBER(I13)),I13*Parametros!$B$12,"") | R13: =IF(AND(ISNUMBER(P13),ISNUMBER(I13)),I13*Parametros!$B$13,"") | S13: =IF(AND(ISNUMBER(P13),ISNUMBER(I13)),I13-P13-Q13-R13,"") | T13: =IF(AND(ISNUMBER(P13),ISNUMBER(I13)),S13/I13,"") | U13: =IF(OR(NOT(ISNUMBER(P13)),Parametros!$B$14>=1),"",P13/(1-Parametros!$B$14)) | V13: =IF(OR(NOT(ISNUMBER(P13)),Parametros!$B$14+Parametros!$B$18>=1),"",P13/(1-Parametros!$B$14-Parametros!$B$18)) | W13: =IF(B13="","",IF(E13="","SIN RECETA",IF(NOT(ISNUMBER(P13)),"FALTAN DATOS",IF(NOT(ISNUMBER(I13)),"FALTA PRECIO",IF(S13<0,"PIERDE",IF(T13<Parametros!$B$18,"BAJO META","OK")))))) -> SIN RECETA | X13: =IF(B13="","",IF(E13="","Elegir receta (molde). ",IF(ISNA(MATCH(E13,Recetas!$A$5:$A$84,0)),"La receta no existe. ",IF(IFERROR(INDEX(Recetas!$T$5:$T$84,MATCH($E13,Recetas!$A$5:$A$84,0))="Lista",FALSE()),"","Receta "&E13&": "&INDEX(Recetas!$T$5:$T$84,MATCH($E13,Recetas!$A$5:$A$84,0)))))&IF(F13="","Elegir tela. ",IF(IFERROR(INDEX(Precios!$F$5:$F$120,MATCH(F13,Precios!$A$5:$A$120,0)),"")="","Tela sin $/metro (falta rendimiento o precio). ",""))&IF(AND(E13<>"",N(IFERROR(INDEX(Recetas!$S$5:$S$84,MATCH($E13,Recetas!$A$5:$A$84,0)),0))>0,G13=""),"Elegir tela 2. ","")&IF(NOT(ISNUMBER(I13)),"Precio de venta.","")) -> Elegir receta (molde). Elegir tela. | Y13: =IF(AND(ISNUMBER(P13),ISNUMBER(I13),ISNUMBER(D13)),P13*D13,0) -> 0 | Z13: =IF(AND(ISNUMBER(P13),ISNUMBER(I13),ISNUMBER(D13)),I13*D13,0) -> 0 | AA13: =IF(AND(ISNUMBER(P13),ISNUMBER(I13),ISNUMBER(D13)),D13,0) -> 0
A14: SAL-PLA-SUB-MC | B14: Polera de presentación Sublim m/c | C14: Salida | D14: 99 | I14: 18729 | J14: Por confirmar | K14: Sin receta: elige el molde que usa (o crea su receta en "Recetas") y la tela. | L14: =IF(OR(B14="",E14=""),"",IFERROR(INDEX(Recetas!$R$5:$R$84,MATCH($E14,Recetas!$A$5:$A$84,0))*IFERROR(INDEX(Precios!$F$5:$F$120,MATCH(F14,Precios!$A$5:$A$120,0)),"")+IF(N(INDEX(Recetas!$S$5:$S$84,MATCH($E14,Recetas!$A$5:$A$84,0)))=0,0,INDEX(Recetas!$S$5:$S$84,MATCH($E14,Recetas!$A$5:$A$84,0))*IFERROR(INDEX(Precios!$F$5:$F$120,MATCH(G14,Precios!$A$5:$A$120,0)),"")),"")) | M14: =IF(OR(B14="",E14=""),"",IFERROR(N(INDEX(Recetas!$L$5:$L$84,MATCH($E14,Recetas!$A$5:$A$84,0)))*Parametros!$B$27,"")) | N14: =IF(OR(B14="",E14=""),"",IFERROR(INDEX(Confeccion!$B$5:$B$100,MATCH(INDEX(Recetas!$M$5:$M$84,MATCH($E14,Recetas!$A$5:$A$84,0)),Confeccion!$A$5:$A$100,0)),"")) | O14: =IF(OR(B14="",E14=""),"",IFERROR(N(INDEX(Recetas!$O$5:$O$84,MATCH($E14,Recetas!$A$5:$A$84,0)))*INDEX(Precios!$D$5:$D$120,MATCH(INDEX(Recetas!$N$5:$N$84,MATCH($E14,Recetas!$A$5:$A$84,0)),Precios!$A$5:$A$120,0)),0)) | P14: =IF(OR(B14="",E14=""),"",IF(AND(IFERROR(INDEX(Recetas!$T$5:$T$84,MATCH($E14,Recetas!$A$5:$A$84,0))="Lista",FALSE()),ISNUMBER(L14),ISNUMBER(M14),ISNUMBER(N14),N(N14)>0),L14+M14+N14+N(O14)+N(H14),"")) | Q14: =IF(AND(ISNUMBER(P14),ISNUMBER(I14)),I14*Parametros!$B$12,"") | R14: =IF(AND(ISNUMBER(P14),ISNUMBER(I14)),I14*Parametros!$B$13,"") | S14: =IF(AND(ISNUMBER(P14),ISNUMBER(I14)),I14-P14-Q14-R14,"") | T14: =IF(AND(ISNUMBER(P14),ISNUMBER(I14)),S14/I14,"") | U14: =IF(OR(NOT(ISNUMBER(P14)),Parametros!$B$14>=1),"",P14/(1-Parametros!$B$14)) | V14: =IF(OR(NOT(ISNUMBER(P14)),Parametros!$B$14+Parametros!$B$18>=1),"",P14/(1-Parametros!$B$14-Parametros!$B$18)) | W14: =IF(B14="","",IF(E14="","SIN RECETA",IF(NOT(ISNUMBER(P14)),"FALTAN DATOS",IF(NOT(ISNUMBER(I14)),"FALTA PRECIO",IF(S14<0,"PIERDE",IF(T14<Parametros!$B$18,"BAJO META","OK")))))) -> SIN RECETA | X14: =IF(B14="","",IF(E14="","Elegir receta (molde). ",IF(ISNA(MATCH(E14,Recetas!$A$5:$A$84,0)),"La receta no existe. ",IF(IFERROR(INDEX(Recetas!$T$5:$T$84,MATCH($E14,Recetas!$A$5:$A$84,0))="Lista",FALSE()),"","Receta "&E14&": "&INDEX(Recetas!$T$5:$T$84,MATCH($E14,Recetas!$A$5:$A$84,0)))))&IF(F14="","Elegir tela. ",IF(IFERROR(INDEX(Precios!$F$5:$F$120,MATCH(F14,Precios!$A$5:$A$120,0)),"")="","Tela sin $/metro (falta rendimiento o precio). ",""))&IF(AND(E14<>"",N(IFERROR(INDEX(Recetas!$S$5:$S$84,MATCH($E14,Recetas!$A$5:$A$84,0)),0))>0,G14=""),"Elegir tela 2. ","")&IF(NOT(ISNUMBER(I14)),"Precio de venta.","")) -> Elegir receta (molde). Elegir tela. | Y14: =IF(AND(ISNUMBER(P14),ISNUMBER(I14),ISNUMBER(D14)),P14*D14,0) -> 0 | Z14: =IF(AND(ISNUMBER(P14),ISNUMBER(I14),ISNUMBER(D14)),I14*D14,0) -> 0 | AA14: =IF(AND(ISNUMBER(P14),ISNUMBER(I14),ISNUMBER(D14)),D14,0) -> 0
A15: POL-CSUB-POL-MC | B15: Polera Playmaker, Cuello Redondo m/c | C15: Juego | D15: 96 | I15: 15588 | J15: Por confirmar | K15: Sin receta: elige el molde que usa (o crea su receta en "Recetas") y la tela. | L15: =IF(OR(B15="",E15=""),"",IFERROR(INDEX(Recetas!$R$5:$R$84,MATCH($E15,Recetas!$A$5:$A$84,0))*IFERROR(INDEX(Precios!$F$5:$F$120,MATCH(F15,Precios!$A$5:$A$120,0)),"")+IF(N(INDEX(Recetas!$S$5:$S$84,MATCH($E15,Recetas!$A$5:$A$84,0)))=0,0,INDEX(Recetas!$S$5:$S$84,MATCH($E15,Recetas!$A$5:$A$84,0))*IFERROR(INDEX(Precios!$F$5:$F$120,MATCH(G15,Precios!$A$5:$A$120,0)),"")),"")) | M15: =IF(OR(B15="",E15=""),"",IFERROR(N(INDEX(Recetas!$L$5:$L$84,MATCH($E15,Recetas!$A$5:$A$84,0)))*Parametros!$B$27,"")) | N15: =IF(OR(B15="",E15=""),"",IFERROR(INDEX(Confeccion!$B$5:$B$100,MATCH(INDEX(Recetas!$M$5:$M$84,MATCH($E15,Recetas!$A$5:$A$84,0)),Confeccion!$A$5:$A$100,0)),"")) | O15: =IF(OR(B15="",E15=""),"",IFERROR(N(INDEX(Recetas!$O$5:$O$84,MATCH($E15,Recetas!$A$5:$A$84,0)))*INDEX(Precios!$D$5:$D$120,MATCH(INDEX(Recetas!$N$5:$N$84,MATCH($E15,Recetas!$A$5:$A$84,0)),Precios!$A$5:$A$120,0)),0)) | P15: =IF(OR(B15="",E15=""),"",IF(AND(IFERROR(INDEX(Recetas!$T$5:$T$84,MATCH($E15,Recetas!$A$5:$A$84,0))="Lista",FALSE()),ISNUMBER(L15),ISNUMBER(M15),ISNUMBER(N15),N(N15)>0),L15+M15+N15+N(O15)+N(H15),"")) | Q15: =IF(AND(ISNUMBER(P15),ISNUMBER(I15)),I15*Parametros!$B$12,"") | R15: =IF(AND(ISNUMBER(P15),ISNUMBER(I15)),I15*Parametros!$B$13,"") | S15: =IF(AND(ISNUMBER(P15),ISNUMBER(I15)),I15-P15-Q15-R15,"") | T15: =IF(AND(ISNUMBER(P15),ISNUMBER(I15)),S15/I15,"") | U15: =IF(OR(NOT(ISNUMBER(P15)),Parametros!$B$14>=1),"",P15/(1-Parametros!$B$14)) | V15: =IF(OR(NOT(ISNUMBER(P15)),Parametros!$B$14+Parametros!$B$18>=1),"",P15/(1-Parametros!$B$14-Parametros!$B$18)) | W15: =IF(B15="","",IF(E15="","SIN RECETA",IF(NOT(ISNUMBER(P15)),"FALTAN DATOS",IF(NOT(ISNUMBER(I15)),"FALTA PRECIO",IF(S15<0,"PIERDE",IF(T15<Parametros!$B$18,"BAJO META","OK")))))) -> SIN RECETA | X15: =IF(B15="","",IF(E15="","Elegir receta (molde). ",IF(ISNA(MATCH(E15,Recetas!$A$5:$A$84,0)),"La receta no existe. ",IF(IFERROR(INDEX(Recetas!$T$5:$T$84,MATCH($E15,Recetas!$A$5:$A$84,0))="Lista",FALSE()),"","Receta "&E15&": "&INDEX(Recetas!$T$5:$T$84,MATCH($E15,Recetas!$A$5:$A$84,0)))))&IF(F15="","Elegir tela. ",IF(IFERROR(INDEX(Precios!$F$5:$F$120,MATCH(F15,Precios!$A$5:$A$120,0)),"")="","Tela sin $/metro (falta rendimiento o precio). ",""))&IF(AND(E15<>"",N(IFERROR(INDEX(Recetas!$S$5:$S$84,MATCH($E15,Recetas!$A$5:$A$84,0)),0))>0,G15=""),"Elegir tela 2. ","")&IF(NOT(ISNUMBER(I15)),"Precio de venta.","")) -> Elegir receta (molde). Elegir tela. | Y15: =IF(AND(ISNUMBER(P15),ISNUMBER(I15),ISNUMBER(D15)),P15*D15,0) -> 0 | Z15: =IF(AND(ISNUMBER(P15),ISNUMBER(I15),ISNUMBER(D15)),I15*D15,0) -> 0 | AA15: =IF(AND(ISNUMBER(P15),ISNUMBER(I15),ISNUMBER(D15)),D15,0) -> 0
A16: RUGCSUBPRO | B16: Camiseta Rugby Pro Pmk | C16: Juego | D16: 93 | I16: 21765 | J16: Por confirmar | K16: Sin receta: elige el molde que usa (o crea su receta en "Recetas") y la tela. | L16: =IF(OR(B16="",E16=""),"",IFERROR(INDEX(Recetas!$R$5:$R$84,MATCH($E16,Recetas!$A$5:$A$84,0))*IFERROR(INDEX(Precios!$F$5:$F$120,MATCH(F16,Precios!$A$5:$A$120,0)),"")+IF(N(INDEX(Recetas!$S$5:$S$84,MATCH($E16,Recetas!$A$5:$A$84,0)))=0,0,INDEX(Recetas!$S$5:$S$84,MATCH($E16,Recetas!$A$5:$A$84,0))*IFERROR(INDEX(Precios!$F$5:$F$120,MATCH(G16,Precios!$A$5:$A$120,0)),"")),"")) | M16: =IF(OR(B16="",E16=""),"",IFERROR(N(INDEX(Recetas!$L$5:$L$84,MATCH($E16,Recetas!$A$5:$A$84,0)))*Parametros!$B$27,"")) | N16: =IF(OR(B16="",E16=""),"",IFERROR(INDEX(Confeccion!$B$5:$B$100,MATCH(INDEX(Recetas!$M$5:$M$84,MATCH($E16,Recetas!$A$5:$A$84,0)),Confeccion!$A$5:$A$100,0)),"")) | O16: =IF(OR(B16="",E16=""),"",IFERROR(N(INDEX(Recetas!$O$5:$O$84,MATCH($E16,Recetas!$A$5:$A$84,0)))*INDEX(Precios!$D$5:$D$120,MATCH(INDEX(Recetas!$N$5:$N$84,MATCH($E16,Recetas!$A$5:$A$84,0)),Precios!$A$5:$A$120,0)),0)) | P16: =IF(OR(B16="",E16=""),"",IF(AND(IFERROR(INDEX(Recetas!$T$5:$T$84,MATCH($E16,Recetas!$A$5:$A$84,0))="Lista",FALSE()),ISNUMBER(L16),ISNUMBER(M16),ISNUMBER(N16),N(N16)>0),L16+M16+N16+N(O16)+N(H16),"")) | Q16: =IF(AND(ISNUMBER(P16),ISNUMBER(I16)),I16*Parametros!$B$12,"") | R16: =IF(AND(ISNUMBER(P16),ISNUMBER(I16)),I16*Parametros!$B$13,"") | S16: =IF(AND(ISNUMBER(P16),ISNUMBER(I16)),I16-P16-Q16-R16,"") | T16: =IF(AND(ISNUMBER(P16),ISNUMBER(I16)),S16/I16,"") | U16: =IF(OR(NOT(ISNUMBER(P16)),Parametros!$B$14>=1),"",P16/(1-Parametros!$B$14)) | V16: =IF(OR(NOT(ISNUMBER(P16)),Parametros!$B$14+Parametros!$B$18>=1),"",P16/(1-Parametros!$B$14-Parametros!$B$18)) | W16: =IF(B16="","",IF(E16="","SIN RECETA",IF(NOT(ISNUMBER(P16)),"FALTAN DATOS",IF(NOT(ISNUMBER(I16)),"FALTA PRECIO",IF(S16<0,"PIERDE",IF(T16<Parametros!$B$18,"BAJO META","OK")))))) -> SIN RECETA | X16: =IF(B16="","",IF(E16="","Elegir receta (molde). ",IF(ISNA(MATCH(E16,Recetas!$A$5:$A$84,0)),"La receta no existe. ",IF(IFERROR(INDEX(Recetas!$T$5:$T$84,MATCH($E16,Recetas!$A$5:$A$84,0))="Lista",FALSE()),"","Receta "&E16&": "&INDEX(Recetas!$T$5:$T$84,MATCH($E16,Recetas!$A$5:$A$84,0)))))&IF(F16="","Elegir tela. ",IF(IFERROR(INDEX(Precios!$F$5:$F$120,MATCH(F16,Precios!$A$5:$A$120,0)),"")="","Tela sin $/metro (falta rendimiento o precio). ",""))&IF(AND(E16<>"",N(IFERROR(INDEX(Recetas!$S$5:$S$84,MATCH($E16,Recetas!$A$5:$A$84,0)),0))>0,G16=""),"Elegir tela 2. ","")&IF(NOT(ISNUMBER(I16)),"Precio de venta.","")) -> Elegir receta (molde). Elegir tela. | Y16: =IF(AND(ISNUMBER(P16),ISNUMBER(I16),ISNUMBER(D16)),P16*D16,0) -> 0 | Z16: =IF(AND(ISNUMBER(P16),ISNUMBER(I16),ISNUMBER(D16)),I16*D16,0) -> 0 | AA16: =IF(AND(ISNUMBER(P16),ISNUMBER(I16),ISNUMBER(D16)),D16,0) -> 0
A17: MDBZCOMENTPITSUB | B17: Conjunto Polerón de Entrenamiento + Buzo Pitillo Subl | C17: Salida | D17: 76 | I17: 44010 | J17: Por confirmar | K17: Sin receta: elige el molde que usa (o crea su receta en "Recetas") y la tela. | L17: =IF(OR(B17="",E17=""),"",IFERROR(INDEX(Recetas!$R$5:$R$84,MATCH($E17,Recetas!$A$5:$A$84,0))*IFERROR(INDEX(Precios!$F$5:$F$120,MATCH(F17,Precios!$A$5:$A$120,0)),"")+IF(N(INDEX(Recetas!$S$5:$S$84,MATCH($E17,Recetas!$A$5:$A$84,0)))=0,0,INDEX(Recetas!$S$5:$S$84,MATCH($E17,Recetas!$A$5:$A$84,0))*IFERROR(INDEX(Precios!$F$5:$F$120,MATCH(G17,Precios!$A$5:$A$120,0)),"")),"")) | M17: =IF(OR(B17="",E17=""),"",IFERROR(N(INDEX(Recetas!$L$5:$L$84,MATCH($E17,Recetas!$A$5:$A$84,0)))*Parametros!$B$27,"")) | N17: =IF(OR(B17="",E17=""),"",IFERROR(INDEX(Confeccion!$B$5:$B$100,MATCH(INDEX(Recetas!$M$5:$M$84,MATCH($E17,Recetas!$A$5:$A$84,0)),Confeccion!$A$5:$A$100,0)),"")) | O17: =IF(OR(B17="",E17=""),"",IFERROR(N(INDEX(Recetas!$O$5:$O$84,MATCH($E17,Recetas!$A$5:$A$84,0)))*INDEX(Precios!$D$5:$D$120,MATCH(INDEX(Recetas!$N$5:$N$84,MATCH($E17,Recetas!$A$5:$A$84,0)),Precios!$A$5:$A$120,0)),0)) | P17: =IF(OR(B17="",E17=""),"",IF(AND(IFERROR(INDEX(Recetas!$T$5:$T$84,MATCH($E17,Recetas!$A$5:$A$84,0))="Lista",FALSE()),ISNUMBER(L17),ISNUMBER(M17),ISNUMBER(N17),N(N17)>0),L17+M17+N17+N(O17)+N(H17),"")) | Q17: =IF(AND(ISNUMBER(P17),ISNUMBER(I17)),I17*Parametros!$B$12,"") | R17: =IF(AND(ISNUMBER(P17),ISNUMBER(I17)),I17*Parametros!$B$13,"") | S17: =IF(AND(ISNUMBER(P17),ISNUMBER(I17)),I17-P17-Q17-R17,"") | T17: =IF(AND(ISNUMBER(P17),ISNUMBER(I17)),S17/I17,"") | U17: =IF(OR(NOT(ISNUMBER(P17)),Parametros!$B$14>=1),"",P17/(1-Parametros!$B$14)) | V17: =IF(OR(NOT(ISNUMBER(P17)),Parametros!$B$14+Parametros!$B$18>=1),"",P17/(1-Parametros!$B$14-Parametros!$B$18)) | W17: =IF(B17="","",IF(E17="","SIN RECETA",IF(NOT(ISNUMBER(P17)),"FALTAN DATOS",IF(NOT(ISNUMBER(I17)),"FALTA PRECIO",IF(S17<0,"PIERDE",IF(T17<Parametros!$B$18,"BAJO META","OK")))))) -> SIN RECETA | X17: =IF(B17="","",IF(E17="","Elegir receta (molde). ",IF(ISNA(MATCH(E17,Recetas!$A$5:$A$84,0)),"La receta no existe. ",IF(IFERROR(INDEX(Recetas!$T$5:$T$84,MATCH($E17,Recetas!$A$5:$A$84,0))="Lista",FALSE()),"","Receta "&E17&": "&INDEX(Recetas!$T$5:$T$84,MATCH($E17,Recetas!$A$5:$A$84,0)))))&IF(F17="","Elegir tela. ",IF(IFERROR(INDEX(Precios!$F$5:$F$120,MATCH(F17,Precios!$A$5:$A$120,0)),"")="","Tela sin $/metro (falta rendimiento o precio). ",""))&IF(AND(E17<>"",N(IFERROR(INDEX(Recetas!$S$5:$S$84,MATCH($E17,Recetas!$A$5:$A$84,0)),0))>0,G17=""),"Elegir tela 2. ","")&IF(NOT(ISNUMBER(I17)),"Precio de venta.","")) -> Elegir receta (molde). Elegir tela. | Y17: =IF(AND(ISNUMBER(P17),ISNUMBER(I17),ISNUMBER(D17)),P17*D17,0) -> 0 | Z17: =IF(AND(ISNUMBER(P17),ISNUMBER(I17),ISNUMBER(D17)),I17*D17,0) -> 0 | AA17: =IF(AND(ISNUMBER(P17),ISNUMBER(I17),ISNUMBER(D17)),D17,0) -> 0
A18: FUTCSUBPROPIQMC | B18: Camiseta Fútbol Pro Playmaker, Piqué m/c | C18: Juego | D18: 66 | I18: 21554 | J18: Por confirmar | K18: Sin receta: elige el molde que usa (o crea su receta en "Recetas") y la tela. | L18: =IF(OR(B18="",E18=""),"",IFERROR(INDEX(Recetas!$R$5:$R$84,MATCH($E18,Recetas!$A$5:$A$84,0))*IFERROR(INDEX(Precios!$F$5:$F$120,MATCH(F18,Precios!$A$5:$A$120,0)),"")+IF(N(INDEX(Recetas!$S$5:$S$84,MATCH($E18,Recetas!$A$5:$A$84,0)))=0,0,INDEX(Recetas!$S$5:$S$84,MATCH($E18,Recetas!$A$5:$A$84,0))*IFERROR(INDEX(Precios!$F$5:$F$120,MATCH(G18,Precios!$A$5:$A$120,0)),"")),"")) | M18: =IF(OR(B18="",E18=""),"",IFERROR(N(INDEX(Recetas!$L$5:$L$84,MATCH($E18,Recetas!$A$5:$A$84,0)))*Parametros!$B$27,"")) | N18: =IF(OR(B18="",E18=""),"",IFERROR(INDEX(Confeccion!$B$5:$B$100,MATCH(INDEX(Recetas!$M$5:$M$84,MATCH($E18,Recetas!$A$5:$A$84,0)),Confeccion!$A$5:$A$100,0)),"")) | O18: =IF(OR(B18="",E18=""),"",IFERROR(N(INDEX(Recetas!$O$5:$O$84,MATCH($E18,Recetas!$A$5:$A$84,0)))*INDEX(Precios!$D$5:$D$120,MATCH(INDEX(Recetas!$N$5:$N$84,MATCH($E18,Recetas!$A$5:$A$84,0)),Precios!$A$5:$A$120,0)),0)) | P18: =IF(OR(B18="",E18=""),"",IF(AND(IFERROR(INDEX(Recetas!$T$5:$T$84,MATCH($E18,Recetas!$A$5:$A$84,0))="Lista",FALSE()),ISNUMBER(L18),ISNUMBER(M18),ISNUMBER(N18),N(N18)>0),L18+M18+N18+N(O18)+N(H18),"")) | Q18: =IF(AND(ISNUMBER(P18),ISNUMBER(I18)),I18*Parametros!$B$12,"") | R18: =IF(AND(ISNUMBER(P18),ISNUMBER(I18)),I18*Parametros!$B$13,"") | S18: =IF(AND(ISNUMBER(P18),ISNUMBER(I18)),I18-P18-Q18-R18,"") | T18: =IF(AND(ISNUMBER(P18),ISNUMBER(I18)),S18/I18,"") | U18: =IF(OR(NOT(ISNUMBER(P18)),Parametros!$B$14>=1),"",P18/(1-Parametros!$B$14)) | V18: =IF(OR(NOT(ISNUMBER(P18)),Parametros!$B$14+Parametros!$B$18>=1),"",P18/(1-Parametros!$B$14-Parametros!$B$18)) | W18: =IF(B18="","",IF(E18="","SIN RECETA",IF(NOT(ISNUMBER(P18)),"FALTAN DATOS",IF(NOT(ISNUMBER(I18)),"FALTA PRECIO",IF(S18<0,"PIERDE",IF(T18<Parametros!$B$18,"BAJO META","OK")))))) -> SIN RECETA | X18: =IF(B18="","",IF(E18="","Elegir receta (molde). ",IF(ISNA(MATCH(E18,Recetas!$A$5:$A$84,0)),"La receta no existe. ",IF(IFERROR(INDEX(Recetas!$T$5:$T$84,MATCH($E18,Recetas!$A$5:$A$84,0))="Lista",FALSE()),"","Receta "&E18&": "&INDEX(Recetas!$T$5:$T$84,MATCH($E18,Recetas!$A$5:$A$84,0)))))&IF(F18="","Elegir tela. ",IF(IFERROR(INDEX(Precios!$F$5:$F$120,MATCH(F18,Precios!$A$5:$A$120,0)),"")="","Tela sin $/metro (falta rendimiento o precio). ",""))&IF(AND(E18<>"",N(IFERROR(INDEX(Recetas!$S$5:$S$84,MATCH($E18,Recetas!$A$5:$A$84,0)),0))>0,G18=""),"Elegir tela 2. ","")&IF(NOT(ISNUMBER(I18)),"Precio de venta.","")) -> Elegir receta (molde). Elegir tela. | Y18: =IF(AND(ISNUMBER(P18),ISNUMBER(I18),ISNUMBER(D18)),P18*D18,0) -> 0 | Z18: =IF(AND(ISNUMBER(P18),ISNUMBER(I18),ISNUMBER(D18)),I18*D18,0) -> 0 | AA18: =IF(AND(ISNUMBER(P18),ISNUMBER(I18),ISNUMBER(D18)),D18,0) -> 0
A19: RUNCSUBPROSM | B19: Camiseta Running Pro s/m | C19: Juego | D19: 65 | E19: SM-03 · Camiseta Running s/m | F19: 5K NACIONAL (running pro) | I19: 19244 | J19: Por confirmar | L19: =IF(OR(B19="",E19=""),"",IFERROR(INDEX(Recetas!$R$5:$R$84,MATCH($E19,Recetas!$A$5:$A$84,0))*IFERROR(INDEX(Precios!$F$5:$F$120,MATCH(F19,Precios!$A$5:$A$120,0)),"")+IF(N(INDEX(Recetas!$S$5:$S$84,MATCH($E19,Recetas!$A$5:$A$84,0)))=0,0,INDEX(Recetas!$S$5:$S$84,MATCH($E19,Recetas!$A$5:$A$84,0))*IFERROR(INDEX(Precios!$F$5:$F$120,MATCH(G19,Precios!$A$5:$A$120,0)),"")),"")) -> 348.008 | M19: =IF(OR(B19="",E19=""),"",IFERROR(N(INDEX(Recetas!$L$5:$L$84,MATCH($E19,Recetas!$A$5:$A$84,0)))*Parametros!$B$27,"")) -> 0 | N19: =IF(OR(B19="",E19=""),"",IFERROR(INDEX(Confeccion!$B$5:$B$100,MATCH(INDEX(Recetas!$M$5:$M$84,MATCH($E19,Recetas!$A$5:$A$84,0)),Confeccion!$A$5:$A$100,0)),"")) -> 1800 | O19: =IF(OR(B19="",E19=""),"",IFERROR(N(INDEX(Recetas!$O$5:$O$84,MATCH($E19,Recetas!$A$5:$A$84,0)))*INDEX(Precios!$D$5:$D$120,MATCH(INDEX(Recetas!$N$5:$N$84,MATCH($E19,Recetas!$A$5:$A$84,0)),Precios!$A$5:$A$120,0)),0)) -> 0 | P19: =IF(OR(B19="",E19=""),"",IF(AND(IFERROR(INDEX(Recetas!$T$5:$T$84,MATCH($E19,Recetas!$A$5:$A$84,0))="Lista",FALSE()),ISNUMBER(L19),ISNUMBER(M19),ISNUMBER(N19),N(N19)>0),L19+M19+N19+N(O19)+N(H19),"")) -> 2148.008 | Q19: =IF(AND(ISNUMBER(P19),ISNUMBER(I19)),I19*Parametros!$B$12,"") -> 6792.1033 | R19: =IF(AND(ISNUMBER(P19),ISNUMBER(I19)),I19*Parametros!$B$13,"") -> 2438.1464 | S19: =IF(AND(ISNUMBER(P19),ISNUMBER(I19)),I19-P19-Q19-R19,"") -> 7865.7424 | T19: =IF(AND(ISNUMBER(P19),ISNUMBER(I19)),S19/I19,"") -> 0.40873739 | U19: =IF(OR(NOT(ISNUMBER(P19)),Parametros!$B$14>=1),"",P19/(1-Parametros!$B$14)) -> 4127.9505 | V19: =IF(OR(NOT(ISNUMBER(P19)),Parametros!$B$14+Parametros!$B$18>=1),"",P19/(1-Parametros!$B$14-Parametros!$B$18)) -> 5109.9611 | W19: =IF(B19="","",IF(E19="","SIN RECETA",IF(NOT(ISNUMBER(P19)),"FALTAN DATOS",IF(NOT(ISNUMBER(I19)),"FALTA PRECIO",IF(S19<0,"PIERDE",IF(T19<Parametros!$B$18,"BAJO META","OK")))))) -> OK | X19: =IF(B19="","",IF(E19="","Elegir receta (molde). ",IF(ISNA(MATCH(E19,Recetas!$A$5:$A$84,0)),"La receta no existe. ",IF(IFERROR(INDEX(Recetas!$T$5:$T$84,MATCH($E19,Recetas!$A$5:$A$84,0))="Lista",FALSE()),"","Receta "&E19&": "&INDEX(Recetas!$T$5:$T$84,MATCH($E19,Recetas!$A$5:$A$84,0)))))&IF(F19="","Elegir tela. ",IF(IFERROR(INDEX(Precios!$F$5:$F$120,MATCH(F19,Precios!$A$5:$A$120,0)),"")="","Tela sin $/metro (falta rendimiento o precio). ",""))&IF(AND(E19<>"",N(IFERROR(INDEX(Recetas!$S$5:$S$84,MATCH($E19,Recetas!$A$5:$A$84,0)),0))>0,G19=""),"Elegir tela 2. ","")&IF(NOT(ISNUMBER(I19)),"Precio de venta.","")) | Y19: =IF(AND(ISNUMBER(P19),ISNUMBER(I19),ISNUMBER(D19)),P19*D19,0) -> 139620.52 | Z19: =IF(AND(ISNUMBER(P19),ISNUMBER(I19),ISNUMBER(D19)),I19*D19,0) -> 1250860 | AA19: =IF(AND(ISNUMBER(P19),ISNUMBER(I19),ISNUMBER(D19)),D19,0) -> 65
A20: SAL-CTV-SUB-SG | B20: CORTAVIENTO SUBLIMADO | C20: Salida | D20: 62 | I20: 36050 | J20: Por confirmar | K20: Sin receta: elige el molde que usa (o crea su receta en "Recetas") y la tela. | L20: =IF(OR(B20="",E20=""),"",IFERROR(INDEX(Recetas!$R$5:$R$84,MATCH($E20,Recetas!$A$5:$A$84,0))*IFERROR(INDEX(Precios!$F$5:$F$120,MATCH(F20,Precios!$A$5:$A$120,0)),"")+IF(N(INDEX(Recetas!$S$5:$S$84,MATCH($E20,Recetas!$A$5:$A$84,0)))=0,0,INDEX(Recetas!$S$5:$S$84,MATCH($E20,Recetas!$A$5:$A$84,0))*IFERROR(INDEX(Precios!$F$5:$F$120,MATCH(G20,Precios!$A$5:$A$120,0)),"")),"")) | M20: =IF(OR(B20="",E20=""),"",IFERROR(N(INDEX(Recetas!$L$5:$L$84,MATCH($E20,Recetas!$A$5:$A$84,0)))*Parametros!$B$27,"")) | N20: =IF(OR(B20="",E20=""),"",IFERROR(INDEX(Confeccion!$B$5:$B$100,MATCH(INDEX(Recetas!$M$5:$M$84,MATCH($E20,Recetas!$A$5:$A$84,0)),Confeccion!$A$5:$A$100,0)),"")) | O20: =IF(OR(B20="",E20=""),"",IFERROR(N(INDEX(Recetas!$O$5:$O$84,MATCH($E20,Recetas!$A$5:$A$84,0)))*INDEX(Precios!$D$5:$D$120,MATCH(INDEX(Recetas!$N$5:$N$84,MATCH($E20,Recetas!$A$5:$A$84,0)),Precios!$A$5:$A$120,0)),0)) | P20: =IF(OR(B20="",E20=""),"",IF(AND(IFERROR(INDEX(Recetas!$T$5:$T$84,MATCH($E20,Recetas!$A$5:$A$84,0))="Lista",FALSE()),ISNUMBER(L20),ISNUMBER(M20),ISNUMBER(N20),N(N20)>0),L20+M20+N20+N(O20)+N(H20),"")) | Q20: =IF(AND(ISNUMBER(P20),ISNUMBER(I20)),I20*Parametros!$B$12,"") | R20: =IF(AND(ISNUMBER(P20),ISNUMBER(I20)),I20*Parametros!$B$13,"") | S20: =IF(AND(ISNUMBER(P20),ISNUMBER(I20)),I20-P20-Q20-R20,"") | T20: =IF(AND(ISNUMBER(P20),ISNUMBER(I20)),S20/I20,"") | U20: =IF(OR(NOT(ISNUMBER(P20)),Parametros!$B$14>=1),"",P20/(1-Parametros!$B$14)) | V20: =IF(OR(NOT(ISNUMBER(P20)),Parametros!$B$14+Parametros!$B$18>=1),"",P20/(1-Parametros!$B$14-Parametros!$B$18)) | W20: =IF(B20="","",IF(E20="","SIN RECETA",IF(NOT(ISNUMBER(P20)),"FALTAN DATOS",IF(NOT(ISNUMBER(I20)),"FALTA PRECIO",IF(S20<0,"PIERDE",IF(T20<Parametros!$B$18,"BAJO META","OK")))))) -> SIN RECETA | X20: =IF(B20="","",IF(E20="","Elegir receta (molde). ",IF(ISNA(MATCH(E20,Recetas!$A$5:$A$84,0)),"La receta no existe. ",IF(IFERROR(INDEX(Recetas!$T$5:$T$84,MATCH($E20,Recetas!$A$5:$A$84,0))="Lista",FALSE()),"","Receta "&E20&": "&INDEX(Recetas!$T$5:$T$84,MATCH($E20,Recetas!$A$5:$A$84,0)))))&IF(F20="","Elegir tela. ",IF(IFERROR(INDEX(Precios!$F$5:$F$120,MATCH(F20,Precios!$A$5:$A$120,0)),"")="","Tela sin $/metro (falta rendimiento o precio). ",""))&IF(AND(E20<>"",N(IFERROR(INDEX(Recetas!$S$5:$S$84,MATCH($E20,Recetas!$A$5:$A$84,0)),0))>0,G20=""),"Elegir tela 2. ","")&IF(NOT(ISNUMBER(I20)),"Precio de venta.","")) -> Elegir receta (molde). Elegir tela. | Y20: =IF(AND(ISNUMBER(P20),ISNUMBER(I20),ISNUMBER(D20)),P20*D20,0) -> 0 | Z20: =IF(AND(ISNUMBER(P20),ISNUMBER(I20),ISNUMBER(D20)),I20*D20,0) -> 0 | AA20: =IF(AND(ISNUMBER(P20),ISNUMBER(I20),ISNUMBER(D20)),D20,0) -> 0
